
--Vine Tree Model
	L0 = {name = "lib_ecology:tree_default_leaves", param2 = 0, prob = 254}
	T0 = {name = "lib_ecology:tree_default_trunk", param2 = 0, prob = 254}
	V0 = {name = "lib_ecology:plant_vine_01", param2 = 0, prob = 254}
	V1 = {name = "lib_ecology:plant_vine_01", param2 = 1, prob = 254}
	V2 = {name = "lib_ecology:plant_vine_01", param2 = 2, prob = 254}
	V3 = {name = "lib_ecology:plant_vine_01", param2 = 3, prob = 254}
	--minetest.log(S("TREES - tree_schem_vinetree"))
	le_temp_schem = {
		size = {x = 7, y = 7, z = 7},
		data = {
			__, __, __, __, __, __, __,
			__, V2, __, __, __, __, __,
			__, V2, __, V2, __, __, __,
			__, V2, __, V2, __, __, __,
			__, V2, __, __, __, V2, __,
			__, V2, __, __, __, V2, __,
			__, __, __, __, __, __, __,

			__, __, __, __, __, __, __,
			__, __, __, __, V2, __, __,
			__, __, __, __, V2, __, __,
			__, L0, L0, L0, V2, L0, __,
			__, L0, L0, __, L0, L0, __,
			__, L0, L0, L0, L0, L0, __,
			__, __, __, __, __, __, __,

			__, __, __, __, __, __, V1,
			__, __, __, __, __, __, V1,
			__, __, __, __, __, __, V1,
			__, L0, T0, __, T0, L0, V1,
			V0, L0, L0, L0, L0, __, __,
			__, __, L0, L0, L0, L0, __,
			__, __, L0, L0, L0, __, __,

			__, __, __, T0, __, __, __,
			__, __, __, T0, __, __, __,
			V0, __, __, T0, __, __, __,
			V0, L0, __, L0, __, L0, __,
			V0, L0, L0, L0, L0, L0, __,
			__, L0, L0, L0, L0, L0, __,
			__, __, L0, L0, L0, __, __,

			__, __, __, __, __, __, __,
			__, __, __, __, __, __, V1,
			__, __, __, __, __, __, V1,
			__, L0, T0, __, T0, L0, V1,
			__, L0, L0, L0, L0, L0, V1,
			__, L0, L0, L0, L0, L0, __,
			__, __, __, L0, L0, __, __,

			__, __, __, __, __, __, __,
			V0, __, __, __, __, __, __,
			V0, __, __, __, V3, __, __,
			V0, L0, L0, L0, V3, L0, __,
			__, L0, L0, L0, L0, __, __,
			__, __, L0, L0, L0, L0, __,
			__, __, __, __, __, __, __,

			__, __, __, __, __, __, __,
			__, __, V3, __, __, __, __,
			__, __, V3, __, __, __, __,
			__, __, V3, V3, __, __, __,
			__, __, __, V3, V3, __, __,
			__, __, __, __, __, __, __,
			__, __, __, __, __, __, __,
		},
		yslice_prob = {
			{ypos = 0, prob = 127},
		}
	}
	lib_ecology.schematics.insert("tree_schem_vinetree", le_temp_schem)

