
--Wild Tree Model		-LegendOfMinetest
	--minetest.log(S("TREES - tree_schem_wildtree"))
	le_temp_schem = {
		size = {x = 5,y = 14,z = 7},
		data = {
			__, __, __, __, __,
			__, __, __, __, __,
			__, __, __, __, __,
			__, __, __, __, __,
			__, __, __, __, __,
			__, __, L0, __, __,
			__, L0, L0, L0, __,
			__, __, L0, __, __,
			__, __, __, __, __,
			__, __, __, __, __,
			__, __, __, __, __,
			__, __, __, __, __,
			__, __, __, __, __,
			__, __, __, __, __,
			__, __, __, __, __,
			
			__, __, __, __, __,
			__, __, __, __, __,
			__, __, __, __, __,
			__, __, __, __, __,
			__, L0, F0, L0, __,
			__, L0, T0, L0, __,
			__, L0, L0, L0, __,
			__, __, __, __, __,
			__, __, __, __, __,
			__, __, __, __, __,
			__, __, __, __, __,
			__, __, __, __, __,
			__, __, __, __, __,
			__, __, __, __, __,

			__, __, __, __, __,
			__, __, __, __, __,
			__, __, __, __, __,
			__, __, __, __, __,
			__, __, T0, __, __,
			__, L0, L0, L0, __,
			__, __, L0, __, __,
			__, __, __, __, __,
			__, L0, L0, L0, __,
			L0, L0, L0, __, __,
			__, L0, __, F0, __,
			__, __, L0, L0, L0,
			__, __, __, L0, __,
			__, __, T0, __, __,

			__, __, T0, __, __,
			__, __, T0, __, __,
			__, __, T0, __, __,
			__, __, T0, __, __,
			__, T0, T0, __, __,
			F0, T0, L0, __, __,
			__, T0, __, __, __,
			__, T0, L0, F0, __,
			L0, T0, T0, T0, L0,
			L0, T0, L0, T0, __,
			L0, L0, L0, T0, L0,
			__, __, L0, T0, L0,
			__, __, L0, L0, L0,
			__, __, __, __, __,

			__, __, __, __, __,
			__, __, __, __, __,
			__, __, __, __, __,
			__, __, __, __, __,
			__, __, __, __, __,
			__, __, __, __, __,
			__, T0, __, __, __,
			L0, L0, L0, __, __,
			__, L0, __, L0, __,
			L0, L0, L0, __, __,
			__, L0, __, L0, __,
			__, __, L0, L0, L0,
			__, __, __, L0, __,
			__, __, __, __, __,

			__, __, __, __, __,
			__, __, __, __, __,
			__, __, __, __, __,
			__, __, __, __, __,
			__, __, __, __, __,
			__, __, __, __, __,
			L0, T0, L0, __, __,
			F0, T0, L0, __, __,
			L0, L0, L0, __, __,
			__, __, __, __, __,
			__, __, __, __, __,
			__, __, __, __, __,
			__, __, __, __, __,
			__, __, __, __, __,

			__, __, __, __, __,
			__, __, __, __, __,
			__, __, __, __, __,
			__, __, __, __, __,
			__, __, __, __, __,
			__, __, __, __, __,
			__, L0, __, __, __,
			L0, L0, L0, __, __,
			__, L0, __, __, __,
			__, __, __, __, __,
			__, __, __, __, __,
			__, __, __, __, __,
			__, __, __, __, __
		},
		yslice_prob = {
			{ypos = 0,prob = 254},
			{ypos = 1,prob = 254},
			{ypos = 2,prob = 254},
			{ypos = 3,prob = 254},
			{ypos = 4,prob = 254},
			{ypos = 5,prob = 254},
			{ypos = 6,prob = 254},
			{ypos = 7,prob = 254},
			{ypos = 8,prob = 254},
			{ypos = 9,prob = 254},
			{ypos = 10,prob = 254},
			{ypos = 11,prob = 254},
			{ypos = 12,prob = 254},
			{ypos = 13,prob = 254}
		}
	}
	lib_ecology.schematics.insert("tree_schem_wildtree", le_temp_schem)

