


--Aspen 06
	local N = lib_ecology.N

	
	return {
		size = {x = 5,y = 14,z = 5},
		data = {
			N["_____"], N["_____"], N["_____"], N["_____"], N["_____"],
			N["_____"], N["_____"], N["_____"], N["_____"], N["_____"],
			N["_____"], N["_____"], N["_____"], N["_____"], N["_____"],
			N["_____"], N["_____"], N["_____"], N["_____"], N["_____"],
			N["_____"], N["_____"], N["_____"], N["_____"], N["_____"],
			N["_____"], N["_____"], N["_____"], N["_____"], N["_____"],
			N["_____"], N["_____"], N["_____"], N["_____"], N["_____"],
			N["L0m03"], N["L0m01"], N["L0m00"], N["L0m01"], N["L0m03"],
			N["_____"], N["_____"], N["_____"], N["_____"], N["_____"],
			N["L0m03"], N["L0m01"], N["L0m00"], N["L0m01"], N["L0m03"],
			N["_____"], N["_____"], N["_____"], N["_____"], N["_____"],
			N["L0m03"], N["L0m01"], N["L0m00"], N["L0m01"], N["L0m03"],
			N["_____"], N["_____"], N["_____"], N["_____"], N["_____"],
			N["_____"], N["_____"], N["_____"], N["_____"], N["_____"],
			
			N["_____"], N["_____"], N["_____"], N["_____"], N["_____"],
			N["_____"], N["_____"], N["_____"], N["_____"], N["_____"],
			N["_____"], N["_____"], N["_____"], N["_____"], N["_____"],
			N["_____"], N["_____"], N["_____"], N["_____"], N["_____"],
			N["_____"], N["_____"], N["_____"], N["_____"], N["_____"],
			N["_____"], N["_____"], N["_____"], N["_____"], N["_____"],
			N["_____"], N["L0m01"], N["L0m00"], N["L0m01"], N["_____"],
			N["L0m01"], N["L0m00"], N["L0m00"], N["L0m00"], N["L0m01"],
			N["_____"], N["L0m01"], N["L0m00"], N["L0m01"], N["_____"],
			N["L0m01"], N["L0m00"], N["L0m00"], N["L0m00"], N["L0m01"],
			N["_____"], N["L0m01"], N["L0m00"], N["L0m01"], N["_____"],
			N["L0m01"], N["L0m00"], N["L0m00"], N["L0m00"], N["L0m01"],
			N["_____"], N["L0m01"], N["L0m00"], N["L0m01"], N["_____"],
			N["_____"], N["_____"], N["_____"], N["_____"], N["_____"],
			
			N["_____"], N["_____"], N["T0m00"], N["_____"], N["_____"],
			N["_____"], N["_____"], N["T0m00"], N["_____"], N["_____"],
			N["_____"], N["_____"], N["T0m00"], N["_____"], N["_____"],
			N["_____"], N["_____"], N["T0m00"], N["_____"], N["_____"],
			N["_____"], N["_____"], N["T0m00"], N["_____"], N["_____"],
			N["_____"], N["_____"], N["T0m00"], N["_____"], N["_____"],
			N["_____"], N["L0m00"], N["T0m00"], N["L0m00"], N["_____"],
			N["L0m00"], N["L0m00"], N["T0m00"], N["L0m00"], N["L0m00"],
			N["_____"], N["L0m00"], N["T0m00"], N["L0m00"], N["_____"],
			N["L0m00"], N["L0m00"], N["T0m00"], N["L0m00"], N["L0m00"],
			N["_____"], N["L0m00"], N["T0m00"], N["L0m00"], N["_____"],
			N["L0m00"], N["L0m00"], N["T0m00"], N["L0m00"], N["L0m00"],
			N["_____"], N["L0m00"], N["L0m00"], N["L0m00"], N["_____"],
			N["_____"], N["_____"], N["L0m00"], N["_____"], N["_____"],
			
			N["_____"], N["_____"], N["_____"], N["_____"], N["_____"],
			N["_____"], N["_____"], N["_____"], N["_____"], N["_____"],
			N["_____"], N["_____"], N["_____"], N["_____"], N["_____"],
			N["_____"], N["_____"], N["_____"], N["_____"], N["_____"],
			N["_____"], N["_____"], N["_____"], N["_____"], N["_____"],
			N["_____"], N["_____"], N["_____"], N["_____"], N["_____"],
			N["_____"], N["L0m01"], N["L0m00"], N["L0m01"], N["_____"],
			N["L0m01"], N["L0m00"], N["L0m00"], N["L0m00"], N["L0m01"],
			N["_____"], N["L0m01"], N["L0m00"], N["L0m01"], N["_____"],
			N["L0m01"], N["L0m00"], N["L0m00"], N["L0m00"], N["L0m01"],
			N["_____"], N["L0m01"], N["L0m00"], N["L0m01"], N["_____"],
			N["L0m01"], N["L0m00"], N["L0m00"], N["L0m00"], N["L0m01"],
			N["_____"], N["L0m01"], N["L0m00"], N["L0m01"], N["_____"],
			N["_____"], N["_____"], N["_____"], N["_____"], N["_____"],
			
			N["_____"], N["_____"], N["_____"], N["_____"], N["_____"],
			N["_____"], N["_____"], N["_____"], N["_____"], N["_____"],
			N["_____"], N["_____"], N["_____"], N["_____"], N["_____"],
			N["_____"], N["_____"], N["_____"], N["_____"], N["_____"],
			N["_____"], N["_____"], N["_____"], N["_____"], N["_____"],
			N["_____"], N["_____"], N["_____"], N["_____"], N["_____"],
			N["_____"], N["_____"], N["_____"], N["_____"], N["_____"],
			N["L0m03"], N["L0m01"], N["L0m00"], N["L0m01"], N["L0m03"],
			N["_____"], N["_____"], N["_____"], N["_____"], N["_____"],
			N["L0m03"], N["L0m01"], N["L0m00"], N["L0m01"], N["L0m03"],
			N["_____"], N["_____"], N["_____"], N["_____"], N["_____"],
			N["L0m03"], N["L0m01"], N["L0m00"], N["L0m01"], N["L0m03"],
			N["_____"], N["_____"], N["_____"], N["_____"], N["_____"],
			N["_____"], N["_____"], N["_____"], N["_____"], N["_____"]
		},
		yslice_prob = {
			{ypos = 0,prob = 254},
			{ypos = 1,prob = 254},
			{ypos = 2,prob = 126},
			{ypos = 3,prob = 126},
			{ypos = 4,prob = 254},
			{ypos = 5,prob = 254},
			{ypos = 6,prob = 254},
			{ypos = 7,prob = 254},
			{ypos = 8,prob = 126},
			{ypos = 9,prob = 254},
			{ypos = 10,prob = 126},
			{ypos = 11,prob = 254},
			{ypos = 12,prob = 254},
			{ypos = 13,prob = 254}
		}
	}
