



--Southern Oak 01
	local N = lib_ecology.N

	
	return 	{
		size = {x = 8,y = 10,z = 8},
		data = {
			N["_____"], N["_____"], N["_____"], N["_____"], N["_____"], N["_____"], N["_____"], N["_____"],
			N["_____"], N["_____"], N["_____"], N["_____"], N["_____"], N["_____"], N["_____"], N["_____"],
			N["_____"], N["_____"], N["_____"], N["_____"], N["_____"], N["_____"], N["_____"], N["_____"],
			N["_____"], N["_____"], N["_____"], N["_____"], N["_____"], N["_____"], N["_____"], N["_____"],
			N["_____"], N["_____"], N["_____"], N["_____"], N["_____"], N["_____"], N["_____"], N["_____"],
			N["_____"], N["_____"], N["_____"], N["_____"], N["_____"], N["_____"], N["_____"], N["_____"],
			N["_____"], N["L0m00"], N["L0m00"], N["L0m00"], N["L0m00"], N["L0m00"], N["L0m00"], N["_____"],
			N["_____"], N["L0m00"], N["L0m00"], N["L0m00"], N["L0m00"], N["L0m00"], N["L0m00"], N["_____"],
			N["_____"], N["_____"], N["_____"], N["_____"], N["_____"], N["_____"], N["_____"], N["_____"],
			N["_____"], N["_____"], N["_____"], N["_____"], N["_____"], N["_____"], N["_____"], N["_____"],
			N["_____"], N["_____"], N["_____"], N["_____"], N["_____"], N["_____"], N["_____"], N["_____"],

			N["_____"], N["_____"], N["_____"], N["_____"], N["_____"], N["_____"], N["_____"], N["_____"],
			N["_____"], N["_____"], N["_____"], N["_____"], N["_____"], N["_____"], N["_____"], N["_____"],
			N["_____"], N["_____"], N["_____"], N["_____"], N["_____"], N["_____"], N["_____"], N["_____"],
			N["_____"], N["_____"], N["_____"], N["_____"], N["_____"], N["_____"], N["_____"], N["_____"],
			N["_____"], N["L0m00"], N["L0m00"], N["L0m00"], N["L0m00"], N["L0m00"], N["L0m00"], N["_____"],
			N["L0m00"], N["T0m00"], N["T0m00"], N["L0m00"], N["L0m00"], N["L0m00"], N["L0m00"], N["L0m00"],
			N["L0m00"], N["L0m00"], N["L0m00"], N["L0m00"], N["L0m00"], N["L0m00"], N["L0m00"], N["L0m00"],
			N["_____"], N["L0m00"], N["L0m00"], N["L0m00"], N["L0m00"], N["L0m00"], N["L0m00"], N["_____"],
			N["_____"], N["_____"], N["_____"], N["_____"], N["_____"], N["_____"], N["_____"], N["_____"],
			N["_____"], N["_____"], N["_____"], N["_____"], N["T0mS0"], N["_____"], N["_____"], N["_____"],

			N["_____"], N["_____"], N["_____"], N["_____"], N["_____"], N["_____"], N["_____"], N["_____"],
			N["_____"], N["_____"], N["_____"], N["_____"], N["_____"], N["_____"], N["_____"], N["_____"],
			N["_____"], N["_____"], N["_____"], N["_____"], N["_____"], N["_____"], N["_____"], N["_____"],
			N["_____"], N["_____"], N["_____"], N["_____"], N["_____"], N["_____"], N["_____"], N["_____"],
			N["_____"], N["L0m00"], N["L0m00"], N["L0m00"], N["L0m00"], N["L0m00"], N["L0m00"], N["_____"],
			N["L0m00"], N["L0m00"], N["T0mS0"], N["L0m00"], N["L0m00"], N["T0m00"], N["L0m00"], N["L0m00"],
			N["L0m00"], N["L0m00"], N["L0m00"], N["L0m00"], N["L0m00"], N["L0m00"], N["L0m00"], N["L0m00"],
			N["_____"], N["L0m00"], N["L0m00"], N["L0m00"], N["L0m00"], N["L0m00"], N["L0m00"], N["_____"],
			N["_____"], N["_____"], N["L0m00"], N["L0m00"], N["L0m00"], N["L0m00"], N["_____"], N["_____"],
			N["_____"], N["_____"], N["T0mW0"], N["T0m00"], N["T0m00"], N["_____"], N["_____"], N["_____"],

			N["_____"], N["_____"], N["_____"], N["T0m00"], N["T0m00"], N["_____"], N["_____"], N["_____"],
			N["_____"], N["_____"], N["_____"], N["T0m00"], N["T0m00"], N["_____"], N["_____"], N["_____"],
			N["_____"], N["_____"], N["_____"], N["T0m00"], N["T0m00"], N["_____"], N["_____"], N["_____"],
			N["_____"], N["_____"], N["T0m00"], N["T0m00"], N["T0m00"], N["_____"], N["_____"], N["_____"],
			N["_____"], N["L0m00"], N["T0m00"], N["T0m00"], N["T0m00"], N["L0m00"], N["L0m00"], N["_____"],
			N["L0m00"], N["L0m00"], N["T0m00"], N["T0m00"], N["T0m00"], N["L0m00"], N["L0m00"], N["L0m00"],
			N["L0m00"], N["L0m00"], N["L0m00"], N["L0m00"], N["T0m00"], N["L0m00"], N["L0m00"], N["L0m00"],
			N["_____"], N["L0m00"], N["L0m00"], N["L0m00"], N["L0m00"], N["L0m00"], N["L0m00"], N["_____"],
			N["_____"], N["_____"], N["L0m00"], N["L0m00"], N["L0m00"], N["L0m00"], N["_____"], N["_____"],
			N["_____"], N["_____"], N["_____"], N["T0m00"], N["T0m00"], N["T0mE0"], N["_____"], N["_____"],

			N["_____"], N["_____"], N["_____"], N["T0m00"], N["T0m00"], N["_____"], N["_____"], N["_____"],
			N["_____"], N["_____"], N["_____"], N["T0m00"], N["T0m00"], N["_____"], N["_____"], N["_____"],
			N["_____"], N["_____"], N["_____"], N["T0m00"], N["T0m00"], N["_____"], N["_____"], N["_____"],
			N["_____"], N["_____"], N["_____"], N["T0m00"], N["T0m00"], N["T0m00"], N["_____"], N["_____"],
			N["_____"], N["L0m00"], N["L0m00"], N["T0m00"], N["T0m00"], N["T0m00"], N["L0m00"], N["_____"],
			N["L0m00"], N["L0m00"], N["L0m00"], N["T0m00"], N["T0m00"], N["T0m00"], N["L0m00"], N["L0m00"],
			N["L0m00"], N["L0m00"], N["L0m00"], N["T0m00"], N["L0m00"], N["L0m00"], N["L0m00"], N["L0m00"],
			N["_____"], N["L0m00"], N["L0m00"], N["L0m00"], N["L0m00"], N["L0m00"], N["L0m00"], N["_____"],
			N["_____"], N["_____"], N["L0m00"], N["L0m00"], N["L0m00"], N["L0m00"], N["_____"], N["_____"],
			N["_____"], N["_____"], N["_____"], N["T0mN0"], N["_____"], N["_____"], N["_____"], N["_____"],

			N["_____"], N["_____"], N["_____"], N["_____"], N["_____"], N["_____"], N["_____"], N["_____"],
			N["_____"], N["_____"], N["_____"], N["_____"], N["_____"], N["_____"], N["_____"], N["_____"],
			N["_____"], N["_____"], N["_____"], N["_____"], N["_____"], N["_____"], N["_____"], N["_____"],
			N["_____"], N["_____"], N["_____"], N["_____"], N["_____"], N["_____"], N["_____"], N["_____"],
			N["_____"], N["L0m00"], N["L0m00"], N["L0m00"], N["L0m00"], N["L0m00"], N["L0m00"], N["_____"],
			N["L0m00"], N["L0m00"], N["T0m00"], N["L0m00"], N["L0m00"], N["T0mN0"], N["L0m00"], N["L0m00"],
			N["L0m00"], N["L0m00"], N["L0m00"], N["L0m00"], N["L0m00"], N["L0m00"], N["L0m00"], N["L0m00"],
			N["_____"], N["L0m00"], N["L0m00"], N["L0m00"], N["L0m00"], N["L0m00"], N["L0m00"], N["_____"],
			N["_____"], N["_____"], N["L0m00"], N["L0m00"], N["L0m00"], N["L0m00"], N["_____"], N["_____"],
			N["_____"], N["_____"], N["_____"], N["_____"], N["_____"], N["_____"], N["_____"], N["_____"],

			N["_____"], N["_____"], N["_____"], N["_____"], N["_____"], N["_____"], N["_____"], N["_____"],
			N["_____"], N["_____"], N["_____"], N["_____"], N["_____"], N["_____"], N["_____"], N["_____"],
			N["_____"], N["_____"], N["_____"], N["_____"], N["_____"], N["_____"], N["_____"], N["_____"],
			N["_____"], N["_____"], N["_____"], N["_____"], N["_____"], N["_____"], N["_____"], N["_____"],
			N["_____"], N["L0m00"], N["L0m00"], N["L0m00"], N["L0m00"], N["L0m00"], N["L0m00"], N["_____"],
			N["L0m00"], N["L0m00"], N["L0m00"], N["L0m00"], N["L0m00"], N["T0mN0"], N["T0m00"], N["L0m00"],
			N["L0m00"], N["L0m00"], N["L0m00"], N["L0m00"], N["L0m00"], N["L0m00"], N["L0m00"], N["L0m00"],
			N["_____"], N["L0m00"], N["L0m00"], N["L0m00"], N["L0m00"], N["L0m00"], N["L0m00"], N["_____"],
			N["_____"], N["_____"], N["_____"], N["_____"], N["_____"], N["_____"], N["_____"], N["_____"],
			N["_____"], N["_____"], N["_____"], N["_____"], N["_____"], N["_____"], N["_____"], N["_____"],

			N["_____"], N["_____"], N["_____"], N["_____"], N["_____"], N["_____"], N["_____"], N["_____"],
			N["_____"], N["_____"], N["_____"], N["_____"], N["_____"], N["_____"], N["_____"], N["_____"],
			N["_____"], N["_____"], N["_____"], N["_____"], N["_____"], N["_____"], N["_____"], N["_____"],
			N["_____"], N["_____"], N["_____"], N["_____"], N["_____"], N["_____"], N["_____"], N["_____"],
			N["_____"], N["_____"], N["_____"], N["_____"], N["_____"], N["_____"], N["_____"], N["_____"],
			N["_____"], N["L0m00"], N["L0m00"], N["L0m00"], N["L0m00"], N["L0m00"], N["L0m00"], N["_____"],
			N["_____"], N["L0m00"], N["L0m00"], N["L0m00"], N["L0m00"], N["L0m00"], N["L0m00"], N["_____"],
			N["_____"], N["_____"], N["_____"], N["_____"], N["_____"], N["_____"], N["_____"], N["_____"],
			N["_____"], N["_____"], N["_____"], N["_____"], N["_____"], N["_____"], N["_____"], N["_____"]
		},
		yslice_prob = {
			{ypos = 0,prob = 254},
			{ypos = 1,prob = 254},
			{ypos = 2,prob = 254},
			{ypos = 3,prob = 254},
			{ypos = 4,prob = 254},
			{ypos = 5,prob = 254},
			{ypos = 6,prob = 254},
			{ypos = 7,prob = 254},
			{ypos = 8,prob = 254},
			{ypos = 9,prob = 254}
		}
	}
