



--Reedmace
	local N = lib_ecology.N

	
		return {
		size = {x = 1,y = 5,z = 1},
		data = {
			{param2 = 0,name = "lib_ecology:plant_reedmace_bottom",prob = 254},
			{param2 = 0,name = "lib_ecology:plant_reedmace",prob = 254},
			{param2 = 0,name = "lib_ecology:plant_reedmace",prob = 127},
			{param2 = 0,name = "lib_ecology:plant_reedmace",prob = 254},
			{param2 = 0,name = "lib_ecology:plant_reedmace_top",prob = 254}
		},
		yslice_prob = {
			{ypos = 0,prob = 254},
			{ypos = 1,prob = 254},
			{ypos = 2,prob = 254},
			{ypos = 3,prob = 254},
			{ypos = 4,prob = 254}
		}
	}
