


--Scorched 03
	local N = lib_ecology.N

	
	return 	{
		size = {x = 4,y = 9,z = 4},
		data = {
			N["_____"], N["_____"], N["_____"], N["_____"],
			N["_____"], N["_____"], N["_____"], N["_____"],
			N["_____"], N["_____"], N["_____"], N["_____"],
			N["_____"], N["_____"], N["_____"], N["_____"],
			N["_____"], N["_____"], N["_____"], N["_____"],
			N["_____"], N["_____"], N["_____"], N["_____"],
			N["_____"], N["_____"], N["_____"], N["_____"],
			N["_____"], N["_____"], N["T0m00"], N["_____"],
			N["_____"], N["_____"], N["_____"], N["T0m00"],

			N["_____"], N["_____"], N["T0m00"], N["_____"],
			N["_____"], N["_____"], N["T0m00"], N["_____"],
			N["_____"], N["_____"], N["T0m00"], N["_____"],
			N["_____"], N["_____"], N["T0m00"], N["_____"],
			N["_____"], N["_____"], N["T0m00"], N["_____"],
			N["_____"], N["_____"], N["T0m00"], N["_____"],
			N["_____"], N["_____"], N["T0m00"], N["_____"],
			N["_____"], N["T0m00"], N["T0m00"], N["_____"],
			N["T0m00"], N["T0m00"], N["_____"], N["_____"],

			N["_____"], N["_____"], N["T0m00"], N["_____"],
			N["_____"], N["_____"], N["T0m00"], N["_____"],
			N["_____"], N["_____"], N["T0m00"], N["_____"],
			N["_____"], N["_____"], N["T0m00"], N["_____"],
			N["_____"], N["_____"], N["T0m00"], N["_____"],
			N["_____"], N["_____"], N["T0m00"], N["_____"],
			N["_____"], N["_____"], N["T0m00"], N["_____"],
			N["_____"], N["_____"], N["_____"], N["T0m00"],
			N["_____"], N["_____"], N["_____"], N["_____"],

			N["_____"], N["_____"], N["_____"], N["_____"],
			N["_____"], N["_____"], N["_____"], N["_____"],
			N["_____"], N["_____"], N["_____"], N["_____"],
			N["_____"], N["_____"], N["_____"], N["_____"],
			N["_____"], N["_____"], N["_____"], N["_____"],
			N["_____"], N["_____"], N["_____"], N["_____"],
			N["_____"], N["_____"], N["_____"], N["_____"],
			N["_____"], N["_____"], N["T0m00"], N["_____"],
			N["_____"], N["T0m00"], N["_____"], N["_____"]
		},
		yslice_prob = {
			{ypos = 0,prob = 254},
			{ypos = 1,prob = 254},
			{ypos = 2,prob = 254},
			{ypos = 3,prob = 254},
			{ypos = 4,prob = 254},
			{ypos = 5,prob = 254},
			{ypos = 6,prob = 254},
			{ypos = 7,prob = 254},
			{ypos = 8,prob = 254}
		}
	}


