



--Mushroom Giant Morel Large
	local N = lib_ecology.N

	
	return {
		size = {x = 6, y = 8, z = 6},
		yslice_prob = {
			{ypos = 1, prob =  200}
		},
		data = {
			N["_____"],N["_____"],N["_____"],N["_____"],N["_____"],N["_____"],
			N["_____"],N["_____"],N["_____"],N["_____"],N["_____"],N["_____"],
			N["_____"],N["_____"],N["_____"],N["_____"],N["_____"],N["_____"],
			N["_____"],N["B0m00"],N["B0m00"],N["B0m00"],N["B0m00"],N["_____"],
			N["_____"],N["_____"],N["_____"],N["_____"],N["_____"],N["_____"],
			N["_____"],N["_____"],N["_____"],N["_____"],N["_____"],N["_____"],
			N["_____"],N["_____"],N["_____"],N["_____"],N["_____"],N["_____"],
			N["_____"],N["_____"],N["_____"],N["_____"],N["_____"],N["_____"],
		
			N["_____"],N["_____"],N["_____"],N["_____"],N["_____"],N["_____"],
			N["_____"],N["_____"],N["_____"],N["_____"],N["_____"],N["_____"],
			N["_____"],N["_____"],N["_____"],N["_____"],N["_____"],N["_____"],
			N["B0m00"],N["B0m00"],N["F0m00"],N["F0m00"],N["B0m00"],N["B0m00"],
			N["_____"],N["_____"],N["B0m00"],N["B0m00"],N["_____"],N["_____"],
			N["_____"],N["_____"],N["B0m00"],N["B0m00"],N["_____"],N["_____"],
			N["_____"],N["_____"],N["B0m00"],N["B0m00"],N["_____"],N["_____"],
			N["_____"],N["_____"],N["_____"],N["_____"],N["_____"],N["_____"],
		
			N["_____"],N["_____"],N["H0m00"],N["H0m00"],N["_____"],N["_____"],
			N["_____"],N["_____"],N["H0m00"],N["H0m00"],N["_____"],N["_____"],
			N["_____"],N["_____"],N["H0m00"],N["H0m00"],N["_____"],N["_____"],
			N["B0m00"],N["F0m00"],N["H0m00"],N["H0m00"],N["F0m00"],N["B0m00"],
			N["_____"],N["B0m00"],N["H0m00"],N["H0m00"],N["B0m00"],N["_____"],
			N["_____"],N["B0m00"],N["H0m00"],N["H0m00"],N["B0m00"],N["_____"],
			N["_____"],N["B0m00"],N["H0m00"],N["H0m00"],N["B0m00"],N["_____"],
			N["_____"],N["_____"],N["B0m00"],N["B0m00"],N["_____"],N["_____"],
		
			N["_____"],N["_____"],N["H0m00"],N["H0m00"],N["_____"],N["_____"],
			N["_____"],N["_____"],N["H0m00"],N["H0m00"],N["_____"],N["_____"],
			N["_____"],N["_____"],N["H0m00"],N["H0m00"],N["_____"],N["_____"],
			N["B0m00"],N["F0m00"],N["H0m00"],N["H0m00"],N["F0m00"],N["B0m00"],
			N["_____"],N["B0m00"],N["H0m00"],N["H0m00"],N["B0m00"],N["_____"],
			N["_____"],N["B0m00"],N["H0m00"],N["H0m00"],N["B0m00"],N["_____"],
			N["_____"],N["B0m00"],N["H0m00"],N["H0m00"],N["B0m00"],N["_____"],
			N["_____"],N["_____"],N["B0m00"],N["B0m00"],N["_____"],N["_____"],
		
			N["_____"],N["_____"],N["_____"],N["_____"],N["_____"],N["_____"],
			N["_____"],N["_____"],N["_____"],N["_____"],N["_____"],N["_____"],
			N["_____"],N["_____"],N["_____"],N["_____"],N["_____"],N["_____"],
			N["B0m00"],N["B0m00"],N["F0m00"],N["F0m00"],N["B0m00"],N["B0m00"],
			N["_____"],N["_____"],N["B0m00"],N["B0m00"],N["_____"],N["_____"],
			N["_____"],N["_____"],N["B0m00"],N["B0m00"],N["_____"],N["_____"],
			N["_____"],N["_____"],N["B0m00"],N["B0m00"],N["_____"],N["_____"],
			N["_____"],N["_____"],N["_____"],N["_____"],N["_____"],N["_____"],
		
			N["_____"],N["_____"],N["_____"],N["_____"],N["_____"],N["_____"],
			N["_____"],N["_____"],N["_____"],N["_____"],N["_____"],N["_____"],
			N["_____"],N["_____"],N["_____"],N["_____"],N["_____"],N["_____"],
			N["_____"],N["B0m00"],N["B0m00"],N["B0m00"],N["B0m00"],N["_____"],
			N["_____"],N["_____"],N["_____"],N["_____"],N["_____"],N["_____"],
			N["_____"],N["_____"],N["_____"],N["_____"],N["_____"],N["_____"],
			N["_____"],N["_____"],N["_____"],N["_____"],N["_____"],N["_____"],
			N["_____"],N["_____"],N["_____"],N["_____"],N["_____"],N["_____"]
		}
	}
