



--Mushroom Short
	local N = lib_ecology.N

	
		return  {
		size = {x = 3,y = 5,z = 3},
		data = {
			N["_____"], N["_____"], N["_____"],
			N["_____"], N["_____"], N["_____"],
			N["_____"], N["_____"], N["_____"],
			N["_____"], N["_____"], N["_____"],
			N["B0m00"], N["B0m00"], N["B0m00"],

			N["_____"], N["H0m00"], N["_____"],
			N["_____"], N["H0m00"], N["_____"],
			N["_____"], N["H0m00"], N["_____"],
			N["_____"], N["H0m00"], N["_____"],
			N["B0m00"], N["B0m00"], N["B0m00"],

			N["_____"], N["_____"], N["_____"],
			N["_____"], N["_____"], N["_____"],
			N["_____"], N["_____"], N["_____"],
			N["_____"], N["_____"], N["_____"],
			N["B0m00"], N["B0m00"], N["B0m00"]
		},
		yslice_prob = {
			{ypos = 0, prob = 254},
			{ypos = 1, prob = 254},
			{ypos = 2, prob = 254},
			{ypos = 3, prob = 254},
			{ypos = 4, prob = 254}
		}
	}
