
--Orange Tree - Ethereal Orange Tree
	local N = lib_ecology.N

	
	return {
		size = {x = 3, y = 6, z = 3},
		data = {
			N["_____"], N["_____"], N["_____"],
			N["_____"], N["_____"], N["_____"],
			N["_____"], N["_____"], N["_____"],
			N["L0m02"], N["L0m02"], N["F0m03"],
			N["L0m00"], N["L0m00"], N["L0m00"],
			N["L0m02"], N["F0m03"], N["L0m02"],

			N["_____"], N["T0m00"], N["_____"],
			N["_____"], N["T0m00"], N["_____"],
			N["_____"], N["T0m00"], N["_____"],
			N["L0m02"], N["T0m00"], N["L0m02"],
			N["L0m00"], N["T0m00"], N["L0m00"],
			N["L0m02"], N["L0m00"], N["L0m02"],

			N["_____"], N["_____"], N["_____"],
			N["_____"], N["_____"], N["_____"],
			N["_____"], N["_____"], N["_____"],
			N["F0m03"], N["L0m02"], N["L0m02"],
			N["L0m00"], N["L0m00"], N["L0m00"],
			N["L0m02"], N["L0m02"], N["L0m02"]
		},
		yslice_prob = {
			{ypos = 1, prob = 127},
		}
	}

