{
	yslice_prob = {
		{prob = 254, ypos = 0},
		{prob = 254, ypos = 1},
		{prob = 254, ypos = 2},
		{prob = 254, ypos = 3},
		{prob = 254, ypos = 4},
		{prob = 254, ypos = 5},
		{prob = 254, ypos = 6},
		{prob = 254, ypos = 7}
	},
	data = {
		T["_____"], T["_____"], T["_____"], T["_____"], T["_____"], T["_____"], T["_____"], T["_____"], T["_____"], T["_____"], T["_____"], T["_____"], T["_____"], T["_____"], T["_____"], T["_____"], T["L0m00"], T["_____"], T["L0m00"], T["_____"], T["_____"], T["_____"], T["L0m00"], T["_____"], T["_____"], T["_____"], T["_____"], T["_____"], T["_____"], T["_____"], T["_____"], T["_____"], T["_____"], T["_____"], T["_____"], T["_____"], T["_____"], T["_____"], T["_____"], T["_____"], T["_____"], T["T0m00"], T["_____"], T["_____"], T["_____"], T["_____"], T["T0m00"], T["_____"], T["_____"], T["_____"], T["_____"], T["T0m00"], T["L0m00"], T["L0m00"], T["_____"], T["L0m00"], T["T0m00"], T["L0m00"], T["L0m00"], T["L0m00"], T["_____"], T["L0m00"], T["L0m00"], T["L0m00"], T["_____"], T["_____"], T["_____"], T["L0m00"], T["_____"], T["_____"], T["_____"], T["_____"], T["_____"], T["_____"], T["_____"], T["_____"], T["_____"], T["_____"], T["_____"], T["_____"], T["_____"], T["T0m00"], T["T0m00"], T["_____"], T["_____"], T["_____"], T["_____"], T["T0m00"], T["_____"], T["_____"], T["_____"], T["L0m00"], T["T0m00"], T["L0m00"], T["_____"], T["L0m00"], T["L0m00"], T["T0m00"], T["L0m00"], T["L0m00"], T["L0m00"], T["L0m00"], T["T0m00"], T["L0m00"], T["L0m00"], T["_____"], T["L0m00"], T["L0m00"], T["L0m00"], T["_____"], T["_____"], T["_____"], T["_____"], T["_____"], T["_____"], T["_____"], T["_____"], T["_____"], T["_____"], T["_____"], T["_____"], T["_____"], T["T0m00"], T["T0m00"], T["_____"], T["_____"], T["_____"], T["T0m00"], T["_____"], T["_____"], T["_____"], T["_____"], T["T0m00"], T["_____"], T["_____"], T["_____"], T["L0m00"], T["L0m00"], T["L0m00"], T["L0m00"], T["L0m00"], T["L0m00"], T["L0m00"], T["L0m00"], T["_____"], T["_____"], T["_____"], T["L0m00"], T["_____"], T["_____"], T["_____"], T["_____"], T["_____"], T["_____"], T["_____"], T["_____"], T["_____"], T["_____"], T["_____"], T["_____"], T["_____"], T["_____"], T["_____"], T["_____"], T["_____"], T["_____"], T["_____"], T["_____"], T["_____"], T["_____"], T["_____"], T["_____"], T["_____"], T["_____"], T["_____"], T["_____"], T["_____"], T["L0m00"], T["_____"], T["_____"], T["_____"], T["L0m00"], T["L0m00"], T["L0m00"], T["_____"], T["_____"], T["_____"], T["L0m00"], T["_____"], T["_____"], T["_____"], T["_____"], T["_____"], T["_____"], T["_____"], T["_____"], T["_____"], T["_____"], T["_____"], T["_____"]
	},
	size = {
		y = 8,
		x = 5,
		z = 5
	}
}