


--Frost Tree Model
	local N = lib_ecology.N

	
	return 	{
		size = {x = 8, y = 19, z = 8},
		data = {
			N["_____"], N["_____"], N["_____"], N["_____"], N["_____"], N["_____"], N["_____"], N["_____"],
			N["_____"], N["_____"], N["_____"], N["_____"], N["_____"], N["_____"], N["_____"], N["_____"],
			N["_____"], N["_____"], N["_____"], N["_____"], N["_____"], N["_____"], N["_____"], N["_____"],
			N["_____"], N["_____"], N["_____"], N["_____"], N["_____"], N["_____"], N["_____"], N["_____"],
			N["_____"], N["_____"], N["_____"], N["_____"], N["_____"], N["_____"], N["_____"], N["_____"],
			N["_____"], N["_____"], N["_____"], N["_____"], N["_____"], N["_____"], N["_____"], N["_____"],
			N["_____"], N["_____"], N["_____"], N["_____"], N["_____"], N["_____"], N["_____"], N["_____"],
			N["_____"], N["_____"], N["_____"], N["_____"], N["_____"], N["_____"], N["_____"], N["_____"],
			N["_____"], N["_____"], N["_____"], N["_____"], N["_____"], N["_____"], N["_____"], N["_____"],
			N["_____"], N["_____"], N["_____"], N["_____"], N["_____"], N["_____"], N["_____"], N["_____"],
			N["_____"], N["_____"], N["_____"], N["_____"], N["_____"], N["_____"], N["_____"], N["_____"],
			N["_____"], N["_____"], N["_____"], N["_____"], N["_____"], N["_____"], N["_____"], N["_____"],
			N["_____"], N["_____"], N["_____"], N["_____"], N["_____"], N["_____"], N["_____"], N["_____"],
			N["_____"], N["_____"], N["_____"], N["L0m00"], N["L0m00"], N["_____"], N["_____"], N["_____"],
			N["_____"], N["_____"], N["_____"], N["_____"], N["_____"], N["_____"], N["_____"], N["_____"],
			N["_____"], N["_____"], N["_____"], N["_____"], N["_____"], N["_____"], N["_____"], N["_____"],
			N["_____"], N["_____"], N["_____"], N["_____"], N["_____"], N["_____"], N["_____"], N["_____"],
			N["_____"], N["_____"], N["_____"], N["_____"], N["_____"], N["_____"], N["_____"], N["_____"],
			N["_____"], N["_____"], N["_____"], N["_____"], N["_____"], N["_____"], N["_____"], N["_____"],

			N["_____"], N["_____"], N["_____"], N["_____"], N["_____"], N["_____"], N["_____"], N["_____"],
			N["_____"], N["_____"], N["_____"], N["_____"], N["_____"], N["_____"], N["_____"], N["_____"],
			N["_____"], N["_____"], N["_____"], N["_____"], N["_____"], N["_____"], N["_____"], N["_____"],
			N["_____"], N["_____"], N["_____"], N["_____"], N["_____"], N["_____"], N["_____"], N["_____"],
			N["_____"], N["_____"], N["_____"], N["_____"], N["_____"], N["_____"], N["_____"], N["_____"],
			N["_____"], N["_____"], N["_____"], N["_____"], N["_____"], N["_____"], N["_____"], N["_____"],
			N["_____"], N["_____"], N["_____"], N["_____"], N["_____"], N["_____"], N["_____"], N["_____"],
			N["_____"], N["_____"], N["_____"], N["_____"], N["_____"], N["_____"], N["_____"], N["_____"],
			N["_____"], N["_____"], N["_____"], N["_____"], N["_____"], N["_____"], N["_____"], N["_____"],
			N["_____"], N["_____"], N["_____"], N["_____"], N["_____"], N["_____"], N["_____"], N["_____"],
			N["_____"], N["_____"], N["_____"], N["_____"], N["_____"], N["_____"], N["_____"], N["_____"],
			N["_____"], N["_____"], N["_____"], N["_____"], N["_____"], N["_____"], N["_____"], N["_____"],
			N["_____"], N["_____"], N["_____"], N["_____"], N["_____"], N["_____"], N["_____"], N["_____"],
			N["_____"], N["_____"], N["L0m00"], N["L0m00"], N["L0m00"], N["L0m00"], N["_____"], N["_____"],
			N["_____"], N["_____"], N["_____"], N["_____"], N["_____"], N["_____"], N["_____"], N["_____"],
			N["_____"], N["_____"], N["_____"], N["L0m00"], N["L0m00"], N["_____"], N["_____"], N["_____"],
			N["_____"], N["_____"], N["_____"], N["_____"], N["_____"], N["_____"], N["_____"], N["_____"],
			N["_____"], N["_____"], N["_____"], N["_____"], N["_____"], N["_____"], N["_____"], N["_____"],
			N["_____"], N["_____"], N["_____"], N["_____"], N["_____"], N["_____"], N["_____"], N["_____"],

			N["_____"], N["_____"], N["_____"], N["_____"], N["_____"], N["_____"], N["_____"], N["_____"],
			N["_____"], N["_____"], N["_____"], N["_____"], N["_____"], N["_____"], N["_____"], N["_____"],
			N["_____"], N["_____"], N["_____"], N["_____"], N["_____"], N["_____"], N["_____"], N["_____"],
			N["_____"], N["_____"], N["_____"], N["_____"], N["_____"], N["_____"], N["_____"], N["_____"],
			N["_____"], N["_____"], N["_____"], N["_____"], N["_____"], N["_____"], N["_____"], N["_____"],
			N["_____"], N["_____"], N["_____"], N["_____"], N["_____"], N["_____"], N["_____"], N["_____"],
			N["_____"], N["_____"], N["_____"], N["_____"], N["_____"], N["_____"], N["_____"], N["_____"],
			N["_____"], N["_____"], N["_____"], N["_____"], N["_____"], N["_____"], N["_____"], N["_____"],
			N["_____"], N["_____"], N["_____"], N["_____"], N["_____"], N["_____"], N["_____"], N["_____"],
			N["_____"], N["_____"], N["_____"], N["_____"], N["_____"], N["_____"], N["_____"], N["_____"],
			N["_____"], N["_____"], N["_____"], N["_____"], N["_____"], N["_____"], N["_____"], N["_____"],
			N["_____"], N["_____"], N["_____"], N["_____"], N["_____"], N["_____"], N["_____"], N["_____"],
			N["_____"], N["_____"], N["_____"], N["L0m00"], N["L0m00"], N["_____"], N["_____"], N["_____"],
			N["_____"], N["L0m00"], N["L0m00"], N["L0m00"], N["L0m00"], N["L0m00"], N["L0m00"], N["_____"],
			N["_____"], N["_____"], N["_____"], N["L0m00"], N["L0m00"], N["_____"], N["_____"], N["_____"],
			N["_____"], N["_____"], N["L0m00"], N["L0m00"], N["L0m00"], N["L0m00"], N["_____"], N["_____"],
			N["_____"], N["_____"], N["_____"], N["L0m00"], N["L0m00"], N["_____"], N["_____"], N["_____"],
			N["_____"], N["_____"], N["_____"], N["L0m00"], N["L0m00"], N["_____"], N["_____"], N["_____"],
			N["_____"], N["_____"], N["_____"], N["_____"], N["_____"], N["_____"], N["_____"], N["_____"],

			N["_____"], N["_____"], N["_____"], N["T0m00"], N["T0m00"], N["_____"], N["_____"], N["_____"],
			N["_____"], N["_____"], N["_____"], N["T0m00"], N["T0m00"], N["_____"], N["_____"], N["_____"],
			N["_____"], N["_____"], N["_____"], N["T0m00"], N["T0m00"], N["_____"], N["_____"], N["_____"],
			N["_____"], N["_____"], N["_____"], N["T0m00"], N["T0m00"], N["_____"], N["_____"], N["_____"],
			N["_____"], N["_____"], N["_____"], N["T0m00"], N["T0m00"], N["_____"], N["_____"], N["_____"],
			N["_____"], N["_____"], N["_____"], N["T0m00"], N["T0m00"], N["_____"], N["_____"], N["_____"],
			N["_____"], N["_____"], N["_____"], N["T0m00"], N["T0m00"], N["_____"], N["_____"], N["_____"],
			N["_____"], N["_____"], N["_____"], N["T0m00"], N["T0m00"], N["_____"], N["_____"], N["_____"],
			N["_____"], N["_____"], N["_____"], N["T0m00"], N["T0m00"], N["_____"], N["_____"], N["_____"],
			N["_____"], N["_____"], N["_____"], N["T0m00"], N["T0m00"], N["_____"], N["_____"], N["_____"],
			N["_____"], N["_____"], N["_____"], N["T0m00"], N["T0m00"], N["_____"], N["_____"], N["_____"],
			N["_____"], N["_____"], N["_____"], N["T0m00"], N["T0m00"], N["_____"], N["_____"], N["_____"],
			N["_____"], N["_____"], N["L0m00"], N["T0m00"], N["T0m00"], N["L0m00"], N["_____"], N["_____"],
			N["L0m00"], N["L0m00"], N["L0m00"], N["T0m00"], N["T0m00"], N["L0m00"], N["L0m00"], N["L0m00"],
			N["_____"], N["_____"], N["L0m00"], N["T0m00"], N["T0m00"], N["L0m00"], N["_____"], N["_____"],
			N["_____"], N["L0m00"], N["L0m00"], N["T0m00"], N["T0m00"], N["L0m00"], N["L0m00"], N["_____"],
			N["_____"], N["_____"], N["L0m00"], N["T0m00"], N["T0m00"], N["L0m00"], N["_____"], N["_____"],
			N["_____"], N["_____"], N["L0m00"], N["T0m00"], N["T0m00"], N["L0m00"], N["_____"], N["_____"],
			N["_____"], N["_____"], N["_____"], N["L0m00"], N["L0m00"], N["_____"], N["_____"], N["_____"],

			N["_____"], N["_____"], N["_____"], N["T0m00"], N["T0m00"], N["_____"], N["_____"], N["_____"],
			N["_____"], N["_____"], N["_____"], N["T0m00"], N["T0m00"], N["_____"], N["_____"], N["_____"],
			N["_____"], N["_____"], N["_____"], N["T0m00"], N["T0m00"], N["_____"], N["_____"], N["_____"],
			N["_____"], N["_____"], N["_____"], N["T0m00"], N["T0m00"], N["_____"], N["_____"], N["_____"],
			N["_____"], N["_____"], N["_____"], N["T0m00"], N["T0m00"], N["_____"], N["_____"], N["_____"],
			N["_____"], N["_____"], N["_____"], N["T0m00"], N["T0m00"], N["_____"], N["_____"], N["_____"],
			N["_____"], N["_____"], N["_____"], N["T0m00"], N["T0m00"], N["_____"], N["_____"], N["_____"],
			N["_____"], N["_____"], N["_____"], N["T0m00"], N["T0m00"], N["_____"], N["_____"], N["_____"],
			N["_____"], N["_____"], N["_____"], N["T0m00"], N["T0m00"], N["_____"], N["_____"], N["_____"],
			N["_____"], N["_____"], N["_____"], N["T0m00"], N["T0m00"], N["_____"], N["_____"], N["_____"],
			N["_____"], N["_____"], N["_____"], N["T0m00"], N["T0m00"], N["_____"], N["_____"], N["_____"],
			N["_____"], N["_____"], N["_____"], N["T0m00"], N["T0m00"], N["_____"], N["_____"], N["_____"],
			N["_____"], N["_____"], N["L0m00"], N["T0m00"], N["T0m00"], N["L0m00"], N["_____"], N["_____"],
			N["L0m00"], N["L0m00"], N["L0m00"], N["T0m00"], N["T0m00"], N["L0m00"], N["L0m00"], N["L0m00"],
			N["_____"], N["_____"], N["L0m00"], N["T0m00"], N["T0m00"], N["L0m00"], N["_____"], N["_____"],
			N["_____"], N["L0m00"], N["L0m00"], N["T0m00"], N["T0m00"], N["L0m00"], N["L0m00"], N["_____"],
			N["_____"], N["_____"], N["L0m00"], N["T0m00"], N["T0m00"], N["L0m00"], N["_____"], N["_____"],
			N["_____"], N["_____"], N["L0m00"], N["T0m00"], N["T0m00"], N["L0m00"], N["_____"], N["_____"],
			N["_____"], N["_____"], N["_____"], N["L0m00"], N["L0m00"], N["_____"], N["_____"], N["_____"],

			N["_____"], N["_____"], N["_____"], N["_____"], N["_____"], N["_____"], N["_____"], N["_____"],
			N["_____"], N["_____"], N["_____"], N["_____"], N["_____"], N["_____"], N["_____"], N["_____"],
			N["_____"], N["_____"], N["_____"], N["_____"], N["_____"], N["_____"], N["_____"], N["_____"],
			N["_____"], N["_____"], N["_____"], N["_____"], N["_____"], N["_____"], N["_____"], N["_____"],
			N["_____"], N["_____"], N["_____"], N["_____"], N["_____"], N["_____"], N["_____"], N["_____"],
			N["_____"], N["_____"], N["_____"], N["_____"], N["_____"], N["_____"], N["_____"], N["_____"],
			N["_____"], N["_____"], N["_____"], N["_____"], N["_____"], N["_____"], N["_____"], N["_____"],
			N["_____"], N["_____"], N["_____"], N["_____"], N["_____"], N["_____"], N["_____"], N["_____"],
			N["_____"], N["_____"], N["_____"], N["_____"], N["_____"], N["_____"], N["_____"], N["_____"],
			N["_____"], N["_____"], N["_____"], N["_____"], N["_____"], N["_____"], N["_____"], N["_____"],
			N["_____"], N["_____"], N["_____"], N["_____"], N["_____"], N["_____"], N["_____"], N["_____"],
			N["_____"], N["_____"], N["_____"], N["_____"], N["_____"], N["_____"], N["_____"], N["_____"],
			N["_____"], N["_____"], N["_____"], N["L0m00"], N["L0m00"], N["_____"], N["_____"], N["_____"],
			N["_____"], N["L0m00"], N["L0m00"], N["L0m00"], N["L0m00"], N["L0m00"], N["L0m00"], N["_____"],
			N["_____"], N["_____"], N["_____"], N["L0m00"], N["L0m00"], N["_____"], N["_____"], N["_____"],
			N["_____"], N["_____"], N["L0m00"], N["L0m00"], N["L0m00"], N["L0m00"], N["_____"], N["_____"],
			N["_____"], N["_____"], N["_____"], N["L0m00"], N["L0m00"], N["_____"], N["_____"], N["_____"],
			N["_____"], N["_____"], N["_____"], N["L0m00"], N["L0m00"], N["_____"], N["_____"], N["_____"],
			N["_____"], N["_____"], N["_____"], N["_____"], N["_____"], N["_____"], N["_____"], N["_____"],

			N["_____"], N["_____"], N["_____"], N["_____"], N["_____"], N["_____"], N["_____"], N["_____"],
			N["_____"], N["_____"], N["_____"], N["_____"], N["_____"], N["_____"], N["_____"], N["_____"],
			N["_____"], N["_____"], N["_____"], N["_____"], N["_____"], N["_____"], N["_____"], N["_____"],
			N["_____"], N["_____"], N["_____"], N["_____"], N["_____"], N["_____"], N["_____"], N["_____"],
			N["_____"], N["_____"], N["_____"], N["_____"], N["_____"], N["_____"], N["_____"], N["_____"],
			N["_____"], N["_____"], N["_____"], N["_____"], N["_____"], N["_____"], N["_____"], N["_____"],
			N["_____"], N["_____"], N["_____"], N["_____"], N["_____"], N["_____"], N["_____"], N["_____"],
			N["_____"], N["_____"], N["_____"], N["_____"], N["_____"], N["_____"], N["_____"], N["_____"],
			N["_____"], N["_____"], N["_____"], N["_____"], N["_____"], N["_____"], N["_____"], N["_____"],
			N["_____"], N["_____"], N["_____"], N["_____"], N["_____"], N["_____"], N["_____"], N["_____"],
			N["_____"], N["_____"], N["_____"], N["_____"], N["_____"], N["_____"], N["_____"], N["_____"],
			N["_____"], N["_____"], N["_____"], N["_____"], N["_____"], N["_____"], N["_____"], N["_____"],
			N["_____"], N["_____"], N["_____"], N["_____"], N["_____"], N["_____"], N["_____"], N["_____"],
			N["_____"], N["_____"], N["L0m00"], N["L0m00"], N["L0m00"], N["L0m00"], N["_____"], N["_____"],
			N["_____"], N["_____"], N["_____"], N["_____"], N["_____"], N["_____"], N["_____"], N["_____"],
			N["_____"], N["_____"], N["_____"], N["L0m00"], N["L0m00"], N["_____"], N["_____"], N["_____"],
			N["_____"], N["_____"], N["_____"], N["_____"], N["_____"], N["_____"], N["_____"], N["_____"],
			N["_____"], N["_____"], N["_____"], N["_____"], N["_____"], N["_____"], N["_____"], N["_____"],
			N["_____"], N["_____"], N["_____"], N["_____"], N["_____"], N["_____"], N["_____"], N["_____"],

			N["_____"], N["_____"], N["_____"], N["_____"], N["_____"], N["_____"], N["_____"], N["_____"],
			N["_____"], N["_____"], N["_____"], N["_____"], N["_____"], N["_____"], N["_____"], N["_____"],
			N["_____"], N["_____"], N["_____"], N["_____"], N["_____"], N["_____"], N["_____"], N["_____"],
			N["_____"], N["_____"], N["_____"], N["_____"], N["_____"], N["_____"], N["_____"], N["_____"],
			N["_____"], N["_____"], N["_____"], N["_____"], N["_____"], N["_____"], N["_____"], N["_____"],
			N["_____"], N["_____"], N["_____"], N["_____"], N["_____"], N["_____"], N["_____"], N["_____"],
			N["_____"], N["_____"], N["_____"], N["_____"], N["_____"], N["_____"], N["_____"], N["_____"],
			N["_____"], N["_____"], N["_____"], N["_____"], N["_____"], N["_____"], N["_____"], N["_____"],
			N["_____"], N["_____"], N["_____"], N["_____"], N["_____"], N["_____"], N["_____"], N["_____"],
			N["_____"], N["_____"], N["_____"], N["_____"], N["_____"], N["_____"], N["_____"], N["_____"],
			N["_____"], N["_____"], N["_____"], N["_____"], N["_____"], N["_____"], N["_____"], N["_____"],
			N["_____"], N["_____"], N["_____"], N["_____"], N["_____"], N["_____"], N["_____"], N["_____"],
			N["_____"], N["_____"], N["_____"], N["_____"], N["_____"], N["_____"], N["_____"], N["_____"],
			N["_____"], N["_____"], N["_____"], N["L0m00"], N["L0m00"], N["_____"], N["_____"], N["_____"],
			N["_____"], N["_____"], N["_____"], N["_____"], N["_____"], N["_____"], N["_____"], N["_____"],
			N["_____"], N["_____"], N["_____"], N["_____"], N["_____"], N["_____"], N["_____"], N["_____"],
			N["_____"], N["_____"], N["_____"], N["_____"], N["_____"], N["_____"], N["_____"], N["_____"],
			N["_____"], N["_____"], N["_____"], N["_____"], N["_____"], N["_____"], N["_____"], N["_____"],
			N["_____"], N["_____"], N["_____"], N["_____"], N["_____"], N["_____"], N["_____"], N["_____"],
		},
		yslice_prob = {
			{ypos = 0, prob = 127}, -- trunk
			{ypos = 1, prob = 127},
			{ypos = 2, prob = 127},
			{ypos = 3, prob = 127},
			{ypos = 4, prob = 127},
			{ypos = 5, prob = 127},
			{ypos = 13, prob = 127}, -- leaves
			{ypos = 15, prob = 127},
		}
	}


