
--mushrooms

	T0 = {name = "lib_ecology:mushroom_01_trunk", param2 = 0, prob = 254}
	L0 = {name = "lib_ecology:mushroom_cap_red_spotted", param2 = 0, prob = 254}
	F0 = {name = "lib_ecology:mushroom_spore_01", param2 = 0, prob = 254}
	le_temp_schem = {
		size = {x = 8,y = 11,z = 8},
		data = {
			__, __, __, __, __, __, __, __,
			__, __, __, __, __, __, __, __,
			__, __, __, __, __, __, __, __,
			__, __, __, __, __, __, __, __,
			__, __, __, __, __, __, __, __,
			__, __, __, __, __, __, __, __,
			__, __, __, __, __, __, __, __,
			__, __, __, L0, L0, __, __, __,
			__, __, __, L0, L0, __, __, __,
			__, __, __, __, __, __, __, __,
			__, __, __, __, __, __, __, __,

			__, __, __, __, __, __, __, __,
			__, __, __, __, __, __, __, __,
			__, __, __, __, __, __, __, __,
			__, __, __, __, __, __, __, __,
			__, __, __, __, __, __, __, __,
			__, __, __, __, __, __, __, __,
			__, __, __, __, __, __, __, __,
			__, __, L0, __, __, L0, __, __,
			__, __, L0, __, __, L0, __, __,
			__, __, __, L0, L0, __, __, __,
			__, __, __, __, __, __, __, __,

			__, __, __, __, __, __, __, __,
			__, __, __, __, __, __, __, __,
			__, __, __, __, __, __, __, __,
			__, __, __, __, __, __, __, __,
			__, __, __, __, __, __, __, __,
			__, __, __, __, __, __, __, __,
			__, __, __, __, __, __, __, __,
			__, L0, __, __, __, __, L0, __,
			__, L0, __, __, __, __, L0, __,
			__, __, L0, F0, F0, L0, __, __,
			__, __, __, L0, L0, __, __, __,

			__, __, __, T0, T0, __, __, __,
			__, __, __, T0, T0, __, __, __,
			__, __, __, T0, T0, __, __, __,
			__, __, __, T0, T0, __, __, __,
			__, __, __, T0, T0, __, __, __,
			__, __, __, T0, T0, __, __, __,
			__, __, __, T0, T0, __, __, __,
			L0, __, __, T0, T0, __, __, L0,
			L0, __, __, T0, T0, __, __, L0,
			__, L0, F0, F0, F0, F0, L0, __,
			__, __, L0, L0, L0, L0, __, __,

			__, __, __, T0, T0, __, __, __,
			__, __, __, T0, T0, __, __, __,
			__, __, __, T0, T0, __, __, __,
			__, __, __, T0, T0, __, __, __,
			__, __, __, T0, T0, __, __, __,
			__, __, __, T0, T0, __, __, __,
			__, __, __, T0, T0, __, __, __,
			L0, __, __, T0, T0, __, __, L0,
			L0, __, __, T0, T0, __, __, L0,
			__, L0, F0, F0, F0, F0, L0, __,
			__, __, L0, L0, L0, L0, __, __,

			__, __, __, __, __, __, __, __,
			__, __, __, __, __, __, __, __,
			__, __, __, __, __, __, __, __,
			__, __, __, __, __, __, __, __,
			__, __, __, __, __, __, __, __,
			__, __, __, __, __, __, __, __,
			__, __, __, __, __, __, __, __,
			__, L0, __, __, __, __, L0, __,
			__, L0, __, __, __, __, L0, __,
			__, __, L0, F0, F0, L0, __, __,
			__, __, __, L0, L0, __, __, __,

			__, __, __, __, __, __, __, __,
			__, __, __, __, __, __, __, __,
			__, __, __, __, __, __, __, __,
			__, __, __, __, __, __, __, __,
			__, __, __, __, __, __, __, __,
			__, __, __, __, __, __, __, __,
			__, __, __, __, __, __, __, __,
			__, __, L0, __, __, L0, __, __,
			__, __, L0, __, __, L0, __, __,
			__, __, __, L0, L0, __, __, __,
			__, __, __, __, __, __, __, __,

			__, __, __, __, __, __, __, __,
			__, __, __, __, __, __, __, __,
			__, __, __, __, __, __, __, __,
			__, __, __, __, __, __, __, __,
			__, __, __, __, __, __, __, __,
			__, __, __, __, __, __, __, __,
			__, __, __, __, __, __, __, __,
			__, __, __, L0, L0, __, __, __,
			__, __, __, L0, L0, __, __, __,
			__, __, __, __, __, __, __, __,
			__, __, __, __, __, __, __, __
		},
		yslice_prob = {
			{ypos = 0, prob = 254},
			{ypos = 1, prob = 254},
			{ypos = 2, prob = 254},
			{ypos = 3, prob = 254},
			{ypos = 4, prob = 254},
			{ypos = 5, prob = 254},
			{ypos = 6, prob = 254},
			{ypos = 7, prob = 254},
			{ypos = 8, prob = 254},
			{ypos = 9, prob = 254},
			{ypos = 10, prob = 254}
		}
	}
	lib_ecology.schematics.insert("schem_mushroom_big", le_temp_schem)
	
	T0 = {name = "lib_ecology:mushroom_02_trunk", param2 = 0, prob = 254}
	L0 = {name = "lib_ecology:mushroom_cap_red_spotted", param2 = 0, prob = 254}
	le_temp_schem = {
		size = {x = 16,y = 11,z = 16},
		data = {
			__, __, __, __, __, __, __, __, __, __, __, __, __, __, __, __,
			__, __, __, __, __, __, __, __, __, __, __, __, __, __, __, __,
			__, __, __, __, __, __, __, __, __, __, __, __, __, __, __, __,
			__, __, __, __, __, __, __, __, __, __, __, __, __, __, __, __,
			__, __, __, __, __, __, __, __, __, __, __, __, __, __, __, __,
			__, __, __, __, __, __, __, __, __, __, __, __, __, __, __, __,
			__, __, __, __, __, __, __, __, __, __, __, __, __, __, __, __,
			__, __, __, __, __, __, __, __, __, __, __, __, __, __, __, __,
			__, __, __, __, __, L0, L0, L0, __, __, __, __, __, __, __, __,
			__, __, __, __, __, __, __, __, L0, L0, L0, __, __, __, __, __,
			__, __, __, __, __, __, __, __, __, __, __, __, __, __, __, __,

			__, __, __, __, __, __, __, __, __, __, __, __, __, __, __, __,
			__, __, __, __, __, __, __, __, __, __, __, __, __, __, __, __,
			__, __, __, __, __, __, __, __, __, __, __, __, __, __, __, __,
			__, __, __, __, __, __, __, __, __, __, __, __, __, __, __, __,
			__, __, __, __, __, __, __, __, __, __, __, __, __, __, __, __,
			__, __, __, __, __, __, __, __, __, __, __, __, __, __, __, __,
			__, __, __, __, __, __, __, __, __, __, __, __, __, __, __, __,
			__, __, __, __, __, __, __, __, __, __, __, __, __, __, __, __,
			__, __, __, L0, L0, L0, L0, L0, __, __, __, __, __, __, __, __,
			__, __, __, __, __, __, __, __, L0, L0, L0, L0, L0, __, __, __,
			__, __, __, __, __, __, __, __, __, __, __, __, __, __, __, __,

			__, __, __, __, __, __, __, __, __, __, __, __, __, __, __, __,
			__, __, __, __, __, __, __, __, __, __, __, __, __, __, __, __,
			__, __, __, __, __, __, __, __, __, __, __, __, __, __, __, __,
			__, __, __, __, __, __, __, __, __, __, __, __, __, __, __, __,
			__, __, __, __, __, __, __, __, __, __, __, __, __, __, __, __,
			__, __, __, __, __, __, __, __, __, __, __, __, __, __, __, __,
			__, __, __, __, __, __, __, __, __, __, __, __, __, __, __, __,
			__, __, __, __, __, __, __, __, __, __, __, __, __, __, __, __,
			__, __, L0, L0, L0, L0, L0, L0, __, __, __, __, __, __, __, __,
			__, __, __, __, __, __, __, __, L0, L0, L0, L0, L0, L0, __, __,
			__, __, __, __, __, __, __, __, __, __, __, __, __, __, __, __,

			__, __, __, __, __, __, __, __, __, __, __, __, __, __, __, __,
			__, __, __, __, __, __, __, __, __, __, __, __, __, __, __, __,
			__, __, __, __, __, __, __, __, __, __, __, __, __, __, __, __,
			__, __, __, __, __, __, __, __, __, __, __, __, __, __, __, __,
			__, __, __, __, __, __, __, __, __, __, __, __, __, __, __, __,
			__, __, __, __, __, __, __, __, __, __, __, __, __, __, __, __,
			__, __, __, __, __, __, __, __, __, __, __, __, __, __, __, __,
			__, __, __, __, __, __, __, __, __, __, __, __, __, __, __, __,
			__, L0, L0, L0, L0, L0, L0, L0, T0, T0, __, __, __, __, __, __,
			__, __, __, __, __, __, __, __, L0, L0, L0, L0, L0, L0, L0, __,
			__, __, __, __, __, __, __, __, __, __, __, __, __, __, __, __,

			__, __, __, __, __, __, T0, T0, T0, T0, __, __, __, __, __, __,
			__, __, __, __, __, T0, T0, T0, T0, T0, T0, __, __, __, __, __,
			__, __, __, __, __, T0, T0, T0, T0, T0, T0, __, __, __, __, __,
			__, __, __, __, __, T0, T0, T0, T0, T0, T0, __, __, __, __, __,
			__, __, __, __, __, T0, T0, T0, T0, T0, T0, __, __, __, __, __,
			__, __, __, __, __, T0, T0, T0, T0, T0, T0, __, __, __, __, __,
			__, __, __, __, __, T0, T0, T0, T0, T0, T0, __, __, __, __, __,
			__, __, __, __, __, T0, T0, T0, T0, T0, T0, __, __, __, __, __,
			__, L0, L0, L0, L0, L0, L0, L0, T0, T0, __, __, __, __, __, __,
			__, __, __, __, __, __, __, __, L0, L0, L0, L0, L0, L0, L0, __,
			__, __, __, __, __, __, __, __, __, __, __, __, __, __, __, __,

			__, __, __, __, __, T0, T0, T0, T0, T0, T0, __, __, __, __, __,
			__, __, __, __, T0, T0, __, __, __, __, T0, T0, __, __, __, __,
			__, __, __, __, T0, T0, __, __, __, __, T0, T0, __, __, __, __,
			__, __, __, __, T0, T0, __, __, __, __, T0, T0, __, __, __, __,
			__, __, __, __, T0, T0, __, __, __, __, T0, T0, __, __, __, __,
			__, __, __, __, T0, T0, __, __, __, __, T0, T0, __, __, __, __,
			__, __, __, __, T0, T0, __, __, __, __, T0, T0, __, __, __, __,
			__, __, __, __, __, __, T0, __, __, __, T0, T0, __, __, __, __,
			__, __, L0, L0, L0, L0, L0, L0, __, T0, T0, __, __, __, __, __,
			L0, L0, __, __, __, __, __, __, L0, L0, L0, L0, L0, L0, L0, L0,
			__, __, __, __, __, __, __, __, __, __, __, __, __, __, __, __,

			__, __, __, __, __, T0, T0, T0, T0, T0, T0, __, __, __, __, __,
			__, __, __, __, T0, __, __, __, __, __, __, T0, __, __, __, __,
			__, __, __, __, T0, __, __, __, __, __, __, T0, __, __, __, __,
			__, __, __, __, T0, __, __, __, __, __, __, T0, __, __, __, __,
			__, __, __, __, T0, __, __, __, __, __, __, T0, __, __, __, __,
			__, __, __, __, T0, __, __, __, __, __, __, T0, __, __, __, __,
			__, __, __, __, T0, __, __, __, __, __, __, T0, __, __, __, __,
			__, __, __, __, __, T0, __, __, __, __, T0, __, __, __, __, __,
			L0, L0, L0, L0, L0, L0, L0, L0, L0, T0, __, __, __, __, __, __,
			__, __, __, __, __, __, __, __, L0, L0, L0, L0, L0, L0, L0, L0,
			__, __, __, __, __, __, __, __, __, __, __, __, __, __, __, __,

			__, __, __, __, __, T0, T0, T0, T0, T0, T0, __, __, __, __, __,
			__, __, __, __, T0, __, __, __, __, __, __, T0, __, __, __, __,
			__, __, __, __, T0, __, __, __, __, __, __, T0, __, __, __, __,
			__, __, __, __, T0, __, __, __, __, __, __, T0, __, __, __, __,
			__, __, __, __, T0, __, __, __, __, __, __, T0, __, __, __, __,
			__, __, __, __, T0, __, __, __, __, __, __, T0, __, __, __, __,
			__, __, __, __, T0, __, __, __, __, __, __, T0, __, __, __, __,
			__, __, __, __, __, T0, __, __, __, __, T0, __, __, __, __, __,
			L0, L0, L0, L0, L0, L0, L0, L0, L0, L0, T0, __, __, __, __, __,
			__, __, __, __, __, __, __, __, __, L0, L0, L0, L0, L0, L0, L0,
			__, __, __, __, __, __, __, __, __, __, __, __, __, __, __, __,

			__, __, __, __, __, T0, T0, T0, T0, T0, T0, __, __, __, __, __,
			__, __, __, __, T0, __, __, __, __, __, __, T0, __, __, __, __,
			__, __, __, __, T0, __, __, __, __, __, __, T0, __, __, __, __,
			__, __, __, __, T0, __, __, __, __, __, __, T0, __, __, __, __,
			__, __, __, __, T0, __, __, __, __, __, __, T0, __, __, __, __,
			__, __, __, __, T0, __, __, __, __, __, __, T0, __, __, __, __,
			__, __, __, __, __, T0, __, __, __, __, T0, __, __, __, __, __,
			L0, L0, L0, L0, L0, L0, L0, L0, __, __, T0, __, __, __, __, __,
			__, __, __, __, __, __, L0, L0, L0, L0, L0, L0, L0, L0, L0, L0,
			__, __, __, __, __, __, __, __, __, __, __, __, __, __, __, __,
			__, __, __, __, __, __, __, __, __, __, __, __, __, __, __, __,

			__, __, __, __, __, T0, T0, T0, T0, T0, T0, __, __, __, __, __,
			__, __, __, __, T0, __, __, __, __, __, __, T0, __, __, __, __,
			__, __, __, __, T0, __, __, __, __, __, __, T0, __, __, __, __,
			__, __, __, __, T0, __, __, __, __, __, __, T0, __, __, __, __,
			__, __, __, __, T0, __, __, __, __, __, __, T0, __, __, __, __,
			__, __, __, __, T0, __, __, __, __, __, __, T0, __, __, __, __,
			__, __, __, __, __, T0, __, __, __, __, T0, __, __, __, __, __,
			L0, L0, L0, L0, L0, L0, L0, L0, __, T0, __, __, __, __, __, __,
			__, __, __, __, __, __, __, L0, L0, L0, L0, L0, L0, L0, L0, L0,
			__, __, __, __, __, __, __, __, __, __, __, __, __, __, __, __,
			__, __, __, __, __, __, __, __, __, __, __, __, __, __, __, __,

			__, __, __, __, __, T0, T0, T0, T0, T0, T0, __, __, __, __, __,
			__, __, __, __, T0, T0, __, __, __, __, T0, T0, __, __, __, __,
			__, __, __, __, T0, T0, __, __, __, __, T0, T0, __, __, __, __,
			__, __, __, __, T0, T0, __, __, __, __, T0, T0, __, __, __, __,
			__, __, __, __, T0, T0, __, __, __, __, T0, T0, __, __, __, __,
			__, __, __, __, T0, T0, __, __, __, __, T0, T0, __, __, __, __,
			__, __, __, __, __, T0, __, __, __, T0, __, __, __, __, __, __,
			L0, L0, L0, L0, L0, L0, L0, L0, __, T0, __, __, __, __, __, __,
			__, __, __, __, __, __, __, __, L0, L0, L0, L0, L0, L0, L0, L0,
			__, __, __, __, __, __, __, __, __, __, __, __, __, __, __, __,
			__, __, __, __, __, __, __, __, __, __, __, __, __, __, __, __,

			__, __, __, __, __, __, T0, T0, T0, T0, __, __, __, __, __, __,
			__, __, __, __, __, T0, T0, T0, T0, T0, T0, __, __, __, __, __,
			__, __, __, __, __, T0, T0, T0, T0, T0, T0, __, __, __, __, __,
			__, __, __, __, __, T0, T0, T0, T0, T0, T0, __, __, __, __, __,
			__, __, __, __, __, T0, T0, T0, T0, T0, T0, __, __, __, __, __,
			__, __, __, __, __, T0, T0, T0, T0, T0, T0, __, __, __, __, __,
			__, __, __, __, __, __, T0, T0, T0, T0, __, __, __, __, __, __,
			__, L0, L0, L0, L0, L0, L0, L0, T0, T0, __, __, __, __, __, __,
			__, __, __, __, __, __, __, __, L0, L0, L0, L0, L0, L0, L0, __,
			__, __, __, __, __, __, __, __, __, __, __, __, __, __, __, __,
			__, __, __, __, __, __, __, __, __, __, __, __, __, __, __, __,

			__, __, __, __, __, __, __, __, __, __, __, __, __, __, __, __,
			__, __, __, __, __, __, __, __, __, __, __, __, __, __, __, __,
			__, __, __, __, __, __, __, __, __, __, __, __, __, __, __, __,
			__, __, __, __, __, __, __, __, __, __, __, __, __, __, __, __,
			__, __, __, __, __, __, __, __, __, __, __, __, __, __, __, __,
			__, __, __, __, __, __, __, __, __, __, __, __, __, __, __, __,
			__, __, __, __, __, __, __, __, __, __, __, __, __, __, __, __,
			__, L0, L0, L0, L0, L0, L0, L0, T0, T0, __, __, __, __, __, __,
			__, __, __, __, __, __, __, __, L0, L0, L0, L0, L0, L0, L0, __,
			__, __, __, __, __, __, __, __, __, __, __, __, __, __, __, __,
			__, __, __, __, __, __, __, __, __, __, __, __, __, __, __, __,
			
			__, __, __, __, __, __, __, __, __, __, __, __, __, __, __, __,
			__, __, __, __, __, __, __, __, __, __, __, __, __, __, __, __,
			__, __, __, __, __, __, __, __, __, __, __, __, __, __, __, __,
			__, __, __, __, __, __, __, __, __, __, __, __, __, __, __, __,
			__, __, __, __, __, __, __, __, __, __, __, __, __, __, __, __,
			__, __, __, __, __, __, __, __, __, __, __, __, __, __, __, __,
			__, __, __, __, __, __, __, __, __, __, __, __, __, __, __, __,
			__, __, L0, L0, L0, L0, L0, L0, __, __, __, __, __, __, __, __,
			__, __, __, __, __, __, __, __, L0, L0, L0, L0, L0, L0, __, __,
			__, __, __, __, __, __, __, __, __, __, __, __, __, __, __, __,
			__, __, __, __, __, __, __, __, __, __, __, __, __, __, __, __,

			__, __, __, __, __, __, __, __, __, __, __, __, __, __, __, __,
			__, __, __, __, __, __, __, __, __, __, __, __, __, __, __, __,
			__, __, __, __, __, __, __, __, __, __, __, __, __, __, __, __,
			__, __, __, __, __, __, __, __, __, __, __, __, __, __, __, __,
			__, __, __, __, __, __, __, __, __, __, __, __, __, __, __, __,
			__, __, __, __, __, __, __, __, __, __, __, __, __, __, __, __,
			__, __, __, __, __, __, __, __, __, __, __, __, __, __, __, __,
			__, __, __, L0, L0, L0, L0, L0, __, __, __, __, __, __, __, __,
			__, __, __, __, __, __, __, __, L0, L0, L0, L0, L0, __, __, __,
			__, __, __, __, __, __, __, __, __, __, __, __, __, __, __, __,
			__, __, __, __, __, __, __, __, __, __, __, __, __, __, __, __,

			__, __, __, __, __, __, __, __, __, __, __, __, __, __, __, __,
			__, __, __, __, __, __, __, __, __, __, __, __, __, __, __, __,
			__, __, __, __, __, __, __, __, __, __, __, __, __, __, __, __,
			__, __, __, __, __, __, __, __, __, __, __, __, __, __, __, __,
			__, __, __, __, __, __, __, __, __, __, __, __, __, __, __, __,
			__, __, __, __, __, __, __, __, __, __, __, __, __, __, __, __,
			__, __, __, __, __, __, __, __, __, __, __, __, __, __, __, __,
			__, __, __, __, __, L0, L0, L0, __, __, __, __, __, __, __, __,
			__, __, __, __, __, __, __, __, L0, L0, L0, __, __, __, __, __,
			__, __, __, __, __, __, __, __, __, __, __, __, __, __, __, __,
			__, __, __, __, __, __, __, __, __, __, __, __, __, __, __, __
		},
		yslice_prob = {
			{prob = 254, ypos = 0},
			{prob = 254, ypos = 1},
			{prob = 254, ypos = 2},
			{prob = 254, ypos = 3},
			{prob = 254, ypos = 4},
			{prob = 254, ypos = 5},
			{prob = 254, ypos = 6},
			{prob = 254, ypos = 7},
			{prob = 254, ypos = 8},
			{prob = 254, ypos = 9},
			{prob = 254, ypos = 10}
		}
	}
	lib_ecology.schematics.insert("schem_mushroom_fat", le_temp_schem)
	
	T0 = {name = "lib_ecology:mushroom_01_trunk", param2 = 0, prob = 254}
	L0 = {name = "lib_ecology:mushroom_cap_brown_01", param2 = 0, prob = 254}
	le_temp_schem = {
		size = {x = 10,y = 11,z = 10},
		data = {
			__, __, __, __, __, __, __, __, __, __,
			__, __, __, __, __, __, __, __, __, __,
			__, __, __, __, __, __, __, __, __, __,
			__, __, __, __, __, __, __, __, __, __,
			__, __, __, __, __, __, __, __, __, __,
			__, __, __, __, __, __, __, __, __, __,
			__, __, __, __, __, __, __, __, __, __,
			__, __, __, __, __, __, __, __, __, __,
			__, __, __, L0, L0, __, __, __, __, __,
			__, __, __, __, __, L0, L0, __, __, __,
			__, __, __, __, __, __, __, __, __, __,

			__, __, __, __, __, __, __, __, __, __,
			__, __, __, __, __, __, __, __, __, __,
			__, __, __, __, __, __, __, __, __, __,
			__, __, __, __, __, __, __, __, __, __,
			__, __, __, __, __, __, __, __, __, __,
			__, __, __, __, __, __, __, __, __, __,
			__, __, __, __, __, __, __, __, __, __,
			__, __, __, __, __, __, __, __, __, __,
			__, __, L0, L0, L0, __, __, __, __, __,
			__, __, __, __, __, L0, L0, L0, __, __,
			__, __, __, __, __, __, __, __, __, __,

			__, __, __, __, __, __, __, __, __, __,
			__, __, __, __, __, __, __, __, __, __,
			__, __, __, __, __, __, __, __, __, __,
			__, __, __, __, __, __, __, __, __, __,
			__, __, __, __, __, __, __, __, __, __,
			__, __, __, __, __, __, __, __, __, __,
			__, __, __, __, __, __, __, __, __, __,
			__, __, __, __, __, __, __, __, __, __,
			__, L0, L0, L0, L0, __, __, __, __, __,
			__, __, __, __, __, L0, L0, L0, L0, __,
			__, __, __, __, __, __, __, __, __, __,

			__, __, __, __, __, __, __, __, __, __,
			__, __, __, __, __, __, __, __, __, __,
			__, __, __, __, __, __, __, __, __, __,
			__, __, __, __, __, __, __, __, __, __,
			__, __, __, __, __, __, __, __, __, __,
			__, __, __, __, __, __, __, __, __, __,
			__, __, __, __, __, __, __, __, __, __,
			__, __, __, __, __, __, __, __, __, __,
			L0, L0, L0, L0, L0, L0, __, __, __, __,
			__, __, __, __, __, L0, L0, L0, L0, L0,
			__, __, __, __, __, __, __, __, __, __,

			__, __, __, __, T0, T0, __, __, __, __,
			__, __, __, __, T0, T0, __, __, __, __,
			__, __, __, __, T0, T0, __, __, __, __,
			__, __, __, __, T0, T0, __, __, __, __,
			__, __, __, __, T0, T0, __, __, __, __,
			__, __, __, __, T0, T0, __, __, __, __,
			__, __, __, __, T0, T0, __, __, __, __,
			__, __, __, __, T0, T0, __, __, __, __,
			L0, L0, L0, L0, L0, L0, L0, __, __, __,
			__, __, __, __, __, __, L0, L0, L0, L0,
			__, __, __, __, __, __, __, __, __, __,

			__, __, __, __, T0, T0, __, __, __, __,
			__, __, __, __, T0, T0, __, __, __, __,
			__, __, __, __, T0, T0, __, __, __, __,
			__, __, __, __, T0, T0, __, __, __, __,
			__, __, __, __, T0, T0, __, __, __, __,
			__, __, __, __, T0, T0, __, __, __, __,
			__, __, __, __, T0, T0, __, __, __, __,
			L0, L0, L0, L0, L0, T0, __, __, __, __,
			__, __, __, L0, L0, L0, L0, L0, L0, L0,
			__, __, __, __, __, __, __, __, __, __,
			__, __, __, __, __, __, __, __, __, __,

			__, __, __, __, __, __, __, __, __, __,
			__, __, __, __, __, __, __, __, __, __,
			__, __, __, __, __, __, __, __, __, __,
			__, __, __, __, __, __, __, __, __, __,
			__, __, __, __, __, __, __, __, __, __,
			__, __, __, __, __, __, __, __, __, __,
			__, __, __, __, __, __, __, __, __, __,
			L0, L0, L0, L0, L0, __, __, __, __, __,
			__, __, __, __, L0, L0, L0, L0, L0, L0,
			__, __, __, __, __, __, __, __, __, __,
			__, __, __, __, __, __, __, __, __, __,

			__, __, __, __, __, __, __, __, __, __,
			__, __, __, __, __, __, __, __, __, __,
			__, __, __, __, __, __, __, __, __, __,
			__, __, __, __, __, __, __, __, __, __,
			__, __, __, __, __, __, __, __, __, __,
			__, __, __, __, __, __, __, __, __, __,
			__, __, __, __, __, __, __, __, __, __,
			__, L0, L0, L0, L0, __, __, __, __, __,
			__, __, __, __, __, L0, L0, L0, L0, __,
			__, __, __, __, __, __, __, __, __, __,
			__, __, __, __, __, __, __, __, __, __,

			__, __, __, __, __, __, __, __, __, __,
			__, __, __, __, __, __, __, __, __, __,
			__, __, __, __, __, __, __, __, __, __,
			__, __, __, __, __, __, __, __, __, __,
			__, __, __, __, __, __, __, __, __, __,
			__, __, __, __, __, __, __, __, __, __,
			__, __, __, __, __, __, __, __, __, __,
			__, __, L0, L0, L0, __, __, __, __, __,
			__, __, __, __, __, L0, L0, L0, __, __,
			__, __, __, __, __, __, __, __, __, __,
			__, __, __, __, __, __, __, __, __, __,

			__, __, __, __, __, __, __, __, __, __,
			__, __, __, __, __, __, __, __, __, __,
			__, __, __, __, __, __, __, __, __, __,
			__, __, __, __, __, __, __, __, __, __,
			__, __, __, __, __, __, __, __, __, __,
			__, __, __, __, __, __, __, __, __, __,
			__, __, __, __, __, __, __, __, __, __,
			__, __, __, L0, L0, __, __, __, __, __,
			__, __, __, __, __, L0, L0, __, __, __,
			__, __, __, __, __, __, __, __, __, __,
			__, __, __, __, __, __, __, __, __, __
		},
		yslice_prob = {
			{prob = 254, ypos = 0},
			{prob = 254, ypos = 1},
			{prob = 254, ypos = 2},
			{prob = 254, ypos = 3},
			{prob = 254, ypos = 4},
			{prob = 254, ypos = 5},
			{prob = 254, ypos = 6},
			{prob = 254, ypos = 7},
			{prob = 254, ypos = 8},
			{prob = 254, ypos = 9},
			{prob = 254, ypos = 10}
		}
	}
	lib_ecology.schematics.insert("schem_mushroom_large", le_temp_schem)
	
	T0 = {name = "lib_ecology:mushroom_02_trunk", param2 = 0, prob = 254}
	L0 = {name = "lib_ecology:mushroom_cap_red_02", param2 = 0, prob = 254}
	le_temp_schem = {
		size = {x = 3,y = 5,z = 3},
		data = {
			__, __, __,
			__, __, __,
			__, __, __,
			__, __, __,
			L0, L0, L0,

			__, T0, __,
			__, T0, __,
			__, T0, __,
			__, T0, __,
			L0, L0, L0,

			__, __, __,
			__, __, __,
			__, __, __,
			__, __, __,
			L0, L0, L0
		},
		yslice_prob = {
			{ypos = 0, prob = 254},
			{ypos = 1, prob = 254},
			{ypos = 2, prob = 254},
			{ypos = 3, prob = 254},
			{ypos = 4, prob = 254}
		}
	}
	lib_ecology.schematics.insert("schem_mushroom_short", le_temp_schem)
	
	T0 = {name = "lib_ecology:mushroom_02_trunk", param2 = 0, prob = 254}
	L0 = {name = "lib_ecology:mushroom_cap_brown_02", param2 = 0, prob = 254}
	le_temp_schem = {
		size = {x = 5,y = 10,z = 5},
		data = {
			__, __, __, __, __,
			__, __, __, __, __,
			__, __, __, __, __,
			__, __, __, __, __,
			__, __, __, __, __,
			__, __, __, __, __,
			__, __, __, __, __,
			__, __, __, __, __,
			__, L0, L0, L0, __,
			__, __, __, __, __,

			__, __, __, __, __,
			__, __, __, __, __,
			__, __, __, __, __,
			__, __, __, __, __,
			__, __, __, __, __,
			__, __, __, __, __,
			__, __, __, __, __,
			__, __, __, __, __,
			L0, L0, L0, L0, L0,
			__, L0, L0, L0, __,

			__, __, T0, __, __,
			__, __, T0, __, __,
			__, __, T0, __, __,
			__, __, T0, __, __,
			__, __, T0, __, __,
			__, __, T0, __, __,
			__, __, T0, __, __,
			__, __, T0, __, __,
			L0, L0, L0, L0, L0,
			__, L0, L0, L0, __,

			__, __, __, __, __,
			__, __, __, __, __,
			__, __, __, __, __,
			__, __, __, __, __,
			__, __, __, __, __,
			__, __, __, __, __,
			__, __, __, __, __,
			__, __, __, __, __,
			L0, L0, L0, L0, L0,
			__, L0, L0, L0, __,

			__, __, __, __, __,
			__, __, __, __, __,
			__, __, __, __, __,
			__, __, __, __, __,
			__, __, __, __, __,
			__, __, __, __, __,
			__, __, __, __, __,
			__, __, __, __, __,
			__, L0, L0, L0, __,
			__, __, __, __, __
		},
		yslice_prob = {
			{ypos = 0, prob = 254},
			{ypos = 1, prob = 254},
			{ypos = 2, prob = 254},
			{ypos = 3, prob = 254},
			{ypos = 4, prob = 254},
			{ypos = 5, prob = 254},
			{ypos = 6, prob = 254},
			{ypos = 7, prob = 254},
			{ypos = 8, prob = 254},
			{ypos = 9, prob = 254}
		}
	}
	lib_ecology.schematics.insert("schem_mushroom_tall", le_temp_schem)

	T0 = {name = "lib_ecology:mushroom_02_trunk", param2 = 0, prob = 254}
	L0 = {name = "lib_ecology:mushroom_cap_blue", param2 = 0, prob = 254}
	le_temp_schem = {
		size = {x = 10,y = 11,z = 10},
		data = {
			__, __, __, __, __, __, __, __, __, __,
			__, __, __, __, __, __, __, __, __, __,
			__, __, __, __, __, __, __, __, __, __,
			__, __, __, __, __, __, __, __, __, __,
			__, __, __, __, __, __, __, __, __, __,
			__, __, __, __, __, __, __, __, __, __,
			__, __, __, __, __, __, __, __, __, __,
			__, __, __, __, __, __, __, __, __, __,
			__, __, __, L0, L0, __, __, __, __, __,
			__, __, __, __, __, L0, L0, __, __, __,
			__, __, __, __, __, __, __, __, __, __,

			__, __, __, __, __, __, __, __, __, __,
			__, __, __, __, __, __, __, __, __, __,
			__, __, __, __, __, __, __, __, __, __,
			__, __, __, __, __, __, __, __, __, __,
			__, __, __, __, __, __, __, __, __, __,
			__, __, __, __, __, __, __, __, __, __,
			__, __, __, __, __, __, __, __, __, __,
			__, __, __, __, __, __, __, __, __, __,
			__, __, L0, L0, L0, __, __, __, __, __,
			__, __, __, __, __, L0, L0, L0, __, __,
			__, __, __, __, __, __, __, __, __, __,

			__, __, __, __, __, __, __, __, __, __,
			__, __, __, __, __, __, __, __, __, __,
			__, __, __, __, __, __, __, __, __, __,
			__, __, __, __, __, __, __, __, __, __,
			__, __, __, __, __, __, __, __, __, __,
			__, __, __, __, __, __, __, __, __, __,
			__, __, __, __, __, __, __, __, __, __,
			__, __, __, __, __, __, __, __, __, __,
			__, L0, L0, L0, L0, __, __, __, __, __,
			__, __, __, __, __, L0, L0, L0, L0, __,
			__, __, __, __, __, __, __, __, __, __,

			__, __, __, __, __, __, __, __, __, __,
			__, __, __, __, __, __, __, __, __, __,
			__, __, __, __, __, __, __, __, __, __,
			__, __, __, __, __, __, __, __, __, __,
			__, __, __, __, __, __, __, __, __, __,
			__, __, __, __, __, __, __, __, __, __,
			__, __, __, __, __, __, __, __, __, __,
			__, __, __, __, __, __, __, __, __, __,
			L0, L0, L0, L0, L0, L0, __, __, __, __,
			__, __, __, __, __, L0, L0, L0, L0, L0,
			__, __, __, __, __, __, __, __, __, __,

			__, __, __, __, T0, T0, __, __, __, __,
			__, __, __, __, T0, T0, __, __, __, __,
			__, __, __, __, T0, T0, __, __, __, __,
			__, __, __, __, T0, T0, __, __, __, __,
			__, __, __, __, T0, T0, __, __, __, __,
			__, __, __, __, T0, T0, __, __, __, __,
			__, __, __, __, T0, T0, __, __, __, __,
			__, __, __, __, T0, T0, __, __, __, __,
			L0, L0, L0, L0, L0, L0, L0, __, __, __,
			__, __, __, __, __, __, L0, L0, L0, L0,
			__, __, __, __, __, __, __, __, __, __,

			__, __, __, __, T0, T0, __, __, __, __,
			__, __, __, __, T0, T0, __, __, __, __,
			__, __, __, __, T0, T0, __, __, __, __,
			__, __, __, __, T0, T0, __, __, __, __,
			__, __, __, __, T0, T0, __, __, __, __,
			__, __, __, __, T0, T0, __, __, __, __,
			__, __, __, __, T0, T0, __, __, __, __,
			L0, L0, L0, L0, L0, T0, __, __, __, __,
			__, __, __, L0, L0, L0, L0, L0, L0, L0,
			__, __, __, __, __, __, __, __, __, __,
			__, __, __, __, __, __, __, __, __, __,

			__, __, __, __, __, __, __, __, __, __,
			__, __, __, __, __, __, __, __, __, __,
			__, __, __, __, __, __, __, __, __, __,
			__, __, __, __, __, __, __, __, __, __,
			__, __, __, __, __, __, __, __, __, __,
			__, __, __, __, __, __, __, __, __, __,
			__, __, __, __, __, __, __, __, __, __,
			L0, L0, L0, L0, L0, __, __, __, __, __,
			__, __, __, __, L0, L0, L0, L0, L0, L0,
			__, __, __, __, __, __, __, __, __, __,
			__, __, __, __, __, __, __, __, __, __,

			__, __, __, __, __, __, __, __, __, __,
			__, __, __, __, __, __, __, __, __, __,
			__, __, __, __, __, __, __, __, __, __,
			__, __, __, __, __, __, __, __, __, __,
			__, __, __, __, __, __, __, __, __, __,
			__, __, __, __, __, __, __, __, __, __,
			__, __, __, __, __, __, __, __, __, __,
			__, L0, L0, L0, L0, __, __, __, __, __,
			__, __, __, __, __, L0, L0, L0, L0, __,
			__, __, __, __, __, __, __, __, __, __,
			__, __, __, __, __, __, __, __, __, __,

			__, __, __, __, __, __, __, __, __, __,
			__, __, __, __, __, __, __, __, __, __,
			__, __, __, __, __, __, __, __, __, __,
			__, __, __, __, __, __, __, __, __, __,
			__, __, __, __, __, __, __, __, __, __,
			__, __, __, __, __, __, __, __, __, __,
			__, __, __, __, __, __, __, __, __, __,
			__, __, L0, L0, L0, __, __, __, __, __,
			__, __, __, __, __, L0, L0, L0, __, __,
			__, __, __, __, __, __, __, __, __, __,
			__, __, __, __, __, __, __, __, __, __,

			__, __, __, __, __, __, __, __, __, __,
			__, __, __, __, __, __, __, __, __, __,
			__, __, __, __, __, __, __, __, __, __,
			__, __, __, __, __, __, __, __, __, __,
			__, __, __, __, __, __, __, __, __, __,
			__, __, __, __, __, __, __, __, __, __,
			__, __, __, __, __, __, __, __, __, __,
			__, __, __, L0, L0, __, __, __, __, __,
			__, __, __, __, __, L0, L0, __, __, __,
			__, __, __, __, __, __, __, __, __, __,
			__, __, __, __, __, __, __, __, __, __
		},
		yslice_prob = {
			{prob = 254, ypos = 0},
			{prob = 254, ypos = 1},
			{prob = 254, ypos = 2},
			{prob = 254, ypos = 3},
			{prob = 254, ypos = 4},
			{prob = 254, ypos = 5},
			{prob = 254, ypos = 6},
			{prob = 254, ypos = 7},
			{prob = 254, ypos = 8},
			{prob = 254, ypos = 9},
			{prob = 254, ypos = 10}
		}
	}
	lib_ecology.schematics.insert("schem_mushroom_blue", le_temp_schem)
	
	T0 = {name = "lib_ecology:mushroom_02_trunk", param2 = 0, prob = 254}
	L0 = {name = "lib_ecology:mushroom_cap_green_spotted", param2 = 0, prob = 254}
	le_temp_schem = {
		size = {x = 3,y = 5,z = 3},
		data = {
			__, __, __,
			__, __, __,
			__, __, __,
			__, __, __,
			L0, L0, L0,

			__, T0, __,
			__, T0, __,
			__, T0, __,
			__, T0, __,
			L0, L0, L0,

			__, __, __,
			__, __, __,
			__, __, __,
			__, __, __,
			L0, L0, L0
		},
		yslice_prob = {
			{ypos = 0, prob = 254},
			{ypos = 1, prob = 254},
			{ypos = 2, prob = 254},
			{ypos = 3, prob = 254},
			{ypos = 4, prob = 254}
		}
	}
	lib_ecology.schematics.insert("schem_mushroom_green_spotted", le_temp_schem)
	
	T0 = {name = "lib_ecology:mushroom_01_trunk", param2 = 0, prob = 254}
	L0 = {name = "lib_ecology:mushroom_cap_green_dk", param2 = 0, prob = 254}
	le_temp_schem = {
		size = {x = 5,y = 10,z = 5},
		data = {
			__, __, __, __, __,
			__, __, __, __, __,
			__, __, __, __, __,
			__, __, __, __, __,
			__, __, __, __, __,
			__, __, __, __, __,
			__, __, __, __, __,
			__, __, __, __, __,
			__, L0, L0, L0, __,
			__, __, __, __, __,

			__, __, __, __, __,
			__, __, __, __, __,
			__, __, __, __, __,
			__, __, __, __, __,
			__, __, __, __, __,
			__, __, __, __, __,
			__, __, __, __, __,
			__, __, __, __, __,
			L0, L0, L0, L0, L0,
			__, L0, L0, L0, __,

			__, __, T0, __, __,
			__, __, T0, __, __,
			__, __, T0, __, __,
			__, __, T0, __, __,
			__, __, T0, __, __,
			__, __, T0, __, __,
			__, __, T0, __, __,
			__, __, T0, __, __,
			L0, L0, L0, L0, L0,
			__, L0, L0, L0, __,

			__, __, __, __, __,
			__, __, __, __, __,
			__, __, __, __, __,
			__, __, __, __, __,
			__, __, __, __, __,
			__, __, __, __, __,
			__, __, __, __, __,
			__, __, __, __, __,
			L0, L0, L0, L0, L0,
			__, L0, L0, L0, __,

			__, __, __, __, __,
			__, __, __, __, __,
			__, __, __, __, __,
			__, __, __, __, __,
			__, __, __, __, __,
			__, __, __, __, __,
			__, __, __, __, __,
			__, __, __, __, __,
			__, L0, L0, L0, __,
			__, __, __, __, __
		},
		yslice_prob = {
			{ypos = 0, prob = 254},
			{ypos = 1, prob = 254},
			{ypos = 2, prob = 254},
			{ypos = 3, prob = 254},
			{ypos = 4, prob = 254},
			{ypos = 5, prob = 254},
			{ypos = 6, prob = 254},
			{ypos = 7, prob = 254},
			{ypos = 8, prob = 254},
			{ypos = 9, prob = 254}
		}
	}
	lib_ecology.schematics.insert("schem_mushroom_green_dark", le_temp_schem)
	
	T0 = {name = "lib_ecology:mushroom_01_trunk", param2 = 0, prob = 254}
	L0 = {name = "lib_ecology:mushroom_cap_purple", param2 = 0, prob = 254}
	le_temp_schem = {
		size = {x = 16,y = 11,z = 16},
		data = {
			__, __, __, __, __, __, __, __, __, __, __, __, __, __, __, __,
			__, __, __, __, __, __, __, __, __, __, __, __, __, __, __, __,
			__, __, __, __, __, __, __, __, __, __, __, __, __, __, __, __,
			__, __, __, __, __, __, __, __, __, __, __, __, __, __, __, __,
			__, __, __, __, __, __, __, __, __, __, __, __, __, __, __, __,
			__, __, __, __, __, __, __, __, __, __, __, __, __, __, __, __,
			__, __, __, __, __, __, __, __, __, __, __, __, __, __, __, __,
			__, __, __, __, __, __, __, __, __, __, __, __, __, __, __, __,
			__, __, __, __, __, L0, L0, L0, __, __, __, __, __, __, __, __,
			__, __, __, __, __, __, __, __, L0, L0, L0, __, __, __, __, __,
			__, __, __, __, __, __, __, __, __, __, __, __, __, __, __, __,

			__, __, __, __, __, __, __, __, __, __, __, __, __, __, __, __,
			__, __, __, __, __, __, __, __, __, __, __, __, __, __, __, __,
			__, __, __, __, __, __, __, __, __, __, __, __, __, __, __, __,
			__, __, __, __, __, __, __, __, __, __, __, __, __, __, __, __,
			__, __, __, __, __, __, __, __, __, __, __, __, __, __, __, __,
			__, __, __, __, __, __, __, __, __, __, __, __, __, __, __, __,
			__, __, __, __, __, __, __, __, __, __, __, __, __, __, __, __,
			__, __, __, __, __, __, __, __, __, __, __, __, __, __, __, __,
			__, __, __, L0, L0, L0, L0, L0, __, __, __, __, __, __, __, __,
			__, __, __, __, __, __, __, __, L0, L0, L0, L0, L0, __, __, __,
			__, __, __, __, __, __, __, __, __, __, __, __, __, __, __, __,

			__, __, __, __, __, __, __, __, __, __, __, __, __, __, __, __,
			__, __, __, __, __, __, __, __, __, __, __, __, __, __, __, __,
			__, __, __, __, __, __, __, __, __, __, __, __, __, __, __, __,
			__, __, __, __, __, __, __, __, __, __, __, __, __, __, __, __,
			__, __, __, __, __, __, __, __, __, __, __, __, __, __, __, __,
			__, __, __, __, __, __, __, __, __, __, __, __, __, __, __, __,
			__, __, __, __, __, __, __, __, __, __, __, __, __, __, __, __,
			__, __, __, __, __, __, __, __, __, __, __, __, __, __, __, __,
			__, __, L0, L0, L0, L0, L0, L0, __, __, __, __, __, __, __, __,
			__, __, __, __, __, __, __, __, L0, L0, L0, L0, L0, L0, __, __,
			__, __, __, __, __, __, __, __, __, __, __, __, __, __, __, __,

			__, __, __, __, __, __, __, __, __, __, __, __, __, __, __, __,
			__, __, __, __, __, __, __, __, __, __, __, __, __, __, __, __,
			__, __, __, __, __, __, __, __, __, __, __, __, __, __, __, __,
			__, __, __, __, __, __, __, __, __, __, __, __, __, __, __, __,
			__, __, __, __, __, __, __, __, __, __, __, __, __, __, __, __,
			__, __, __, __, __, __, __, __, __, __, __, __, __, __, __, __,
			__, __, __, __, __, __, __, __, __, __, __, __, __, __, __, __,
			__, __, __, __, __, __, __, __, __, __, __, __, __, __, __, __,
			__, L0, L0, L0, L0, L0, L0, L0, T0, T0, __, __, __, __, __, __,
			__, __, __, __, __, __, __, __, L0, L0, L0, L0, L0, L0, L0, __,
			__, __, __, __, __, __, __, __, __, __, __, __, __, __, __, __,

			__, __, __, __, __, __, T0, T0, T0, T0, __, __, __, __, __, __,
			__, __, __, __, __, T0, T0, T0, T0, T0, T0, __, __, __, __, __,
			__, __, __, __, __, T0, T0, T0, T0, T0, T0, __, __, __, __, __,
			__, __, __, __, __, T0, T0, T0, T0, T0, T0, __, __, __, __, __,
			__, __, __, __, __, T0, T0, T0, T0, T0, T0, __, __, __, __, __,
			__, __, __, __, __, T0, T0, T0, T0, T0, T0, __, __, __, __, __,
			__, __, __, __, __, T0, T0, T0, T0, T0, T0, __, __, __, __, __,
			__, __, __, __, __, T0, T0, T0, T0, T0, T0, __, __, __, __, __,
			__, L0, L0, L0, L0, L0, L0, L0, T0, T0, __, __, __, __, __, __,
			__, __, __, __, __, __, __, __, L0, L0, L0, L0, L0, L0, L0, __,
			__, __, __, __, __, __, __, __, __, __, __, __, __, __, __, __,

			__, __, __, __, __, T0, T0, T0, T0, T0, T0, __, __, __, __, __,
			__, __, __, __, T0, T0, __, __, __, __, T0, T0, __, __, __, __,
			__, __, __, __, T0, T0, __, __, __, __, T0, T0, __, __, __, __,
			__, __, __, __, T0, T0, __, __, __, __, T0, T0, __, __, __, __,
			__, __, __, __, T0, T0, __, __, __, __, T0, T0, __, __, __, __,
			__, __, __, __, T0, T0, __, __, __, __, T0, T0, __, __, __, __,
			__, __, __, __, T0, T0, __, __, __, __, T0, T0, __, __, __, __,
			__, __, __, __, __, __, T0, __, __, __, T0, T0, __, __, __, __,
			__, __, L0, L0, L0, L0, L0, L0, __, T0, T0, __, __, __, __, __,
			L0, L0, __, __, __, __, __, __, L0, L0, L0, L0, L0, L0, L0, L0,
			__, __, __, __, __, __, __, __, __, __, __, __, __, __, __, __,

			__, __, __, __, __, T0, T0, T0, T0, T0, T0, __, __, __, __, __,
			__, __, __, __, T0, __, __, __, __, __, __, T0, __, __, __, __,
			__, __, __, __, T0, __, __, __, __, __, __, T0, __, __, __, __,
			__, __, __, __, T0, __, __, __, __, __, __, T0, __, __, __, __,
			__, __, __, __, T0, __, __, __, __, __, __, T0, __, __, __, __,
			__, __, __, __, T0, __, __, __, __, __, __, T0, __, __, __, __,
			__, __, __, __, T0, __, __, __, __, __, __, T0, __, __, __, __,
			__, __, __, __, __, T0, __, __, __, __, T0, __, __, __, __, __,
			L0, L0, L0, L0, L0, L0, L0, L0, L0, T0, __, __, __, __, __, __,
			__, __, __, __, __, __, __, __, L0, L0, L0, L0, L0, L0, L0, L0,
			__, __, __, __, __, __, __, __, __, __, __, __, __, __, __, __,

			__, __, __, __, __, T0, T0, T0, T0, T0, T0, __, __, __, __, __,
			__, __, __, __, T0, __, __, __, __, __, __, T0, __, __, __, __,
			__, __, __, __, T0, __, __, __, __, __, __, T0, __, __, __, __,
			__, __, __, __, T0, __, __, __, __, __, __, T0, __, __, __, __,
			__, __, __, __, T0, __, __, __, __, __, __, T0, __, __, __, __,
			__, __, __, __, T0, __, __, __, __, __, __, T0, __, __, __, __,
			__, __, __, __, T0, __, __, __, __, __, __, T0, __, __, __, __,
			__, __, __, __, __, T0, __, __, __, __, T0, __, __, __, __, __,
			L0, L0, L0, L0, L0, L0, L0, L0, L0, L0, T0, __, __, __, __, __,
			__, __, __, __, __, __, __, __, __, L0, L0, L0, L0, L0, L0, L0,
			__, __, __, __, __, __, __, __, __, __, __, __, __, __, __, __,

			__, __, __, __, __, T0, T0, T0, T0, T0, T0, __, __, __, __, __,
			__, __, __, __, T0, __, __, __, __, __, __, T0, __, __, __, __,
			__, __, __, __, T0, __, __, __, __, __, __, T0, __, __, __, __,
			__, __, __, __, T0, __, __, __, __, __, __, T0, __, __, __, __,
			__, __, __, __, T0, __, __, __, __, __, __, T0, __, __, __, __,
			__, __, __, __, T0, __, __, __, __, __, __, T0, __, __, __, __,
			__, __, __, __, __, T0, __, __, __, __, T0, __, __, __, __, __,
			L0, L0, L0, L0, L0, L0, L0, L0, __, __, T0, __, __, __, __, __,
			__, __, __, __, __, __, L0, L0, L0, L0, L0, L0, L0, L0, L0, L0,
			__, __, __, __, __, __, __, __, __, __, __, __, __, __, __, __,
			__, __, __, __, __, __, __, __, __, __, __, __, __, __, __, __,

			__, __, __, __, __, T0, T0, T0, T0, T0, T0, __, __, __, __, __,
			__, __, __, __, T0, __, __, __, __, __, __, T0, __, __, __, __,
			__, __, __, __, T0, __, __, __, __, __, __, T0, __, __, __, __,
			__, __, __, __, T0, __, __, __, __, __, __, T0, __, __, __, __,
			__, __, __, __, T0, __, __, __, __, __, __, T0, __, __, __, __,
			__, __, __, __, T0, __, __, __, __, __, __, T0, __, __, __, __,
			__, __, __, __, __, T0, __, __, __, __, T0, __, __, __, __, __,
			L0, L0, L0, L0, L0, L0, L0, L0, __, T0, __, __, __, __, __, __,
			__, __, __, __, __, __, __, L0, L0, L0, L0, L0, L0, L0, L0, L0,
			__, __, __, __, __, __, __, __, __, __, __, __, __, __, __, __,
			__, __, __, __, __, __, __, __, __, __, __, __, __, __, __, __,

			__, __, __, __, __, T0, T0, T0, T0, T0, T0, __, __, __, __, __,
			__, __, __, __, T0, T0, __, __, __, __, T0, T0, __, __, __, __,
			__, __, __, __, T0, T0, __, __, __, __, T0, T0, __, __, __, __,
			__, __, __, __, T0, T0, __, __, __, __, T0, T0, __, __, __, __,
			__, __, __, __, T0, T0, __, __, __, __, T0, T0, __, __, __, __,
			__, __, __, __, T0, T0, __, __, __, __, T0, T0, __, __, __, __,
			__, __, __, __, __, T0, __, __, __, T0, __, __, __, __, __, __,
			L0, L0, L0, L0, L0, L0, L0, L0, __, T0, __, __, __, __, __, __,
			__, __, __, __, __, __, __, __, L0, L0, L0, L0, L0, L0, L0, L0,
			__, __, __, __, __, __, __, __, __, __, __, __, __, __, __, __,
			__, __, __, __, __, __, __, __, __, __, __, __, __, __, __, __,

			__, __, __, __, __, __, T0, T0, T0, T0, __, __, __, __, __, __,
			__, __, __, __, __, T0, T0, T0, T0, T0, T0, __, __, __, __, __,
			__, __, __, __, __, T0, T0, T0, T0, T0, T0, __, __, __, __, __,
			__, __, __, __, __, T0, T0, T0, T0, T0, T0, __, __, __, __, __,
			__, __, __, __, __, T0, T0, T0, T0, T0, T0, __, __, __, __, __,
			__, __, __, __, __, T0, T0, T0, T0, T0, T0, __, __, __, __, __,
			__, __, __, __, __, __, T0, T0, T0, T0, __, __, __, __, __, __,
			__, L0, L0, L0, L0, L0, L0, L0, T0, T0, __, __, __, __, __, __,
			__, __, __, __, __, __, __, __, L0, L0, L0, L0, L0, L0, L0, __,
			__, __, __, __, __, __, __, __, __, __, __, __, __, __, __, __,
			__, __, __, __, __, __, __, __, __, __, __, __, __, __, __, __,

			__, __, __, __, __, __, __, __, __, __, __, __, __, __, __, __,
			__, __, __, __, __, __, __, __, __, __, __, __, __, __, __, __,
			__, __, __, __, __, __, __, __, __, __, __, __, __, __, __, __,
			__, __, __, __, __, __, __, __, __, __, __, __, __, __, __, __,
			__, __, __, __, __, __, __, __, __, __, __, __, __, __, __, __,
			__, __, __, __, __, __, __, __, __, __, __, __, __, __, __, __,
			__, __, __, __, __, __, __, __, __, __, __, __, __, __, __, __,
			__, L0, L0, L0, L0, L0, L0, L0, T0, T0, __, __, __, __, __, __,
			__, __, __, __, __, __, __, __, L0, L0, L0, L0, L0, L0, L0, __,
			__, __, __, __, __, __, __, __, __, __, __, __, __, __, __, __,
			__, __, __, __, __, __, __, __, __, __, __, __, __, __, __, __,
			
			__, __, __, __, __, __, __, __, __, __, __, __, __, __, __, __,
			__, __, __, __, __, __, __, __, __, __, __, __, __, __, __, __,
			__, __, __, __, __, __, __, __, __, __, __, __, __, __, __, __,
			__, __, __, __, __, __, __, __, __, __, __, __, __, __, __, __,
			__, __, __, __, __, __, __, __, __, __, __, __, __, __, __, __,
			__, __, __, __, __, __, __, __, __, __, __, __, __, __, __, __,
			__, __, __, __, __, __, __, __, __, __, __, __, __, __, __, __,
			__, __, L0, L0, L0, L0, L0, L0, __, __, __, __, __, __, __, __,
			__, __, __, __, __, __, __, __, L0, L0, L0, L0, L0, L0, __, __,
			__, __, __, __, __, __, __, __, __, __, __, __, __, __, __, __,
			__, __, __, __, __, __, __, __, __, __, __, __, __, __, __, __,

			__, __, __, __, __, __, __, __, __, __, __, __, __, __, __, __,
			__, __, __, __, __, __, __, __, __, __, __, __, __, __, __, __,
			__, __, __, __, __, __, __, __, __, __, __, __, __, __, __, __,
			__, __, __, __, __, __, __, __, __, __, __, __, __, __, __, __,
			__, __, __, __, __, __, __, __, __, __, __, __, __, __, __, __,
			__, __, __, __, __, __, __, __, __, __, __, __, __, __, __, __,
			__, __, __, __, __, __, __, __, __, __, __, __, __, __, __, __,
			__, __, __, L0, L0, L0, L0, L0, __, __, __, __, __, __, __, __,
			__, __, __, __, __, __, __, __, L0, L0, L0, L0, L0, __, __, __,
			__, __, __, __, __, __, __, __, __, __, __, __, __, __, __, __,
			__, __, __, __, __, __, __, __, __, __, __, __, __, __, __, __,

			__, __, __, __, __, __, __, __, __, __, __, __, __, __, __, __,
			__, __, __, __, __, __, __, __, __, __, __, __, __, __, __, __,
			__, __, __, __, __, __, __, __, __, __, __, __, __, __, __, __,
			__, __, __, __, __, __, __, __, __, __, __, __, __, __, __, __,
			__, __, __, __, __, __, __, __, __, __, __, __, __, __, __, __,
			__, __, __, __, __, __, __, __, __, __, __, __, __, __, __, __,
			__, __, __, __, __, __, __, __, __, __, __, __, __, __, __, __,
			__, __, __, __, __, L0, L0, L0, __, __, __, __, __, __, __, __,
			__, __, __, __, __, __, __, __, L0, L0, L0, __, __, __, __, __,
			__, __, __, __, __, __, __, __, __, __, __, __, __, __, __, __,
			__, __, __, __, __, __, __, __, __, __, __, __, __, __, __, __
		},
		yslice_prob = {
			{prob = 254, ypos = 0},
			{prob = 254, ypos = 1},
			{prob = 254, ypos = 2},
			{prob = 254, ypos = 3},
			{prob = 254, ypos = 4},
			{prob = 254, ypos = 5},
			{prob = 254, ypos = 6},
			{prob = 254, ypos = 7},
			{prob = 254, ypos = 8},
			{prob = 254, ypos = 9},
			{prob = 254, ypos = 10}
		}
	}
	lib_ecology.schematics.insert("schem_mushroom_purple", le_temp_schem)

	local _ = {name = "air", prob = 0}
	local M = {name = "lib_ecology:mushroom_cap_mottled", prob = 255}
	local T = {name = "lib_ecology:mushroom_01_trunk", prob = 255}
	local P = {name = "lib_ecology:mushroom_spore_02", prob = 255}
	le_temp_schem = {
		size = {x = 6, y = 8, z = 6},
		yslice_prob = {
			{ypos = 1, prob =  200}
		},
		data = {
			_,_,_,_,_,_,
			_,_,_,_,_,_,
			_,_,_,_,_,_,
			_,M,M,M,M,_,
			_,_,_,_,_,_,
			_,_,_,_,_,_,
			_,_,_,_,_,_,
			_,_,_,_,_,_,
		
			_,_,_,_,_,_,
			_,_,_,_,_,_,
			_,_,_,_,_,_,
			M,M,P,P,M,M,
			_,_,M,M,_,_,
			_,_,M,M,_,_,
			_,_,M,M,_,_,
			_,_,_,_,_,_,
		
			_,_,T,T,_,_,
			_,_,T,T,_,_,
			_,_,T,T,_,_,
			M,P,T,T,P,M,
			_,M,T,T,M,_,
			_,M,T,T,M,_,
			_,M,T,T,M,_,
			_,_,M,M,_,_,
		
			_,_,T,T,_,_,
			_,_,T,T,_,_,
			_,_,T,T,_,_,
			M,P,T,T,P,M,
			_,M,T,T,M,_,
			_,M,T,T,M,_,
			_,M,T,T,M,_,
			_,_,M,M,_,_,
		
			_,_,_,_,_,_,
			_,_,_,_,_,_,
			_,_,_,_,_,_,
			M,M,P,P,M,M,
			_,_,M,M,_,_,
			_,_,M,M,_,_,
			_,_,M,M,_,_,
			_,_,_,_,_,_,
		
			_,_,_,_,_,_,
			_,_,_,_,_,_,
			_,_,_,_,_,_,
			_,M,M,M,M,_,
			_,_,_,_,_,_,
			_,_,_,_,_,_,
			_,_,_,_,_,_,
			_,_,_,_,_,_
		}
	}
	lib_ecology.schematics.insert("schem_mushroom_giant_morel_large", le_temp_schem)

	local _ = {name = "air", prob = 0}
	local M = {name = "lib_ecology:mushroom_cap_brown_01", prob = 255}
	local T = {name = "lib_ecology:mushroom_01_trunk", prob = 255}
	local P = {name = "lib_ecology:mushroom_spore_01", prob = 255}
	le_temp_schem = {
		size = {x = 4, y = 8, z = 4},
		yslice_prob = {
			{ypos = 1, prob =  200}
		},
		data = {
			_,_,_,_,
			_,_,_,_,
			_,_,_,_,
			_,M,M,_,
			_,M,M,_,
			_,M,M,_,
			_,M,M,_,
			_,_,_,_,
		
			_,T,T,_,
			_,T,T,_,
			_,T,T,_,
			M,T,T,M,
			M,T,T,M,
			M,T,T,M,
			M,T,T,M,
			_,M,M,_,
		
			_,T,T,_,
			_,T,T,_,
			_,T,T,_,
			M,T,T,M,
			M,T,T,M,
			M,T,T,M,
			M,T,T,M,
			_,M,M,_,
		
			_,_,_,_,
			_,_,_,_,
			_,_,_,_,
			_,M,M,_,
			_,M,M,_,
			_,M,M,_,
			_,M,M,_,
			_,_,_,_
		}
	}
	lib_ecology.schematics.insert("schem_mushroom_giant_morel", le_temp_schem)

	local _ = {name = "air", prob = 0}
	local M = {name = "lib_ecology:mushroom_cap_red_01", prob = 255}
	local T = {name = "lib_ecology:mushroom_02_trunk", prob = 255}
	local P = {name = "lib_ecology:mushroom_spore_03", prob = 255}
	le_temp_schem = {
		size = {x = 18, y = 17, z = 18},
		yslice_prob = {
			{ypos = 2, prob = 200},
			{ypos = 9, prob = 200},
			{ypos =10, prob = 200},
		},
		data = {
		_,_,_,_,_,_,_,_,_,_,_,_,_,_,_,_,_,_,
		_,_,_,_,_,_,_,_,_,_,_,_,_,_,_,_,_,_,
		_,_,_,_,_,_,_,_,_,_,_,_,_,_,_,_,_,_,
		_,_,_,_,_,_,_,_,_,_,_,_,_,_,_,_,_,_,
		_,_,_,_,_,_,_,_,_,_,_,_,_,_,_,_,_,_,
		_,_,_,_,_,_,_,_,_,_,_,_,_,_,_,_,_,_,
		_,_,_,_,_,_,_,_,_,_,_,_,_,_,_,_,_,_,
		_,_,_,_,_,_,_,_,_,_,_,_,_,_,_,_,_,_,
		_,_,_,_,_,_,_,_,_,_,_,_,_,_,_,_,_,_,
		_,_,_,_,_,_,_,_,_,_,_,_,_,_,_,_,_,_,
		_,_,_,_,_,_,_,_,_,_,_,_,_,_,_,_,_,_,
		_,_,_,_,_,_,_,_,_,_,_,_,_,_,_,_,_,_,
		_,_,_,_,_,_,_,_,_,_,_,_,_,_,_,_,_,_,
		_,_,_,_,_,_,_,_,_,_,_,_,_,_,_,_,_,_,
		_,_,_,_,_,_,M,M,M,M,M,M,_,_,_,_,_,_,
		_,_,_,_,_,_,_,_,_,_,_,_,_,_,_,_,_,_,
		_,_,_,_,_,_,_,_,_,_,_,_,_,_,_,_,_,_,
	
		_,_,_,_,_,_,_,_,_,_,_,_,_,_,_,_,_,_,
		_,_,_,_,_,_,_,_,_,_,_,_,_,_,_,_,_,_,
		_,_,_,_,_,_,_,_,_,_,_,_,_,_,_,_,_,_,
		_,_,_,_,_,_,_,_,_,_,_,_,_,_,_,_,_,_,
		_,_,_,_,_,_,_,_,_,_,_,_,_,_,_,_,_,_,
		_,_,_,_,_,_,_,_,_,_,_,_,_,_,_,_,_,_,
		_,_,_,_,_,_,_,_,_,_,_,_,_,_,_,_,_,_,
		_,_,_,_,_,_,_,_,_,_,_,_,_,_,_,_,_,_,
		_,_,_,_,_,_,_,_,_,_,_,_,_,_,_,_,_,_,
		_,_,_,_,_,_,_,_,_,_,_,_,_,_,_,_,_,_,
		_,_,_,_,_,_,_,_,_,_,_,_,_,_,_,_,_,_,
		_,_,_,_,_,_,_,_,_,_,_,_,_,_,_,_,_,_,
		_,_,_,_,_,_,_,_,_,_,_,_,_,_,_,_,_,_,
		_,_,_,_,_,_,_,_,_,_,_,_,_,_,_,_,_,_,
		_,_,_,_,_,M,M,M,M,M,M,M,M,_,_,_,_,_,
		_,_,_,_,_,_,_,_,_,_,_,_,_,_,_,_,_,_,
		_,_,_,_,_,_,_,_,_,_,_,_,_,_,_,_,_,_,
	
		_,_,_,_,_,_,_,_,_,_,_,_,_,_,_,_,_,_,
		_,_,_,_,_,_,_,_,_,_,_,_,_,_,_,_,_,_,
		_,_,_,_,_,_,_,_,_,_,_,_,_,_,_,_,_,_,
		_,_,_,_,_,_,_,_,_,_,_,_,_,_,_,_,_,_,
		_,_,_,_,_,_,_,_,_,_,_,_,_,_,_,_,_,_,
		_,_,_,_,_,_,_,_,_,_,_,_,_,_,_,_,_,_,
		_,_,_,_,_,_,_,_,_,_,_,_,_,_,_,_,_,_,
		_,_,_,_,_,_,_,_,_,_,_,_,_,_,_,_,_,_,
		_,_,_,_,_,_,_,_,_,_,_,_,_,_,_,_,_,_,
		_,_,_,_,_,_,_,_,_,_,_,_,_,_,_,_,_,_,
		_,_,_,_,_,_,_,_,_,_,_,_,_,_,_,_,_,_,
		_,_,_,_,_,_,_,_,_,_,_,_,_,_,_,_,_,_,
		_,_,_,_,_,_,_,_,_,_,_,_,_,_,_,_,_,_,
		_,_,_,_,_,_,_,_,_,_,_,_,_,_,_,_,_,_,
		_,_,_,_,M,M,M,M,M,M,M,M,M,M,_,_,_,_,
		_,_,_,_,_,_,_,_,_,_,_,_,_,_,_,_,_,_,
		_,_,_,_,_,_,_,_,_,_,_,_,_,_,_,_,_,_,
	
		_,_,_,_,_,_,_,_,_,_,_,_,_,_,_,_,_,_,
		_,_,_,_,_,_,_,_,_,_,_,_,_,_,_,_,_,_,
		_,_,_,_,_,_,_,_,_,_,_,_,_,_,_,_,_,_,
		_,_,_,_,_,_,_,_,_,_,_,_,_,_,_,_,_,_,
		_,_,_,_,_,_,_,_,_,_,_,_,_,_,_,_,_,_,
		_,_,_,_,_,_,_,_,_,_,_,_,_,_,_,_,_,_,
		_,_,_,_,_,_,_,_,_,_,_,_,_,_,_,_,_,_,
		_,_,_,_,_,_,_,_,_,_,_,_,_,_,_,_,_,_,
		_,_,_,_,_,_,_,_,_,_,_,_,_,_,_,_,_,_,
		_,_,_,_,_,_,_,_,_,_,_,_,_,_,_,_,_,_,
		_,_,_,_,_,_,_,_,_,_,_,_,_,_,_,_,_,_,
		_,_,_,_,_,_,_,_,_,_,_,_,_,_,_,_,_,_,
		_,_,_,_,_,_,_,_,_,_,_,_,_,_,_,_,_,_,
		_,_,_,_,_,_,_,_,_,_,_,_,_,_,_,_,_,_,
		_,_,_,M,M,M,M,_,_,_,_,M,M,M,M,_,_,_,
		_,_,_,_,_,_,_,M,M,M,M,_,_,_,_,_,_,_,
		_,_,_,_,_,_,_,_,_,_,_,_,_,_,_,_,_,_,
	
		_,_,_,_,_,_,_,_,_,_,_,_,_,_,_,_,_,_,
		_,_,_,_,_,_,_,_,_,_,_,_,_,_,_,_,_,_,
		_,_,_,_,_,_,_,_,_,_,_,_,_,_,_,_,_,_,
		_,_,_,_,_,_,_,_,_,_,_,_,_,_,_,_,_,_,
		_,_,_,_,_,_,_,_,_,_,_,_,_,_,_,_,_,_,
		_,_,_,_,_,_,_,_,_,_,_,_,_,_,_,_,_,_,
		_,_,_,_,_,_,_,_,_,_,_,_,_,_,_,_,_,_,
		_,_,_,_,_,_,_,_,_,_,_,_,_,_,_,_,_,_,
		_,_,_,_,_,_,_,_,_,_,_,_,_,_,_,_,_,_,
		_,_,_,_,_,_,_,_,_,_,_,_,_,_,_,_,_,_,
		_,_,_,_,_,_,_,_,_,_,_,_,_,_,_,_,_,_,
		_,_,_,_,_,_,_,_,_,_,_,_,_,_,_,_,_,_,
		_,_,_,_,_,_,_,_,_,_,_,_,_,_,_,_,_,_,
		_,_,_,_,_,_,_,_,_,_,_,_,_,_,_,_,_,_,
		_,M,M,M,M,_,_,_,_,_,_,_,_,M,M,M,M,_,
		_,_,_,_,_,M,M,M,M,M,M,M,M,_,_,_,_,_,
		_,_,_,_,_,_,_,_,_,_,_,_,_,_,_,_,_,_,
	
		_,_,_,_,_,_,_,_,_,_,_,_,_,_,_,_,_,_,
		_,_,_,_,_,_,_,_,_,_,_,_,_,_,_,_,_,_,
		_,_,_,_,_,_,_,_,_,_,_,_,_,_,_,_,_,_,
		_,_,_,_,_,_,_,_,_,_,_,_,_,_,_,_,_,_,
		_,_,_,_,_,_,_,_,_,_,_,_,_,_,_,_,_,_,
		_,_,_,_,_,_,_,_,_,_,_,_,_,_,_,_,_,_,
		_,_,_,_,_,_,_,_,_,_,_,_,_,_,_,_,_,_,
		_,_,_,_,_,_,_,_,_,_,_,_,_,_,_,_,_,_,
		_,_,_,_,_,_,_,_,_,_,_,_,_,_,_,_,_,_,
		_,_,_,_,_,_,_,_,_,_,_,_,_,_,_,_,_,_,
		_,_,_,_,_,_,_,_,_,_,_,_,_,_,_,_,_,_,
		_,_,_,_,_,_,_,_,_,_,_,_,_,_,_,_,_,_,
		_,_,_,_,_,_,_,_,_,_,_,_,_,_,_,_,_,_,
		_,_,_,_,_,_,_,_,_,_,_,_,_,_,_,_,_,_,
		_,M,M,M,_,_,_,_,_,_,_,_,_,_,M,M,M,_,
		_,_,_,_,M,M,M,M,M,M,M,M,M,M,_,_,_,_,
		_,_,_,_,_,_,_,_,_,_,_,_,_,_,_,_,_,_,
	
		_,_,_,_,_,_,_,_,_,_,_,_,_,_,_,_,_,_,
		_,_,_,_,_,_,_,_,_,_,_,_,_,_,_,_,_,_,
		_,_,_,_,_,_,_,_,_,_,_,_,_,_,_,_,_,_,
		_,_,_,_,_,_,_,_,_,_,_,_,_,_,_,_,_,_,
		_,_,_,_,_,_,_,_,_,_,_,_,_,_,_,_,_,_,
		_,_,_,_,_,_,_,_,_,_,_,_,_,_,_,_,_,_,
		_,_,_,_,_,_,_,_,_,_,_,_,_,_,_,_,_,_,
		_,_,_,_,_,_,_,_,_,_,_,_,_,_,_,_,_,_,
		_,_,_,_,_,_,_,_,_,_,_,_,_,_,_,_,_,_,
		_,_,_,_,_,_,_,_,_,_,_,_,_,_,_,_,_,_,
		_,_,_,_,_,_,_,_,_,_,_,_,_,_,_,_,_,_,
		_,_,_,_,_,_,_,_,_,_,_,_,_,_,_,_,_,_,
		_,_,_,_,_,_,_,_,_,_,_,_,_,_,_,_,_,_,
		_,_,_,_,_,_,_,_,_,_,_,_,_,_,_,_,_,_,
		M,M,M,M,_,_,_,_,_,_,_,_,_,_,M,M,M,M,
		_,_,_,_,M,M,M,_,_,_,_,M,M,M,_,_,_,_,
		_,_,_,_,_,_,_,M,M,M,M,_,_,_,_,_,_,_,
	
		_,_,_,_,_,_,_,_,_,_,_,_,_,_,_,_,_,_,
		_,_,_,_,_,_,_,_,_,_,_,_,_,_,_,_,_,_,
		_,_,_,_,_,_,_,_,_,_,_,_,_,_,_,_,_,_,
		_,_,_,_,_,_,_,_,_,_,_,_,_,_,_,_,_,_,
		_,_,_,_,_,_,_,_,_,_,_,_,_,_,_,_,_,_,
		_,_,_,_,_,_,_,_,_,_,_,_,_,_,_,_,_,_,
		_,_,_,_,_,_,_,_,_,_,_,_,_,_,_,_,_,_,
		_,_,_,_,_,_,_,_,_,_,_,_,_,_,_,_,_,_,
		_,_,_,_,_,_,_,_,_,_,_,_,_,_,_,_,_,_,
		_,_,_,_,_,_,_,_,_,_,_,_,_,_,_,_,_,_,
		_,_,_,_,_,_,_,_,_,_,_,_,_,_,_,_,_,_,
		_,_,_,_,_,_,_,_,_,_,_,_,_,_,_,_,_,_,
		_,_,_,_,_,_,_,_,_,_,_,_,_,_,_,_,_,_,
		_,_,_,_,_,_,_,_,_,_,_,_,_,_,_,_,_,_,
		M,M,M,_,_,_,_,_,_,_,_,_,_,_,_,M,M,M,
		_,_,_,M,M,M,_,_,_,_,_,_,M,M,M,_,_,_,
		_,_,_,_,_,_,M,M,M,M,M,M,_,_,_,_,_,_,
	
		_,_,_,_,_,T,T,_,_,_,_,_,_,_,_,_,_,_,
		_,_,_,_,_,T,T,_,_,_,_,_,_,_,_,_,_,_,
		_,_,_,_,_,T,T,_,_,_,_,_,_,_,_,_,_,_,
		_,_,_,_,_,T,T,_,_,_,_,_,_,_,_,_,_,_,
		_,_,_,_,_,_,T,T,_,_,_,_,_,_,_,_,_,_,
		_,_,_,_,_,_,T,T,_,_,_,_,_,_,_,_,_,_,
		_,_,_,_,_,_,_,T,T,_,_,_,_,_,_,_,_,_,
		_,_,_,_,_,_,_,_,T,T,_,_,_,_,_,_,_,_,
		_,_,_,_,_,_,_,_,_,T,T,_,_,_,_,_,_,_,
		_,_,_,_,_,_,_,_,_,T,T,_,_,_,_,_,_,_,
		_,_,_,_,_,_,_,_,_,_,T,T,_,_,_,_,_,_,
		_,_,_,_,_,_,_,_,_,_,T,T,_,_,_,_,_,_,
		_,_,_,_,_,_,_,_,_,_,T,T,_,_,_,_,_,_,
		_,_,_,_,_,_,_,_,_,T,T,_,_,_,_,_,_,_,
		M,M,M,_,_,_,_,_,_,T,T,_,_,_,_,M,M,M,
		_,_,_,M,M,M,_,_,T,T,_,_,M,M,M,_,_,_,
		_,_,_,_,_,_,M,M,M,M,M,M,_,_,_,_,_,_,
	
		_,_,_,_,_,T,T,_,_,_,_,_,_,_,_,_,_,_,
		_,_,_,_,_,T,T,_,_,_,_,_,_,_,_,_,_,_,
		_,_,_,_,_,T,T,_,_,_,_,_,_,_,_,_,_,_,
		_,_,_,_,_,T,T,_,_,_,_,_,_,_,_,_,_,_,
		_,_,_,_,_,_,T,T,_,_,_,_,_,_,_,_,_,_,
		_,_,_,_,_,_,T,T,_,_,_,_,_,_,_,_,_,_,
		_,_,_,_,_,_,_,T,T,_,_,_,_,_,_,_,_,_,
		_,_,_,_,_,_,_,_,T,T,_,_,_,_,_,_,_,_,
		_,_,_,_,_,_,_,_,_,T,T,_,_,_,_,_,_,_,
		_,_,_,_,_,_,_,_,_,T,T,_,_,_,_,_,_,_,
		_,_,_,_,_,_,_,_,_,_,T,T,_,_,_,_,_,_,
		_,_,_,_,_,_,_,_,_,_,T,T,_,_,_,_,_,_,
		_,_,_,_,_,_,_,_,_,_,T,T,_,_,_,_,_,_,
		_,_,_,_,_,_,_,_,_,T,T,_,_,_,_,_,_,_,
		M,M,M,_,_,_,_,_,_,T,T,_,_,_,_,M,M,M,
		_,_,_,M,M,M,_,_,T,T,_,_,M,M,M,_,_,_,
		_,_,_,_,_,_,M,M,M,M,M,M,_,_,_,_,_,_,
	
		_,_,_,_,_,_,_,_,_,_,_,_,_,_,_,_,_,_,
		_,_,_,_,_,_,_,_,_,_,_,_,_,_,_,_,_,_,
		_,_,_,_,_,_,_,_,_,_,_,_,_,_,_,_,_,_,
		_,_,_,_,_,_,_,_,_,_,_,_,_,_,_,_,_,_,
		_,_,_,_,_,_,_,_,_,_,_,_,_,_,_,_,_,_,
		_,_,_,_,_,_,_,_,_,_,_,_,_,_,_,_,_,_,
		_,_,_,_,_,_,_,_,_,_,_,_,_,_,_,_,_,_,
		_,_,_,_,_,_,_,_,_,_,_,_,_,_,_,_,_,_,
		_,_,_,_,_,_,_,_,_,_,_,_,_,_,_,_,_,_,
		_,_,_,_,_,_,_,_,_,_,_,_,_,_,_,_,_,_,
		_,_,_,_,_,_,_,_,_,_,_,_,_,_,_,_,_,_,
		_,_,_,_,_,_,_,_,_,_,_,_,_,_,_,_,_,_,
		_,_,_,_,_,_,_,_,_,_,_,_,_,_,_,_,_,_,
		_,_,_,_,_,_,_,_,_,_,_,_,_,_,_,_,_,_,
		M,M,M,_,_,_,_,_,_,_,_,_,_,_,_,M,M,M,
		_,_,_,M,M,M,_,_,_,_,_,_,M,M,M,_,_,_,
		_,_,_,_,_,_,M,M,M,M,M,M,_,_,_,_,_,_,
	
		_,_,_,_,_,_,_,_,_,_,_,_,_,_,_,_,_,_,
		_,_,_,_,_,_,_,_,_,_,_,_,_,_,_,_,_,_,
		_,_,_,_,_,_,_,_,_,_,_,_,_,_,_,_,_,_,
		_,_,_,_,_,_,_,_,_,_,_,_,_,_,_,_,_,_,
		_,_,_,_,_,_,_,_,_,_,_,_,_,_,_,_,_,_,
		_,_,_,_,_,_,_,_,_,_,_,_,_,_,_,_,_,_,
		_,_,_,_,_,_,_,_,_,_,_,_,_,_,_,_,_,_,
		_,_,_,_,_,_,_,_,_,_,_,_,_,_,_,_,_,_,
		_,_,_,_,_,_,_,_,_,_,_,_,_,_,_,_,_,_,
		_,_,_,_,_,_,_,_,_,_,_,_,_,_,_,_,_,_,
		_,_,_,_,_,_,_,_,_,_,_,_,_,_,_,_,_,_,
		_,_,_,_,_,_,_,_,_,_,_,_,_,_,_,_,_,_,
		_,_,_,_,_,_,_,_,_,_,_,_,_,_,_,_,_,_,
		_,_,_,_,_,_,_,_,_,_,_,_,_,_,_,_,_,_,
		M,M,M,M,_,_,_,_,_,_,_,_,_,_,M,M,M,M,
		_,_,_,_,M,M,M,_,_,_,_,M,M,M,_,_,_,_,
		_,_,_,_,_,_,_,M,M,M,M,_,_,_,_,_,_,_,
	
		_,_,_,_,_,_,_,_,_,_,_,_,_,_,_,_,_,_,
		_,_,_,_,_,_,_,_,_,_,_,_,_,_,_,_,_,_,
		_,_,_,_,_,_,_,_,_,_,_,_,_,_,_,_,_,_,
		_,_,_,_,_,_,_,_,_,_,_,_,_,_,_,_,_,_,
		_,_,_,_,_,_,_,_,_,_,_,_,_,_,_,_,_,_,
		_,_,_,_,_,_,_,_,_,_,_,_,_,_,_,_,_,_,
		_,_,_,_,_,_,_,_,_,_,_,_,_,_,_,_,_,_,
		_,_,_,_,_,_,_,_,_,_,_,_,_,_,_,_,_,_,
		_,_,_,_,_,_,_,_,_,_,_,_,_,_,_,_,_,_,
		_,_,_,_,_,_,_,_,_,_,_,_,_,_,_,_,_,_,
		_,_,_,_,_,_,_,_,_,_,_,_,_,_,_,_,_,_,
		_,_,_,_,_,_,_,_,_,_,_,_,_,_,_,_,_,_,
		_,_,_,_,_,_,_,_,_,_,_,_,_,_,_,_,_,_,
		_,_,_,_,_,_,_,_,_,_,_,_,_,_,_,_,_,_,
		_,M,M,M,_,_,_,_,_,_,_,_,_,_,M,M,M,_,
		_,_,_,_,M,M,M,M,M,M,M,M,M,M,_,_,_,_,
		_,_,_,_,_,_,_,_,_,_,_,_,_,_,_,_,_,_,
	
		_,_,_,_,_,_,_,_,_,_,_,_,_,_,_,_,_,_,
		_,_,_,_,_,_,_,_,_,_,_,_,_,_,_,_,_,_,
		_,_,_,_,_,_,_,_,_,_,_,_,_,_,_,_,_,_,
		_,_,_,_,_,_,_,_,_,_,_,_,_,_,_,_,_,_,
		_,_,_,_,_,_,_,_,_,_,_,_,_,_,_,_,_,_,
		_,_,_,_,_,_,_,_,_,_,_,_,_,_,_,_,_,_,
		_,_,_,_,_,_,_,_,_,_,_,_,_,_,_,_,_,_,
		_,_,_,_,_,_,_,_,_,_,_,_,_,_,_,_,_,_,
		_,_,_,_,_,_,_,_,_,_,_,_,_,_,_,_,_,_,
		_,_,_,_,_,_,_,_,_,_,_,_,_,_,_,_,_,_,
		_,_,_,_,_,_,_,_,_,_,_,_,_,_,_,_,_,_,
		_,_,_,_,_,_,_,_,_,_,_,_,_,_,_,_,_,_,
		_,_,_,_,_,_,_,_,_,_,_,_,_,_,_,_,_,_,
		_,_,_,_,_,_,_,_,_,_,_,_,_,_,_,_,_,_,
		_,M,M,M,M,_,_,_,_,_,_,_,_,M,M,M,M,_,
		_,_,_,_,_,M,M,M,M,M,M,M,M,_,_,_,_,_,
		_,_,_,_,_,_,_,_,_,_,_,_,_,_,_,_,_,_,
	
		_,_,_,_,_,_,_,_,_,_,_,_,_,_,_,_,_,_,
		_,_,_,_,_,_,_,_,_,_,_,_,_,_,_,_,_,_,
		_,_,_,_,_,_,_,_,_,_,_,_,_,_,_,_,_,_,
		_,_,_,_,_,_,_,_,_,_,_,_,_,_,_,_,_,_,
		_,_,_,_,_,_,_,_,_,_,_,_,_,_,_,_,_,_,
		_,_,_,_,_,_,_,_,_,_,_,_,_,_,_,_,_,_,
		_,_,_,_,_,_,_,_,_,_,_,_,_,_,_,_,_,_,
		_,_,_,_,_,_,_,_,_,_,_,_,_,_,_,_,_,_,
		_,_,_,_,_,_,_,_,_,_,_,_,_,_,_,_,_,_,
		_,_,_,_,_,_,_,_,_,_,_,_,_,_,_,_,_,_,
		_,_,_,_,_,_,_,_,_,_,_,_,_,_,_,_,_,_,
		_,_,_,_,_,_,_,_,_,_,_,_,_,_,_,_,_,_,
		_,_,_,_,_,_,_,_,_,_,_,_,_,_,_,_,_,_,
		_,_,_,_,_,_,_,_,_,_,_,_,_,_,_,_,_,_,
		_,_,_,M,M,M,M,_,_,_,_,M,M,M,M,_,_,_,
		_,_,_,_,_,_,_,M,M,M,M,_,_,_,_,_,_,_,
		_,_,_,_,_,_,_,_,_,_,_,_,_,_,_,_,_,_,
	
		_,_,_,_,_,_,_,_,_,_,_,_,_,_,_,_,_,_,
		_,_,_,_,_,_,_,_,_,_,_,_,_,_,_,_,_,_,
		_,_,_,_,_,_,_,_,_,_,_,_,_,_,_,_,_,_,
		_,_,_,_,_,_,_,_,_,_,_,_,_,_,_,_,_,_,
		_,_,_,_,_,_,_,_,_,_,_,_,_,_,_,_,_,_,
		_,_,_,_,_,_,_,_,_,_,_,_,_,_,_,_,_,_,
		_,_,_,_,_,_,_,_,_,_,_,_,_,_,_,_,_,_,
		_,_,_,_,_,_,_,_,_,_,_,_,_,_,_,_,_,_,
		_,_,_,_,_,_,_,_,_,_,_,_,_,_,_,_,_,_,
		_,_,_,_,_,_,_,_,_,_,_,_,_,_,_,_,_,_,
		_,_,_,_,_,_,_,_,_,_,_,_,_,_,_,_,_,_,
		_,_,_,_,_,_,_,_,_,_,_,_,_,_,_,_,_,_,
		_,_,_,_,_,_,_,_,_,_,_,_,_,_,_,_,_,_,
		_,_,_,_,_,_,_,_,_,_,_,_,_,_,_,_,_,_,
		_,_,_,_,M,M,M,M,M,M,M,M,M,M,_,_,_,_,
		_,_,_,_,_,_,_,_,_,_,_,_,_,_,_,_,_,_,
		_,_,_,_,_,_,_,_,_,_,_,_,_,_,_,_,_,_,
	
		_,_,_,_,_,_,_,_,_,_,_,_,_,_,_,_,_,_,
		_,_,_,_,_,_,_,_,_,_,_,_,_,_,_,_,_,_,
		_,_,_,_,_,_,_,_,_,_,_,_,_,_,_,_,_,_,
		_,_,_,_,_,_,_,_,_,_,_,_,_,_,_,_,_,_,
		_,_,_,_,_,_,_,_,_,_,_,_,_,_,_,_,_,_,
		_,_,_,_,_,_,_,_,_,_,_,_,_,_,_,_,_,_,
		_,_,_,_,_,_,_,_,_,_,_,_,_,_,_,_,_,_,
		_,_,_,_,_,_,_,_,_,_,_,_,_,_,_,_,_,_,
		_,_,_,_,_,_,_,_,_,_,_,_,_,_,_,_,_,_,
		_,_,_,_,_,_,_,_,_,_,_,_,_,_,_,_,_,_,
		_,_,_,_,_,_,_,_,_,_,_,_,_,_,_,_,_,_,
		_,_,_,_,_,_,_,_,_,_,_,_,_,_,_,_,_,_,
		_,_,_,_,_,_,_,_,_,_,_,_,_,_,_,_,_,_,
		_,_,_,_,_,_,_,_,_,_,_,_,_,_,_,_,_,_,
		_,_,_,_,_,M,M,M,M,M,M,M,M,_,_,_,_,_,
		_,_,_,_,_,_,_,_,_,_,_,_,_,_,_,_,_,_,
		_,_,_,_,_,_,_,_,_,_,_,_,_,_,_,_,_,_,
	
		_,_,_,_,_,_,_,_,_,_,_,_,_,_,_,_,_,_,
		_,_,_,_,_,_,_,_,_,_,_,_,_,_,_,_,_,_,
		_,_,_,_,_,_,_,_,_,_,_,_,_,_,_,_,_,_,
		_,_,_,_,_,_,_,_,_,_,_,_,_,_,_,_,_,_,
		_,_,_,_,_,_,_,_,_,_,_,_,_,_,_,_,_,_,
		_,_,_,_,_,_,_,_,_,_,_,_,_,_,_,_,_,_,
		_,_,_,_,_,_,_,_,_,_,_,_,_,_,_,_,_,_,
		_,_,_,_,_,_,_,_,_,_,_,_,_,_,_,_,_,_,
		_,_,_,_,_,_,_,_,_,_,_,_,_,_,_,_,_,_,
		_,_,_,_,_,_,_,_,_,_,_,_,_,_,_,_,_,_,
		_,_,_,_,_,_,_,_,_,_,_,_,_,_,_,_,_,_,
		_,_,_,_,_,_,_,_,_,_,_,_,_,_,_,_,_,_,
		_,_,_,_,_,_,_,_,_,_,_,_,_,_,_,_,_,_,
		_,_,_,_,_,_,_,_,_,_,_,_,_,_,_,_,_,_,
		_,_,_,_,_,_,M,M,M,M,M,M,_,_,_,_,_,_,
		_,_,_,_,_,_,_,_,_,_,_,_,_,_,_,_,_,_,
		_,_,_,_,_,_,_,_,_,_,_,_,_,_,_,_,_,_
		}
	}
	lib_ecology.schematics.insert("schem_mushroom_giant_tall", le_temp_schem)


--[[
	local ms = {name = "lib_ecology:mushroom_small_trunk", param2 = 0, prob = 254}
	local mc = {name = "lib_ecology:mushroom_small_cap_01", param2 = 0, prob = 254}
	le_temp_schem = {
		size = {x = 1, y = 3, z = 1},
		data = {
			ms,
			ms,
			mc,
		},
	}
	lib_ecology.schematics.insert("schem_mushroom_03_a", le_temp_schem)


	local ms = {name = "lib_ecology:mushroom_small_trunk", param2 = 0, prob = 254}
	local mc = {name = "lib_ecology:mushroom_small_cap_02", param2 = 0, prob = 254}
	le_temp_schem = {
		size = {x = 1, y = 3, z = 1},
		data = {
			ms,
			ms,
			mc,
		},
	}
	lib_ecology.schematics.insert("schem_mushroom_03_b", le_temp_schem)
--]]

