



--Bamboo Tropical _01
	local N = lib_ecology.N

	
		return {
			size = {x = 3, y = 12, z = 3},
			data = {

				N["_____"], N["_____"], N["_____"],
				N["_____"], N["_____"], N["_____"],
				N["_____"], N["_____"], N["_____"],
				N["_____"], N["_____"], N["_____"],
				N["_____"], N["_____"], N["_____"],
				N["_____"], N["_____"], N["_____"],
				N["_____"], N["_____"], N["_____"],
				N["_____"], N["_____"], N["_____"],
				N["_____"], N["_____"], N["_____"],
				N["L0m03"], N["L0m00"], N["L0m03"],
				N["_____"], N["L0m00"], N["_____"],
				N["_____"], N["_____"], N["_____"],

				N["_____"], N["T0m00"], N["_____"],
				N["_____"], N["T0m00"], N["_____"],
				N["_____"], N["T0m00"], N["_____"],
				N["_____"], N["T0m00"], N["_____"],
				N["_____"], N["T0m00"], N["_____"],
				N["_____"], N["T0m00"], N["_____"],
				N["_____"], N["T0m00"], N["_____"],
				N["_____"], N["T0m00"], N["_____"],
				N["_____"], N["T0m00"], N["_____"],
				N["L0m03"], N["L0m00"], N["L0m03"],
				N["_____"], N["L0m00"], N["_____"],
				N["_____"], N["L0m03"], N["_____"],

				N["_____"], N["_____"], N["_____"],
				N["_____"], N["_____"], N["_____"],
				N["_____"], N["_____"], N["_____"],
				N["_____"], N["_____"], N["_____"],
				N["_____"], N["_____"], N["_____"],
				N["_____"], N["_____"], N["_____"],
				N["_____"], N["_____"], N["_____"],
				N["_____"], N["_____"], N["_____"],
				N["_____"], N["_____"], N["_____"],
				N["L0m03"], N["L0m00"], N["L0m03"],
				N["_____"], N["L0m00"], N["_____"],
				N["_____"], N["_____"], N["_____"]

			},
			yslice_prob = {
				{ypos = 0,prob = 254},
				{ypos = 1,prob = 254},
				{ypos = 2,prob = 254},
				{ypos = 3,prob = 254},
				{ypos = 4,prob = 254},
				{ypos = 5,prob = 127},
				{ypos = 6,prob = 254},
				{ypos = 7,prob = 254},
				{ypos = 8,prob = 254},
				{ypos = 9,prob = 254},
				{ypos = 10,prob = 254},
				{ypos = 11,prob = 254}
			},
		}
