



--Mushroom Tall
	local N = lib_ecology.N

	
		return {
		size = {x = 5,y = 10,z = 5},
		data = {
			N["_____"], N["_____"], N["_____"], N["_____"], N["_____"],
			N["_____"], N["_____"], N["_____"], N["_____"], N["_____"],
			N["_____"], N["_____"], N["_____"], N["_____"], N["_____"],
			N["_____"], N["_____"], N["_____"], N["_____"], N["_____"],
			N["_____"], N["_____"], N["_____"], N["_____"], N["_____"],
			N["_____"], N["_____"], N["_____"], N["_____"], N["_____"],
			N["_____"], N["_____"], N["_____"], N["_____"], N["_____"],
			N["_____"], N["_____"], N["_____"], N["_____"], N["_____"],
			N["_____"], N["B0m00"], N["B0m00"], N["B0m00"], N["_____"],
			N["_____"], N["_____"], N["_____"], N["_____"], N["_____"],

			N["_____"], N["_____"], N["_____"], N["_____"], N["_____"],
			N["_____"], N["_____"], N["_____"], N["_____"], N["_____"],
			N["_____"], N["_____"], N["_____"], N["_____"], N["_____"],
			N["_____"], N["_____"], N["_____"], N["_____"], N["_____"],
			N["_____"], N["_____"], N["_____"], N["_____"], N["_____"],
			N["_____"], N["_____"], N["_____"], N["_____"], N["_____"],
			N["_____"], N["_____"], N["_____"], N["_____"], N["_____"],
			N["_____"], N["_____"], N["_____"], N["_____"], N["_____"],
			N["B0m00"], N["B0m00"], N["B0m00"], N["B0m00"], N["B0m00"],
			N["_____"], N["B0m00"], N["B0m00"], N["B0m00"], N["_____"],

			N["_____"], N["_____"], N["H0m00"], N["_____"], N["_____"],
			N["_____"], N["_____"], N["H0m00"], N["_____"], N["_____"],
			N["_____"], N["_____"], N["H0m00"], N["_____"], N["_____"],
			N["_____"], N["_____"], N["H0m00"], N["_____"], N["_____"],
			N["_____"], N["_____"], N["H0m00"], N["_____"], N["_____"],
			N["_____"], N["_____"], N["H0m00"], N["_____"], N["_____"],
			N["_____"], N["_____"], N["H0m00"], N["_____"], N["_____"],
			N["_____"], N["_____"], N["H0m00"], N["_____"], N["_____"],
			N["B0m00"], N["B0m00"], N["B0m00"], N["B0m00"], N["B0m00"],
			N["_____"], N["B0m00"], N["B0m00"], N["B0m00"], N["_____"],

			N["_____"], N["_____"], N["_____"], N["_____"], N["_____"],
			N["_____"], N["_____"], N["_____"], N["_____"], N["_____"],
			N["_____"], N["_____"], N["_____"], N["_____"], N["_____"],
			N["_____"], N["_____"], N["_____"], N["_____"], N["_____"],
			N["_____"], N["_____"], N["_____"], N["_____"], N["_____"],
			N["_____"], N["_____"], N["_____"], N["_____"], N["_____"],
			N["_____"], N["_____"], N["_____"], N["_____"], N["_____"],
			N["_____"], N["_____"], N["_____"], N["_____"], N["_____"],
			N["B0m00"], N["B0m00"], N["B0m00"], N["B0m00"], N["B0m00"],
			N["_____"], N["B0m00"], N["B0m00"], N["B0m00"], N["_____"],

			N["_____"], N["_____"], N["_____"], N["_____"], N["_____"],
			N["_____"], N["_____"], N["_____"], N["_____"], N["_____"],
			N["_____"], N["_____"], N["_____"], N["_____"], N["_____"],
			N["_____"], N["_____"], N["_____"], N["_____"], N["_____"],
			N["_____"], N["_____"], N["_____"], N["_____"], N["_____"],
			N["_____"], N["_____"], N["_____"], N["_____"], N["_____"],
			N["_____"], N["_____"], N["_____"], N["_____"], N["_____"],
			N["_____"], N["_____"], N["_____"], N["_____"], N["_____"],
			N["_____"], N["B0m00"], N["B0m00"], N["B0m00"], N["_____"],
			N["_____"], N["_____"], N["_____"], N["_____"], N["_____"]
		},
		yslice_prob = {
			{ypos = 0, prob = 254},
			{ypos = 1, prob = 254},
			{ypos = 2, prob = 254},
			{ypos = 3, prob = 254},
			{ypos = 4, prob = 254},
			{ypos = 5, prob = 254},
			{ypos = 6, prob = 254},
			{ypos = 7, prob = 254},
			{ypos = 8, prob = 254},
			{ypos = 9, prob = 254}
		}
	}
