

--Acacia Tree
	local N = lib_ecology.N

	-- N["T0m00"] = {name = "lib_ecology:tree_acacia_trunk", param2 = 0, prob = 254}
	-- N["L0m00"] = {name = "lib_ecology:tree_acacia_leaves", param2 = 0, prob = 254}
	-- N["L0m01"] = {name = "lib_ecology:tree_acacia_leaves", param2 = 0, prob = 222}
	
	return {
		size = {x = 9,y = 8,z = 9},
		data = {
			N["_____"], N["_____"], N["_____"], N["_____"], N["_____"], N["_____"], N["_____"], N["_____"], N["_____"],
			N["_____"], N["_____"], N["_____"], N["_____"], N["_____"], N["_____"], N["_____"], N["_____"], N["_____"],
			N["_____"], N["_____"], N["_____"], N["_____"], N["_____"], N["_____"], N["_____"], N["_____"], N["_____"],
			N["_____"], N["_____"], N["_____"], N["_____"], N["_____"], N["_____"], N["_____"], N["_____"], N["_____"],
			N["_____"], N["_____"], N["_____"], N["_____"], N["_____"], N["_____"], N["_____"], N["_____"], N["_____"],
			N["_____"], N["_____"], N["_____"], N["_____"], N["_____"], N["_____"], N["_____"], N["_____"], N["_____"],
			N["L0m01"], N["L0m01"], N["L0m01"], N["L0m01"], N["_____"], N["_____"], N["_____"], N["_____"], N["_____"],
			N["_____"], N["_____"], N["_____"], N["_____"], N["L0m01"], N["L0m01"], N["L0m01"], N["L0m01"], N["L0m01"],
			N["_____"], N["_____"], N["_____"], N["_____"], N["_____"], N["_____"], N["_____"], N["_____"], N["_____"],
			
			N["_____"], N["_____"], N["_____"], N["_____"], N["_____"], N["_____"], N["_____"], N["_____"], N["_____"],
			N["_____"], N["_____"], N["_____"], N["_____"], N["_____"], N["_____"], N["_____"], N["_____"], N["_____"],
			N["_____"], N["_____"], N["_____"], N["_____"], N["_____"], N["_____"], N["_____"], N["_____"], N["_____"],
			N["_____"], N["_____"], N["_____"], N["_____"], N["_____"], N["_____"], N["_____"], N["_____"], N["_____"],
			N["_____"], N["_____"], N["_____"], N["_____"], N["_____"], N["_____"], N["_____"], N["_____"], N["_____"],
			N["L0m01"], N["L0m00"], N["L0m00"], N["L0m01"], N["_____"], N["_____"], N["_____"], N["_____"], N["_____"],
			N["_____"], N["_____"], N["_____"], N["_____"], N["L0m01"], N["L0m00"], N["L0m00"], N["L0m00"], N["L0m01"],
			N["_____"], N["_____"], N["_____"], N["_____"], N["_____"], N["_____"], N["_____"], N["_____"], N["_____"],
			N["_____"], N["_____"], N["_____"], N["_____"], N["_____"], N["_____"], N["_____"], N["_____"], N["_____"],
			
			N["_____"], N["_____"], N["_____"], N["_____"], N["_____"], N["_____"], N["_____"], N["_____"], N["_____"],
			N["_____"], N["_____"], N["_____"], N["_____"], N["_____"], N["_____"], N["_____"], N["_____"], N["_____"],
			N["_____"], N["_____"], N["_____"], N["_____"], N["_____"], N["_____"], N["_____"], N["_____"], N["_____"],
			N["_____"], N["_____"], N["T0m00"], N["_____"], N["_____"], N["_____"], N["_____"], N["_____"], N["_____"],
			N["L0m01"], N["L0m00"], N["L0m00"], N["L0m01"], N["_____"], N["_____"], N["T0m00"], N["_____"], N["_____"],
			N["_____"], N["_____"], N["_____"], N["_____"], N["L0m01"], N["L0m00"], N["L0m00"], N["L0m00"], N["L0m01"],
			N["_____"], N["_____"], N["_____"], N["_____"], N["_____"], N["_____"], N["_____"], N["_____"], N["_____"],
			N["_____"], N["_____"], N["_____"], N["_____"], N["_____"], N["_____"], N["_____"], N["_____"], N["_____"],
			N["_____"], N["_____"], N["_____"], N["_____"], N["_____"], N["_____"], N["_____"], N["_____"], N["_____"],
			
			N["_____"], N["_____"], N["_____"], N["_____"], N["_____"], N["_____"], N["_____"], N["_____"], N["_____"],
			N["_____"], N["_____"], N["_____"], N["T0m00"], N["_____"], N["_____"], N["_____"], N["_____"], N["_____"],
			N["_____"], N["_____"], N["_____"], N["_____"], N["_____"], N["T0m00"], N["_____"], N["_____"], N["_____"],
			N["L0m01"], N["L0m01"], N["L0m01"], N["L0m01"], N["_____"], N["_____"], N["_____"], N["_____"], N["_____"],
			N["_____"], N["_____"], N["_____"], N["_____"], N["L0m01"], N["L0m00"], N["L0m00"], N["L0m00"], N["L0m01"],
			N["_____"], N["_____"], N["_____"], N["_____"], N["T0m00"], N["_____"], N["_____"], N["_____"], N["_____"],
			N["_____"], N["_____"], N["_____"], N["_____"], N["T0m00"], N["_____"], N["_____"], N["_____"], N["_____"],
			N["_____"], N["_____"], N["_____"], N["_____"], N["T0m00"], N["_____"], N["_____"], N["_____"], N["_____"],
			N["_____"], N["_____"], N["_____"], N["_____"], N["T0m00"], N["_____"], N["_____"], N["_____"], N["_____"],
			
			N["_____"], N["_____"], N["_____"], N["_____"], N["T0m00"], N["_____"], N["_____"], N["_____"], N["_____"],
			N["_____"], N["_____"], N["_____"], N["_____"], N["_____"], N["_____"], N["_____"], N["_____"], N["_____"],
			N["_____"], N["_____"], N["_____"], N["_____"], N["_____"], N["_____"], N["_____"], N["_____"], N["_____"],
			N["L0m01"], N["L0m01"], N["L0m01"], N["L0m01"], N["L0m01"], N["L0m01"], N["L0m01"], N["L0m01"], N["L0m01"],
			N["_____"], N["_____"], N["_____"], N["_____"], N["_____"], N["_____"], N["_____"], N["_____"], N["_____"],
			N["_____"], N["_____"], N["_____"], N["_____"], N["_____"], N["_____"], N["_____"], N["_____"], N["_____"],
			N["_____"], N["_____"], N["_____"], N["_____"], N["_____"], N["_____"], N["_____"], N["_____"], N["_____"],
			N["_____"], N["_____"], N["_____"], N["_____"], N["_____"], N["_____"], N["_____"], N["_____"], N["_____"],
			N["_____"], N["_____"], N["_____"], N["_____"], N["_____"], N["T0m00"], N["_____"], N["_____"], N["_____"],
			
			N["_____"], N["_____"], N["_____"], N["T0m00"], N["_____"], N["_____"], N["_____"], N["_____"], N["_____"],
			N["_____"], N["_____"], N["_____"], N["_____"], N["_____"], N["L0m01"], N["L0m01"], N["L0m01"], N["L0m01"],
			N["L0m01"], N["L0m00"], N["L0m00"], N["L0m00"], N["L0m01"], N["_____"], N["_____"], N["_____"], N["_____"],
			N["_____"], N["_____"], N["_____"], N["_____"], N["_____"], N["_____"], N["_____"], N["_____"], N["_____"],
			N["_____"], N["_____"], N["_____"], N["_____"], N["_____"], N["_____"], N["_____"], N["_____"], N["_____"],
			N["_____"], N["_____"], N["_____"], N["_____"], N["_____"], N["_____"], N["_____"], N["_____"], N["_____"],
			N["_____"], N["_____"], N["_____"], N["_____"], N["_____"], N["_____"], N["_____"], N["_____"], N["_____"],
			N["_____"], N["_____"], N["_____"], N["_____"], N["_____"], N["_____"], N["_____"], N["_____"], N["_____"],
			N["_____"], N["_____"], N["_____"], N["_____"], N["_____"], N["_____"], N["T0m00"], N["_____"], N["_____"],
			
			N["_____"], N["_____"], N["T0m00"], N["_____"], N["_____"], N["L0m01"], N["L0m00"], N["L0m00"], N["L0m01"],
			N["L0m01"], N["L0m00"], N["L0m00"], N["L0m00"], N["L0m01"], N["_____"], N["_____"], N["_____"], N["_____"],
			N["_____"], N["_____"], N["_____"], N["_____"], N["_____"], N["_____"], N["_____"], N["_____"], N["_____"],
			N["_____"], N["_____"], N["_____"], N["_____"], N["_____"], N["_____"], N["_____"], N["_____"], N["_____"],
			N["_____"], N["_____"], N["_____"], N["_____"], N["_____"], N["_____"], N["_____"], N["_____"], N["_____"],
			N["_____"], N["_____"], N["_____"], N["_____"], N["_____"], N["_____"], N["_____"], N["_____"], N["_____"],
			N["_____"], N["_____"], N["_____"], N["_____"], N["_____"], N["_____"], N["_____"], N["_____"], N["_____"],
			N["_____"], N["_____"], N["_____"], N["_____"], N["_____"], N["_____"], N["_____"], N["_____"], N["_____"],
			N["_____"], N["_____"], N["_____"], N["_____"], N["_____"], N["L0m01"], N["L0m00"], N["L0m00"], N["L0m01"],
			
			N["L0m01"], N["L0m00"], N["L0m00"], N["L0m00"], N["L0m01"], N["_____"], N["_____"], N["_____"], N["_____"],
			N["_____"], N["_____"], N["_____"], N["_____"], N["_____"], N["_____"], N["_____"], N["_____"], N["_____"],
			N["_____"], N["_____"], N["_____"], N["_____"], N["_____"], N["_____"], N["_____"], N["_____"], N["_____"],
			N["_____"], N["_____"], N["_____"], N["_____"], N["_____"], N["_____"], N["_____"], N["_____"], N["_____"],
			N["_____"], N["_____"], N["_____"], N["_____"], N["_____"], N["_____"], N["_____"], N["_____"], N["_____"],
			N["_____"], N["_____"], N["_____"], N["_____"], N["_____"], N["_____"], N["_____"], N["_____"], N["_____"],
			N["_____"], N["_____"], N["_____"], N["_____"], N["_____"], N["_____"], N["_____"], N["_____"], N["_____"],
			N["_____"], N["_____"], N["_____"], N["_____"], N["_____"], N["L0m01"], N["L0m01"], N["L0m01"], N["L0m01"],
			N["L0m01"], N["L0m01"], N["L0m01"], N["L0m01"], N["L0m01"], N["_____"], N["_____"], N["_____"], N["_____"]
		},
		yslice_prob = {
			{ypos = 0,prob = 254},
			{ypos = 1,prob = 254},
			{ypos = 2,prob = 126},
			{ypos = 3,prob = 254},
			{ypos = 4,prob = 254},
			{ypos = 5,prob = 254},
			{ypos = 6,prob = 254},
			{ypos = 7,prob = 254}
		}
	}
