



--Banana Tree
	local N = lib_ecology.N

	
		return {
			size = {x = 7, y = 8, z = 7},
			data = {
				N["_____"], N["_____"], N["_____"], N["_____"], N["_____"], N["_____"], N["_____"],
				N["_____"], N["_____"], N["_____"], N["_____"], N["_____"], N["_____"], N["_____"],
				N["_____"], N["_____"], N["_____"], N["_____"], N["_____"], N["_____"], N["_____"],
				N["_____"], N["_____"], N["_____"], N["_____"], N["_____"], N["_____"], N["_____"],
				N["_____"], N["_____"], N["_____"], N["_____"], N["_____"], N["_____"], N["_____"],
				N["_____"], N["_____"], N["_____"], N["_____"], N["_____"], N["_____"], N["_____"],
				N["_____"], N["_____"], N["_____"], N["L0m02"], N["_____"], N["_____"], N["_____"],
				N["_____"], N["_____"], N["_____"], N["L0m00"], N["_____"], N["_____"], N["_____"],

				N["_____"], N["_____"], N["_____"], N["_____"], N["_____"], N["_____"], N["_____"],
				N["_____"], N["_____"], N["_____"], N["_____"], N["_____"], N["_____"], N["_____"],
				N["_____"], N["_____"], N["_____"], N["_____"], N["_____"], N["_____"], N["_____"],
				N["_____"], N["_____"], N["_____"], N["_____"], N["_____"], N["_____"], N["_____"],
				N["_____"], N["_____"], N["_____"], N["F0m04"], N["_____"], N["_____"], N["_____"],
				N["_____"], N["_____"], N["_____"], N["F0m00"], N["_____"], N["_____"], N["_____"],
				N["_____"], N["_____"], N["_____"], N["L0m00"], N["_____"], N["_____"], N["_____"],
				N["_____"], N["_____"], N["_____"], N["_____"], N["_____"], N["_____"], N["_____"],

				N["_____"], N["_____"], N["_____"], N["_____"], N["_____"], N["_____"], N["_____"],
				N["_____"], N["_____"], N["_____"], N["_____"], N["_____"], N["_____"], N["_____"],
				N["_____"], N["_____"], N["_____"], N["_____"], N["_____"], N["_____"], N["_____"],
				N["_____"], N["_____"], N["_____"], N["_____"], N["_____"], N["_____"], N["_____"],
				N["_____"], N["_____"], N["F0m04"], N["T0m00"], N["F0m04"], N["_____"], N["_____"],
				N["_____"], N["_____"], N["F0m00"], N["L0m00"], N["F0m00"], N["_____"], N["_____"],
				N["_____"], N["L0m00"], N["L0m00"], N["L0m00"], N["L0m00"], N["L0m00"], N["_____"],
				N["L0m00"], N["L0m02"], N["_____"], N["L0m00"], N["_____"], N["L0m02"], N["L0m00"],

				N["_____"], N["_____"], N["_____"], N["T0m00"], N["_____"], N["_____"], N["_____"],
				N["_____"], N["_____"], N["_____"], N["T0m00"], N["_____"], N["_____"], N["_____"],
				N["_____"], N["_____"], N["_____"], N["T0m00"], N["_____"], N["_____"], N["_____"],
				N["_____"], N["_____"], N["_____"], N["T0m00"], N["_____"], N["_____"], N["_____"],
				N["_____"], N["_____"], N["_____"], N["F0m04"], N["_____"], N["_____"], N["_____"],
				N["_____"], N["_____"], N["_____"], N["F0m00"], N["_____"], N["_____"], N["_____"],
				N["_____"], N["_____"], N["_____"], N["L0m00"], N["_____"], N["_____"], N["_____"],
				N["_____"], N["_____"], N["_____"], N["_____"], N["_____"], N["_____"], N["_____"],

				N["_____"], N["_____"], N["_____"], N["_____"], N["_____"], N["_____"], N["_____"],
				N["_____"], N["_____"], N["_____"], N["_____"], N["_____"], N["_____"], N["_____"],
				N["_____"], N["_____"], N["_____"], N["_____"], N["_____"], N["_____"], N["_____"],
				N["_____"], N["_____"], N["_____"], N["_____"], N["_____"], N["_____"], N["_____"],
				N["_____"], N["_____"], N["_____"], N["_____"], N["_____"], N["_____"], N["_____"],
				N["_____"], N["_____"], N["_____"], N["_____"], N["_____"], N["_____"], N["_____"],
				N["_____"], N["_____"], N["_____"], N["L0m00"], N["_____"], N["_____"], N["_____"],
				N["_____"], N["_____"], N["_____"], N["L0m02"], N["_____"], N["_____"], N["_____"],

				N["_____"], N["_____"], N["_____"], N["_____"], N["_____"], N["_____"], N["_____"],
				N["_____"], N["_____"], N["_____"], N["_____"], N["_____"], N["_____"], N["_____"],
				N["_____"], N["_____"], N["_____"], N["_____"], N["_____"], N["_____"], N["_____"],
				N["_____"], N["_____"], N["_____"], N["_____"], N["_____"], N["_____"], N["_____"],
				N["_____"], N["_____"], N["_____"], N["_____"], N["_____"], N["_____"], N["_____"],
				N["_____"], N["_____"], N["_____"], N["_____"], N["_____"], N["_____"], N["_____"],
				N["_____"], N["_____"], N["_____"], N["_____"], N["_____"], N["_____"], N["_____"],
				N["_____"], N["_____"], N["_____"], N["L0m00"], N["_____"], N["_____"], N["_____"],

				N["_____"], N["_____"], N["_____"], N["_____"], N["_____"], N["_____"], N["_____"],
				N["_____"], N["_____"], N["_____"], N["_____"], N["_____"], N["_____"], N["_____"],
				N["_____"], N["_____"], N["_____"], N["_____"], N["_____"], N["_____"], N["_____"],
				N["_____"], N["_____"], N["_____"], N["_____"], N["_____"], N["_____"], N["_____"],
				N["_____"], N["_____"], N["_____"], N["_____"], N["_____"], N["_____"], N["_____"],
				N["_____"], N["_____"], N["_____"], N["_____"], N["_____"], N["_____"], N["_____"],
				N["_____"], N["_____"], N["_____"], N["_____"], N["_____"], N["_____"], N["_____"],
				N["_____"], N["_____"], N["_____"], N["_____"], N["_____"], N["_____"], N["_____"]
			},
			yslice_prob = {
				{ypos = 0, prob = 127},
				{ypos = 1, prob = 127},
				{ypos = 2, prob = 127},
				{ypos = 3, prob = 127},
				{ypos = 4, prob = 127},
				{ypos = 5, prob = 127},
				{ypos = 6, prob = 127},
				{ypos = 7, prob = 127}
			},
		}

