

local S = lib_ecology.intllib

--Local vars to define air and tree trunks, leaves, fruits, vines, and other associated nodes for use within the lua schematics
--air is defined as an _ (underscore) throughout
--Leaf direction and probabilities are defined.
--Trunk direction and probabilities are defined
--Vine direction is defined
--Fruit uses a generic probability of 127


--[[  LUA SCHEMATICS NEED TO BE REDEFINED TO USE CENTRALIZED LOCAL VARIABLES UPDATING EACH VAR FOR EACH SCHEMATIC
--]]

local __ = {name = "air",param2 = 0,prob = 0}
local D0 = {name = "lib_materials:dirt", param2 = 0, prob = 254}
local S0 = {name = "lib_materials:stone", param2 = 0, prob = 254}

local LL --= {name = "lib_ecology:tree_NAME_leaves",param2 = 0,prob = 254, force_place = true}
local L0 --= {name = "lib_ecology:tree_NAME_leaves",param2 = 0,prob = 254}
local L1 --= {name = "lib_ecology:tree_NAME_leaves",param2 = 0,prob = 222}
local L2 --= {name = "lib_ecology:tree_NAME_leaves",param2 = 0,prob = 190}
local L3 --= {name = "lib_ecology:tree_NAME_leaves",param2 = 0,prob = 126}
local L4 --= {name = "lib_ecology:tree_NAME_leaves",param2 = 0,prob = 96}
local L5 --= {name = "lib_ecology:tree_NAME_leaves",param2 = 0,prob = 64}
local L6 --= {name = "lib_ecology:tree_NAME_leaves",param2 = 0,prob = 32}
local LN --= {name = "lib_ecology:tree_NAME_leaves",param2 = 0,prob = 254}
local LE --= {name = "lib_ecology:tree_NAME_leaves",param2 = 1,prob = 254}
local LS --= {name = "lib_ecology:tree_NAME_leaves",param2 = 2,prob = 254}
local LW --= {name = "lib_ecology:tree_NAME_leaves",param2 = 3,prob = 254}

local TT --= {name = "lib_ecology:tree_NAME_trunk",param2 = 0,prob = 254, force_place = true}
local T0 --= {name = "lib_ecology:tree_NAME_trunk",param2 = 0,prob = 254}
local T1 --= {name = "lib_ecology:tree_NAME_trunk",param2 = 0,prob = 254}
local T2 --= {name = "lib_ecology:tree_NAME_trunk",param2 = 0,prob = 160}
local T3 --= {name = "lib_ecology:tree_NAME_trunk",param2 = 0,prob = 127}
local TN --= {name = "lib_ecology:tree_NAME_trunk",param2 = 4,prob = 254}
local TS --= {name = "lib_ecology:tree_NAME_trunk",param2 = 8,prob = 254}
local TE --= {name = "lib_ecology:tree_NAME_trunk",param2 = 12,prob = 254}
local TW --= {name = "lib_ecology:tree_NAME_trunk",param2 = 16,prob = 254}

local V0 --= {name = "lib_ecology:plant_vine_01",param2 = 0,prob = 254}
local V1 --= {name = "lib_ecology:plant_vine_01",param2 = 1,prob = 254}
local V2 --= {name = "lib_ecology:plant_vine_01",param2 = 2,prob = 254}
local V3 --= {name = "lib_ecology:plant_vine_01",param2 = 3,prob = 254}
local VN --= {name = "lib_ecology:plant_vine_01",param2 = 0,prob = 254}
local VE --= {name = "lib_ecology:plant_vine_01",param2 = 1,prob = 254}
local VS --= {name = "lib_ecology:plant_vine_01",param2 = 2,prob = 254}
local VW --= {name = "lib_ecology:plant_vine_01",param2 = 3,prob = 254}

local F0 --= {name = "lib_ecology:fruit_NAME",param2 = 0,prob = 254}
local F1 --= {name = "lib_ecology:fruit_NAME",param2 = 0,prob = 222}
local F2 --= {name = "lib_ecology:fruit_NAME",param2 = 0,prob = 190}
local F3 --= {name = "lib_ecology:fruit_NAME",param2 = 0,prob = 127}
local F4 --= {name = "lib_ecology:fruit_NAME",param2 = 0,prob = 62}
local FN --= {name = "lib_ecology:fruit_NAME",param2 = 0,prob = 254}
local FE --= {name = "lib_ecology:fruit_NAME",param2 = 1,prob = 254}
local FS --= {name = "lib_ecology:fruit_NAME",param2 = 2,prob = 254}
local FW --= {name = "lib_ecology:fruit_NAME",param2 = 3,prob = 254}

local CN --= {name = "lib_ecology:fruit_NAME",param2 = 0,prob = 254}
local CE --= {name = "lib_ecology:fruit_NAME",param2 = 1,prob = 254}
local CS --= {name = "lib_ecology:fruit_NAME",param2 = 2,prob = 254}
local CW --= {name = "lib_ecology:fruit_NAME",param2 = 3,prob = 254}

local le_temp_schem = {}

--PLANTS

-- Bamboo Stalk with Leaves
	le_temp_schem = {
		size = {x = 1,y = 7,z = 1},
		data = {
			{param2 = 0,name = "lib_ecology:tree_bamboo_small",prob = 254},
			{param2 = 0,name = "lib_ecology:tree_bamboo_small",prob = 254},
			{param2 = 0,name = "lib_ecology:tree_bamboo_small",prob = 254},
			{param2 = 0,name = "lib_ecology:tree_bamboo_small",prob = 254},
			{param2 = 0,name = "lib_ecology:tree_bamboo_small",prob = 254},
			{param2 = 0,name = "lib_ecology:tree_bamboo_small",prob = 254},
			{param2 = 0,name = "lib_ecology:tree_bamboo_small_top",prob = 254}
		},
		yslice_prob = {
			{ypos = 0,prob = 254},
			{ypos = 1,prob = 127},
			{ypos = 2,prob = 254},
			{ypos = 3,prob = 127},
			{ypos = 4,prob = 254},
			{ypos = 5,prob = 254},
			{ypos = 6,prob = 254}
		}
	}
lib_ecology.schematics.insert("tree_bamboo_small_01", le_temp_schem)

--Cactus
	T0 = {name = "lib_ecology:cactus_green_trunk", param2 = 0, prob = 254}
	le_temp_schem = {
		size = {x = 5,y = 6,z = 1},
		data = {
			__, __, T0, __, __,
			__, __, T0, __, __,
			__, __, T0, __, __,
			T0, T0, T0, T0, T0,
			T0, __, T0, __, T0,
			__, __, T0, __, __
		},
		yslice_prob = {
			{ypos = 0,prob = 254},
			{ypos = 1,prob = 127},
			{ypos = 2,prob = 254},
			{ypos = 3,prob = 127},
			{ypos = 4,prob = 254},
			{ypos = 5,prob = 254}
		}
	}
lib_ecology.schematics.insert("schem_cactus_01", le_temp_schem)



--Fern Trees
	local tr = {name = "lib_ecology:tree_fern_giant_trunk", param2 = 0, prob = 254}
	local tt = {name = "lib_ecology:tree_fern_giant_trunk_top", param2 = 0, prob = 254}
	local lp = {name = "lib_ecology:tree_fern_giant_leaves", param2 = 0, prob = 254}
	local ln = {name = "lib_ecology:tree_fern_giant_leaves_end", param2 = 0, prob = 254}
	local le = {name = "lib_ecology:tree_fern_giant_leaves_end", param2 = 1, prob = 254}
	local ls = {name = "lib_ecology:tree_fern_giant_leaves_end", param2 = 2, prob = 254}
	local lw = {name = "lib_ecology:tree_fern_giant_leaves_end", param2 = 3, prob = 254}
	local cr = {name = "lib_ecology:tree_fern_giant_crown", param2 = 0, prob = 254}
	le_temp_schem = {
		size = {x = 7, y = 21, z = 7},
		data = {

			__, __, __, __, __, __, __, 
			__, __, __, __, __, __, __, 
			__, __, __, __, __, __, __, 
			__, __, __, __, __, __, __, 
			__, __, __, __, __, __, __, 
			__, __, __, __, __, __, __, 
			__, __, __, __, __, __, __, 
			__, __, __, __, __, __, __, 
			__, __, __, __, __, __, __, 
			__, __, __, __, __, __, __, 
			__, __, __, __, __, __, __, 
			__, __, __, __, __, __, __, 
			__, __, __, __, __, __, __, 
			__, __, __, __, __, __, __, 
			__, __, __, __, __, __, __, 
			__, __, __, __, __, __, __, 
			__, __, __, __, __, __, __, 
			__, __, __, __, __, __, __, 
			__, __, __, ls, __, __, __, 
			__, __, __, lp, __, __, __, 
			__, __, __, __, __, __, __, 

			__, __, __, __, __, __, __, 
			__, __, __, __, __, __, __, 
			__, __, __, __, __, __, __, 
			__, __, __, __, __, __, __, 
			__, __, __, __, __, __, __, 
			__, __, __, __, __, __, __, 
			__, __, __, __, __, __, __, 
			__, __, __, __, __, __, __, 
			__, __, __, __, __, __, __, 
			__, __, __, __, __, __, __, 
			__, __, __, __, __, __, __, 
			__, __, __, __, __, __, __, 
			__, __, __, __, __, __, __, 
			__, __, __, __, __, __, __, 
			__, __, __, __, __, __, __, 
			__, __, __, __, __, __, __, 
			__, __, __, __, __, __, __, 
			__, __, __, __, __, __, __, 
			__, __, __, __, __, __, __, 
			__, __, __, __, __, __, __, 
			__, __, __, lp, __, __, __, 

			__, __, __, __, __, __, __, 
			__, __, __, __, __, __, __, 
			__, __, __, __, __, __, __, 
			__, __, __, __, __, __, __, 
			__, __, __, __, __, __, __, 
			__, __, __, __, __, __, __, 
			__, __, __, __, __, __, __, 
			__, __, __, __, __, __, __, 
			__, __, __, __, __, __, __, 
			__, __, __, __, __, __, __, 
			__, __, __, __, __, __, __, 
			__, __, __, __, __, __, __, 
			__, __, __, __, __, __, __, 
			__, __, __, __, __, __, __, 
			__, __, __, __, __, __, __, 
			__, __, __, __, __, __, __, 
			__, __, __, __, __, __, __, 
			__, __, __, __, __, __, __, 
			__, __, __, __, __, __, __, 
			__, __, __, lp, __, __, __, 
			__, __, __, __, __, __, __, 

			__, __, __, tr, __, __, __, 
			__, __, __, tr, __, __, __, 
			__, __, __, tr, __, __, __, 
			__, __, __, tr, __, __, __, 
			__, __, __, tr, __, __, __, 
			__, __, __, tr, __, __, __, 
			__, __, __, tr, __, __, __, 
			__, __, __, tr, __, __, __, 
			__, __, __, tr, __, __, __, 
			__, __, __, tr, __, __, __, 
			__, __, __, tr, __, __, __, 
			__, __, __, tr, __, __, __, 
			__, __, __, tr, __, __, __, 
			__, __, __, tr, __, __, __, 
			__, __, __, tr, __, __, __, 
			__, __, __, tr, __, __, __, 
			__, __, __, tr, __, __, __, 
			__, __, __, tr, __, __, __, 
			lw, __, __, tr, __, __, le, 
			lp, __, lp, cr, lp, __, lp, 
			__, lp, __, __, __, lp, __, 

			__, __, __, __, __, __, __, 
			__, __, __, __, __, __, __, 
			__, __, __, __, __, __, __, 
			__, __, __, __, __, __, __, 
			__, __, __, __, __, __, __, 
			__, __, __, __, __, __, __, 
			__, __, __, __, __, __, __, 
			__, __, __, __, __, __, __, 
			__, __, __, __, __, __, __, 
			__, __, __, __, __, __, __, 
			__, __, __, __, __, __, __, 
			__, __, __, __, __, __, __, 
			__, __, __, __, __, __, __, 
			__, __, __, __, __, __, __, 
			__, __, __, __, __, __, __, 
			__, __, __, __, __, __, __, 
			__, __, __, __, __, __, __, 
			__, __, __, __, __, __, __, 
			__, __, __, __, __, __, __, 
			__, __, __, lp, __, __, __, 
			__, __, __, __, __, __, __, 

			__, __, __, __, __, __, __, 
			__, __, __, __, __, __, __, 
			__, __, __, __, __, __, __, 
			__, __, __, __, __, __, __, 
			__, __, __, __, __, __, __, 
			__, __, __, __, __, __, __, 
			__, __, __, __, __, __, __, 
			__, __, __, __, __, __, __, 
			__, __, __, __, __, __, __, 
			__, __, __, __, __, __, __, 
			__, __, __, __, __, __, __, 
			__, __, __, __, __, __, __, 
			__, __, __, __, __, __, __, 
			__, __, __, __, __, __, __, 
			__, __, __, __, __, __, __, 
			__, __, __, __, __, __, __, 
			__, __, __, __, __, __, __, 
			__, __, __, __, __, __, __, 
			__, __, __, __, __, __, __, 
			__, __, __, __, __, __, __, 
			__, __, __, lp, __, __, __, 

			__, __, __, __, __, __, __, 
			__, __, __, __, __, __, __, 
			__, __, __, __, __, __, __, 
			__, __, __, __, __, __, __, 
			__, __, __, __, __, __, __, 
			__, __, __, __, __, __, __, 
			__, __, __, __, __, __, __, 
			__, __, __, __, __, __, __, 
			__, __, __, __, __, __, __, 
			__, __, __, __, __, __, __, 
			__, __, __, __, __, __, __, 
			__, __, __, __, __, __, __, 
			__, __, __, __, __, __, __, 
			__, __, __, __, __, __, __, 
			__, __, __, __, __, __, __, 
			__, __, __, __, __, __, __, 
			__, __, __, __, __, __, __, 
			__, __, __, __, __, __, __, 
			__, __, __, ln, __, __, __, 
			__, __, __, lp, __, __, __, 
			__, __, __, __, __, __, __, 

		},
		yslice_prob = {
			{ypos = 0,prob = 254},
			{ypos = 1,prob = 127},
			{ypos = 2,prob = 254},
			{ypos = 3,prob = 127},
			{ypos = 4,prob = 254},
			{ypos = 5,prob = 127},
			{ypos = 6,prob = 254},
			{ypos = 7,prob = 127},
			{ypos = 8,prob = 254},
			{ypos = 9,prob = 127},
			{ypos = 10,prob = 254},
			{ypos = 11,prob = 127},
			{ypos = 12,prob = 254},
			{ypos = 13,prob = 127},
			{ypos = 14,prob = 254},
			{ypos = 15,prob = 127},
			{ypos = 16,prob = 254},
			{ypos = 17,prob = 254},
			{ypos = 18,prob = 254},
			{ypos = 19,prob = 254},
			{ypos = 20,prob = 254}
		}
	}
lib_ecology.schematics.insert("schem_tree_fern_giant", le_temp_schem)

	local lbn = {name = "lib_ecology:tree_fern_giant_leaves_big", param2 = 0, prob = 254}
	local lbe = {name = "lib_ecology:tree_fern_giant_leaves_big", param2 = 1, prob = 254}
	local lbs = {name = "lib_ecology:tree_fern_giant_leaves_big", param2 = 2, prob = 254}
	local lbw = {name = "lib_ecology:tree_fern_giant_leaves_big", param2 = 3, prob = 254}
	le_temp_schem = {
		size = {x = 7, y = 7, z = 7},
		data = {

			__, __, __, __, __, __, __, 
			__, __, __, __, __, __, __, 
			__, __, __, __, __, __, __, 
			__, __, __, __, __, __, __, 
			__, __, __, __, __, __, __, 
			__, __, __,lbs, __, __, __, 
			__, __, __, __, __, __, __, 

			__, __, __, __, __, __, __, 
			__, __, __, __, __, __, __, 
			__, __, __, __, __, __, __, 
			__, __, __, __, __, __, __, 
			__, __, __, __, __, __, __, 
			__, __, __, __, __, __, __, 
			__, __, __,lbs, __, __, __, 

			__, __, __, __, __, __, __, 
			__, __, __, __, __, __, __, 
			__, __, __, __, __, __, __, 
			__, __, __, __, __, __, __, 
			__, __, __, __, __, __, __, 
			__, __, __,lbs, __, __, __, 
			__, __, __, __, __, __, __, 

			__, __, __, tr, __, __, __, 
			__, __, __, tr, __, __, __, 
			__, __, __, tr, __, __, __, 
			__, __, __, tr, __, __, __, 
			__, __, __, tr, __, __, __, 
			lbw, __,lbw,cr,lbe, __,lbe, 
			__, lbw, __,__, __,lbe, __, 

			__, __, __, __, __, __, __, 
			__, __, __, __, __, __, __, 
			__, __, __, __, __, __, __, 
			__, __, __, __, __, __, __, 
			__, __, __, __, __, __, __, 
			__, __, __,lbn, __, __, __, 
			__, __, __, __, __, __, __, 

			__, __, __, __, __, __, __, 
			__, __, __, __, __, __, __, 
			__, __, __, __, __, __, __, 
			__, __, __, __, __, __, __, 
			__, __, __, __, __, __, __, 
			__, __, __, __, __, __, __, 
			__, __, __,lbn, __, __, __, 

			__, __, __, __, __, __, __, 
			__, __, __, __, __, __, __, 
			__, __, __, __, __, __, __, 
			__, __, __, __, __, __, __, 
			__, __, __, __, __, __, __, 
			__, __, __,lbn, __, __, __, 
			__, __, __, __, __, __, __, 

		},
		yslice_prob = {
			{ypos = 0,prob = 254},
			{ypos = 1,prob = 127},
			{ypos = 2,prob = 254},
			{ypos = 3,prob = 127},
			{ypos = 4,prob = 254},
			{ypos = 5,prob = 254},
			{ypos = 6,prob = 254}
		}
	}
lib_ecology.schematics.insert("schem_tree_fern", le_temp_schem)

	cr = {name = "lib_ecology:fern_giant_tree_crown2", param2 = 0, prob = 254}
	lp = {name = "lib_ecology:fern_giant_tree_leaves_2", param2 = 0, prob = 254}
	ln = {name = "lib_ecology:fern_giant_tree_leaves_end_2", param2 = 0, prob = 254}
	le = {name = "lib_ecology:fern_giant_tree_leaves_end_2", param2 = 1, prob = 254}
	ls = {name = "lib_ecology:fern_giant_tree_leaves_end_2", param2 = 2, prob = 254}
	lw = {name = "lib_ecology:fern_giant_tree_leaves_end_2", param2 = 3, prob = 254}
	le_temp_schem = {
		size = {x = 7, y = 7, z = 7},
		data = {

			__, __, __, __, __, __, __, 
			__, __, __, __, __, __, __, 
			__, __, __, __, __, __, __, 
			__, __, __, __, __, __, __, 
			__, __, __, ls, __, __, __, 
			__, __, __, lp, __, __, __, 
			__, __, __, __, __, __, __, 

			__, __, __, __, __, __, __, 
			__, __, __, __, __, __, __, 
			__, __, __, __, __, __, __, 
			__, __, __, __, __, __, __, 
			__, __, __, __, __, __, __, 
			__, __, __, __, __, __, __, 
			__, __, __, lp, __, __, __, 

			__, __, __, __, __, __, __, 
			__, __, __, __, __, __, __, 
			__, __, __, __, __, __, __, 
			__, __, __, __, __, __, __, 
			__, __, __, __, __, __, __, 
			__, __, __, lp, __, __, __, 
			__, __, __, __, __, __, __, 

			__, __, __, tr, __, __, __, 
			__, __, __, tr, __, __, __, 
			__, __, __, tr, __, __, __, 
			__, __, __, tr, __, __, __, 
			lw, __, __, tt, __, __, le, 
			lp, __, lp, cr, lp, __, lp, 
			__, lp, __, __, __, lp, __, 

			__, __, __, __, __, __, __, 
			__, __, __, __, __, __, __, 
			__, __, __, __, __, __, __, 
			__, __, __, __, __, __, __, 
			__, __, __, __, __, __, __, 
			__, __, __, lp, __, __, __, 
			__, __, __, __, __, __, __, 

			__, __, __, __, __, __, __, 
			__, __, __, __, __, __, __, 
			__, __, __, __, __, __, __, 
			__, __, __, __, __, __, __, 
			__, __, __, __, __, __, __, 
			__, __, __, __, __, __, __, 
			__, __, __, lp, __, __, __, 

			__, __, __, __, __, __, __, 
			__, __, __, __, __, __, __, 
			__, __, __, __, __, __, __, 
			__, __, __, __, __, __, __, 
			__, __, __, ln, __, __, __, 
			__, __, __, lp, __, __, __, 
			__, __, __, __, __, __, __, 

		},
		yslice_prob = {
			{ypos = 0,prob = 254},
			{ypos = 1,prob = 127},
			{ypos = 2,prob = 254},
			{ypos = 3,prob = 254},
			{ypos = 4,prob = 254},
			{ypos = 5,prob = 254},
			{ypos = 6,prob = 254}
		}
	}
lib_ecology.schematics.insert("schem_tree_fern_giant_2", le_temp_schem)

	le_temp_schem = {
		size = {x = 1,y = 4,z = 1},
		data = {
			{param2 = 0,name = "lib_ecology:tree_fern_small_trunk",prob = 254},
			{param2 = 0,name = "lib_ecology:tree_fern_small_trunk",prob = 254},
			{param2 = 0,name = "lib_ecology:tree_fern_small_trunk",prob = 254},
			{param2 = 0,name = "lib_ecology:tree_fern_small_leaves_01",prob = 254}
		},
		yslice_prob = {
			{ypos = 0,prob = 254},
			{ypos = 1,prob = 127},
			{ypos = 2,prob = 254},
			{ypos = 3,prob = 254}
		}
	}
lib_ecology.schematics.insert("schem_tree_fern_small_01", le_temp_schem)

	le_temp_schem = {
		size = {x = 1,y = 4,z = 1},
		data = {
			{param2 = 0,name = "lib_ecology:tree_fern_small_trunk",prob = 254},
			{param2 = 0,name = "lib_ecology:tree_fern_small_trunk",prob = 254},
			{param2 = 0,name = "lib_ecology:tree_fern_small_trunk",prob = 254},
			{param2 = 0,name = "lib_ecology:tree_fern_small_leaves_02",prob = 254}
		},
		yslice_prob = {
			{ypos = 0,prob = 254},
			{ypos = 1,prob = 127},
			{ypos = 2,prob = 254},
			{ypos = 3,prob = 254}
		}
	}
lib_ecology.schematics.insert("schem_tree_fern_small_02", le_temp_schem)

	le_temp_schem = {
		size = {x = 1,y = 6,z = 1},
		data = {
			{param2 = 0,name = "lib_ecology:tree_fern_small_trunk",prob = 254},
			{param2 = 0,name = "lib_ecology:tree_fern_small_trunk",prob = 254},
			{param2 = 0,name = "lib_ecology:tree_fern_small_trunk",prob = 254},
			{param2 = 0,name = "lib_ecology:tree_fern_small_trunk",prob = 254},
			{param2 = 0,name = "lib_ecology:tree_fern_small_trunk_top",prob = 254},
			{param2 = 0,name = "lib_ecology:tree_fern_small_leaves",prob = 254}
		},
		yslice_prob = {
			{ypos = 0,prob = 254},
			{ypos = 1,prob = 127},
			{ypos = 2,prob = 254},
			{ypos = 3,prob = 127},
			{ypos = 4,prob = 254},
			{ypos = 5,prob = 254},
			{ypos = 6,prob = 254}
		}
	}
lib_ecology.schematics.insert("schem_tree_fern_small", le_temp_schem)

-- Reedmace
	le_temp_schem = {
		size = {x = 1,y = 4,z = 1},
		data = {
			{param2 = 0,name = "lib_ecology:plant_reedmace_bottom",prob = 254},
			{param2 = 0,name = "lib_ecology:plant_reedmace_bottom",prob = 254},
			{param2 = 0,name = "lib_ecology:plant_reedmace",prob = 254},
			{param2 = 0,name = "lib_ecology:plant_reedmace_top",prob = 254}
		},
		yslice_prob = {
			{ypos = 0,prob = 254},
			{ypos = 1,prob = 254},
			{ypos = 2,prob = 254},
--			{ypos = 3,prob = 254}
		}
	}
lib_ecology.schematics.insert("schem_plant_reedmace", le_temp_schem)

	le_temp_schem = {
		size = {x = 1,y = 4,z = 1},
		data = {
			{param2 = 0,name = "lib_ecology:plant_reedmace_bottom",prob = 254},
			{param2 = 0,name = "lib_ecology:plant_reedmace_bottom",prob = 254},
			{param2 = 0,name = "lib_ecology:plant_reedmace",prob = 254},
			{param2 = 0,name = "lib_ecology:plant_reedmace_spikes",prob = 254}
		},
		yslice_prob = {
			{ypos = 0,prob = 254},
			{ypos = 1,prob = 254},
			{ypos = 2,prob = 254},
--			{ypos = 3,prob = 254}
		}
	}
lib_ecology.schematics.insert("schem_plant_reedmace_with_flowers", le_temp_schem)

-- Kelp / Seaweed
	lib_ecology.schem_plant_kelp_02_1 = {
		size = {x = 1,y = 3,z = 1},
		data = {
			{param2 = 0,name = "lib_materials:sand",prob = 254},
			{param2 = 0,name = "lib_materials:sand",prob = 254},
			{param2 = 0,name = "lib_ecology:plant_kelp_02_1",prob = 254}
		},
		yslice_prob = {
			{ypos = 0,prob = 254},
			{ypos = 1,prob = 254},
			{ypos = 2,prob = 254}
		}
	}
	lib_ecology.schem_plant_seaweed2 = {
		size = {x = 1,y = 3,z = 1},
		data = {
			{param2 = 0,name = "lib_materials:sand",prob = 254},
			{param2 = 0,name = "lib_materials:sand",prob = 254},
			{param2 = 0,name = "lib_ecology:plant_seaweed2",prob = 254}
		},
		yslice_prob = {
			{ypos = 0,prob = 254},
			{ypos = 1,prob = 254},
			{ypos = 2,prob = 254}
		}
	}
	lib_ecology.schem_plant_seaweed3 = {
		size = {x = 1,y = 3,z = 1},
		data = {
			{param2 = 0,name = "lib_materials:sand",prob = 254},
			{param2 = 0,name = "lib_materials:sand",prob = 254},
			{param2 = 0,name = "lib_ecology:plant_seaweed3",prob = 254}
		},
		yslice_prob = {
			{ypos = 0,prob = 254},
			{ypos = 1,prob = 254},
			{ypos = 2,prob = 254}
		}
	}


-- custom
	lib_ecology.plant_test_banana = {
		size = {x = 1,y = 3,z = 1},
		data = {
			{param2 = 0,name = "lib_materials:dirt",prob = 254},
			{param2 = 0,name = "lib_ecology:plant_test_plant_rooted_01",prob = 254},
			{param2 = 0,name = "lib_ecology:plant_bananaplant2",prob = 254}
		},
		yslice_prob = {
			{ypos = 0,prob = 254},
			{ypos = 1,prob = 254},
			{ypos = 2,prob = 254}
		}
	}
	lib_ecology.plant_test_fern = {
		size = {x = 1,y = 3,z = 1},
		data = {
			{param2 = 0,name = "lib_materials:dirt",prob = 254},
			{param2 = 0,name = "lib_ecology:plant_test_plant_rooted_02",prob = 254},
			{param2 = 0,name = "lib_ecology:fern_ladyfern",prob = 254}
		},
		yslice_prob = {
			{ypos = 0,prob = 254},
			{ypos = 1,prob = 254},
			{ypos = 2,prob = 254}
		}
	}
	lib_ecology.plant_tree_palmetto = {
		size = {x = 1,y = 2,z = 1},
		data = {
			{param2 = 0,name = "lib_materials:dirt",prob = 254},
			{param2 = 0,name = "lib_ecology:tree_palm_palmetto",prob = 254}
		},
		yslice_prob = {
			{ypos = 0,prob = 254},
			{ypos = 1,prob = 254}
		}
	}
	lib_ecology.plant_banana_tree_01 = {
		size = {x = 1,y = 4,z = 1},
		data = {
			{param2 = 0,name = "lib_materials:dirt",prob = 254},
			{param2 = 0,name = "lib_ecology:plant_banana_tree_trunk",prob = 254},
			{param2 = 0,name = "lib_ecology:plant_banana_tree_trunk_top",prob = 254},
			{param2 = 0,name = "lib_ecology:plant_banana_tree_leaves",prob = 254}
		},
		yslice_prob = {
			{ypos = 0,prob = 254},
			{ypos = 1,prob = 254},
			{ypos = 2,prob = 254},
			{ypos = 3,prob = 254}
		}
	}

-- bush
local ai = {name = "air", param1 = 000}
local bp = {name = "lib_ecology:bush", param1 = 255}
local br = {name = "lib_ecology:bush", param1 = 100}
lib_ecology.bush = {

	size = {x = 5, y = 3, z = 5},

	data = {

		br, bp, bp, bp, br,
		ai, ai, ai, ai, ai,
		ai, ai, ai, ai, ai,

		bp, bp, bp, bp, bp,
		ai, br, bp, br, ai,
		ai, ai, ai, ai, ai,

		bp, bp, bp, bp, bp,
		ai, bp, bp, bp, ai,
		ai, ai, br, ai, ai,

		bp, bp, bp, bp, bp,
		ai, br, bp, br, ai,
		ai, ai, ai, ai, ai,

		br, bp, bp, bp, br,
		ai, ai, ai, ai, ai,
		ai, ai, ai, ai, ai,

	},

	yslice_prob = {
		{ypos = 1, prob = 127},
	},
}




--Blueberry bush
T0 = {name = "lib_ecology:bush_trunk", param2 = 0, prob = 254}
L0 = {name = "lib_ecology:bush_blueberry_leaves", param2 = 0, prob = 254}
L1 = {name = "lib_ecology:bush_blueberry_leaves", param2 = 0, prob = 192}
le_temp_schem = {
	size = {x = 3, y = 4, z = 3},
	data = {
		__, __, __,
		__, __, __,
		L0, L0, L0,
		L0, L1, L0,

		__, D0, __,
		__, T0, __,
		L0, L0, L0,
		L1, L0, L0,

		__, __, __,
		__, __, __,
		L0, L0, L0,
		L0, L0, L1
	},
	yslice_prob = {
		{ypos = 0,prob = 254},
		{ypos = 1,prob = 254},
		{ypos = 2,prob = 254},
		{ypos = 3,prob = 254},
	}
}
lib_ecology.schematics.insert("schem_bush_blueberry", le_temp_schem)

--Hawthorne bush
T0 = {name = "lib_ecology:bush_trunk", param2 = 0, prob = 254}
L0 = {name = "lib_ecology:bush_hawthorne_leaves", param2 = 0, prob = 254}
L1 = {name = "lib_ecology:bush_hawthorne_leaves", param2 = 0, prob = 192}
le_temp_schem = {
	size = {x = 3, y = 4, z = 3},
	data = {
		__, __, __,
		__, __, __,
		L0, L0, L0,
		L0, L1, L0,

		__, D0, __,
		__, T0, __,
		L0, L0, L0,
		L1, L0, L0,

		__, __, __,
		__, __, __,
		L0, L0, L0,
		L0, L0, L1
	},
	yslice_prob = {
		{ypos = 0,prob = 254},
		{ypos = 1,prob = 254},
		{ypos = 2,prob = 254},
		{ypos = 3,prob = 254},
	}
}
lib_ecology.schematics.insert("schem_bush_hawthorne", le_temp_schem)

--Rhodedendron bush
T0 = {name = "lib_ecology:bush_trunk", param2 = 0, prob = 254}
L0 = {name = "lib_ecology:bush_rhodedendron_leaves_1", param2 = 0, prob = 254}
L1 = {name = "lib_ecology:bush_rhodedendron_leaves_1", param2 = 0, prob = 192}
le_temp_schem = {
	size = {x = 3, y = 4, z = 3},
	data = {
		__, __, __,
		__, __, __,
		L0, L0, L0,
		L0, L1, L0,

		__, D0, __,
		__, T0, __,
		L0, L0, L0,
		L1, L0, L0,

		__, __, __,
		__, __, __,
		L0, L0, L0,
		L0, L0, L1
	},
	yslice_prob = {
		{ypos = 0,prob = 254},
		{ypos = 1,prob = 254},
		{ypos = 2,prob = 254},
		{ypos = 3,prob = 254},
	}
}
lib_ecology.schematics.insert("schem_bush_rhodedendron", le_temp_schem)

--Rhodedendron bush
T0 = {name = "lib_ecology:bush_trunk", param2 = 0, prob = 254}
L0 = {name = "lib_ecology:bush_rhodedendron_leaves_3", param2 = 0, prob = 254}
L1 = {name = "lib_ecology:bush_rhodedendron_leaves_3", param2 = 0, prob = 192}
le_temp_schem = {
	size = {x = 3, y = 4, z = 3},
	data = {
		__, __, __,
		__, __, __,
		L0, L0, L0,
		L0, L1, L0,

		__, D0, __,
		__, T0, __,
		L0, L0, L0,
		L1, L0, L0,

		__, __, __,
		__, __, __,
		L0, L0, L0,
		L0, L0, L1
	},
	yslice_prob = {
		{ypos = 0,prob = 254},
		{ypos = 1,prob = 254},
		{ypos = 2,prob = 254},
		{ypos = 3,prob = 254},
	}
}
lib_ecology.schematics.insert("schem_bush_rhodedendron_blooming", le_temp_schem)


--mushrooms

	T0 = {name = "lib_ecology:mushroom_01_trunk", param2 = 0, prob = 254}
	L0 = {name = "lib_ecology:mushroom_cap_red_spotted", param2 = 0, prob = 254}
	F0 = {name = "lib_ecology:mushroom_spore_01", param2 = 0, prob = 254}
	le_temp_schem = {
		size = {x = 8,y = 11,z = 8},
		data = {
			__, __, __, __, __, __, __, __,
			__, __, __, __, __, __, __, __,
			__, __, __, __, __, __, __, __,
			__, __, __, __, __, __, __, __,
			__, __, __, __, __, __, __, __,
			__, __, __, __, __, __, __, __,
			__, __, __, __, __, __, __, __,
			__, __, __, L0, L0, __, __, __,
			__, __, __, L0, L0, __, __, __,
			__, __, __, __, __, __, __, __,
			__, __, __, __, __, __, __, __,

			__, __, __, __, __, __, __, __,
			__, __, __, __, __, __, __, __,
			__, __, __, __, __, __, __, __,
			__, __, __, __, __, __, __, __,
			__, __, __, __, __, __, __, __,
			__, __, __, __, __, __, __, __,
			__, __, __, __, __, __, __, __,
			__, __, L0, __, __, L0, __, __,
			__, __, L0, __, __, L0, __, __,
			__, __, __, L0, L0, __, __, __,
			__, __, __, __, __, __, __, __,

			__, __, __, __, __, __, __, __,
			__, __, __, __, __, __, __, __,
			__, __, __, __, __, __, __, __,
			__, __, __, __, __, __, __, __,
			__, __, __, __, __, __, __, __,
			__, __, __, __, __, __, __, __,
			__, __, __, __, __, __, __, __,
			__, L0, __, __, __, __, L0, __,
			__, L0, __, __, __, __, L0, __,
			__, __, L0, F0, F0, L0, __, __,
			__, __, __, L0, L0, __, __, __,

			__, __, __, T0, T0, __, __, __,
			__, __, __, T0, T0, __, __, __,
			__, __, __, T0, T0, __, __, __,
			__, __, __, T0, T0, __, __, __,
			__, __, __, T0, T0, __, __, __,
			__, __, __, T0, T0, __, __, __,
			__, __, __, T0, T0, __, __, __,
			L0, __, __, T0, T0, __, __, L0,
			L0, __, __, T0, T0, __, __, L0,
			__, L0, F0, F0, F0, F0, L0, __,
			__, __, L0, L0, L0, L0, __, __,

			__, __, __, T0, T0, __, __, __,
			__, __, __, T0, T0, __, __, __,
			__, __, __, T0, T0, __, __, __,
			__, __, __, T0, T0, __, __, __,
			__, __, __, T0, T0, __, __, __,
			__, __, __, T0, T0, __, __, __,
			__, __, __, T0, T0, __, __, __,
			L0, __, __, T0, T0, __, __, L0,
			L0, __, __, T0, T0, __, __, L0,
			__, L0, F0, F0, F0, F0, L0, __,
			__, __, L0, L0, L0, L0, __, __,

			__, __, __, __, __, __, __, __,
			__, __, __, __, __, __, __, __,
			__, __, __, __, __, __, __, __,
			__, __, __, __, __, __, __, __,
			__, __, __, __, __, __, __, __,
			__, __, __, __, __, __, __, __,
			__, __, __, __, __, __, __, __,
			__, L0, __, __, __, __, L0, __,
			__, L0, __, __, __, __, L0, __,
			__, __, L0, F0, F0, L0, __, __,
			__, __, __, L0, L0, __, __, __,

			__, __, __, __, __, __, __, __,
			__, __, __, __, __, __, __, __,
			__, __, __, __, __, __, __, __,
			__, __, __, __, __, __, __, __,
			__, __, __, __, __, __, __, __,
			__, __, __, __, __, __, __, __,
			__, __, __, __, __, __, __, __,
			__, __, L0, __, __, L0, __, __,
			__, __, L0, __, __, L0, __, __,
			__, __, __, L0, L0, __, __, __,
			__, __, __, __, __, __, __, __,

			__, __, __, __, __, __, __, __,
			__, __, __, __, __, __, __, __,
			__, __, __, __, __, __, __, __,
			__, __, __, __, __, __, __, __,
			__, __, __, __, __, __, __, __,
			__, __, __, __, __, __, __, __,
			__, __, __, __, __, __, __, __,
			__, __, __, L0, L0, __, __, __,
			__, __, __, L0, L0, __, __, __,
			__, __, __, __, __, __, __, __,
			__, __, __, __, __, __, __, __
		},
		yslice_prob = {
			{ypos = 0, prob = 254},
			{ypos = 1, prob = 254},
			{ypos = 2, prob = 254},
			{ypos = 3, prob = 254},
			{ypos = 4, prob = 254},
			{ypos = 5, prob = 254},
			{ypos = 6, prob = 254},
			{ypos = 7, prob = 254},
			{ypos = 8, prob = 254},
			{ypos = 9, prob = 254},
			{ypos = 10, prob = 254}
		}
	}
	lib_ecology.schematics.insert("schem_mushroom_big", le_temp_schem)
	
	T0 = {name = "lib_ecology:mushroom_02_trunk", param2 = 0, prob = 254}
	L0 = {name = "lib_ecology:mushroom_cap_red_spotted", param2 = 0, prob = 254}
	le_temp_schem = {
		size = {x = 16,y = 11,z = 16},
		data = {
			__, __, __, __, __, __, __, __, __, __, __, __, __, __, __, __,
			__, __, __, __, __, __, __, __, __, __, __, __, __, __, __, __,
			__, __, __, __, __, __, __, __, __, __, __, __, __, __, __, __,
			__, __, __, __, __, __, __, __, __, __, __, __, __, __, __, __,
			__, __, __, __, __, __, __, __, __, __, __, __, __, __, __, __,
			__, __, __, __, __, __, __, __, __, __, __, __, __, __, __, __,
			__, __, __, __, __, __, __, __, __, __, __, __, __, __, __, __,
			__, __, __, __, __, __, __, __, __, __, __, __, __, __, __, __,
			__, __, __, __, __, L0, L0, L0, __, __, __, __, __, __, __, __,
			__, __, __, __, __, __, __, __, L0, L0, L0, __, __, __, __, __,
			__, __, __, __, __, __, __, __, __, __, __, __, __, __, __, __,

			__, __, __, __, __, __, __, __, __, __, __, __, __, __, __, __,
			__, __, __, __, __, __, __, __, __, __, __, __, __, __, __, __,
			__, __, __, __, __, __, __, __, __, __, __, __, __, __, __, __,
			__, __, __, __, __, __, __, __, __, __, __, __, __, __, __, __,
			__, __, __, __, __, __, __, __, __, __, __, __, __, __, __, __,
			__, __, __, __, __, __, __, __, __, __, __, __, __, __, __, __,
			__, __, __, __, __, __, __, __, __, __, __, __, __, __, __, __,
			__, __, __, __, __, __, __, __, __, __, __, __, __, __, __, __,
			__, __, __, L0, L0, L0, L0, L0, __, __, __, __, __, __, __, __,
			__, __, __, __, __, __, __, __, L0, L0, L0, L0, L0, __, __, __,
			__, __, __, __, __, __, __, __, __, __, __, __, __, __, __, __,

			__, __, __, __, __, __, __, __, __, __, __, __, __, __, __, __,
			__, __, __, __, __, __, __, __, __, __, __, __, __, __, __, __,
			__, __, __, __, __, __, __, __, __, __, __, __, __, __, __, __,
			__, __, __, __, __, __, __, __, __, __, __, __, __, __, __, __,
			__, __, __, __, __, __, __, __, __, __, __, __, __, __, __, __,
			__, __, __, __, __, __, __, __, __, __, __, __, __, __, __, __,
			__, __, __, __, __, __, __, __, __, __, __, __, __, __, __, __,
			__, __, __, __, __, __, __, __, __, __, __, __, __, __, __, __,
			__, __, L0, L0, L0, L0, L0, L0, __, __, __, __, __, __, __, __,
			__, __, __, __, __, __, __, __, L0, L0, L0, L0, L0, L0, __, __,
			__, __, __, __, __, __, __, __, __, __, __, __, __, __, __, __,

			__, __, __, __, __, __, __, __, __, __, __, __, __, __, __, __,
			__, __, __, __, __, __, __, __, __, __, __, __, __, __, __, __,
			__, __, __, __, __, __, __, __, __, __, __, __, __, __, __, __,
			__, __, __, __, __, __, __, __, __, __, __, __, __, __, __, __,
			__, __, __, __, __, __, __, __, __, __, __, __, __, __, __, __,
			__, __, __, __, __, __, __, __, __, __, __, __, __, __, __, __,
			__, __, __, __, __, __, __, __, __, __, __, __, __, __, __, __,
			__, __, __, __, __, __, __, __, __, __, __, __, __, __, __, __,
			__, L0, L0, L0, L0, L0, L0, L0, T0, T0, __, __, __, __, __, __,
			__, __, __, __, __, __, __, __, L0, L0, L0, L0, L0, L0, L0, __,
			__, __, __, __, __, __, __, __, __, __, __, __, __, __, __, __,

			__, __, __, __, __, __, T0, T0, T0, T0, __, __, __, __, __, __,
			__, __, __, __, __, T0, T0, T0, T0, T0, T0, __, __, __, __, __,
			__, __, __, __, __, T0, T0, T0, T0, T0, T0, __, __, __, __, __,
			__, __, __, __, __, T0, T0, T0, T0, T0, T0, __, __, __, __, __,
			__, __, __, __, __, T0, T0, T0, T0, T0, T0, __, __, __, __, __,
			__, __, __, __, __, T0, T0, T0, T0, T0, T0, __, __, __, __, __,
			__, __, __, __, __, T0, T0, T0, T0, T0, T0, __, __, __, __, __,
			__, __, __, __, __, T0, T0, T0, T0, T0, T0, __, __, __, __, __,
			__, L0, L0, L0, L0, L0, L0, L0, T0, T0, __, __, __, __, __, __,
			__, __, __, __, __, __, __, __, L0, L0, L0, L0, L0, L0, L0, __,
			__, __, __, __, __, __, __, __, __, __, __, __, __, __, __, __,

			__, __, __, __, __, T0, T0, T0, T0, T0, T0, __, __, __, __, __,
			__, __, __, __, T0, T0, __, __, __, __, T0, T0, __, __, __, __,
			__, __, __, __, T0, T0, __, __, __, __, T0, T0, __, __, __, __,
			__, __, __, __, T0, T0, __, __, __, __, T0, T0, __, __, __, __,
			__, __, __, __, T0, T0, __, __, __, __, T0, T0, __, __, __, __,
			__, __, __, __, T0, T0, __, __, __, __, T0, T0, __, __, __, __,
			__, __, __, __, T0, T0, __, __, __, __, T0, T0, __, __, __, __,
			__, __, __, __, __, __, T0, __, __, __, T0, T0, __, __, __, __,
			__, __, L0, L0, L0, L0, L0, L0, __, T0, T0, __, __, __, __, __,
			L0, L0, __, __, __, __, __, __, L0, L0, L0, L0, L0, L0, L0, L0,
			__, __, __, __, __, __, __, __, __, __, __, __, __, __, __, __,

			__, __, __, __, __, T0, T0, T0, T0, T0, T0, __, __, __, __, __,
			__, __, __, __, T0, __, __, __, __, __, __, T0, __, __, __, __,
			__, __, __, __, T0, __, __, __, __, __, __, T0, __, __, __, __,
			__, __, __, __, T0, __, __, __, __, __, __, T0, __, __, __, __,
			__, __, __, __, T0, __, __, __, __, __, __, T0, __, __, __, __,
			__, __, __, __, T0, __, __, __, __, __, __, T0, __, __, __, __,
			__, __, __, __, T0, __, __, __, __, __, __, T0, __, __, __, __,
			__, __, __, __, __, T0, __, __, __, __, T0, __, __, __, __, __,
			L0, L0, L0, L0, L0, L0, L0, L0, L0, T0, __, __, __, __, __, __,
			__, __, __, __, __, __, __, __, L0, L0, L0, L0, L0, L0, L0, L0,
			__, __, __, __, __, __, __, __, __, __, __, __, __, __, __, __,

			__, __, __, __, __, T0, T0, T0, T0, T0, T0, __, __, __, __, __,
			__, __, __, __, T0, __, __, __, __, __, __, T0, __, __, __, __,
			__, __, __, __, T0, __, __, __, __, __, __, T0, __, __, __, __,
			__, __, __, __, T0, __, __, __, __, __, __, T0, __, __, __, __,
			__, __, __, __, T0, __, __, __, __, __, __, T0, __, __, __, __,
			__, __, __, __, T0, __, __, __, __, __, __, T0, __, __, __, __,
			__, __, __, __, T0, __, __, __, __, __, __, T0, __, __, __, __,
			__, __, __, __, __, T0, __, __, __, __, T0, __, __, __, __, __,
			L0, L0, L0, L0, L0, L0, L0, L0, L0, L0, T0, __, __, __, __, __,
			__, __, __, __, __, __, __, __, __, L0, L0, L0, L0, L0, L0, L0,
			__, __, __, __, __, __, __, __, __, __, __, __, __, __, __, __,

			__, __, __, __, __, T0, T0, T0, T0, T0, T0, __, __, __, __, __,
			__, __, __, __, T0, __, __, __, __, __, __, T0, __, __, __, __,
			__, __, __, __, T0, __, __, __, __, __, __, T0, __, __, __, __,
			__, __, __, __, T0, __, __, __, __, __, __, T0, __, __, __, __,
			__, __, __, __, T0, __, __, __, __, __, __, T0, __, __, __, __,
			__, __, __, __, T0, __, __, __, __, __, __, T0, __, __, __, __,
			__, __, __, __, __, T0, __, __, __, __, T0, __, __, __, __, __,
			L0, L0, L0, L0, L0, L0, L0, L0, __, __, T0, __, __, __, __, __,
			__, __, __, __, __, __, L0, L0, L0, L0, L0, L0, L0, L0, L0, L0,
			__, __, __, __, __, __, __, __, __, __, __, __, __, __, __, __,
			__, __, __, __, __, __, __, __, __, __, __, __, __, __, __, __,

			__, __, __, __, __, T0, T0, T0, T0, T0, T0, __, __, __, __, __,
			__, __, __, __, T0, __, __, __, __, __, __, T0, __, __, __, __,
			__, __, __, __, T0, __, __, __, __, __, __, T0, __, __, __, __,
			__, __, __, __, T0, __, __, __, __, __, __, T0, __, __, __, __,
			__, __, __, __, T0, __, __, __, __, __, __, T0, __, __, __, __,
			__, __, __, __, T0, __, __, __, __, __, __, T0, __, __, __, __,
			__, __, __, __, __, T0, __, __, __, __, T0, __, __, __, __, __,
			L0, L0, L0, L0, L0, L0, L0, L0, __, T0, __, __, __, __, __, __,
			__, __, __, __, __, __, __, L0, L0, L0, L0, L0, L0, L0, L0, L0,
			__, __, __, __, __, __, __, __, __, __, __, __, __, __, __, __,
			__, __, __, __, __, __, __, __, __, __, __, __, __, __, __, __,

			__, __, __, __, __, T0, T0, T0, T0, T0, T0, __, __, __, __, __,
			__, __, __, __, T0, T0, __, __, __, __, T0, T0, __, __, __, __,
			__, __, __, __, T0, T0, __, __, __, __, T0, T0, __, __, __, __,
			__, __, __, __, T0, T0, __, __, __, __, T0, T0, __, __, __, __,
			__, __, __, __, T0, T0, __, __, __, __, T0, T0, __, __, __, __,
			__, __, __, __, T0, T0, __, __, __, __, T0, T0, __, __, __, __,
			__, __, __, __, __, T0, __, __, __, T0, __, __, __, __, __, __,
			L0, L0, L0, L0, L0, L0, L0, L0, __, T0, __, __, __, __, __, __,
			__, __, __, __, __, __, __, __, L0, L0, L0, L0, L0, L0, L0, L0,
			__, __, __, __, __, __, __, __, __, __, __, __, __, __, __, __,
			__, __, __, __, __, __, __, __, __, __, __, __, __, __, __, __,

			__, __, __, __, __, __, T0, T0, T0, T0, __, __, __, __, __, __,
			__, __, __, __, __, T0, T0, T0, T0, T0, T0, __, __, __, __, __,
			__, __, __, __, __, T0, T0, T0, T0, T0, T0, __, __, __, __, __,
			__, __, __, __, __, T0, T0, T0, T0, T0, T0, __, __, __, __, __,
			__, __, __, __, __, T0, T0, T0, T0, T0, T0, __, __, __, __, __,
			__, __, __, __, __, T0, T0, T0, T0, T0, T0, __, __, __, __, __,
			__, __, __, __, __, __, T0, T0, T0, T0, __, __, __, __, __, __,
			__, L0, L0, L0, L0, L0, L0, L0, T0, T0, __, __, __, __, __, __,
			__, __, __, __, __, __, __, __, L0, L0, L0, L0, L0, L0, L0, __,
			__, __, __, __, __, __, __, __, __, __, __, __, __, __, __, __,
			__, __, __, __, __, __, __, __, __, __, __, __, __, __, __, __,

			__, __, __, __, __, __, __, __, __, __, __, __, __, __, __, __,
			__, __, __, __, __, __, __, __, __, __, __, __, __, __, __, __,
			__, __, __, __, __, __, __, __, __, __, __, __, __, __, __, __,
			__, __, __, __, __, __, __, __, __, __, __, __, __, __, __, __,
			__, __, __, __, __, __, __, __, __, __, __, __, __, __, __, __,
			__, __, __, __, __, __, __, __, __, __, __, __, __, __, __, __,
			__, __, __, __, __, __, __, __, __, __, __, __, __, __, __, __,
			__, L0, L0, L0, L0, L0, L0, L0, T0, T0, __, __, __, __, __, __,
			__, __, __, __, __, __, __, __, L0, L0, L0, L0, L0, L0, L0, __,
			__, __, __, __, __, __, __, __, __, __, __, __, __, __, __, __,
			__, __, __, __, __, __, __, __, __, __, __, __, __, __, __, __,
			
			__, __, __, __, __, __, __, __, __, __, __, __, __, __, __, __,
			__, __, __, __, __, __, __, __, __, __, __, __, __, __, __, __,
			__, __, __, __, __, __, __, __, __, __, __, __, __, __, __, __,
			__, __, __, __, __, __, __, __, __, __, __, __, __, __, __, __,
			__, __, __, __, __, __, __, __, __, __, __, __, __, __, __, __,
			__, __, __, __, __, __, __, __, __, __, __, __, __, __, __, __,
			__, __, __, __, __, __, __, __, __, __, __, __, __, __, __, __,
			__, __, L0, L0, L0, L0, L0, L0, __, __, __, __, __, __, __, __,
			__, __, __, __, __, __, __, __, L0, L0, L0, L0, L0, L0, __, __,
			__, __, __, __, __, __, __, __, __, __, __, __, __, __, __, __,
			__, __, __, __, __, __, __, __, __, __, __, __, __, __, __, __,

			__, __, __, __, __, __, __, __, __, __, __, __, __, __, __, __,
			__, __, __, __, __, __, __, __, __, __, __, __, __, __, __, __,
			__, __, __, __, __, __, __, __, __, __, __, __, __, __, __, __,
			__, __, __, __, __, __, __, __, __, __, __, __, __, __, __, __,
			__, __, __, __, __, __, __, __, __, __, __, __, __, __, __, __,
			__, __, __, __, __, __, __, __, __, __, __, __, __, __, __, __,
			__, __, __, __, __, __, __, __, __, __, __, __, __, __, __, __,
			__, __, __, L0, L0, L0, L0, L0, __, __, __, __, __, __, __, __,
			__, __, __, __, __, __, __, __, L0, L0, L0, L0, L0, __, __, __,
			__, __, __, __, __, __, __, __, __, __, __, __, __, __, __, __,
			__, __, __, __, __, __, __, __, __, __, __, __, __, __, __, __,

			__, __, __, __, __, __, __, __, __, __, __, __, __, __, __, __,
			__, __, __, __, __, __, __, __, __, __, __, __, __, __, __, __,
			__, __, __, __, __, __, __, __, __, __, __, __, __, __, __, __,
			__, __, __, __, __, __, __, __, __, __, __, __, __, __, __, __,
			__, __, __, __, __, __, __, __, __, __, __, __, __, __, __, __,
			__, __, __, __, __, __, __, __, __, __, __, __, __, __, __, __,
			__, __, __, __, __, __, __, __, __, __, __, __, __, __, __, __,
			__, __, __, __, __, L0, L0, L0, __, __, __, __, __, __, __, __,
			__, __, __, __, __, __, __, __, L0, L0, L0, __, __, __, __, __,
			__, __, __, __, __, __, __, __, __, __, __, __, __, __, __, __,
			__, __, __, __, __, __, __, __, __, __, __, __, __, __, __, __
		},
		yslice_prob = {
			{prob = 254, ypos = 0},
			{prob = 254, ypos = 1},
			{prob = 254, ypos = 2},
			{prob = 254, ypos = 3},
			{prob = 254, ypos = 4},
			{prob = 254, ypos = 5},
			{prob = 254, ypos = 6},
			{prob = 254, ypos = 7},
			{prob = 254, ypos = 8},
			{prob = 254, ypos = 9},
			{prob = 254, ypos = 10}
		}
	}
	lib_ecology.schematics.insert("schem_mushroom_fat", le_temp_schem)
	
	T0 = {name = "lib_ecology:mushroom_01_trunk", param2 = 0, prob = 254}
	L0 = {name = "lib_ecology:mushroom_cap_brown_01", param2 = 0, prob = 254}
	le_temp_schem = {
		size = {x = 10,y = 11,z = 10},
		data = {
			__, __, __, __, __, __, __, __, __, __,
			__, __, __, __, __, __, __, __, __, __,
			__, __, __, __, __, __, __, __, __, __,
			__, __, __, __, __, __, __, __, __, __,
			__, __, __, __, __, __, __, __, __, __,
			__, __, __, __, __, __, __, __, __, __,
			__, __, __, __, __, __, __, __, __, __,
			__, __, __, __, __, __, __, __, __, __,
			__, __, __, L0, L0, __, __, __, __, __,
			__, __, __, __, __, L0, L0, __, __, __,
			__, __, __, __, __, __, __, __, __, __,

			__, __, __, __, __, __, __, __, __, __,
			__, __, __, __, __, __, __, __, __, __,
			__, __, __, __, __, __, __, __, __, __,
			__, __, __, __, __, __, __, __, __, __,
			__, __, __, __, __, __, __, __, __, __,
			__, __, __, __, __, __, __, __, __, __,
			__, __, __, __, __, __, __, __, __, __,
			__, __, __, __, __, __, __, __, __, __,
			__, __, L0, L0, L0, __, __, __, __, __,
			__, __, __, __, __, L0, L0, L0, __, __,
			__, __, __, __, __, __, __, __, __, __,

			__, __, __, __, __, __, __, __, __, __,
			__, __, __, __, __, __, __, __, __, __,
			__, __, __, __, __, __, __, __, __, __,
			__, __, __, __, __, __, __, __, __, __,
			__, __, __, __, __, __, __, __, __, __,
			__, __, __, __, __, __, __, __, __, __,
			__, __, __, __, __, __, __, __, __, __,
			__, __, __, __, __, __, __, __, __, __,
			__, L0, L0, L0, L0, __, __, __, __, __,
			__, __, __, __, __, L0, L0, L0, L0, __,
			__, __, __, __, __, __, __, __, __, __,

			__, __, __, __, __, __, __, __, __, __,
			__, __, __, __, __, __, __, __, __, __,
			__, __, __, __, __, __, __, __, __, __,
			__, __, __, __, __, __, __, __, __, __,
			__, __, __, __, __, __, __, __, __, __,
			__, __, __, __, __, __, __, __, __, __,
			__, __, __, __, __, __, __, __, __, __,
			__, __, __, __, __, __, __, __, __, __,
			L0, L0, L0, L0, L0, L0, __, __, __, __,
			__, __, __, __, __, L0, L0, L0, L0, L0,
			__, __, __, __, __, __, __, __, __, __,

			__, __, __, __, T0, T0, __, __, __, __,
			__, __, __, __, T0, T0, __, __, __, __,
			__, __, __, __, T0, T0, __, __, __, __,
			__, __, __, __, T0, T0, __, __, __, __,
			__, __, __, __, T0, T0, __, __, __, __,
			__, __, __, __, T0, T0, __, __, __, __,
			__, __, __, __, T0, T0, __, __, __, __,
			__, __, __, __, T0, T0, __, __, __, __,
			L0, L0, L0, L0, L0, L0, L0, __, __, __,
			__, __, __, __, __, __, L0, L0, L0, L0,
			__, __, __, __, __, __, __, __, __, __,

			__, __, __, __, T0, T0, __, __, __, __,
			__, __, __, __, T0, T0, __, __, __, __,
			__, __, __, __, T0, T0, __, __, __, __,
			__, __, __, __, T0, T0, __, __, __, __,
			__, __, __, __, T0, T0, __, __, __, __,
			__, __, __, __, T0, T0, __, __, __, __,
			__, __, __, __, T0, T0, __, __, __, __,
			L0, L0, L0, L0, L0, T0, __, __, __, __,
			__, __, __, L0, L0, L0, L0, L0, L0, L0,
			__, __, __, __, __, __, __, __, __, __,
			__, __, __, __, __, __, __, __, __, __,

			__, __, __, __, __, __, __, __, __, __,
			__, __, __, __, __, __, __, __, __, __,
			__, __, __, __, __, __, __, __, __, __,
			__, __, __, __, __, __, __, __, __, __,
			__, __, __, __, __, __, __, __, __, __,
			__, __, __, __, __, __, __, __, __, __,
			__, __, __, __, __, __, __, __, __, __,
			L0, L0, L0, L0, L0, __, __, __, __, __,
			__, __, __, __, L0, L0, L0, L0, L0, L0,
			__, __, __, __, __, __, __, __, __, __,
			__, __, __, __, __, __, __, __, __, __,

			__, __, __, __, __, __, __, __, __, __,
			__, __, __, __, __, __, __, __, __, __,
			__, __, __, __, __, __, __, __, __, __,
			__, __, __, __, __, __, __, __, __, __,
			__, __, __, __, __, __, __, __, __, __,
			__, __, __, __, __, __, __, __, __, __,
			__, __, __, __, __, __, __, __, __, __,
			__, L0, L0, L0, L0, __, __, __, __, __,
			__, __, __, __, __, L0, L0, L0, L0, __,
			__, __, __, __, __, __, __, __, __, __,
			__, __, __, __, __, __, __, __, __, __,

			__, __, __, __, __, __, __, __, __, __,
			__, __, __, __, __, __, __, __, __, __,
			__, __, __, __, __, __, __, __, __, __,
			__, __, __, __, __, __, __, __, __, __,
			__, __, __, __, __, __, __, __, __, __,
			__, __, __, __, __, __, __, __, __, __,
			__, __, __, __, __, __, __, __, __, __,
			__, __, L0, L0, L0, __, __, __, __, __,
			__, __, __, __, __, L0, L0, L0, __, __,
			__, __, __, __, __, __, __, __, __, __,
			__, __, __, __, __, __, __, __, __, __,

			__, __, __, __, __, __, __, __, __, __,
			__, __, __, __, __, __, __, __, __, __,
			__, __, __, __, __, __, __, __, __, __,
			__, __, __, __, __, __, __, __, __, __,
			__, __, __, __, __, __, __, __, __, __,
			__, __, __, __, __, __, __, __, __, __,
			__, __, __, __, __, __, __, __, __, __,
			__, __, __, L0, L0, __, __, __, __, __,
			__, __, __, __, __, L0, L0, __, __, __,
			__, __, __, __, __, __, __, __, __, __,
			__, __, __, __, __, __, __, __, __, __
		},
		yslice_prob = {
			{prob = 254, ypos = 0},
			{prob = 254, ypos = 1},
			{prob = 254, ypos = 2},
			{prob = 254, ypos = 3},
			{prob = 254, ypos = 4},
			{prob = 254, ypos = 5},
			{prob = 254, ypos = 6},
			{prob = 254, ypos = 7},
			{prob = 254, ypos = 8},
			{prob = 254, ypos = 9},
			{prob = 254, ypos = 10}
		}
	}
	lib_ecology.schematics.insert("schem_mushroom_large", le_temp_schem)
	
	T0 = {name = "lib_ecology:mushroom_02_trunk", param2 = 0, prob = 254}
	L0 = {name = "lib_ecology:mushroom_cap_red_02", param2 = 0, prob = 254}
	le_temp_schem = {
		size = {x = 3,y = 5,z = 3},
		data = {
			__, __, __,
			__, __, __,
			__, __, __,
			__, __, __,
			L0, L0, L0,

			__, T0, __,
			__, T0, __,
			__, T0, __,
			__, T0, __,
			L0, L0, L0,

			__, __, __,
			__, __, __,
			__, __, __,
			__, __, __,
			L0, L0, L0
		},
		yslice_prob = {
			{ypos = 0, prob = 254},
			{ypos = 1, prob = 254},
			{ypos = 2, prob = 254},
			{ypos = 3, prob = 254},
			{ypos = 4, prob = 254}
		}
	}
	lib_ecology.schematics.insert("schem_mushroom_short", le_temp_schem)
	
	T0 = {name = "lib_ecology:mushroom_02_trunk", param2 = 0, prob = 254}
	L0 = {name = "lib_ecology:mushroom_cap_brown_02", param2 = 0, prob = 254}
	le_temp_schem = {
		size = {x = 5,y = 10,z = 5},
		data = {
			__, __, __, __, __,
			__, __, __, __, __,
			__, __, __, __, __,
			__, __, __, __, __,
			__, __, __, __, __,
			__, __, __, __, __,
			__, __, __, __, __,
			__, __, __, __, __,
			__, L0, L0, L0, __,
			__, __, __, __, __,

			__, __, __, __, __,
			__, __, __, __, __,
			__, __, __, __, __,
			__, __, __, __, __,
			__, __, __, __, __,
			__, __, __, __, __,
			__, __, __, __, __,
			__, __, __, __, __,
			L0, L0, L0, L0, L0,
			__, L0, L0, L0, __,

			__, __, T0, __, __,
			__, __, T0, __, __,
			__, __, T0, __, __,
			__, __, T0, __, __,
			__, __, T0, __, __,
			__, __, T0, __, __,
			__, __, T0, __, __,
			__, __, T0, __, __,
			L0, L0, L0, L0, L0,
			__, L0, L0, L0, __,

			__, __, __, __, __,
			__, __, __, __, __,
			__, __, __, __, __,
			__, __, __, __, __,
			__, __, __, __, __,
			__, __, __, __, __,
			__, __, __, __, __,
			__, __, __, __, __,
			L0, L0, L0, L0, L0,
			__, L0, L0, L0, __,

			__, __, __, __, __,
			__, __, __, __, __,
			__, __, __, __, __,
			__, __, __, __, __,
			__, __, __, __, __,
			__, __, __, __, __,
			__, __, __, __, __,
			__, __, __, __, __,
			__, L0, L0, L0, __,
			__, __, __, __, __
		},
		yslice_prob = {
			{ypos = 0, prob = 254},
			{ypos = 1, prob = 254},
			{ypos = 2, prob = 254},
			{ypos = 3, prob = 254},
			{ypos = 4, prob = 254},
			{ypos = 5, prob = 254},
			{ypos = 6, prob = 254},
			{ypos = 7, prob = 254},
			{ypos = 8, prob = 254},
			{ypos = 9, prob = 254}
		}
	}
	lib_ecology.schematics.insert("schem_mushroom_tall", le_temp_schem)

	T0 = {name = "lib_ecology:mushroom_02_trunk", param2 = 0, prob = 254}
	L0 = {name = "lib_ecology:mushroom_cap_blue", param2 = 0, prob = 254}
	le_temp_schem = {
		size = {x = 10,y = 11,z = 10},
		data = {
			__, __, __, __, __, __, __, __, __, __,
			__, __, __, __, __, __, __, __, __, __,
			__, __, __, __, __, __, __, __, __, __,
			__, __, __, __, __, __, __, __, __, __,
			__, __, __, __, __, __, __, __, __, __,
			__, __, __, __, __, __, __, __, __, __,
			__, __, __, __, __, __, __, __, __, __,
			__, __, __, __, __, __, __, __, __, __,
			__, __, __, L0, L0, __, __, __, __, __,
			__, __, __, __, __, L0, L0, __, __, __,
			__, __, __, __, __, __, __, __, __, __,

			__, __, __, __, __, __, __, __, __, __,
			__, __, __, __, __, __, __, __, __, __,
			__, __, __, __, __, __, __, __, __, __,
			__, __, __, __, __, __, __, __, __, __,
			__, __, __, __, __, __, __, __, __, __,
			__, __, __, __, __, __, __, __, __, __,
			__, __, __, __, __, __, __, __, __, __,
			__, __, __, __, __, __, __, __, __, __,
			__, __, L0, L0, L0, __, __, __, __, __,
			__, __, __, __, __, L0, L0, L0, __, __,
			__, __, __, __, __, __, __, __, __, __,

			__, __, __, __, __, __, __, __, __, __,
			__, __, __, __, __, __, __, __, __, __,
			__, __, __, __, __, __, __, __, __, __,
			__, __, __, __, __, __, __, __, __, __,
			__, __, __, __, __, __, __, __, __, __,
			__, __, __, __, __, __, __, __, __, __,
			__, __, __, __, __, __, __, __, __, __,
			__, __, __, __, __, __, __, __, __, __,
			__, L0, L0, L0, L0, __, __, __, __, __,
			__, __, __, __, __, L0, L0, L0, L0, __,
			__, __, __, __, __, __, __, __, __, __,

			__, __, __, __, __, __, __, __, __, __,
			__, __, __, __, __, __, __, __, __, __,
			__, __, __, __, __, __, __, __, __, __,
			__, __, __, __, __, __, __, __, __, __,
			__, __, __, __, __, __, __, __, __, __,
			__, __, __, __, __, __, __, __, __, __,
			__, __, __, __, __, __, __, __, __, __,
			__, __, __, __, __, __, __, __, __, __,
			L0, L0, L0, L0, L0, L0, __, __, __, __,
			__, __, __, __, __, L0, L0, L0, L0, L0,
			__, __, __, __, __, __, __, __, __, __,

			__, __, __, __, T0, T0, __, __, __, __,
			__, __, __, __, T0, T0, __, __, __, __,
			__, __, __, __, T0, T0, __, __, __, __,
			__, __, __, __, T0, T0, __, __, __, __,
			__, __, __, __, T0, T0, __, __, __, __,
			__, __, __, __, T0, T0, __, __, __, __,
			__, __, __, __, T0, T0, __, __, __, __,
			__, __, __, __, T0, T0, __, __, __, __,
			L0, L0, L0, L0, L0, L0, L0, __, __, __,
			__, __, __, __, __, __, L0, L0, L0, L0,
			__, __, __, __, __, __, __, __, __, __,

			__, __, __, __, T0, T0, __, __, __, __,
			__, __, __, __, T0, T0, __, __, __, __,
			__, __, __, __, T0, T0, __, __, __, __,
			__, __, __, __, T0, T0, __, __, __, __,
			__, __, __, __, T0, T0, __, __, __, __,
			__, __, __, __, T0, T0, __, __, __, __,
			__, __, __, __, T0, T0, __, __, __, __,
			L0, L0, L0, L0, L0, T0, __, __, __, __,
			__, __, __, L0, L0, L0, L0, L0, L0, L0,
			__, __, __, __, __, __, __, __, __, __,
			__, __, __, __, __, __, __, __, __, __,

			__, __, __, __, __, __, __, __, __, __,
			__, __, __, __, __, __, __, __, __, __,
			__, __, __, __, __, __, __, __, __, __,
			__, __, __, __, __, __, __, __, __, __,
			__, __, __, __, __, __, __, __, __, __,
			__, __, __, __, __, __, __, __, __, __,
			__, __, __, __, __, __, __, __, __, __,
			L0, L0, L0, L0, L0, __, __, __, __, __,
			__, __, __, __, L0, L0, L0, L0, L0, L0,
			__, __, __, __, __, __, __, __, __, __,
			__, __, __, __, __, __, __, __, __, __,

			__, __, __, __, __, __, __, __, __, __,
			__, __, __, __, __, __, __, __, __, __,
			__, __, __, __, __, __, __, __, __, __,
			__, __, __, __, __, __, __, __, __, __,
			__, __, __, __, __, __, __, __, __, __,
			__, __, __, __, __, __, __, __, __, __,
			__, __, __, __, __, __, __, __, __, __,
			__, L0, L0, L0, L0, __, __, __, __, __,
			__, __, __, __, __, L0, L0, L0, L0, __,
			__, __, __, __, __, __, __, __, __, __,
			__, __, __, __, __, __, __, __, __, __,

			__, __, __, __, __, __, __, __, __, __,
			__, __, __, __, __, __, __, __, __, __,
			__, __, __, __, __, __, __, __, __, __,
			__, __, __, __, __, __, __, __, __, __,
			__, __, __, __, __, __, __, __, __, __,
			__, __, __, __, __, __, __, __, __, __,
			__, __, __, __, __, __, __, __, __, __,
			__, __, L0, L0, L0, __, __, __, __, __,
			__, __, __, __, __, L0, L0, L0, __, __,
			__, __, __, __, __, __, __, __, __, __,
			__, __, __, __, __, __, __, __, __, __,

			__, __, __, __, __, __, __, __, __, __,
			__, __, __, __, __, __, __, __, __, __,
			__, __, __, __, __, __, __, __, __, __,
			__, __, __, __, __, __, __, __, __, __,
			__, __, __, __, __, __, __, __, __, __,
			__, __, __, __, __, __, __, __, __, __,
			__, __, __, __, __, __, __, __, __, __,
			__, __, __, L0, L0, __, __, __, __, __,
			__, __, __, __, __, L0, L0, __, __, __,
			__, __, __, __, __, __, __, __, __, __,
			__, __, __, __, __, __, __, __, __, __
		},
		yslice_prob = {
			{prob = 254, ypos = 0},
			{prob = 254, ypos = 1},
			{prob = 254, ypos = 2},
			{prob = 254, ypos = 3},
			{prob = 254, ypos = 4},
			{prob = 254, ypos = 5},
			{prob = 254, ypos = 6},
			{prob = 254, ypos = 7},
			{prob = 254, ypos = 8},
			{prob = 254, ypos = 9},
			{prob = 254, ypos = 10}
		}
	}
	lib_ecology.schematics.insert("schem_mushroom_blue", le_temp_schem)
	
	T0 = {name = "lib_ecology:mushroom_02_trunk", param2 = 0, prob = 254}
	L0 = {name = "lib_ecology:mushroom_cap_green_spotted", param2 = 0, prob = 254}
	le_temp_schem = {
		size = {x = 3,y = 5,z = 3},
		data = {
			__, __, __,
			__, __, __,
			__, __, __,
			__, __, __,
			L0, L0, L0,

			__, T0, __,
			__, T0, __,
			__, T0, __,
			__, T0, __,
			L0, L0, L0,

			__, __, __,
			__, __, __,
			__, __, __,
			__, __, __,
			L0, L0, L0
		},
		yslice_prob = {
			{ypos = 0, prob = 254},
			{ypos = 1, prob = 254},
			{ypos = 2, prob = 254},
			{ypos = 3, prob = 254},
			{ypos = 4, prob = 254}
		}
	}
	lib_ecology.schematics.insert("schem_mushroom_green_spotted", le_temp_schem)
	
	T0 = {name = "lib_ecology:mushroom_01_trunk", param2 = 0, prob = 254}
	L0 = {name = "lib_ecology:mushroom_cap_green_dk", param2 = 0, prob = 254}
	le_temp_schem = {
		size = {x = 5,y = 10,z = 5},
		data = {
			__, __, __, __, __,
			__, __, __, __, __,
			__, __, __, __, __,
			__, __, __, __, __,
			__, __, __, __, __,
			__, __, __, __, __,
			__, __, __, __, __,
			__, __, __, __, __,
			__, L0, L0, L0, __,
			__, __, __, __, __,

			__, __, __, __, __,
			__, __, __, __, __,
			__, __, __, __, __,
			__, __, __, __, __,
			__, __, __, __, __,
			__, __, __, __, __,
			__, __, __, __, __,
			__, __, __, __, __,
			L0, L0, L0, L0, L0,
			__, L0, L0, L0, __,

			__, __, T0, __, __,
			__, __, T0, __, __,
			__, __, T0, __, __,
			__, __, T0, __, __,
			__, __, T0, __, __,
			__, __, T0, __, __,
			__, __, T0, __, __,
			__, __, T0, __, __,
			L0, L0, L0, L0, L0,
			__, L0, L0, L0, __,

			__, __, __, __, __,
			__, __, __, __, __,
			__, __, __, __, __,
			__, __, __, __, __,
			__, __, __, __, __,
			__, __, __, __, __,
			__, __, __, __, __,
			__, __, __, __, __,
			L0, L0, L0, L0, L0,
			__, L0, L0, L0, __,

			__, __, __, __, __,
			__, __, __, __, __,
			__, __, __, __, __,
			__, __, __, __, __,
			__, __, __, __, __,
			__, __, __, __, __,
			__, __, __, __, __,
			__, __, __, __, __,
			__, L0, L0, L0, __,
			__, __, __, __, __
		},
		yslice_prob = {
			{ypos = 0, prob = 254},
			{ypos = 1, prob = 254},
			{ypos = 2, prob = 254},
			{ypos = 3, prob = 254},
			{ypos = 4, prob = 254},
			{ypos = 5, prob = 254},
			{ypos = 6, prob = 254},
			{ypos = 7, prob = 254},
			{ypos = 8, prob = 254},
			{ypos = 9, prob = 254}
		}
	}
	lib_ecology.schematics.insert("schem_mushroom_green_dark", le_temp_schem)
	
	T0 = {name = "lib_ecology:mushroom_01_trunk", param2 = 0, prob = 254}
	L0 = {name = "lib_ecology:mushroom_cap_purple", param2 = 0, prob = 254}
	le_temp_schem = {
		size = {x = 16,y = 11,z = 16},
		data = {
			__, __, __, __, __, __, __, __, __, __, __, __, __, __, __, __,
			__, __, __, __, __, __, __, __, __, __, __, __, __, __, __, __,
			__, __, __, __, __, __, __, __, __, __, __, __, __, __, __, __,
			__, __, __, __, __, __, __, __, __, __, __, __, __, __, __, __,
			__, __, __, __, __, __, __, __, __, __, __, __, __, __, __, __,
			__, __, __, __, __, __, __, __, __, __, __, __, __, __, __, __,
			__, __, __, __, __, __, __, __, __, __, __, __, __, __, __, __,
			__, __, __, __, __, __, __, __, __, __, __, __, __, __, __, __,
			__, __, __, __, __, L0, L0, L0, __, __, __, __, __, __, __, __,
			__, __, __, __, __, __, __, __, L0, L0, L0, __, __, __, __, __,
			__, __, __, __, __, __, __, __, __, __, __, __, __, __, __, __,

			__, __, __, __, __, __, __, __, __, __, __, __, __, __, __, __,
			__, __, __, __, __, __, __, __, __, __, __, __, __, __, __, __,
			__, __, __, __, __, __, __, __, __, __, __, __, __, __, __, __,
			__, __, __, __, __, __, __, __, __, __, __, __, __, __, __, __,
			__, __, __, __, __, __, __, __, __, __, __, __, __, __, __, __,
			__, __, __, __, __, __, __, __, __, __, __, __, __, __, __, __,
			__, __, __, __, __, __, __, __, __, __, __, __, __, __, __, __,
			__, __, __, __, __, __, __, __, __, __, __, __, __, __, __, __,
			__, __, __, L0, L0, L0, L0, L0, __, __, __, __, __, __, __, __,
			__, __, __, __, __, __, __, __, L0, L0, L0, L0, L0, __, __, __,
			__, __, __, __, __, __, __, __, __, __, __, __, __, __, __, __,

			__, __, __, __, __, __, __, __, __, __, __, __, __, __, __, __,
			__, __, __, __, __, __, __, __, __, __, __, __, __, __, __, __,
			__, __, __, __, __, __, __, __, __, __, __, __, __, __, __, __,
			__, __, __, __, __, __, __, __, __, __, __, __, __, __, __, __,
			__, __, __, __, __, __, __, __, __, __, __, __, __, __, __, __,
			__, __, __, __, __, __, __, __, __, __, __, __, __, __, __, __,
			__, __, __, __, __, __, __, __, __, __, __, __, __, __, __, __,
			__, __, __, __, __, __, __, __, __, __, __, __, __, __, __, __,
			__, __, L0, L0, L0, L0, L0, L0, __, __, __, __, __, __, __, __,
			__, __, __, __, __, __, __, __, L0, L0, L0, L0, L0, L0, __, __,
			__, __, __, __, __, __, __, __, __, __, __, __, __, __, __, __,

			__, __, __, __, __, __, __, __, __, __, __, __, __, __, __, __,
			__, __, __, __, __, __, __, __, __, __, __, __, __, __, __, __,
			__, __, __, __, __, __, __, __, __, __, __, __, __, __, __, __,
			__, __, __, __, __, __, __, __, __, __, __, __, __, __, __, __,
			__, __, __, __, __, __, __, __, __, __, __, __, __, __, __, __,
			__, __, __, __, __, __, __, __, __, __, __, __, __, __, __, __,
			__, __, __, __, __, __, __, __, __, __, __, __, __, __, __, __,
			__, __, __, __, __, __, __, __, __, __, __, __, __, __, __, __,
			__, L0, L0, L0, L0, L0, L0, L0, T0, T0, __, __, __, __, __, __,
			__, __, __, __, __, __, __, __, L0, L0, L0, L0, L0, L0, L0, __,
			__, __, __, __, __, __, __, __, __, __, __, __, __, __, __, __,

			__, __, __, __, __, __, T0, T0, T0, T0, __, __, __, __, __, __,
			__, __, __, __, __, T0, T0, T0, T0, T0, T0, __, __, __, __, __,
			__, __, __, __, __, T0, T0, T0, T0, T0, T0, __, __, __, __, __,
			__, __, __, __, __, T0, T0, T0, T0, T0, T0, __, __, __, __, __,
			__, __, __, __, __, T0, T0, T0, T0, T0, T0, __, __, __, __, __,
			__, __, __, __, __, T0, T0, T0, T0, T0, T0, __, __, __, __, __,
			__, __, __, __, __, T0, T0, T0, T0, T0, T0, __, __, __, __, __,
			__, __, __, __, __, T0, T0, T0, T0, T0, T0, __, __, __, __, __,
			__, L0, L0, L0, L0, L0, L0, L0, T0, T0, __, __, __, __, __, __,
			__, __, __, __, __, __, __, __, L0, L0, L0, L0, L0, L0, L0, __,
			__, __, __, __, __, __, __, __, __, __, __, __, __, __, __, __,

			__, __, __, __, __, T0, T0, T0, T0, T0, T0, __, __, __, __, __,
			__, __, __, __, T0, T0, __, __, __, __, T0, T0, __, __, __, __,
			__, __, __, __, T0, T0, __, __, __, __, T0, T0, __, __, __, __,
			__, __, __, __, T0, T0, __, __, __, __, T0, T0, __, __, __, __,
			__, __, __, __, T0, T0, __, __, __, __, T0, T0, __, __, __, __,
			__, __, __, __, T0, T0, __, __, __, __, T0, T0, __, __, __, __,
			__, __, __, __, T0, T0, __, __, __, __, T0, T0, __, __, __, __,
			__, __, __, __, __, __, T0, __, __, __, T0, T0, __, __, __, __,
			__, __, L0, L0, L0, L0, L0, L0, __, T0, T0, __, __, __, __, __,
			L0, L0, __, __, __, __, __, __, L0, L0, L0, L0, L0, L0, L0, L0,
			__, __, __, __, __, __, __, __, __, __, __, __, __, __, __, __,

			__, __, __, __, __, T0, T0, T0, T0, T0, T0, __, __, __, __, __,
			__, __, __, __, T0, __, __, __, __, __, __, T0, __, __, __, __,
			__, __, __, __, T0, __, __, __, __, __, __, T0, __, __, __, __,
			__, __, __, __, T0, __, __, __, __, __, __, T0, __, __, __, __,
			__, __, __, __, T0, __, __, __, __, __, __, T0, __, __, __, __,
			__, __, __, __, T0, __, __, __, __, __, __, T0, __, __, __, __,
			__, __, __, __, T0, __, __, __, __, __, __, T0, __, __, __, __,
			__, __, __, __, __, T0, __, __, __, __, T0, __, __, __, __, __,
			L0, L0, L0, L0, L0, L0, L0, L0, L0, T0, __, __, __, __, __, __,
			__, __, __, __, __, __, __, __, L0, L0, L0, L0, L0, L0, L0, L0,
			__, __, __, __, __, __, __, __, __, __, __, __, __, __, __, __,

			__, __, __, __, __, T0, T0, T0, T0, T0, T0, __, __, __, __, __,
			__, __, __, __, T0, __, __, __, __, __, __, T0, __, __, __, __,
			__, __, __, __, T0, __, __, __, __, __, __, T0, __, __, __, __,
			__, __, __, __, T0, __, __, __, __, __, __, T0, __, __, __, __,
			__, __, __, __, T0, __, __, __, __, __, __, T0, __, __, __, __,
			__, __, __, __, T0, __, __, __, __, __, __, T0, __, __, __, __,
			__, __, __, __, T0, __, __, __, __, __, __, T0, __, __, __, __,
			__, __, __, __, __, T0, __, __, __, __, T0, __, __, __, __, __,
			L0, L0, L0, L0, L0, L0, L0, L0, L0, L0, T0, __, __, __, __, __,
			__, __, __, __, __, __, __, __, __, L0, L0, L0, L0, L0, L0, L0,
			__, __, __, __, __, __, __, __, __, __, __, __, __, __, __, __,

			__, __, __, __, __, T0, T0, T0, T0, T0, T0, __, __, __, __, __,
			__, __, __, __, T0, __, __, __, __, __, __, T0, __, __, __, __,
			__, __, __, __, T0, __, __, __, __, __, __, T0, __, __, __, __,
			__, __, __, __, T0, __, __, __, __, __, __, T0, __, __, __, __,
			__, __, __, __, T0, __, __, __, __, __, __, T0, __, __, __, __,
			__, __, __, __, T0, __, __, __, __, __, __, T0, __, __, __, __,
			__, __, __, __, __, T0, __, __, __, __, T0, __, __, __, __, __,
			L0, L0, L0, L0, L0, L0, L0, L0, __, __, T0, __, __, __, __, __,
			__, __, __, __, __, __, L0, L0, L0, L0, L0, L0, L0, L0, L0, L0,
			__, __, __, __, __, __, __, __, __, __, __, __, __, __, __, __,
			__, __, __, __, __, __, __, __, __, __, __, __, __, __, __, __,

			__, __, __, __, __, T0, T0, T0, T0, T0, T0, __, __, __, __, __,
			__, __, __, __, T0, __, __, __, __, __, __, T0, __, __, __, __,
			__, __, __, __, T0, __, __, __, __, __, __, T0, __, __, __, __,
			__, __, __, __, T0, __, __, __, __, __, __, T0, __, __, __, __,
			__, __, __, __, T0, __, __, __, __, __, __, T0, __, __, __, __,
			__, __, __, __, T0, __, __, __, __, __, __, T0, __, __, __, __,
			__, __, __, __, __, T0, __, __, __, __, T0, __, __, __, __, __,
			L0, L0, L0, L0, L0, L0, L0, L0, __, T0, __, __, __, __, __, __,
			__, __, __, __, __, __, __, L0, L0, L0, L0, L0, L0, L0, L0, L0,
			__, __, __, __, __, __, __, __, __, __, __, __, __, __, __, __,
			__, __, __, __, __, __, __, __, __, __, __, __, __, __, __, __,

			__, __, __, __, __, T0, T0, T0, T0, T0, T0, __, __, __, __, __,
			__, __, __, __, T0, T0, __, __, __, __, T0, T0, __, __, __, __,
			__, __, __, __, T0, T0, __, __, __, __, T0, T0, __, __, __, __,
			__, __, __, __, T0, T0, __, __, __, __, T0, T0, __, __, __, __,
			__, __, __, __, T0, T0, __, __, __, __, T0, T0, __, __, __, __,
			__, __, __, __, T0, T0, __, __, __, __, T0, T0, __, __, __, __,
			__, __, __, __, __, T0, __, __, __, T0, __, __, __, __, __, __,
			L0, L0, L0, L0, L0, L0, L0, L0, __, T0, __, __, __, __, __, __,
			__, __, __, __, __, __, __, __, L0, L0, L0, L0, L0, L0, L0, L0,
			__, __, __, __, __, __, __, __, __, __, __, __, __, __, __, __,
			__, __, __, __, __, __, __, __, __, __, __, __, __, __, __, __,

			__, __, __, __, __, __, T0, T0, T0, T0, __, __, __, __, __, __,
			__, __, __, __, __, T0, T0, T0, T0, T0, T0, __, __, __, __, __,
			__, __, __, __, __, T0, T0, T0, T0, T0, T0, __, __, __, __, __,
			__, __, __, __, __, T0, T0, T0, T0, T0, T0, __, __, __, __, __,
			__, __, __, __, __, T0, T0, T0, T0, T0, T0, __, __, __, __, __,
			__, __, __, __, __, T0, T0, T0, T0, T0, T0, __, __, __, __, __,
			__, __, __, __, __, __, T0, T0, T0, T0, __, __, __, __, __, __,
			__, L0, L0, L0, L0, L0, L0, L0, T0, T0, __, __, __, __, __, __,
			__, __, __, __, __, __, __, __, L0, L0, L0, L0, L0, L0, L0, __,
			__, __, __, __, __, __, __, __, __, __, __, __, __, __, __, __,
			__, __, __, __, __, __, __, __, __, __, __, __, __, __, __, __,

			__, __, __, __, __, __, __, __, __, __, __, __, __, __, __, __,
			__, __, __, __, __, __, __, __, __, __, __, __, __, __, __, __,
			__, __, __, __, __, __, __, __, __, __, __, __, __, __, __, __,
			__, __, __, __, __, __, __, __, __, __, __, __, __, __, __, __,
			__, __, __, __, __, __, __, __, __, __, __, __, __, __, __, __,
			__, __, __, __, __, __, __, __, __, __, __, __, __, __, __, __,
			__, __, __, __, __, __, __, __, __, __, __, __, __, __, __, __,
			__, L0, L0, L0, L0, L0, L0, L0, T0, T0, __, __, __, __, __, __,
			__, __, __, __, __, __, __, __, L0, L0, L0, L0, L0, L0, L0, __,
			__, __, __, __, __, __, __, __, __, __, __, __, __, __, __, __,
			__, __, __, __, __, __, __, __, __, __, __, __, __, __, __, __,
			
			__, __, __, __, __, __, __, __, __, __, __, __, __, __, __, __,
			__, __, __, __, __, __, __, __, __, __, __, __, __, __, __, __,
			__, __, __, __, __, __, __, __, __, __, __, __, __, __, __, __,
			__, __, __, __, __, __, __, __, __, __, __, __, __, __, __, __,
			__, __, __, __, __, __, __, __, __, __, __, __, __, __, __, __,
			__, __, __, __, __, __, __, __, __, __, __, __, __, __, __, __,
			__, __, __, __, __, __, __, __, __, __, __, __, __, __, __, __,
			__, __, L0, L0, L0, L0, L0, L0, __, __, __, __, __, __, __, __,
			__, __, __, __, __, __, __, __, L0, L0, L0, L0, L0, L0, __, __,
			__, __, __, __, __, __, __, __, __, __, __, __, __, __, __, __,
			__, __, __, __, __, __, __, __, __, __, __, __, __, __, __, __,

			__, __, __, __, __, __, __, __, __, __, __, __, __, __, __, __,
			__, __, __, __, __, __, __, __, __, __, __, __, __, __, __, __,
			__, __, __, __, __, __, __, __, __, __, __, __, __, __, __, __,
			__, __, __, __, __, __, __, __, __, __, __, __, __, __, __, __,
			__, __, __, __, __, __, __, __, __, __, __, __, __, __, __, __,
			__, __, __, __, __, __, __, __, __, __, __, __, __, __, __, __,
			__, __, __, __, __, __, __, __, __, __, __, __, __, __, __, __,
			__, __, __, L0, L0, L0, L0, L0, __, __, __, __, __, __, __, __,
			__, __, __, __, __, __, __, __, L0, L0, L0, L0, L0, __, __, __,
			__, __, __, __, __, __, __, __, __, __, __, __, __, __, __, __,
			__, __, __, __, __, __, __, __, __, __, __, __, __, __, __, __,

			__, __, __, __, __, __, __, __, __, __, __, __, __, __, __, __,
			__, __, __, __, __, __, __, __, __, __, __, __, __, __, __, __,
			__, __, __, __, __, __, __, __, __, __, __, __, __, __, __, __,
			__, __, __, __, __, __, __, __, __, __, __, __, __, __, __, __,
			__, __, __, __, __, __, __, __, __, __, __, __, __, __, __, __,
			__, __, __, __, __, __, __, __, __, __, __, __, __, __, __, __,
			__, __, __, __, __, __, __, __, __, __, __, __, __, __, __, __,
			__, __, __, __, __, L0, L0, L0, __, __, __, __, __, __, __, __,
			__, __, __, __, __, __, __, __, L0, L0, L0, __, __, __, __, __,
			__, __, __, __, __, __, __, __, __, __, __, __, __, __, __, __,
			__, __, __, __, __, __, __, __, __, __, __, __, __, __, __, __
		},
		yslice_prob = {
			{prob = 254, ypos = 0},
			{prob = 254, ypos = 1},
			{prob = 254, ypos = 2},
			{prob = 254, ypos = 3},
			{prob = 254, ypos = 4},
			{prob = 254, ypos = 5},
			{prob = 254, ypos = 6},
			{prob = 254, ypos = 7},
			{prob = 254, ypos = 8},
			{prob = 254, ypos = 9},
			{prob = 254, ypos = 10}
		}
	}
	lib_ecology.schematics.insert("schem_mushroom_purple", le_temp_schem)

	local _ = {name = "air", prob = 0}
	local M = {name = "lib_ecology:mushroom_cap_mottled", prob = 255}
	local T = {name = "lib_ecology:mushroom_01_trunk", prob = 255}
	local P = {name = "lib_ecology:mushroom_spore_02", prob = 255}
	le_temp_schem = {
		size = {x = 6, y = 8, z = 6},
		yslice_prob = {
			{ypos = 1, prob =  200}
		},
		data = {
			_,_,_,_,_,_,
			_,_,_,_,_,_,
			_,_,_,_,_,_,
			_,M,M,M,M,_,
			_,_,_,_,_,_,
			_,_,_,_,_,_,
			_,_,_,_,_,_,
			_,_,_,_,_,_,
		
			_,_,_,_,_,_,
			_,_,_,_,_,_,
			_,_,_,_,_,_,
			M,M,P,P,M,M,
			_,_,M,M,_,_,
			_,_,M,M,_,_,
			_,_,M,M,_,_,
			_,_,_,_,_,_,
		
			_,_,T,T,_,_,
			_,_,T,T,_,_,
			_,_,T,T,_,_,
			M,P,T,T,P,M,
			_,M,T,T,M,_,
			_,M,T,T,M,_,
			_,M,T,T,M,_,
			_,_,M,M,_,_,
		
			_,_,T,T,_,_,
			_,_,T,T,_,_,
			_,_,T,T,_,_,
			M,P,T,T,P,M,
			_,M,T,T,M,_,
			_,M,T,T,M,_,
			_,M,T,T,M,_,
			_,_,M,M,_,_,
		
			_,_,_,_,_,_,
			_,_,_,_,_,_,
			_,_,_,_,_,_,
			M,M,P,P,M,M,
			_,_,M,M,_,_,
			_,_,M,M,_,_,
			_,_,M,M,_,_,
			_,_,_,_,_,_,
		
			_,_,_,_,_,_,
			_,_,_,_,_,_,
			_,_,_,_,_,_,
			_,M,M,M,M,_,
			_,_,_,_,_,_,
			_,_,_,_,_,_,
			_,_,_,_,_,_,
			_,_,_,_,_,_
		}
	}
	lib_ecology.schematics.insert("schem_mushroom_giant_morel_large", le_temp_schem)

	local _ = {name = "air", prob = 0}
	local M = {name = "lib_ecology:mushroom_cap_brown_01", prob = 255}
	local T = {name = "lib_ecology:mushroom_01_trunk", prob = 255}
	local P = {name = "lib_ecology:mushroom_spore_01", prob = 255}
	le_temp_schem = {
		size = {x = 4, y = 8, z = 4},
		yslice_prob = {
			{ypos = 1, prob =  200}
		},
		data = {
			_,_,_,_,
			_,_,_,_,
			_,_,_,_,
			_,M,M,_,
			_,M,M,_,
			_,M,M,_,
			_,M,M,_,
			_,_,_,_,
		
			_,T,T,_,
			_,T,T,_,
			_,T,T,_,
			M,T,T,M,
			M,T,T,M,
			M,T,T,M,
			M,T,T,M,
			_,M,M,_,
		
			_,T,T,_,
			_,T,T,_,
			_,T,T,_,
			M,T,T,M,
			M,T,T,M,
			M,T,T,M,
			M,T,T,M,
			_,M,M,_,
		
			_,_,_,_,
			_,_,_,_,
			_,_,_,_,
			_,M,M,_,
			_,M,M,_,
			_,M,M,_,
			_,M,M,_,
			_,_,_,_
		}
	}
	lib_ecology.schematics.insert("schem_mushroom_giant_morel", le_temp_schem)

	local _ = {name = "air", prob = 0}
	local M = {name = "lib_ecology:mushroom_cap_red_01", prob = 255}
	local T = {name = "lib_ecology:mushroom_02_trunk", prob = 255}
	local P = {name = "lib_ecology:mushroom_spore_03", prob = 255}
	le_temp_schem = {
		size = {x = 18, y = 17, z = 18},
		yslice_prob = {
			{ypos = 2, prob = 200},
			{ypos = 9, prob = 200},
			{ypos =10, prob = 200},
		},
		data = {
		_,_,_,_,_,_,_,_,_,_,_,_,_,_,_,_,_,_,
		_,_,_,_,_,_,_,_,_,_,_,_,_,_,_,_,_,_,
		_,_,_,_,_,_,_,_,_,_,_,_,_,_,_,_,_,_,
		_,_,_,_,_,_,_,_,_,_,_,_,_,_,_,_,_,_,
		_,_,_,_,_,_,_,_,_,_,_,_,_,_,_,_,_,_,
		_,_,_,_,_,_,_,_,_,_,_,_,_,_,_,_,_,_,
		_,_,_,_,_,_,_,_,_,_,_,_,_,_,_,_,_,_,
		_,_,_,_,_,_,_,_,_,_,_,_,_,_,_,_,_,_,
		_,_,_,_,_,_,_,_,_,_,_,_,_,_,_,_,_,_,
		_,_,_,_,_,_,_,_,_,_,_,_,_,_,_,_,_,_,
		_,_,_,_,_,_,_,_,_,_,_,_,_,_,_,_,_,_,
		_,_,_,_,_,_,_,_,_,_,_,_,_,_,_,_,_,_,
		_,_,_,_,_,_,_,_,_,_,_,_,_,_,_,_,_,_,
		_,_,_,_,_,_,_,_,_,_,_,_,_,_,_,_,_,_,
		_,_,_,_,_,_,M,M,M,M,M,M,_,_,_,_,_,_,
		_,_,_,_,_,_,_,_,_,_,_,_,_,_,_,_,_,_,
		_,_,_,_,_,_,_,_,_,_,_,_,_,_,_,_,_,_,
	
		_,_,_,_,_,_,_,_,_,_,_,_,_,_,_,_,_,_,
		_,_,_,_,_,_,_,_,_,_,_,_,_,_,_,_,_,_,
		_,_,_,_,_,_,_,_,_,_,_,_,_,_,_,_,_,_,
		_,_,_,_,_,_,_,_,_,_,_,_,_,_,_,_,_,_,
		_,_,_,_,_,_,_,_,_,_,_,_,_,_,_,_,_,_,
		_,_,_,_,_,_,_,_,_,_,_,_,_,_,_,_,_,_,
		_,_,_,_,_,_,_,_,_,_,_,_,_,_,_,_,_,_,
		_,_,_,_,_,_,_,_,_,_,_,_,_,_,_,_,_,_,
		_,_,_,_,_,_,_,_,_,_,_,_,_,_,_,_,_,_,
		_,_,_,_,_,_,_,_,_,_,_,_,_,_,_,_,_,_,
		_,_,_,_,_,_,_,_,_,_,_,_,_,_,_,_,_,_,
		_,_,_,_,_,_,_,_,_,_,_,_,_,_,_,_,_,_,
		_,_,_,_,_,_,_,_,_,_,_,_,_,_,_,_,_,_,
		_,_,_,_,_,_,_,_,_,_,_,_,_,_,_,_,_,_,
		_,_,_,_,_,M,M,M,M,M,M,M,M,_,_,_,_,_,
		_,_,_,_,_,_,_,_,_,_,_,_,_,_,_,_,_,_,
		_,_,_,_,_,_,_,_,_,_,_,_,_,_,_,_,_,_,
	
		_,_,_,_,_,_,_,_,_,_,_,_,_,_,_,_,_,_,
		_,_,_,_,_,_,_,_,_,_,_,_,_,_,_,_,_,_,
		_,_,_,_,_,_,_,_,_,_,_,_,_,_,_,_,_,_,
		_,_,_,_,_,_,_,_,_,_,_,_,_,_,_,_,_,_,
		_,_,_,_,_,_,_,_,_,_,_,_,_,_,_,_,_,_,
		_,_,_,_,_,_,_,_,_,_,_,_,_,_,_,_,_,_,
		_,_,_,_,_,_,_,_,_,_,_,_,_,_,_,_,_,_,
		_,_,_,_,_,_,_,_,_,_,_,_,_,_,_,_,_,_,
		_,_,_,_,_,_,_,_,_,_,_,_,_,_,_,_,_,_,
		_,_,_,_,_,_,_,_,_,_,_,_,_,_,_,_,_,_,
		_,_,_,_,_,_,_,_,_,_,_,_,_,_,_,_,_,_,
		_,_,_,_,_,_,_,_,_,_,_,_,_,_,_,_,_,_,
		_,_,_,_,_,_,_,_,_,_,_,_,_,_,_,_,_,_,
		_,_,_,_,_,_,_,_,_,_,_,_,_,_,_,_,_,_,
		_,_,_,_,M,M,M,M,M,M,M,M,M,M,_,_,_,_,
		_,_,_,_,_,_,_,_,_,_,_,_,_,_,_,_,_,_,
		_,_,_,_,_,_,_,_,_,_,_,_,_,_,_,_,_,_,
	
		_,_,_,_,_,_,_,_,_,_,_,_,_,_,_,_,_,_,
		_,_,_,_,_,_,_,_,_,_,_,_,_,_,_,_,_,_,
		_,_,_,_,_,_,_,_,_,_,_,_,_,_,_,_,_,_,
		_,_,_,_,_,_,_,_,_,_,_,_,_,_,_,_,_,_,
		_,_,_,_,_,_,_,_,_,_,_,_,_,_,_,_,_,_,
		_,_,_,_,_,_,_,_,_,_,_,_,_,_,_,_,_,_,
		_,_,_,_,_,_,_,_,_,_,_,_,_,_,_,_,_,_,
		_,_,_,_,_,_,_,_,_,_,_,_,_,_,_,_,_,_,
		_,_,_,_,_,_,_,_,_,_,_,_,_,_,_,_,_,_,
		_,_,_,_,_,_,_,_,_,_,_,_,_,_,_,_,_,_,
		_,_,_,_,_,_,_,_,_,_,_,_,_,_,_,_,_,_,
		_,_,_,_,_,_,_,_,_,_,_,_,_,_,_,_,_,_,
		_,_,_,_,_,_,_,_,_,_,_,_,_,_,_,_,_,_,
		_,_,_,_,_,_,_,_,_,_,_,_,_,_,_,_,_,_,
		_,_,_,M,M,M,M,_,_,_,_,M,M,M,M,_,_,_,
		_,_,_,_,_,_,_,M,M,M,M,_,_,_,_,_,_,_,
		_,_,_,_,_,_,_,_,_,_,_,_,_,_,_,_,_,_,
	
		_,_,_,_,_,_,_,_,_,_,_,_,_,_,_,_,_,_,
		_,_,_,_,_,_,_,_,_,_,_,_,_,_,_,_,_,_,
		_,_,_,_,_,_,_,_,_,_,_,_,_,_,_,_,_,_,
		_,_,_,_,_,_,_,_,_,_,_,_,_,_,_,_,_,_,
		_,_,_,_,_,_,_,_,_,_,_,_,_,_,_,_,_,_,
		_,_,_,_,_,_,_,_,_,_,_,_,_,_,_,_,_,_,
		_,_,_,_,_,_,_,_,_,_,_,_,_,_,_,_,_,_,
		_,_,_,_,_,_,_,_,_,_,_,_,_,_,_,_,_,_,
		_,_,_,_,_,_,_,_,_,_,_,_,_,_,_,_,_,_,
		_,_,_,_,_,_,_,_,_,_,_,_,_,_,_,_,_,_,
		_,_,_,_,_,_,_,_,_,_,_,_,_,_,_,_,_,_,
		_,_,_,_,_,_,_,_,_,_,_,_,_,_,_,_,_,_,
		_,_,_,_,_,_,_,_,_,_,_,_,_,_,_,_,_,_,
		_,_,_,_,_,_,_,_,_,_,_,_,_,_,_,_,_,_,
		_,M,M,M,M,_,_,_,_,_,_,_,_,M,M,M,M,_,
		_,_,_,_,_,M,M,M,M,M,M,M,M,_,_,_,_,_,
		_,_,_,_,_,_,_,_,_,_,_,_,_,_,_,_,_,_,
	
		_,_,_,_,_,_,_,_,_,_,_,_,_,_,_,_,_,_,
		_,_,_,_,_,_,_,_,_,_,_,_,_,_,_,_,_,_,
		_,_,_,_,_,_,_,_,_,_,_,_,_,_,_,_,_,_,
		_,_,_,_,_,_,_,_,_,_,_,_,_,_,_,_,_,_,
		_,_,_,_,_,_,_,_,_,_,_,_,_,_,_,_,_,_,
		_,_,_,_,_,_,_,_,_,_,_,_,_,_,_,_,_,_,
		_,_,_,_,_,_,_,_,_,_,_,_,_,_,_,_,_,_,
		_,_,_,_,_,_,_,_,_,_,_,_,_,_,_,_,_,_,
		_,_,_,_,_,_,_,_,_,_,_,_,_,_,_,_,_,_,
		_,_,_,_,_,_,_,_,_,_,_,_,_,_,_,_,_,_,
		_,_,_,_,_,_,_,_,_,_,_,_,_,_,_,_,_,_,
		_,_,_,_,_,_,_,_,_,_,_,_,_,_,_,_,_,_,
		_,_,_,_,_,_,_,_,_,_,_,_,_,_,_,_,_,_,
		_,_,_,_,_,_,_,_,_,_,_,_,_,_,_,_,_,_,
		_,M,M,M,_,_,_,_,_,_,_,_,_,_,M,M,M,_,
		_,_,_,_,M,M,M,M,M,M,M,M,M,M,_,_,_,_,
		_,_,_,_,_,_,_,_,_,_,_,_,_,_,_,_,_,_,
	
		_,_,_,_,_,_,_,_,_,_,_,_,_,_,_,_,_,_,
		_,_,_,_,_,_,_,_,_,_,_,_,_,_,_,_,_,_,
		_,_,_,_,_,_,_,_,_,_,_,_,_,_,_,_,_,_,
		_,_,_,_,_,_,_,_,_,_,_,_,_,_,_,_,_,_,
		_,_,_,_,_,_,_,_,_,_,_,_,_,_,_,_,_,_,
		_,_,_,_,_,_,_,_,_,_,_,_,_,_,_,_,_,_,
		_,_,_,_,_,_,_,_,_,_,_,_,_,_,_,_,_,_,
		_,_,_,_,_,_,_,_,_,_,_,_,_,_,_,_,_,_,
		_,_,_,_,_,_,_,_,_,_,_,_,_,_,_,_,_,_,
		_,_,_,_,_,_,_,_,_,_,_,_,_,_,_,_,_,_,
		_,_,_,_,_,_,_,_,_,_,_,_,_,_,_,_,_,_,
		_,_,_,_,_,_,_,_,_,_,_,_,_,_,_,_,_,_,
		_,_,_,_,_,_,_,_,_,_,_,_,_,_,_,_,_,_,
		_,_,_,_,_,_,_,_,_,_,_,_,_,_,_,_,_,_,
		M,M,M,M,_,_,_,_,_,_,_,_,_,_,M,M,M,M,
		_,_,_,_,M,M,M,_,_,_,_,M,M,M,_,_,_,_,
		_,_,_,_,_,_,_,M,M,M,M,_,_,_,_,_,_,_,
	
		_,_,_,_,_,_,_,_,_,_,_,_,_,_,_,_,_,_,
		_,_,_,_,_,_,_,_,_,_,_,_,_,_,_,_,_,_,
		_,_,_,_,_,_,_,_,_,_,_,_,_,_,_,_,_,_,
		_,_,_,_,_,_,_,_,_,_,_,_,_,_,_,_,_,_,
		_,_,_,_,_,_,_,_,_,_,_,_,_,_,_,_,_,_,
		_,_,_,_,_,_,_,_,_,_,_,_,_,_,_,_,_,_,
		_,_,_,_,_,_,_,_,_,_,_,_,_,_,_,_,_,_,
		_,_,_,_,_,_,_,_,_,_,_,_,_,_,_,_,_,_,
		_,_,_,_,_,_,_,_,_,_,_,_,_,_,_,_,_,_,
		_,_,_,_,_,_,_,_,_,_,_,_,_,_,_,_,_,_,
		_,_,_,_,_,_,_,_,_,_,_,_,_,_,_,_,_,_,
		_,_,_,_,_,_,_,_,_,_,_,_,_,_,_,_,_,_,
		_,_,_,_,_,_,_,_,_,_,_,_,_,_,_,_,_,_,
		_,_,_,_,_,_,_,_,_,_,_,_,_,_,_,_,_,_,
		M,M,M,_,_,_,_,_,_,_,_,_,_,_,_,M,M,M,
		_,_,_,M,M,M,_,_,_,_,_,_,M,M,M,_,_,_,
		_,_,_,_,_,_,M,M,M,M,M,M,_,_,_,_,_,_,
	
		_,_,_,_,_,T,T,_,_,_,_,_,_,_,_,_,_,_,
		_,_,_,_,_,T,T,_,_,_,_,_,_,_,_,_,_,_,
		_,_,_,_,_,T,T,_,_,_,_,_,_,_,_,_,_,_,
		_,_,_,_,_,T,T,_,_,_,_,_,_,_,_,_,_,_,
		_,_,_,_,_,_,T,T,_,_,_,_,_,_,_,_,_,_,
		_,_,_,_,_,_,T,T,_,_,_,_,_,_,_,_,_,_,
		_,_,_,_,_,_,_,T,T,_,_,_,_,_,_,_,_,_,
		_,_,_,_,_,_,_,_,T,T,_,_,_,_,_,_,_,_,
		_,_,_,_,_,_,_,_,_,T,T,_,_,_,_,_,_,_,
		_,_,_,_,_,_,_,_,_,T,T,_,_,_,_,_,_,_,
		_,_,_,_,_,_,_,_,_,_,T,T,_,_,_,_,_,_,
		_,_,_,_,_,_,_,_,_,_,T,T,_,_,_,_,_,_,
		_,_,_,_,_,_,_,_,_,_,T,T,_,_,_,_,_,_,
		_,_,_,_,_,_,_,_,_,T,T,_,_,_,_,_,_,_,
		M,M,M,_,_,_,_,_,_,T,T,_,_,_,_,M,M,M,
		_,_,_,M,M,M,_,_,T,T,_,_,M,M,M,_,_,_,
		_,_,_,_,_,_,M,M,M,M,M,M,_,_,_,_,_,_,
	
		_,_,_,_,_,T,T,_,_,_,_,_,_,_,_,_,_,_,
		_,_,_,_,_,T,T,_,_,_,_,_,_,_,_,_,_,_,
		_,_,_,_,_,T,T,_,_,_,_,_,_,_,_,_,_,_,
		_,_,_,_,_,T,T,_,_,_,_,_,_,_,_,_,_,_,
		_,_,_,_,_,_,T,T,_,_,_,_,_,_,_,_,_,_,
		_,_,_,_,_,_,T,T,_,_,_,_,_,_,_,_,_,_,
		_,_,_,_,_,_,_,T,T,_,_,_,_,_,_,_,_,_,
		_,_,_,_,_,_,_,_,T,T,_,_,_,_,_,_,_,_,
		_,_,_,_,_,_,_,_,_,T,T,_,_,_,_,_,_,_,
		_,_,_,_,_,_,_,_,_,T,T,_,_,_,_,_,_,_,
		_,_,_,_,_,_,_,_,_,_,T,T,_,_,_,_,_,_,
		_,_,_,_,_,_,_,_,_,_,T,T,_,_,_,_,_,_,
		_,_,_,_,_,_,_,_,_,_,T,T,_,_,_,_,_,_,
		_,_,_,_,_,_,_,_,_,T,T,_,_,_,_,_,_,_,
		M,M,M,_,_,_,_,_,_,T,T,_,_,_,_,M,M,M,
		_,_,_,M,M,M,_,_,T,T,_,_,M,M,M,_,_,_,
		_,_,_,_,_,_,M,M,M,M,M,M,_,_,_,_,_,_,
	
		_,_,_,_,_,_,_,_,_,_,_,_,_,_,_,_,_,_,
		_,_,_,_,_,_,_,_,_,_,_,_,_,_,_,_,_,_,
		_,_,_,_,_,_,_,_,_,_,_,_,_,_,_,_,_,_,
		_,_,_,_,_,_,_,_,_,_,_,_,_,_,_,_,_,_,
		_,_,_,_,_,_,_,_,_,_,_,_,_,_,_,_,_,_,
		_,_,_,_,_,_,_,_,_,_,_,_,_,_,_,_,_,_,
		_,_,_,_,_,_,_,_,_,_,_,_,_,_,_,_,_,_,
		_,_,_,_,_,_,_,_,_,_,_,_,_,_,_,_,_,_,
		_,_,_,_,_,_,_,_,_,_,_,_,_,_,_,_,_,_,
		_,_,_,_,_,_,_,_,_,_,_,_,_,_,_,_,_,_,
		_,_,_,_,_,_,_,_,_,_,_,_,_,_,_,_,_,_,
		_,_,_,_,_,_,_,_,_,_,_,_,_,_,_,_,_,_,
		_,_,_,_,_,_,_,_,_,_,_,_,_,_,_,_,_,_,
		_,_,_,_,_,_,_,_,_,_,_,_,_,_,_,_,_,_,
		M,M,M,_,_,_,_,_,_,_,_,_,_,_,_,M,M,M,
		_,_,_,M,M,M,_,_,_,_,_,_,M,M,M,_,_,_,
		_,_,_,_,_,_,M,M,M,M,M,M,_,_,_,_,_,_,
	
		_,_,_,_,_,_,_,_,_,_,_,_,_,_,_,_,_,_,
		_,_,_,_,_,_,_,_,_,_,_,_,_,_,_,_,_,_,
		_,_,_,_,_,_,_,_,_,_,_,_,_,_,_,_,_,_,
		_,_,_,_,_,_,_,_,_,_,_,_,_,_,_,_,_,_,
		_,_,_,_,_,_,_,_,_,_,_,_,_,_,_,_,_,_,
		_,_,_,_,_,_,_,_,_,_,_,_,_,_,_,_,_,_,
		_,_,_,_,_,_,_,_,_,_,_,_,_,_,_,_,_,_,
		_,_,_,_,_,_,_,_,_,_,_,_,_,_,_,_,_,_,
		_,_,_,_,_,_,_,_,_,_,_,_,_,_,_,_,_,_,
		_,_,_,_,_,_,_,_,_,_,_,_,_,_,_,_,_,_,
		_,_,_,_,_,_,_,_,_,_,_,_,_,_,_,_,_,_,
		_,_,_,_,_,_,_,_,_,_,_,_,_,_,_,_,_,_,
		_,_,_,_,_,_,_,_,_,_,_,_,_,_,_,_,_,_,
		_,_,_,_,_,_,_,_,_,_,_,_,_,_,_,_,_,_,
		M,M,M,M,_,_,_,_,_,_,_,_,_,_,M,M,M,M,
		_,_,_,_,M,M,M,_,_,_,_,M,M,M,_,_,_,_,
		_,_,_,_,_,_,_,M,M,M,M,_,_,_,_,_,_,_,
	
		_,_,_,_,_,_,_,_,_,_,_,_,_,_,_,_,_,_,
		_,_,_,_,_,_,_,_,_,_,_,_,_,_,_,_,_,_,
		_,_,_,_,_,_,_,_,_,_,_,_,_,_,_,_,_,_,
		_,_,_,_,_,_,_,_,_,_,_,_,_,_,_,_,_,_,
		_,_,_,_,_,_,_,_,_,_,_,_,_,_,_,_,_,_,
		_,_,_,_,_,_,_,_,_,_,_,_,_,_,_,_,_,_,
		_,_,_,_,_,_,_,_,_,_,_,_,_,_,_,_,_,_,
		_,_,_,_,_,_,_,_,_,_,_,_,_,_,_,_,_,_,
		_,_,_,_,_,_,_,_,_,_,_,_,_,_,_,_,_,_,
		_,_,_,_,_,_,_,_,_,_,_,_,_,_,_,_,_,_,
		_,_,_,_,_,_,_,_,_,_,_,_,_,_,_,_,_,_,
		_,_,_,_,_,_,_,_,_,_,_,_,_,_,_,_,_,_,
		_,_,_,_,_,_,_,_,_,_,_,_,_,_,_,_,_,_,
		_,_,_,_,_,_,_,_,_,_,_,_,_,_,_,_,_,_,
		_,M,M,M,_,_,_,_,_,_,_,_,_,_,M,M,M,_,
		_,_,_,_,M,M,M,M,M,M,M,M,M,M,_,_,_,_,
		_,_,_,_,_,_,_,_,_,_,_,_,_,_,_,_,_,_,
	
		_,_,_,_,_,_,_,_,_,_,_,_,_,_,_,_,_,_,
		_,_,_,_,_,_,_,_,_,_,_,_,_,_,_,_,_,_,
		_,_,_,_,_,_,_,_,_,_,_,_,_,_,_,_,_,_,
		_,_,_,_,_,_,_,_,_,_,_,_,_,_,_,_,_,_,
		_,_,_,_,_,_,_,_,_,_,_,_,_,_,_,_,_,_,
		_,_,_,_,_,_,_,_,_,_,_,_,_,_,_,_,_,_,
		_,_,_,_,_,_,_,_,_,_,_,_,_,_,_,_,_,_,
		_,_,_,_,_,_,_,_,_,_,_,_,_,_,_,_,_,_,
		_,_,_,_,_,_,_,_,_,_,_,_,_,_,_,_,_,_,
		_,_,_,_,_,_,_,_,_,_,_,_,_,_,_,_,_,_,
		_,_,_,_,_,_,_,_,_,_,_,_,_,_,_,_,_,_,
		_,_,_,_,_,_,_,_,_,_,_,_,_,_,_,_,_,_,
		_,_,_,_,_,_,_,_,_,_,_,_,_,_,_,_,_,_,
		_,_,_,_,_,_,_,_,_,_,_,_,_,_,_,_,_,_,
		_,M,M,M,M,_,_,_,_,_,_,_,_,M,M,M,M,_,
		_,_,_,_,_,M,M,M,M,M,M,M,M,_,_,_,_,_,
		_,_,_,_,_,_,_,_,_,_,_,_,_,_,_,_,_,_,
	
		_,_,_,_,_,_,_,_,_,_,_,_,_,_,_,_,_,_,
		_,_,_,_,_,_,_,_,_,_,_,_,_,_,_,_,_,_,
		_,_,_,_,_,_,_,_,_,_,_,_,_,_,_,_,_,_,
		_,_,_,_,_,_,_,_,_,_,_,_,_,_,_,_,_,_,
		_,_,_,_,_,_,_,_,_,_,_,_,_,_,_,_,_,_,
		_,_,_,_,_,_,_,_,_,_,_,_,_,_,_,_,_,_,
		_,_,_,_,_,_,_,_,_,_,_,_,_,_,_,_,_,_,
		_,_,_,_,_,_,_,_,_,_,_,_,_,_,_,_,_,_,
		_,_,_,_,_,_,_,_,_,_,_,_,_,_,_,_,_,_,
		_,_,_,_,_,_,_,_,_,_,_,_,_,_,_,_,_,_,
		_,_,_,_,_,_,_,_,_,_,_,_,_,_,_,_,_,_,
		_,_,_,_,_,_,_,_,_,_,_,_,_,_,_,_,_,_,
		_,_,_,_,_,_,_,_,_,_,_,_,_,_,_,_,_,_,
		_,_,_,_,_,_,_,_,_,_,_,_,_,_,_,_,_,_,
		_,_,_,M,M,M,M,_,_,_,_,M,M,M,M,_,_,_,
		_,_,_,_,_,_,_,M,M,M,M,_,_,_,_,_,_,_,
		_,_,_,_,_,_,_,_,_,_,_,_,_,_,_,_,_,_,
	
		_,_,_,_,_,_,_,_,_,_,_,_,_,_,_,_,_,_,
		_,_,_,_,_,_,_,_,_,_,_,_,_,_,_,_,_,_,
		_,_,_,_,_,_,_,_,_,_,_,_,_,_,_,_,_,_,
		_,_,_,_,_,_,_,_,_,_,_,_,_,_,_,_,_,_,
		_,_,_,_,_,_,_,_,_,_,_,_,_,_,_,_,_,_,
		_,_,_,_,_,_,_,_,_,_,_,_,_,_,_,_,_,_,
		_,_,_,_,_,_,_,_,_,_,_,_,_,_,_,_,_,_,
		_,_,_,_,_,_,_,_,_,_,_,_,_,_,_,_,_,_,
		_,_,_,_,_,_,_,_,_,_,_,_,_,_,_,_,_,_,
		_,_,_,_,_,_,_,_,_,_,_,_,_,_,_,_,_,_,
		_,_,_,_,_,_,_,_,_,_,_,_,_,_,_,_,_,_,
		_,_,_,_,_,_,_,_,_,_,_,_,_,_,_,_,_,_,
		_,_,_,_,_,_,_,_,_,_,_,_,_,_,_,_,_,_,
		_,_,_,_,_,_,_,_,_,_,_,_,_,_,_,_,_,_,
		_,_,_,_,M,M,M,M,M,M,M,M,M,M,_,_,_,_,
		_,_,_,_,_,_,_,_,_,_,_,_,_,_,_,_,_,_,
		_,_,_,_,_,_,_,_,_,_,_,_,_,_,_,_,_,_,
	
		_,_,_,_,_,_,_,_,_,_,_,_,_,_,_,_,_,_,
		_,_,_,_,_,_,_,_,_,_,_,_,_,_,_,_,_,_,
		_,_,_,_,_,_,_,_,_,_,_,_,_,_,_,_,_,_,
		_,_,_,_,_,_,_,_,_,_,_,_,_,_,_,_,_,_,
		_,_,_,_,_,_,_,_,_,_,_,_,_,_,_,_,_,_,
		_,_,_,_,_,_,_,_,_,_,_,_,_,_,_,_,_,_,
		_,_,_,_,_,_,_,_,_,_,_,_,_,_,_,_,_,_,
		_,_,_,_,_,_,_,_,_,_,_,_,_,_,_,_,_,_,
		_,_,_,_,_,_,_,_,_,_,_,_,_,_,_,_,_,_,
		_,_,_,_,_,_,_,_,_,_,_,_,_,_,_,_,_,_,
		_,_,_,_,_,_,_,_,_,_,_,_,_,_,_,_,_,_,
		_,_,_,_,_,_,_,_,_,_,_,_,_,_,_,_,_,_,
		_,_,_,_,_,_,_,_,_,_,_,_,_,_,_,_,_,_,
		_,_,_,_,_,_,_,_,_,_,_,_,_,_,_,_,_,_,
		_,_,_,_,_,M,M,M,M,M,M,M,M,_,_,_,_,_,
		_,_,_,_,_,_,_,_,_,_,_,_,_,_,_,_,_,_,
		_,_,_,_,_,_,_,_,_,_,_,_,_,_,_,_,_,_,
	
		_,_,_,_,_,_,_,_,_,_,_,_,_,_,_,_,_,_,
		_,_,_,_,_,_,_,_,_,_,_,_,_,_,_,_,_,_,
		_,_,_,_,_,_,_,_,_,_,_,_,_,_,_,_,_,_,
		_,_,_,_,_,_,_,_,_,_,_,_,_,_,_,_,_,_,
		_,_,_,_,_,_,_,_,_,_,_,_,_,_,_,_,_,_,
		_,_,_,_,_,_,_,_,_,_,_,_,_,_,_,_,_,_,
		_,_,_,_,_,_,_,_,_,_,_,_,_,_,_,_,_,_,
		_,_,_,_,_,_,_,_,_,_,_,_,_,_,_,_,_,_,
		_,_,_,_,_,_,_,_,_,_,_,_,_,_,_,_,_,_,
		_,_,_,_,_,_,_,_,_,_,_,_,_,_,_,_,_,_,
		_,_,_,_,_,_,_,_,_,_,_,_,_,_,_,_,_,_,
		_,_,_,_,_,_,_,_,_,_,_,_,_,_,_,_,_,_,
		_,_,_,_,_,_,_,_,_,_,_,_,_,_,_,_,_,_,
		_,_,_,_,_,_,_,_,_,_,_,_,_,_,_,_,_,_,
		_,_,_,_,_,_,M,M,M,M,M,M,_,_,_,_,_,_,
		_,_,_,_,_,_,_,_,_,_,_,_,_,_,_,_,_,_,
		_,_,_,_,_,_,_,_,_,_,_,_,_,_,_,_,_,_
		}
	}
	lib_ecology.schematics.insert("schem_mushroom_giant_tall", le_temp_schem)

--[[
	local ms = {name = "lib_ecology:mushroom_small_trunk", param2 = 0, prob = 254}
	local mc = {name = "lib_ecology:mushroom_small_cap_01", param2 = 0, prob = 254}
	le_temp_schem = {
		size = {x = 1, y = 3, z = 1},
		data = {
			ms,
			ms,
			mc,
		},
	}
	lib_ecology.schematics.insert("schem_mushroom_03_a", le_temp_schem)


	local ms = {name = "lib_ecology:mushroom_small_trunk", param2 = 0, prob = 254}
	local mc = {name = "lib_ecology:mushroom_small_cap_02", param2 = 0, prob = 254}
	le_temp_schem = {
		size = {x = 1, y = 3, z = 1},
		data = {
			ms,
			ms,
			mc,
		},
	}
	lib_ecology.schematics.insert("schem_mushroom_03_b", le_temp_schem)
--]]


-- waterlilies
	le_temp_schem = {
		size = {x = 1, y = 3, z = 1},
		data = {
			{name = "lib_materials:sand", param2 = 0, prob = 254},
			{name = "lib_materials:liquid_water_source", param2 = 0, prob = 254},
			{name = "lib_ecology:plant_waterlily_pink", param2 = 0, prob = 254}
		},
	}
	lib_ecology.schematics.insert("schem_waterlily_pink", le_temp_schem)

	le_temp_schem = {
		size = {x = 1, y = 3, z = 1},
		data = {
			{name = "lib_materials:sand", param2 = 0, prob = 254},
			{name = "lib_materials:liquid_water_source", param2 = 0, prob = 254},
			{name = "lib_ecology:plant_waterlily_yellow", param2 = 0, prob = 254}
		},
	}
	lib_ecology.schematics.insert("schem_waterlily_yellow", le_temp_schem)



--TREES

--Acacia Tree
	T0 = {name = "lib_ecology:tree_acacia_trunk", param2 = 0, prob = 254}
	L0 = {name = "lib_ecology:tree_acacia_leaves", param2 = 0, prob = 254}
	L1 = {name = "lib_ecology:tree_acacia_leaves", param2 = 0, prob = 222}
	le_temp_schem = {
		size = {x = 9,y = 8,z = 9},
		data = {
			__, __, __, __, __, __, __, __, __,
			__, __, __, __, __, __, __, __, __,
			__, __, __, __, __, __, __, __, __,
			__, __, __, __, __, __, __, __, __,
			__, __, __, __, __, __, __, __, __,
			__, __, __, __, __, __, __, __, __,
			L1, L1, L1, L1, __, __, __, __, __,
			__, __, __, __, L1, L1, L1, L1, L1,
			
			__, __, __, __, __, __, __, __, __,
			__, __, __, __, __, __, __, __, __,
			__, __, __, __, __, __, __, __, __,
			__, __, __, __, __, __, __, __, __,
			__, __, __, __, __, __, __, __, __,
			__, __, __, __, __, __, __, __, __,
			L1, L0, L0, L1, __, __, __, __, __,
			__, __, __, __, L1, L0, L0, L0, L1,
			
			__, __, __, __, __, __, __, __, __,
			__, __, __, __, __, __, __, __, __,
			__, __, __, __, __, __, __, __, __,
			__, __, __, __, __, __, __, __, __,
			__, __, __, __, __, __, __, __, __,
			__, __, T0, __, __, __, __, __, __,
			L1, L0, L0, L1, __, __, T0, __, __,
			__, __, __, __, L1, L0, L0, L0, L1,
			
			__, __, __, __, __, __, __, __, __,
			__, __, __, __, __, __, __, __, __,
			__, __, __, __, __, __, __, __, __,
			__, __, __, __, __, __, __, __, __,
			__, __, __, T0, __, __, __, __, __,
			__, __, __, __, __, T0, __, __, __,
			L1, L1, L1, L1, __, __, __, __, __,
			__, __, __, __, L1, L0, L0, L0, L1,
			
			__, __, __, __, T0, __, __, __, __,
			__, __, __, __, T0, __, __, __, __,
			__, __, __, __, T0, __, __, __, __,
			__, __, __, __, T0, __, __, __, __,
			__, __, __, __, T0, __, __, __, __,
			__, __, __, __, __, __, __, __, __,
			__, __, __, __, __, __, __, __, __,
			L1, L1, L1, L1, L1, L1, L1, L1, L1,
			
			__, __, __, __, __, __, __, __, __,
			__, __, __, __, __, __, __, __, __,
			__, __, __, __, __, __, __, __, __,
			__, __, __, __, __, __, __, __, __,
			__, __, __, __, __, T0, __, __, __,
			__, __, __, T0, __, __, __, __, __,
			__, __, __, __, __, L1, L1, L1, L1,
			L1, L0, L0, L0, L1, __, __, __, __,
			
			__, __, __, __, __, __, __, __, __,
			__, __, __, __, __, __, __, __, __,
			__, __, __, __, __, __, __, __, __,
			__, __, __, __, __, __, __, __, __,
			__, __, __, __, __, __, __, __, __,
			__, __, __, __, __, __, T0, __, __,
			__, __, T0, __, __, L1, L0, L0, L1,
			L1, L0, L0, L0, L1, __, __, __, __,
			
			__, __, __, __, __, __, __, __, __,
			__, __, __, __, __, __, __, __, __,
			__, __, __, __, __, __, __, __, __,
			__, __, __, __, __, __, __, __, __,
			__, __, __, __, __, __, __, __, __,
			__, __, __, __, __, __, __, __, __,
			__, __, __, __, __, L1, L0, L0, L1,
			L1, L0, L0, L0, L1, __, __, __, __,
			
			__, __, __, __, __, __, __, __, __,
			__, __, __, __, __, __, __, __, __,
			__, __, __, __, __, __, __, __, __,
			__, __, __, __, __, __, __, __, __,
			__, __, __, __, __, __, __, __, __,
			__, __, __, __, __, __, __, __, __,
			__, __, __, __, __, L1, L1, L1, L1,
			L1, L1, L1, L1, L1, __, __, __, __
		},
		yslice_prob = {
			{ypos = 0,prob = 254},
			{ypos = 1,prob = 254},
			{ypos = 2,prob = 126},
			{ypos = 3,prob = 254},
			{ypos = 4,prob = 254},
			{ypos = 5,prob = 254},
			{ypos = 6,prob = 254},
			{ypos = 7,prob = 254}
		}
	}
	lib_ecology.schematics.insert("schem_tree_acacia_01", le_temp_schem)
	le_temp_schem = {
		size = {x = 11,y = 11,z = 11},
		data = {
			__, __, __, __, __, __, __, __, __, __, __,
			__, __, __, __, __, __, __, __, __, __, __,
			__, __, __, __, __, __, __, __, __, __, __,
			__, __, __, __, __, __, __, __, __, __, __,
			__, __, __, __, __, __, __, __, __, __, __,
			__, __, __, __, __, __, __, __, __, __, __,
			__, __, __, __, __, __, __, __, __, __, __,
			__, __, __, __, __, __, __, __, __, __, __,
			__, __, __, __, __, __, __, __, __, __, __,
			__, __, __, __, __, L0, __, __, __, __, __,
			__, __, __, __, __, __, __, __, __, __, __,
			
			__, __, __, __, __, __, __, __, __, __, __,
			__, __, __, __, __, __, __, __, __, __, __,
			__, __, __, __, __, __, __, __, __, __, __,
			__, __, __, __, __, __, __, __, __, __, __,
			__, __, __, __, __, __, __, __, __, __, __,
			__, __, __, __, __, __, __, __, __, __, __,
			__, __, __, __, __, __, __, __, __, __, __,
			__, __, __, __, __, __, __, __, __, __, __,
			__, __, __, __, __, __, __, __, __, __, __,
			__, __, __, __, L0, L0, L0, __, __, __, __,
			__, __, __, __, __, __, __, __, __, __, __,
			
			__, __, __, __, __, __, __, __, __, __, __,
			__, __, __, __, __, __, __, __, __, __, __,
			__, __, __, __, __, __, __, __, __, __, __,
			__, __, __, __, __, __, __, __, __, __, __,
			__, __, __, __, __, __, __, __, __, __, __,
			__, __, __, __, __, __, __, __, __, __, __,
			__, __, __, __, __, __, __, __, __, __, __,
			__, __, __, __, __, __, __, __, __, __, __,
			__, __, __, __, __, T0, __, __, __, __, __,
			__, __, __, L0, L0, L0, L0, L0, __, __, __,
			__, __, __, __, __, L0, __, __, __, __, __,
			
			__, __, __, __, __, __, __, __, __, __, __,
			__, __, __, __, __, __, __, __, __, __, __,
			__, __, __, __, __, __, __, __, __, __, __,
			__, __, __, __, __, __, __, __, __, __, __,
			__, __, __, __, __, __, __, __, __, __, __,
			__, __, __, __, __, __, __, __, __, __, __,
			__, __, __, __, __, __, __, __, __, __, __,
			__, __, __, __, __, T0, __, __, __, __, __,
			__, __, __, __, __, __, __, __, __, __, __,
			__, __, L0, L0, L0, L0, L0, L0, L0, __, __,
			__, __, __, L0, L0, L0, L0, L0, __, __, __,
			
			__, __, __, __, __, __, __, __, __, __, __,
			__, __, __, __, __, __, __, __, __, __, __,
			__, __, __, __, __, __, __, __, __, __, __,
			__, __, __, __, __, __, __, __, __, __, __,
			__, __, __, __, __, __, __, __, __, __, __,
			__, __, __, __, __, __, __, __, __, __, __,
			__, __, __, __, __, T0, __, __, __, __, __,
			__, __, __, __, __, __, __, __, __, __, __,
			__, __, __, __, __, __, __, __, __, __, __,
			__, L0, L0, L0, L0, L0, L0, L0, L0, L0, __,
			__, __, __, L0, L0, L0, L0, L0, __, __, __,
			
			__, __, __, __, __, T0, __, __, __, __, __,
			__, __, __, __, __, T0, __, __, __, __, __,
			__, __, __, __, __, T0, __, __, __, __, __,
			__, __, __, __, __, T0, __, __, __, __, __,
			__, __, __, __, __, T0, __, __, __, __, __,
			__, __, __, __, __, T0, __, __, __, __, __,
			__, __, __, __, T0, __, T0, __, __, __, __,
			__, __, __, T0, __, __, __, T0, __, __, __,
			__, __, T0, __, __, __, __, __, T0, __, __,
			L0, L0, L0, L0, L0, L0, L0, L0, L0, L0, L0,
			__, __, L0, L0, L0, L0, L0, L0, L0, __, __,
			
			__, __, __, __, __, __, __, __, __, __, __,
			__, __, __, __, __, __, __, __, __, __, __,
			__, __, __, __, __, __, __, __, __, __, __,
			__, __, __, __, __, __, __, __, __, __, __,
			__, __, __, __, __, __, __, __, __, __, __,
			__, __, __, __, __, __, __, __, __, __, __,
			__, __, __, __, __, T0, __, __, __, __, __,
			__, __, __, __, __, __, __, __, __, __, __,
			__, __, __, __, __, __, __, __, __, __, __,
			__, L0, L0, L0, L0, L0, L0, L0, L0, L0, __,
			__, __, __, L0, L0, L0, L0, L0, __, __, __,
			
			__, __, __, __, __, __, __, __, __, __, __,
			__, __, __, __, __, __, __, __, __, __, __,
			__, __, __, __, __, __, __, __, __, __, __,
			__, __, __, __, __, __, __, __, __, __, __,
			__, __, __, __, __, __, __, __, __, __, __,
			__, __, __, __, __, __, __, __, __, __, __,
			__, __, __, __, __, __, __, __, __, __, __,
			__, __, __, __, __, T0, __, __, __, __, __,
			__, __, __, __, __, __, __, __, __, __, __,
			__, __, L0, L0, L0, L0, L0, L0, L0, __, __,
			__, __, __, L0, L0, L0, L0, L0, __, __, __,
			
			__, __, __, __, __, __, __, __, __, __, __,
			__, __, __, __, __, __, __, __, __, __, __,
			__, __, __, __, __, __, __, __, __, __, __,
			__, __, __, __, __, __, __, __, __, __, __,
			__, __, __, __, __, __, __, __, __, __, __,
			__, __, __, __, __, __, __, __, __, __, __,
			__, __, __, __, __, __, __, __, __, __, __,
			__, __, __, __, __, __, __, __, __, __, __,
			__, __, __, __, __, T0, __, __, __, __, __,
			__, __, __, L0, L0, L0, L0, L0, __, __, __,
			__, __, __, __, __, L0, __, __, __, __, __,
			
			__, __, __, __, __, __, __, __, __, __, __,
			__, __, __, __, __, __, __, __, __, __, __,
			__, __, __, __, __, __, __, __, __, __, __,
			__, __, __, __, __, __, __, __, __, __, __,
			__, __, __, __, __, __, __, __, __, __, __,
			__, __, __, __, __, __, __, __, __, __, __,
			__, __, __, __, __, __, __, __, __, __, __,
			__, __, __, __, __, __, __, __, __, __, __,
			__, __, __, __, __, __, __, __, __, __, __,
			__, __, __, __, L0, L0, L0, __, __, __, __,
			__, __, __, __, __, __, __, __, __, __, __,
			
			__, __, __, __, __, __, __, __, __, __, __,
			__, __, __, __, __, __, __, __, __, __, __,
			__, __, __, __, __, __, __, __, __, __, __,
			__, __, __, __, __, __, __, __, __, __, __,
			__, __, __, __, __, __, __, __, __, __, __,
			__, __, __, __, __, __, __, __, __, __, __,
			__, __, __, __, __, __, __, __, __, __, __,
			__, __, __, __, __, __, __, __, __, __, __,
			__, __, __, __, __, __, __, __, __, __, __,
			__, __, __, __, __, L0, __, __, __, __, __,
			__, __, __, __, __, __, __, __, __, __, __
		},
		yslice_prob = {
			{ypos = 0,prob = 254},
			{ypos = 1,prob = 254},
			{ypos = 2,prob = 254},
			{ypos = 3,prob = 254},
			{ypos = 4,prob = 254},
			{ypos = 5,prob = 254},
			{ypos = 6,prob = 254},
			{ypos = 7,prob = 254},
			{ypos = 8,prob = 254},
			{ypos = 9,prob = 254},
			{ypos = 10,prob = 254}
		}
	}
	lib_ecology.schematics.insert("schem_tree_acacia_02", le_temp_schem)
	le_temp_schem = {
		size = {x = 9,y = 8,z = 9},
		data = {
			__, __, __, __, __, __, __, __, __,
			__, __, __, __, __, __, __, __, __,
			__, __, __, __, __, __, __, __, __,
			__, __, __, __, __, __, __, __, __,
			__, __, __, __, __, __, __, __, __,
			__, __, __, __, __, __, __, __, __,
			L1, L1, L1, L1, __, __, __, __, __,
			__, __, __, __, L1, L1, L1, L1, L1,
			__, __, __, __, __, __, __, __, __,
			
			__, __, __, __, __, __, __, __, __,
			__, __, __, __, __, __, __, __, __,
			__, __, __, __, __, __, __, __, __,
			__, __, __, __, __, __, __, __, __,
			__, __, __, __, __, __, __, __, __,
			L1, L0, L0, L1, __, __, __, __, __,
			__, __, __, __, L1, L0, L0, L0, L1,
			__, __, __, __, __, __, __, __, __,
			__, __, __, __, __, __, __, __, __,
			
			__, __, __, __, __, __, __, __, __,
			__, __, __, __, __, __, __, __, __,
			__, __, __, __, __, __, __, __, __,
			__, __, T0, __, __, __, __, __, __,
			L1, L0, L0, L1, __, __, T0, __, __,
			__, __, __, __, L1, L0, L0, L0, L1,
			__, __, __, __, __, __, __, __, __,
			__, __, __, __, __, __, __, __, __,
			__, __, __, __, __, __, __, __, __,
			
			__, __, __, __, __, __, __, __, __,
			__, __, __, T0, __, __, __, __, __,
			__, __, __, __, __, T0, __, __, __,
			L1, L1, L1, L1, __, __, __, __, __,
			__, __, __, __, L1, L0, L0, L0, L1,
			__, __, __, __, T0, __, __, __, __,
			__, __, __, __, T0, __, __, __, __,
			__, __, __, __, T0, __, __, __, __,
			__, __, __, __, T0, __, __, __, __,
			
			__, __, __, __, T0, __, __, __, __,
			__, __, __, __, __, __, __, __, __,
			__, __, __, __, __, __, __, __, __,
			L1, L1, L1, L1, L1, L1, L1, L1, L1,
			__, __, __, __, __, __, __, __, __,
			__, __, __, __, __, __, __, __, __,
			__, __, __, __, __, __, __, __, __,
			__, __, __, __, __, __, __, __, __,
			__, __, __, __, __, T0, __, __, __,
			
			__, __, __, T0, __, __, __, __, __,
			__, __, __, __, __, L1, L1, L1, L1,
			L1, L0, L0, L0, L1, __, __, __, __,
			__, __, __, __, __, __, __, __, __,
			__, __, __, __, __, __, __, __, __,
			__, __, __, __, __, __, __, __, __,
			__, __, __, __, __, __, __, __, __,
			__, __, __, __, __, __, __, __, __,
			__, __, __, __, __, __, T0, __, __,
			
			__, __, T0, __, __, L1, L0, L0, L1,
			L1, L0, L0, L0, L1, __, __, __, __,
			__, __, __, __, __, __, __, __, __,
			__, __, __, __, __, __, __, __, __,
			__, __, __, __, __, __, __, __, __,
			__, __, __, __, __, __, __, __, __,
			__, __, __, __, __, __, __, __, __,
			__, __, __, __, __, __, __, __, __,
			__, __, __, __, __, L1, L0, L0, L1,
			
			L1, L0, L0, L0, L1, __, __, __, __,
			__, __, __, __, __, __, __, __, __,
			__, __, __, __, __, __, __, __, __,
			__, __, __, __, __, __, __, __, __,
			__, __, __, __, __, __, __, __, __,
			__, __, __, __, __, __, __, __, __,
			__, __, __, __, __, __, __, __, __,
			__, __, __, __, __, L1, L1, L1, L1,
			L1, L1, L1, L1, L1, __, __, __, __
		},
		yslice_prob = {
			{ypos = 0,prob = 254},
			{ypos = 1,prob = 254},
			{ypos = 2,prob = 126},
			{ypos = 3,prob = 254},
			{ypos = 4,prob = 254},
			{ypos = 5,prob = 254},
			{ypos = 6,prob = 254},
			{ypos = 7,prob = 254}
		}
	}
	lib_ecology.schematics.insert("schem_tree_acacia_03", le_temp_schem)
	le_temp_schem = {
		size = {x = 17,y = 12,z = 17},
		data = {
			__, __, __, __, __, __, __, __, __, __, __, __, __, __, __, __, __,
