

local S = lib_ecology.intllib

--Local vars to define air and tree trunks, leaves, fruits, vines, and other associated nodes for use within the lua schematics
--air is defined as an _ (underscore) throughout
--Leaf direction and probabilities are defined.
--Trunk direction and probabilities are defined
--Vine direction is defined
--Fruit uses a generic probability of 127


--[[  LUA SCHEMATICS NEED TO BE REDEFINED TO USE CENTRALIZED LOCAL VARIABLES UPDATING EACH VAR FOR EACH SCHEMATIC
--]]

local __ = {name = "air",param2 = 0,prob = 0}
local D0 = {name = "lib_materials:dirt", param2 = 0, prob = 254}

local LL --= {name = "lib_ecology:tree_NAME_leaves",param2 = 0,prob = 254, force_place = true}
local L0 --= {name = "lib_ecology:tree_NAME_leaves",param2 = 0,prob = 254}
local L1 --= {name = "lib_ecology:tree_NAME_leaves",param2 = 0,prob = 222}
local L2 --= {name = "lib_ecology:tree_NAME_leaves",param2 = 0,prob = 190}
local L3 --= {name = "lib_ecology:tree_NAME_leaves",param2 = 0,prob = 126}
local L4 --= {name = "lib_ecology:tree_NAME_leaves",param2 = 0,prob = 96}
local L5 --= {name = "lib_ecology:tree_NAME_leaves",param2 = 0,prob = 64}
local L6 --= {name = "lib_ecology:tree_NAME_leaves",param2 = 0,prob = 32}
local LN --= {name = "lib_ecology:tree_NAME_leaves",param2 = 0,prob = 254}
local LE --= {name = "lib_ecology:tree_NAME_leaves",param2 = 1,prob = 254}
local LS --= {name = "lib_ecology:tree_NAME_leaves",param2 = 2,prob = 254}
local LW --= {name = "lib_ecology:tree_NAME_leaves",param2 = 3,prob = 254}

local TT --= {name = "lib_ecology:tree_NAME_trunk",param2 = 0,prob = 254, force_place = true}
local T0 --= {name = "lib_ecology:tree_NAME_trunk",param2 = 0,prob = 254}
local T1 --= {name = "lib_ecology:tree_NAME_trunk",param2 = 0,prob = 254}
local T2 --= {name = "lib_ecology:tree_NAME_trunk",param2 = 0,prob = 160}
local T3 --= {name = "lib_ecology:tree_NAME_trunk",param2 = 0,prob = 127}
local TN --= {name = "lib_ecology:tree_NAME_trunk",param2 = 4,prob = 254}
local TS --= {name = "lib_ecology:tree_NAME_trunk",param2 = 8,prob = 254}
local TE --= {name = "lib_ecology:tree_NAME_trunk",param2 = 12,prob = 254}
local TW --= {name = "lib_ecology:tree_NAME_trunk",param2 = 16,prob = 254}

local V0 --= {name = "lib_ecology:plant_vine_01",param2 = 0,prob = 254}
local V1 --= {name = "lib_ecology:plant_vine_01",param2 = 1,prob = 254}
local V2 --= {name = "lib_ecology:plant_vine_01",param2 = 2,prob = 254}
local V3 --= {name = "lib_ecology:plant_vine_01",param2 = 3,prob = 254}
local VN --= {name = "lib_ecology:plant_vine_01",param2 = 0,prob = 254}
local VE --= {name = "lib_ecology:plant_vine_01",param2 = 1,prob = 254}
local VS --= {name = "lib_ecology:plant_vine_01",param2 = 2,prob = 254}
local VW --= {name = "lib_ecology:plant_vine_01",param2 = 3,prob = 254}

local F0 --= {name = "lib_ecology:fruit_NAME",param2 = 0,prob = 254}
local F1 --= {name = "lib_ecology:fruit_NAME",param2 = 0,prob = 222}
local F2 --= {name = "lib_ecology:fruit_NAME",param2 = 0,prob = 190}
local F3 --= {name = "lib_ecology:fruit_NAME",param2 = 0,prob = 127}
local F4 --= {name = "lib_ecology:fruit_NAME",param2 = 0,prob = 62}
local FN --= {name = "lib_ecology:fruit_NAME",param2 = 0,prob = 254}
local FE --= {name = "lib_ecology:fruit_NAME",param2 = 1,prob = 254}
local FS --= {name = "lib_ecology:fruit_NAME",param2 = 2,prob = 254}
local FW --= {name = "lib_ecology:fruit_NAME",param2 = 3,prob = 254}

local CN --= {name = "lib_ecology:fruit_NAME",param2 = 0,prob = 254}
local CE --= {name = "lib_ecology:fruit_NAME",param2 = 1,prob = 254}
local CS --= {name = "lib_ecology:fruit_NAME",param2 = 2,prob = 254}
local CW --= {name = "lib_ecology:fruit_NAME",param2 = 3,prob = 254}

--PLANTS

-- Bamboo Stalk with Leaves
	lib_ecology.tree_bamboo_small_01 = {
		size = {x = 1,y = 7,z = 1},
		data = {
			{param2 = 0,name = "lib_ecology:tree_bamboo_small",prob = 254},
			{param2 = 0,name = "lib_ecology:tree_bamboo_small",prob = 254},
			{param2 = 0,name = "lib_ecology:tree_bamboo_small",prob = 254},
			{param2 = 0,name = "lib_ecology:tree_bamboo_small",prob = 254},
			{param2 = 0,name = "lib_ecology:tree_bamboo_small",prob = 254},
			{param2 = 0,name = "lib_ecology:tree_bamboo_small",prob = 254},
			{param2 = 0,name = "lib_ecology:tree_bamboo_small_top",prob = 254}
		},
		yslice_prob = {
			{ypos = 0,prob = 254},
			{ypos = 1,prob = 127},
			{ypos = 2,prob = 254},
			{ypos = 3,prob = 127},
			{ypos = 4,prob = 254},
			{ypos = 5,prob = 254},
			{ypos = 6,prob = 254}
		}
	}

--Cactus
	T0 = {name = "lib_ecology:cactus_green_trunk", param2 = 0, prob = 254}
	lib_ecology.schem_cactus_01 = {
		size = {x = 5,y = 6,z = 1},
		data = {
			__, __, T0, __, __,
			__, __, T0, __, __,
			__, __, T0, __, __,
			T0, T0, T0, T0, T0,
			T0, __, T0, __, T0,
			__, __, T0, __, __
		},
		yslice_prob = {
			{ypos = 0,prob = 254},
			{ypos = 1,prob = 127},
			{ypos = 2,prob = 254},
			{ypos = 3,prob = 127},
			{ypos = 4,prob = 254},
			{ypos = 5,prob = 254}
		}
	}



--Fern Trees
	local tr = {name = "lib_ecology:tree_fern_giant_trunk", param2 = 0, prob = 254}
	local tt = {name = "lib_ecology:tree_fern_giant_trunk_top", param2 = 0, prob = 254}
	local lp = {name = "lib_ecology:tree_fern_giant_leaves", param2 = 0, prob = 254}
	local ln = {name = "lib_ecology:tree_fern_giant_leaves_end", param2 = 0, prob = 254}
	local le = {name = "lib_ecology:tree_fern_giant_leaves_end", param2 = 1, prob = 254}
	local ls = {name = "lib_ecology:tree_fern_giant_leaves_end", param2 = 2, prob = 254}
	local lw = {name = "lib_ecology:tree_fern_giant_leaves_end", param2 = 3, prob = 254}
	local cr = {name = "lib_ecology:tree_fern_giant_crown", param2 = 0, prob = 254}
	lib_ecology.schem_tree_fern_giant = {
		size = {x = 7, y = 21, z = 7},
		data = {

			__, __, __, __, __, __, __, 
			__, __, __, __, __, __, __, 
			__, __, __, __, __, __, __, 
			__, __, __, __, __, __, __, 
			__, __, __, __, __, __, __, 
			__, __, __, __, __, __, __, 
			__, __, __, __, __, __, __, 
			__, __, __, __, __, __, __, 
			__, __, __, __, __, __, __, 
			__, __, __, __, __, __, __, 
			__, __, __, __, __, __, __, 
			__, __, __, __, __, __, __, 
			__, __, __, __, __, __, __, 
			__, __, __, __, __, __, __, 
			__, __, __, __, __, __, __, 
			__, __, __, __, __, __, __, 
			__, __, __, __, __, __, __, 
			__, __, __, __, __, __, __, 
			__, __, __, ls, __, __, __, 
			__, __, __, lp, __, __, __, 
			__, __, __, __, __, __, __, 

			__, __, __, __, __, __, __, 
			__, __, __, __, __, __, __, 
			__, __, __, __, __, __, __, 
			__, __, __, __, __, __, __, 
			__, __, __, __, __, __, __, 
			__, __, __, __, __, __, __, 
			__, __, __, __, __, __, __, 
			__, __, __, __, __, __, __, 
			__, __, __, __, __, __, __, 
			__, __, __, __, __, __, __, 
			__, __, __, __, __, __, __, 
			__, __, __, __, __, __, __, 
			__, __, __, __, __, __, __, 
			__, __, __, __, __, __, __, 
			__, __, __, __, __, __, __, 
			__, __, __, __, __, __, __, 
			__, __, __, __, __, __, __, 
			__, __, __, __, __, __, __, 
			__, __, __, __, __, __, __, 
			__, __, __, __, __, __, __, 
			__, __, __, lp, __, __, __, 

			__, __, __, __, __, __, __, 
			__, __, __, __, __, __, __, 
			__, __, __, __, __, __, __, 
			__, __, __, __, __, __, __, 
			__, __, __, __, __, __, __, 
			__, __, __, __, __, __, __, 
			__, __, __, __, __, __, __, 
			__, __, __, __, __, __, __, 
			__, __, __, __, __, __, __, 
			__, __, __, __, __, __, __, 
			__, __, __, __, __, __, __, 
			__, __, __, __, __, __, __, 
			__, __, __, __, __, __, __, 
			__, __, __, __, __, __, __, 
			__, __, __, __, __, __, __, 
			__, __, __, __, __, __, __, 
			__, __, __, __, __, __, __, 
			__, __, __, __, __, __, __, 
			__, __, __, __, __, __, __, 
			__, __, __, lp, __, __, __, 
			__, __, __, __, __, __, __, 

			__, __, __, tr, __, __, __, 
			__, __, __, tr, __, __, __, 
			__, __, __, tr, __, __, __, 
			__, __, __, tr, __, __, __, 
			__, __, __, tr, __, __, __, 
			__, __, __, tr, __, __, __, 
			__, __, __, tr, __, __, __, 
			__, __, __, tr, __, __, __, 
			__, __, __, tr, __, __, __, 
			__, __, __, tr, __, __, __, 
			__, __, __, tr, __, __, __, 
			__, __, __, tr, __, __, __, 
			__, __, __, tr, __, __, __, 
			__, __, __, tr, __, __, __, 
			__, __, __, tr, __, __, __, 
			__, __, __, tr, __, __, __, 
			__, __, __, tr, __, __, __, 
			__, __, __, tr, __, __, __, 
			lw, __, __, tr, __, __, le, 
			lp, __, lp, cr, lp, __, lp, 
			__, lp, __, __, __, lp, __, 

			__, __, __, __, __, __, __, 
			__, __, __, __, __, __, __, 
			__, __, __, __, __, __, __, 
			__, __, __, __, __, __, __, 
			__, __, __, __, __, __, __, 
			__, __, __, __, __, __, __, 
			__, __, __, __, __, __, __, 
			__, __, __, __, __, __, __, 
			__, __, __, __, __, __, __, 
			__, __, __, __, __, __, __, 
			__, __, __, __, __, __, __, 
			__, __, __, __, __, __, __, 
			__, __, __, __, __, __, __, 
			__, __, __, __, __, __, __, 
			__, __, __, __, __, __, __, 
			__, __, __, __, __, __, __, 
			__, __, __, __, __, __, __, 
			__, __, __, __, __, __, __, 
			__, __, __, __, __, __, __, 
			__, __, __, lp, __, __, __, 
			__, __, __, __, __, __, __, 

			__, __, __, __, __, __, __, 
			__, __, __, __, __, __, __, 
			__, __, __, __, __, __, __, 
			__, __, __, __, __, __, __, 
			__, __, __, __, __, __, __, 
			__, __, __, __, __, __, __, 
			__, __, __, __, __, __, __, 
			__, __, __, __, __, __, __, 
			__, __, __, __, __, __, __, 
			__, __, __, __, __, __, __, 
			__, __, __, __, __, __, __, 
			__, __, __, __, __, __, __, 
			__, __, __, __, __, __, __, 
			__, __, __, __, __, __, __, 
			__, __, __, __, __, __, __, 
			__, __, __, __, __, __, __, 
			__, __, __, __, __, __, __, 
			__, __, __, __, __, __, __, 
			__, __, __, __, __, __, __, 
			__, __, __, __, __, __, __, 
			__, __, __, lp, __, __, __, 

			__, __, __, __, __, __, __, 
			__, __, __, __, __, __, __, 
			__, __, __, __, __, __, __, 
			__, __, __, __, __, __, __, 
			__, __, __, __, __, __, __, 
			__, __, __, __, __, __, __, 
			__, __, __, __, __, __, __, 
			__, __, __, __, __, __, __, 
			__, __, __, __, __, __, __, 
			__, __, __, __, __, __, __, 
			__, __, __, __, __, __, __, 
			__, __, __, __, __, __, __, 
			__, __, __, __, __, __, __, 
			__, __, __, __, __, __, __, 
			__, __, __, __, __, __, __, 
			__, __, __, __, __, __, __, 
			__, __, __, __, __, __, __, 
			__, __, __, __, __, __, __, 
			__, __, __, ln, __, __, __, 
			__, __, __, lp, __, __, __, 
			__, __, __, __, __, __, __, 

		},
		yslice_prob = {
			{ypos = 0,prob = 254},
			{ypos = 1,prob = 127},
			{ypos = 2,prob = 254},
			{ypos = 3,prob = 127},
			{ypos = 4,prob = 254},
			{ypos = 5,prob = 127},
			{ypos = 6,prob = 254},
			{ypos = 7,prob = 127},
			{ypos = 8,prob = 254},
			{ypos = 9,prob = 127},
			{ypos = 10,prob = 254},
			{ypos = 11,prob = 127},
			{ypos = 12,prob = 254},
			{ypos = 13,prob = 127},
			{ypos = 14,prob = 254},
			{ypos = 15,prob = 127},
			{ypos = 16,prob = 254},
			{ypos = 17,prob = 254},
			{ypos = 18,prob = 254},
			{ypos = 19,prob = 254},
			{ypos = 20,prob = 254}
		}
	}

	local lbn = {name = "lib_ecology:tree_fern_giant_leaves_big", param2 = 0, prob = 254}
	local lbe = {name = "lib_ecology:tree_fern_giant_leaves_big", param2 = 1, prob = 254}
	local lbs = {name = "lib_ecology:tree_fern_giant_leaves_big", param2 = 2, prob = 254}
	local lbw = {name = "lib_ecology:tree_fern_giant_leaves_big", param2 = 3, prob = 254}
	lib_ecology.schem_tree_fern = {
		size = {x = 7, y = 7, z = 7},
		data = {

			__, __, __, __, __, __, __, 
			__, __, __, __, __, __, __, 
			__, __, __, __, __, __, __, 
			__, __, __, __, __, __, __, 
			__, __, __, __, __, __, __, 
			__, __, __,lbs, __, __, __, 
			__, __, __, __, __, __, __, 

			__, __, __, __, __, __, __, 
			__, __, __, __, __, __, __, 
			__, __, __, __, __, __, __, 
			__, __, __, __, __, __, __, 
			__, __, __, __, __, __, __, 
			__, __, __, __, __, __, __, 
			__, __, __,lbs, __, __, __, 

			__, __, __, __, __, __, __, 
			__, __, __, __, __, __, __, 
			__, __, __, __, __, __, __, 
			__, __, __, __, __, __, __, 
			__, __, __, __, __, __, __, 
			__, __, __,lbs, __, __, __, 
			__, __, __, __, __, __, __, 

			__, __, __, tr, __, __, __, 
			__, __, __, tr, __, __, __, 
			__, __, __, tr, __, __, __, 
			__, __, __, tr, __, __, __, 
			__, __, __, tr, __, __, __, 
			lbw, __,lbw,cr,lbe, __,lbe, 
			__, lbw, __,__, __,lbe, __, 

			__, __, __, __, __, __, __, 
			__, __, __, __, __, __, __, 
			__, __, __, __, __, __, __, 
			__, __, __, __, __, __, __, 
			__, __, __, __, __, __, __, 
			__, __, __,lbn, __, __, __, 
			__, __, __, __, __, __, __, 

			__, __, __, __, __, __, __, 
			__, __, __, __, __, __, __, 
			__, __, __, __, __, __, __, 
			__, __, __, __, __, __, __, 
			__, __, __, __, __, __, __, 
			__, __, __, __, __, __, __, 
			__, __, __,lbn, __, __, __, 

			__, __, __, __, __, __, __, 
			__, __, __, __, __, __, __, 
			__, __, __, __, __, __, __, 
			__, __, __, __, __, __, __, 
			__, __, __, __, __, __, __, 
			__, __, __,lbn, __, __, __, 
			__, __, __, __, __, __, __, 

		},
		yslice_prob = {
			{ypos = 0,prob = 254},
			{ypos = 1,prob = 127},
			{ypos = 2,prob = 254},
			{ypos = 3,prob = 127},
			{ypos = 4,prob = 254},
			{ypos = 5,prob = 254},
			{ypos = 6,prob = 254}
		}
	}

	cr = {name = "lib_ecology:fern_giant_tree_crown2", param2 = 0, prob = 254}
	lp = {name = "lib_ecology:fern_giant_tree_leaves_2", param2 = 0, prob = 254}
	ln = {name = "lib_ecology:fern_giant_tree_leaves_end_2", param2 = 0, prob = 254}
	le = {name = "lib_ecology:fern_giant_tree_leaves_end_2", param2 = 1, prob = 254}
	ls = {name = "lib_ecology:fern_giant_tree_leaves_end_2", param2 = 2, prob = 254}
	lw = {name = "lib_ecology:fern_giant_tree_leaves_end_2", param2 = 3, prob = 254}
	lib_ecology.schem_tree_fern_giant_2 = {
		size = {x = 7, y = 7, z = 7},
		data = {

			__, __, __, __, __, __, __, 
			__, __, __, __, __, __, __, 
			__, __, __, __, __, __, __, 
			__, __, __, __, __, __, __, 
			__, __, __, ls, __, __, __, 
			__, __, __, lp, __, __, __, 
			__, __, __, __, __, __, __, 

			__, __, __, __, __, __, __, 
			__, __, __, __, __, __, __, 
			__, __, __, __, __, __, __, 
			__, __, __, __, __, __, __, 
			__, __, __, __, __, __, __, 
			__, __, __, __, __, __, __, 
			__, __, __, lp, __, __, __, 

			__, __, __, __, __, __, __, 
			__, __, __, __, __, __, __, 
			__, __, __, __, __, __, __, 
			__, __, __, __, __, __, __, 
			__, __, __, __, __, __, __, 
			__, __, __, lp, __, __, __, 
			__, __, __, __, __, __, __, 

			__, __, __, tr, __, __, __, 
			__, __, __, tr, __, __, __, 
			__, __, __, tr, __, __, __, 
			__, __, __, tr, __, __, __, 
			lw, __, __, tt, __, __, le, 
			lp, __, lp, cr, lp, __, lp, 
			__, lp, __, __, __, lp, __, 

			__, __, __, __, __, __, __, 
			__, __, __, __, __, __, __, 
			__, __, __, __, __, __, __, 
			__, __, __, __, __, __, __, 
			__, __, __, __, __, __, __, 
			__, __, __, lp, __, __, __, 
			__, __, __, __, __, __, __, 

			__, __, __, __, __, __, __, 
			__, __, __, __, __, __, __, 
			__, __, __, __, __, __, __, 
			__, __, __, __, __, __, __, 
			__, __, __, __, __, __, __, 
			__, __, __, __, __, __, __, 
			__, __, __, lp, __, __, __, 

			__, __, __, __, __, __, __, 
			__, __, __, __, __, __, __, 
			__, __, __, __, __, __, __, 
			__, __, __, __, __, __, __, 
			__, __, __, ln, __, __, __, 
			__, __, __, lp, __, __, __, 
			__, __, __, __, __, __, __, 

		},
		yslice_prob = {
			{ypos = 0,prob = 254},
			{ypos = 1,prob = 127},
			{ypos = 2,prob = 254},
			{ypos = 3,prob = 254},
			{ypos = 4,prob = 254},
			{ypos = 5,prob = 254},
			{ypos = 6,prob = 254}
		}
	}

	lib_ecology.schem_tree_fern_small_01 = {
		size = {x = 1,y = 4,z = 1},
		data = {
			{param2 = 0,name = "lib_ecology:tree_fern_small_trunk",prob = 254},
			{param2 = 0,name = "lib_ecology:tree_fern_small_trunk",prob = 254},
			{param2 = 0,name = "lib_ecology:tree_fern_small_trunk",prob = 254},
			{param2 = 0,name = "lib_ecology:tree_fern_small_leaves_01",prob = 254}
		},
		yslice_prob = {
			{ypos = 0,prob = 254},
			{ypos = 1,prob = 127},
			{ypos = 2,prob = 254},
			{ypos = 3,prob = 254}
		}
	}
	lib_ecology.schem_tree_fern_small_02 = {
		size = {x = 1,y = 4,z = 1},
		data = {
			{param2 = 0,name = "lib_ecology:tree_fern_small_trunk",prob = 254},
			{param2 = 0,name = "lib_ecology:tree_fern_small_trunk",prob = 254},
			{param2 = 0,name = "lib_ecology:tree_fern_small_trunk",prob = 254},
			{param2 = 0,name = "lib_ecology:tree_fern_small_leaves_02",prob = 254}
		},
		yslice_prob = {
			{ypos = 0,prob = 254},
			{ypos = 1,prob = 127},
			{ypos = 2,prob = 254},
			{ypos = 3,prob = 254}
		}
	}

-- Reedmace
	lib_ecology.schem_plant_reedmace = {
		size = {x = 1,y = 3,z = 1},
		data = {
			{param2 = 0,name = "lib_ecology:plant_reedmace",prob = 254},
			{param2 = 0,name = "lib_ecology:plant_reedmace",prob = 254},
			{param2 = 0,name = "lib_ecology:plant_reedmace_top",prob = 254}
		},
		yslice_prob = {
			{ypos = 0,prob = 254},
			{ypos = 1,prob = 254},
			{ypos = 2,prob = 254}
		}
	}
	lib_ecology.schem_plant_reedmace_with_flowers = {
		size = {x = 1,y = 3,z = 1},
		data = {
			{param2 = 0,name = "lib_ecology:plant_reedmace",prob = 254},
			{param2 = 0,name = "lib_ecology:plant_reedmace",prob = 254},
			{param2 = 0,name = "lib_ecology:plant_reedmace_spikes",prob = 254}
		},
		yslice_prob = {
			{ypos = 0,prob = 254},
			{ypos = 1,prob = 254},
			{ypos = 2,prob = 254}
		}
	}

-- Kelp / Seaweed
	lib_ecology.schem_plant_kelp_02_1 = {
		size = {x = 1,y = 3,z = 1},
		data = {
			{param2 = 0,name = "lib_materials:sand",prob = 254},
			{param2 = 0,name = "lib_materials:sand",prob = 254},
			{param2 = 0,name = "lib_ecology:plant_kelp_02_1",prob = 254}
		},
		yslice_prob = {
			{ypos = 0,prob = 254},
			{ypos = 1,prob = 254},
			{ypos = 2,prob = 254}
		}
	}
	lib_ecology.schem_plant_seaweed2 = {
		size = {x = 1,y = 3,z = 1},
		data = {
			{param2 = 0,name = "lib_materials:sand",prob = 254},
			{param2 = 0,name = "lib_materials:sand",prob = 254},
			{param2 = 0,name = "lib_ecology:plant_seaweed2",prob = 254}
		},
		yslice_prob = {
			{ypos = 0,prob = 254},
			{ypos = 1,prob = 254},
			{ypos = 2,prob = 254}
		}
	}
	lib_ecology.schem_plant_seaweed3 = {
		size = {x = 1,y = 3,z = 1},
		data = {
			{param2 = 0,name = "lib_materials:sand",prob = 254},
			{param2 = 0,name = "lib_materials:sand",prob = 254},
			{param2 = 0,name = "lib_ecology:plant_seaweed3",prob = 254}
		},
		yslice_prob = {
			{ypos = 0,prob = 254},
			{ypos = 1,prob = 254},
			{ypos = 2,prob = 254}
		}
	}


-- custom
	lib_ecology.plant_test_banana = {
		size = {x = 1,y = 3,z = 1},
		data = {
			{param2 = 0,name = "lib_materials:dirt",prob = 254},
			{param2 = 0,name = "lib_ecology:plant_test_plant_rooted_01",prob = 254},
			{param2 = 0,name = "lib_ecology:plant_bananaplant2",prob = 254}
		},
		yslice_prob = {
			{ypos = 0,prob = 254},
			{ypos = 1,prob = 254},
			{ypos = 2,prob = 254}
		}
	}
	lib_ecology.plant_test_fern = {
		size = {x = 1,y = 3,z = 1},
		data = {
			{param2 = 0,name = "lib_materials:dirt",prob = 254},
			{param2 = 0,name = "lib_ecology:plant_test_plant_rooted_02",prob = 254},
			{param2 = 0,name = "lib_ecology:fern_ladyfern",prob = 254}
		},
		yslice_prob = {
			{ypos = 0,prob = 254},
			{ypos = 1,prob = 254},
			{ypos = 2,prob = 254}
		}
	}
	lib_ecology.plant_tree_palmetto = {
		size = {x = 1,y = 2,z = 1},
		data = {
			{param2 = 0,name = "lib_materials:dirt",prob = 254},
			{param2 = 0,name = "lib_ecology:tree_palm_palmetto",prob = 254}
		},
		yslice_prob = {
			{ypos = 0,prob = 254},
			{ypos = 1,prob = 254}
		}
	}
	lib_ecology.plant_banana_tree_01 = {
		size = {x = 1,y = 4,z = 1},
		data = {
			{param2 = 0,name = "lib_materials:dirt",prob = 254},
			{param2 = 0,name = "lib_ecology:plant_banana_tree_trunk",prob = 254},
			{param2 = 0,name = "lib_ecology:plant_banana_tree_trunk_top",prob = 254},
			{param2 = 0,name = "lib_ecology:plant_banana_tree_leaves",prob = 254}
		},
		yslice_prob = {
			{ypos = 0,prob = 254},
			{ypos = 1,prob = 254},
			{ypos = 2,prob = 254},
			{ypos = 3,prob = 254}
		}
	}

-- bush
local ai = {name = "air", param1 = 000}
local bp = {name = "lib_ecology:bush", param1 = 255}
local br = {name = "lib_ecology:bush", param1 = 100}
lib_ecology.bush = {

	size = {x = 5, y = 3, z = 5},

	data = {

		br, bp, bp, bp, br,
		ai, ai, ai, ai, ai,
		ai, ai, ai, ai, ai,

		bp, bp, bp, bp, bp,
		ai, br, bp, br, ai,
		ai, ai, ai, ai, ai,

		bp, bp, bp, bp, bp,
		ai, bp, bp, bp, ai,
		ai, ai, br, ai, ai,

		bp, bp, bp, bp, bp,
		ai, br, bp, br, ai,
		ai, ai, ai, ai, ai,

		br, bp, bp, bp, br,
		ai, ai, ai, ai, ai,
		ai, ai, ai, ai, ai,

	},

	yslice_prob = {
		{ypos = 1, prob = 127},
	},
}




--Blueberry bush
T0 = {name = "lib_ecology:bush_trunk", param2 = 0, prob = 254}
L0 = {name = "lib_ecology:bush_blueberry_leaves", param2 = 0, prob = 254}
L1 = {name = "lib_ecology:bush_blueberry_leaves", param2 = 0, prob = 192}
lib_ecology.schem_bush_blueberry = {
	size = {x = 3, y = 4, z = 3},
	data = {
		__, __, __,
		__, __, __,
		L0, L0, L0,
		L0, L1, L0,

		__, D0, __,
		__, T0, __,
		L0, L0, L0,
		L1, L0, L0,

		__, __, __,
		__, __, __,
		L0, L0, L0,
		L0, L0, L1
	},
	yslice_prob = {
		{ypos = 0,prob = 254},
		{ypos = 1,prob = 254},
		{ypos = 2,prob = 254},
		{ypos = 3,prob = 254},
	}
}

--Hawthorne bush
T0 = {name = "lib_ecology:bush_trunk", param2 = 0, prob = 254}
L0 = {name = "lib_ecology:bush_hawthorne_leaves", param2 = 0, prob = 254}
L1 = {name = "lib_ecology:bush_hawthorne_leaves", param2 = 0, prob = 192}
lib_ecology.schem_bush_hawthorne = {
	size = {x = 3, y = 4, z = 3},
	data = {
		__, __, __,
		__, __, __,
		L0, L0, L0,
		L0, L1, L0,

		__, D0, __,
		__, T0, __,
		L0, L0, L0,
		L1, L0, L0,

		__, __, __,
		__, __, __,
		L0, L0, L0,
		L0, L0, L1
	},
	yslice_prob = {
		{ypos = 0,prob = 254},
		{ypos = 1,prob = 254},
		{ypos = 2,prob = 254},
		{ypos = 3,prob = 254},
	}
}

--Rhodedendron bush
T0 = {name = "lib_ecology:bush_trunk", param2 = 0, prob = 254}
L0 = {name = "lib_ecology:bush_rhodedendron_leaves_1", param2 = 0, prob = 254}
L1 = {name = "lib_ecology:bush_rhodedendron_leaves_1", param2 = 0, prob = 192}
lib_ecology.schem_bush_rhodedendron = {
	size = {x = 3, y = 4, z = 3},
	data = {
		__, __, __,
		__, __, __,
		L0, L0, L0,
		L0, L1, L0,

		__, D0, __,
		__, T0, __,
		L0, L0, L0,
		L1, L0, L0,

		__, __, __,
		__, __, __,
		L0, L0, L0,
		L0, L0, L1
	},
	yslice_prob = {
		{ypos = 0,prob = 254},
		{ypos = 1,prob = 254},
		{ypos = 2,prob = 254},
		{ypos = 3,prob = 254},
	}
}

--Rhodedendron bush
T0 = {name = "lib_ecology:bush_trunk", param2 = 0, prob = 254}
L0 = {name = "lib_ecology:bush_rhodedendron_leaves_3", param2 = 0, prob = 254}
L1 = {name = "lib_ecology:bush_rhodedendron_leaves_3", param2 = 0, prob = 192}
lib_ecology.schem_bush_rhodedendron_blooming = {
	size = {x = 3, y = 4, z = 3},
	data = {
		__, __, __,
		__, __, __,
		L0, L0, L0,
		L0, L1, L0,

		__, D0, __,
		__, T0, __,
		L0, L0, L0,
		L1, L0, L0,

		__, __, __,
		__, __, __,
		L0, L0, L0,
		L0, L0, L1
	},
	yslice_prob = {
		{ypos = 0,prob = 254},
		{ypos = 1,prob = 254},
		{ypos = 2,prob = 254},
		{ypos = 3,prob = 254},
	}
}



--mushrooms

	T0 = {name = "lib_ecology:mushroom_01_trunk", param2 = 0, prob = 254}
	L0 = {name = "lib_ecology:mushroom_01_cap_spotted_red", param2 = 0, prob = 254}
	F0 = {name = "lib_ecology:mushroom_spores", param2 = 0, prob = 254}
	lib_ecology.schem_mushroom_big = {
		size = {x = 8,y = 11,z = 8},
		data = {
			__, __, __, __, __, __, __, __,
			__, __, __, __, __, __, __, __,
			__, __, __, __, __, __, __, __,
			__, __, __, __, __, __, __, __,
			__, __, __, __, __, __, __, __,
			__, __, __, __, __, __, __, __,
			__, __, __, __, __, __, __, __,
			__, __, __, L0, L0, __, __, __,
			__, __, __, L0, L0, __, __, __,
			__, __, __, __, __, __, __, __,
			__, __, __, __, __, __, __, __,

			__, __, __, __, __, __, __, __,
			__, __, __, __, __, __, __, __,
			__, __, __, __, __, __, __, __,
			__, __, __, __, __, __, __, __,
			__, __, __, __, __, __, __, __,
			__, __, __, __, __, __, __, __,
			__, __, __, __, __, __, __, __,
			__, __, L0, __, __, L0, __, __,
			__, __, L0, __, __, L0, __, __,
			__, __, __, L0, L0, __, __, __,
			__, __, __, __, __, __, __, __,

			__, __, __, __, __, __, __, __,
			__, __, __, __, __, __, __, __,
			__, __, __, __, __, __, __, __,
			__, __, __, __, __, __, __, __,
			__, __, __, __, __, __, __, __,
			__, __, __, __, __, __, __, __,
			__, __, __, __, __, __, __, __,
			__, L0, __, __, __, __, L0, __,
			__, L0, __, __, __, __, L0, __,
			__, __, L0, F0, F0, L0, __, __,
			__, __, __, L0, L0, __, __, __,

			__, __, __, T0, T0, __, __, __,
			__, __, __, T0, T0, __, __, __,
			__, __, __, T0, T0, __, __, __,
			__, __, __, T0, T0, __, __, __,
			__, __, __, T0, T0, __, __, __,
			__, __, __, T0, T0, __, __, __,
			__, __, __, T0, T0, __, __, __,
			L0, __, __, T0, T0, __, __, L0,
			L0, __, __, T0, T0, __, __, L0,
			__, L0, F0, F0, F0, F0, L0, __,
			__, __, L0, L0, L0, L0, __, __,

			__, __, __, T0, T0, __, __, __,
			__, __, __, T0, T0, __, __, __,
			__, __, __, T0, T0, __, __, __,
			__, __, __, T0, T0, __, __, __,
			__, __, __, T0, T0, __, __, __,
			__, __, __, T0, T0, __, __, __,
			__, __, __, T0, T0, __, __, __,
			L0, __, __, T0, T0, __, __, L0,
			L0, __, __, T0, T0, __, __, L0,
			__, L0, F0, F0, F0, F0, L0, __,
			__, __, L0, L0, L0, L0, __, __,

			__, __, __, __, __, __, __, __,
			__, __, __, __, __, __, __, __,
			__, __, __, __, __, __, __, __,
			__, __, __, __, __, __, __, __,
			__, __, __, __, __, __, __, __,
			__, __, __, __, __, __, __, __,
			__, __, __, __, __, __, __, __,
			__, L0, __, __, __, __, L0, __,
			__, L0, __, __, __, __, L0, __,
			__, __, L0, F0, F0, L0, __, __,
			__, __, __, L0, L0, __, __, __,

			__, __, __, __, __, __, __, __,
			__, __, __, __, __, __, __, __,
			__, __, __, __, __, __, __, __,
			__, __, __, __, __, __, __, __,
			__, __, __, __, __, __, __, __,
			__, __, __, __, __, __, __, __,
			__, __, __, __, __, __, __, __,
			__, __, L0, __, __, L0, __, __,
			__, __, L0, __, __, L0, __, __,
			__, __, __, L0, L0, __, __, __,
			__, __, __, __, __, __, __, __,

			__, __, __, __, __, __, __, __,
			__, __, __, __, __, __, __, __,
			__, __, __, __, __, __, __, __,
			__, __, __, __, __, __, __, __,
			__, __, __, __, __, __, __, __,
			__, __, __, __, __, __, __, __,
			__, __, __, __, __, __, __, __,
			__, __, __, L0, L0, __, __, __,
			__, __, __, L0, L0, __, __, __,
			__, __, __, __, __, __, __, __,
			__, __, __, __, __, __, __, __
		},
		yslice_prob = {
			{ypos = 0, prob = 254},
			{ypos = 1, prob = 254},
			{ypos = 2, prob = 254},
			{ypos = 3, prob = 254},
			{ypos = 4, prob = 254},
			{ypos = 5, prob = 254},
			{ypos = 6, prob = 254},
			{ypos = 7, prob = 254},
			{ypos = 8, prob = 254},
			{ypos = 9, prob = 254},
			{ypos = 10, prob = 254}
		}
	}

	T0 = {name = "lib_ecology:mushroom_02_trunk", param2 = 0, prob = 254}
	L0 = {name = "lib_ecology:mushroom_01_cap_spotted_red", param2 = 0, prob = 254}
	lib_ecology.schem_mushroom_fat = {
		size = {x = 16,y = 11,z = 16},
		data = {
			__, __, __, __, __, __, __, __, __, __, __, __, __, __, __, __,
			__, __, __, __, __, __, __, __, __, __, __, __, __, __, __, __,
			__, __, __, __, __, __, __, __, __, __, __, __, __, __, __, __,
			__, __, __, __, __, __, __, __, __, __, __, __, __, __, __, __,
			__, __, __, __, __, __, __, __, __, __, __, __, __, __, __, __,
			__, __, __, __, __, __, __, __, __, __, __, __, __, __, __, __,
			__, __, __, __, __, __, __, __, __, __, __, __, __, __, __, __,
			__, __, __, __, __, __, __, __, __, __, __, __, __, __, __, __,
			__, __, __, __, __, L0, L0, L0, __, __, __, __, __, __, __, __,
			__, __, __, __, __, __, __, __, L0, L0, L0, __, __, __, __, __,
			__, __, __, __, __, __, __, __, __, __, __, __, __, __, __, __,

			__, __, __, __, __, __, __, __, __, __, __, __, __, __, __, __,
			__, __, __, __, __, __, __, __, __, __, __, __, __, __, __, __,
			__, __, __, __, __, __, __, __, __, __, __, __, __, __, __, __,
			__, __, __, __, __, __, __, __, __, __, __, __, __, __, __, __,
			__, __, __, __, __, __, __, __, __, __, __, __, __, __, __, __,
			__, __, __, __, __, __, __, __, __, __, __, __, __, __, __, __,
			__, __, __, __, __, __, __, __, __, __, __, __, __, __, __, __,
			__, __, __, __, __, __, __, __, __, __, __, __, __, __, __, __,
			__, __, __, L0, L0, L0, L0, L0, __, __, __, __, __, __, __, __,
			__, __, __, __, __, __, __, __, L0, L0, L0, L0, L0, __, __, __,
			__, __, __, __, __, __, __, __, __, __, __, __, __, __, __, __,

			__, __, __, __, __, __, __, __, __, __, __, __, __, __, __, __,
			__, __, __, __, __, __, __, __, __, __, __, __, __, __, __, __,
			__, __, __, __, __, __, __, __, __, __, __, __, __, __, __, __,
			__, __, __, __, __, __, __, __, __, __, __, __, __, __, __, __,
			__, __, __, __, __, __, __, __, __, __, __, __, __, __, __, __,
			__, __, __, __, __, __, __, __, __, __, __, __, __, __, __, __,
			__, __, __, __, __, __, __, __, __, __, __, __, __, __, __, __,
			__, __, __, __, __, __, __, __, __, __, __, __, __, __, __, __,
			__, __, L0, L0, L0, L0, L0, L0, __, __, __, __, __, __, __, __,
			__, __, __, __, __, __, __, __, L0, L0, L0, L0, L0, L0, __, __,
			__, __, __, __, __, __, __, __, __, __, __, __, __, __, __, __,

			__, __, __, __, __, __, __, __, __, __, __, __, __, __, __, __,
			__, __, __, __, __, __, __, __, __, __, __, __, __, __, __, __,
			__, __, __, __, __, __, __, __, __, __, __, __, __, __, __, __,
			__, __, __, __, __, __, __, __, __, __, __, __, __, __, __, __,
			__, __, __, __, __, __, __, __, __, __, __, __, __, __, __, __,
			__, __, __, __, __, __, __, __, __, __, __, __, __, __, __, __,
			__, __, __, __, __, __, __, __, __, __, __, __, __, __, __, __,
			__, __, __, __, __, __, __, __, __, __, __, __, __, __, __, __,
			__, L0, L0, L0, L0, L0, L0, L0, T0, T0, __, __, __, __, __, __,
			__, __, __, __, __, __, __, __, L0, L0, L0, L0, L0, L0, L0, __,
			__, __, __, __, __, __, __, __, __, __, __, __, __, __, __, __,

			__, __, __, __, __, __, T0, T0, T0, T0, __, __, __, __, __, __,
			__, __, __, __, __, T0, T0, T0, T0, T0, T0, __, __, __, __, __,
			__, __, __, __, __, T0, T0, T0, T0, T0, T0, __, __, __, __, __,
			__, __, __, __, __, T0, T0, T0, T0, T0, T0, __, __, __, __, __,
			__, __, __, __, __, T0, T0, T0, T0, T0, T0, __, __, __, __, __,
			__, __, __, __, __, T0, T0, T0, T0, T0, T0, __, __, __, __, __,
			__, __, __, __, __, T0, T0, T0, T0, T0, T0, __, __, __, __, __,
			__, __, __, __, __, T0, T0, T0, T0, T0, T0, __, __, __, __, __,
			__, L0, L0, L0, L0, L0, L0, L0, T0, T0, __, __, __, __, __, __,
			__, __, __, __, __, __, __, __, L0, L0, L0, L0, L0, L0, L0, __,
			__, __, __, __, __, __, __, __, __, __, __, __, __, __, __, __,

			__, __, __, __, __, T0, T0, T0, T0, T0, T0, __, __, __, __, __,
			__, __, __, __, T0, T0, __, __, __, __, T0, T0, __, __, __, __,
			__, __, __, __, T0, T0, __, __, __, __, T0, T0, __, __, __, __,
			__, __, __, __, T0, T0, __, __, __, __, T0, T0, __, __, __, __,
			__, __, __, __, T0, T0, __, __, __, __, T0, T0, __, __, __, __,
			__, __, __, __, T0, T0, __, __, __, __, T0, T0, __, __, __, __,
			__, __, __, __, T0, T0, __, __, __, __, T0, T0, __, __, __, __,
			__, __, __, __, __, __, T0, __, __, __, T0, T0, __, __, __, __,
			__, __, L0, L0, L0, L0, L0, L0, __, T0, T0, __, __, __, __, __,
			L0, L0, __, __, __, __, __, __, L0, L0, L0, L0, L0, L0, L0, L0,
			__, __, __, __, __, __, __, __, __, __, __, __, __, __, __, __,

			__, __, __, __, __, T0, T0, T0, T0, T0, T0, __, __, __, __, __,
			__, __, __, __, T0, __, __, __, __, __, __, T0, __, __, __, __,
			__, __, __, __, T0, __, __, __, __, __, __, T0, __, __, __, __,
			__, __, __, __, T0, __, __, __, __, __, __, T0, __, __, __, __,
			__, __, __, __, T0, __, __, __, __, __, __, T0, __, __, __, __,
			__, __, __, __, T0, __, __, __, __, __, __, T0, __, __, __, __,
			__, __, __, __, T0, __, __, __, __, __, __, T0, __, __, __, __,
			__, __, __, __, __, T0, __, __, __, __, T0, __, __, __, __, __,
			L0, L0, L0, L0, L0, L0, L0, L0, L0, T0, __, __, __, __, __, __,
			__, __, __, __, __, __, __, __, L0, L0, L0, L0, L0, L0, L0, L0,
			__, __, __, __, __, __, __, __, __, __, __, __, __, __, __, __,

			__, __, __, __, __, T0, T0, T0, T0, T0, T0, __, __, __, __, __,
			__, __, __, __, T0, __, __, __, __, __, __, T0, __, __, __, __,
			__, __, __, __, T0, __, __, __, __, __, __, T0, __, __, __, __,
			__, __, __, __, T0, __, __, __, __, __, __, T0, __, __, __, __,
			__, __, __, __, T0, __, __, __, __, __, __, T0, __, __, __, __,
			__, __, __, __, T0, __, __, __, __, __, __, T0, __, __, __, __,
			__, __, __, __, T0, __, __, __, __, __, __, T0, __, __, __, __,
			__, __, __, __, __, T0, __, __, __, __, T0, __, __, __, __, __,
			L0, L0, L0, L0, L0, L0, L0, L0, L0, L0, T0, __, __, __, __, __,
			__, __, __, __, __, __, __, __, __, L0, L0, L0, L0, L0, L0, L0,
			__, __, __, __, __, __, __, __, __, __, __, __, __, __, __, __,

			__, __, __, __, __, T0, T0, T0, T0, T0, T0, __, __, __, __, __,
			__, __, __, __, T0, __, __, __, __, __, __, T0, __, __, __, __,
			__, __, __, __, T0, __, __, __, __, __, __, T0, __, __, __, __,
			__, __, __, __, T0, __, __, __, __, __, __, T0, __, __, __, __,
			__, __, __, __, T0, __, __, __, __, __, __, T0, __, __, __, __,
			__, __, __, __, T0, __, __, __, __, __, __, T0, __, __, __, __,
			__, __, __, __, __, T0, __, __, __, __, T0, __, __, __, __, __,
			L0, L0, L0, L0, L0, L0, L0, L0, __, __, T0, __, __, __, __, __,
			__, __, __, __, __, __, L0, L0, L0, L0, L0, L0, L0, L0, L0, L0,
			__, __, __, __, __, __, __, __, __, __, __, __, __, __, __, __,
			__, __, __, __, __, __, __, __, __, __, __, __, __, __, __, __,

			__, __, __, __, __, T0, T0, T0, T0, T0, T0, __, __, __, __, __,
			__, __, __, __, T0, __, __, __, __, __, __, T0, __, __, __, __,
			__, __, __, __, T0, __, __, __, __, __, __, T0, __, __, __, __,
			__, __, __, __, T0, __, __, __, __, __, __, T0, __, __, __, __,
			__, __, __, __, T0, __, __, __, __, __, __, T0, __, __, __, __,
			__, __, __, __, T0, __, __, __, __, __, __, T0, __, __, __, __,
			__, __, __, __, __, T0, __, __, __, __, T0, __, __, __, __, __,
			L0, L0, L0, L0, L0, L0, L0, L0, __, T0, __, __, __, __, __, __,
			__, __, __, __, __, __, __, L0, L0, L0, L0, L0, L0, L0, L0, L0,
			__, __, __, __, __, __, __, __, __, __, __, __, __, __, __, __,
			__, __, __, __, __, __, __, __, __, __, __, __, __, __, __, __,

			__, __, __, __, __, T0, T0, T0, T0, T0, T0, __, __, __, __, __,
			__, __, __, __, T0, T0, __, __, __, __, T0, T0, __, __, __, __,
			__, __, __, __, T0, T0, __, __, __, __, T0, T0, __, __, __, __,
			__, __, __, __, T0, T0, __, __, __, __, T0, T0, __, __, __, __,
			__, __, __, __, T0, T0, __, __, __, __, T0, T0, __, __, __, __,
			__, __, __, __, T0, T0, __, __, __, __, T0, T0, __, __, __, __,
			__, __, __, __, __, T0, __, __, __, T0, __, __, __, __, __, __,
			L0, L0, L0, L0, L0, L0, L0, L0, __, T0, __, __, __, __, __, __,
			__, __, __, __, __, __, __, __, L0, L0, L0, L0, L0, L0, L0, L0,
			__, __, __, __, __, __, __, __, __, __, __, __, __, __, __, __,
			__, __, __, __, __, __, __, __, __, __, __, __, __, __, __, __,

			__, __, __, __, __, __, T0, T0, T0, T0, __, __, __, __, __, __,
			__, __, __, __, __, T0, T0, T0, T0, T0, T0, __, __, __, __, __,
			__, __, __, __, __, T0, T0, T0, T0, T0, T0, __, __, __, __, __,
			__, __, __, __, __, T0, T0, T0, T0, T0, T0, __, __, __, __, __,
			__, __, __, __, __, T0, T0, T0, T0, T0, T0, __, __, __, __, __,
			__, __, __, __, __, T0, T0, T0, T0, T0, T0, __, __, __, __, __,
			__, __, __, __, __, __, T0, T0, T0, T0, __, __, __, __, __, __,
			__, L0, L0, L0, L0, L0, L0, L0, T0, T0, __, __, __, __, __, __,
			__, __, __, __, __, __, __, __, L0, L0, L0, L0, L0, L0, L0, __,
			__, __, __, __, __, __, __, __, __, __, __, __, __, __, __, __,
			__, __, __, __, __, __, __, __, __, __, __, __, __, __, __, __,

			__, __, __, __, __, __, __, __, __, __, __, __, __, __, __, __,
			__, __, __, __, __, __, __, __, __, __, __, __, __, __, __, __,
			__, __, __, __, __, __, __, __, __, __, __, __, __, __, __, __,
			__, __, __, __, __, __, __, __, __, __, __, __, __, __, __, __,
			__, __, __, __, __, __, __, __, __, __, __, __, __, __, __, __,
			__, __, __, __, __, __, __, __, __, __, __, __, __, __, __, __,
			__, __, __, __, __, __, __, __, __, __, __, __, __, __, __, __,
			__, L0, L0, L0, L0, L0, L0, L0, T0, T0, __, __, __, __, __, __,
			__, __, __, __, __, __, __, __, L0, L0, L0, L0, L0, L0, L0, __,
			__, __, __, __, __, __, __, __, __, __, __, __, __, __, __, __,
			__, __, __, __, __, __, __, __, __, __, __, __, __, __, __, __,
			
			__, __, __, __, __, __, __, __, __, __, __, __, __, __, __, __,
			__, __, __, __, __, __, __, __, __, __, __, __, __, __, __, __,
			__, __, __, __, __, __, __, __, __, __, __, __, __, __, __, __,
			__, __, __, __, __, __, __, __, __, __, __, __, __, __, __, __,
			__, __, __, __, __, __, __, __, __, __, __, __, __, __, __, __,
			__, __, __, __, __, __, __, __, __, __, __, __, __, __, __, __,
			__, __, __, __, __, __, __, __, __, __, __, __, __, __, __, __,
			__, __, L0, L0, L0, L0, L0, L0, __, __, __, __, __, __, __, __,
			__, __, __, __, __, __, __, __, L0, L0, L0, L0, L0, L0, __, __,
			__, __, __, __, __, __, __, __, __, __, __, __, __, __, __, __,
			__, __, __, __, __, __, __, __, __, __, __, __, __, __, __, __,

			__, __, __, __, __, __, __, __, __, __, __, __, __, __, __, __,
			__, __, __, __, __, __, __, __, __, __, __, __, __, __, __, __,
			__, __, __, __, __, __, __, __, __, __, __, __, __, __, __, __,
			__, __, __, __, __, __, __, __, __, __, __, __, __, __, __, __,
			__, __, __, __, __, __, __, __, __, __, __, __, __, __, __, __,
			__, __, __, __, __, __, __, __, __, __, __, __, __, __, __, __,
			__, __, __, __, __, __, __, __, __, __, __, __, __, __, __, __,
			__, __, __, L0, L0, L0, L0, L0, __, __, __, __, __, __, __, __,
			__, __, __, __, __, __, __, __, L0, L0, L0, L0, L0, __, __, __,
			__, __, __, __, __, __, __, __, __, __, __, __, __, __, __, __,
			__, __, __, __, __, __, __, __, __, __, __, __, __, __, __, __,

			__, __, __, __, __, __, __, __, __, __, __, __, __, __, __, __,
			__, __, __, __, __, __, __, __, __, __, __, __, __, __, __, __,
			__, __, __, __, __, __, __, __, __, __, __, __, __, __, __, __,
			__, __, __, __, __, __, __, __, __, __, __, __, __, __, __, __,
			__, __, __, __, __, __, __, __, __, __, __, __, __, __, __, __,
			__, __, __, __, __, __, __, __, __, __, __, __, __, __, __, __,
			__, __, __, __, __, __, __, __, __, __, __, __, __, __, __, __,
			__, __, __, __, __, L0, L0, L0, __, __, __, __, __, __, __, __,
			__, __, __, __, __, __, __, __, L0, L0, L0, __, __, __, __, __,
			__, __, __, __, __, __, __, __, __, __, __, __, __, __, __, __,
			__, __, __, __, __, __, __, __, __, __, __, __, __, __, __, __
		},
		yslice_prob = {
			{prob = 254, ypos = 0},
			{prob = 254, ypos = 1},
			{prob = 254, ypos = 2},
			{prob = 254, ypos = 3},
			{prob = 254, ypos = 4},
			{prob = 254, ypos = 5},
			{prob = 254, ypos = 6},
			{prob = 254, ypos = 7},
			{prob = 254, ypos = 8},
			{prob = 254, ypos = 9},
			{prob = 254, ypos = 10}
		}
	}

	T0 = {name = "lib_ecology:mushroom_01_trunk", param2 = 0, prob = 254}
	L0 = {name = "lib_ecology:mushroom_02_cap_brown", param2 = 0, prob = 254}
	lib_ecology.schem_mushroom_large = {
		size = {x = 10,y = 11,z = 10},
		data = {
			__, __, __, __, __, __, __, __, __, __,
			__, __, __, __, __, __, __, __, __, __,
			__, __, __, __, __, __, __, __, __, __,
			__, __, __, __, __, __, __, __, __, __,
			__, __, __, __, __, __, __, __, __, __,
			__, __, __, __, __, __, __, __, __, __,
			__, __, __, __, __, __, __, __, __, __,
			__, __, __, __, __, __, __, __, __, __,
			__, __, __, L0, L0, __, __, __, __, __,
			__, __, __, __, __, L0, L0, __, __, __,
			__, __, __, __, __, __, __, __, __, __,

			__, __, __, __, __, __, __, __, __, __,
			__, __, __, __, __, __, __, __, __, __,
			__, __, __, __, __, __, __, __, __, __,
			__, __, __, __, __, __, __, __, __, __,
			__, __, __, __, __, __, __, __, __, __,
			__, __, __, __, __, __, __, __, __, __,
			__, __, __, __, __, __, __, __, __, __,
			__, __, __, __, __, __, __, __, __, __,
			__, __, L0, L0, L0, __, __, __, __, __,
			__, __, __, __, __, L0, L0, L0, __, __,
			__, __, __, __, __, __, __, __, __, __,

			__, __, __, __, __, __, __, __, __, __,
			__, __, __, __, __, __, __, __, __, __,
			__, __, __, __, __, __, __, __, __, __,
			__, __, __, __, __, __, __, __, __, __,
			__, __, __, __, __, __, __, __, __, __,
			__, __, __, __, __, __, __, __, __, __,
			__, __, __, __, __, __, __, __, __, __,
			__, __, __, __, __, __, __, __, __, __,
			__, L0, L0, L0, L0, __, __, __, __, __,
			__, __, __, __, __, L0, L0, L0, L0, __,
			__, __, __, __, __, __, __, __, __, __,

			__, __, __, __, __, __, __, __, __, __,
			__, __, __, __, __, __, __, __, __, __,
			__, __, __, __, __, __, __, __, __, __,
			__, __, __, __, __, __, __, __, __, __,
			__, __, __, __, __, __, __, __, __, __,
			__, __, __, __, __, __, __, __, __, __,
			__, __, __, __, __, __, __, __, __, __,
			__, __, __, __, __, __, __, __, __, __,
			L0, L0, L0, L0, L0, L0, __, __, __, __,
			__, __, __, __, __, L0, L0, L0, L0, L0,
			__, __, __, __, __, __, __, __, __, __,

			__, __, __, __, T0, T0, __, __, __, __,
			__, __, __, __, T0, T0, __, __, __, __,
			__, __, __, __, T0, T0, __, __, __, __,
			__, __, __, __, T0, T0, __, __, __, __,
			__, __, __, __, T0, T0, __, __, __, __,
			__, __, __, __, T0, T0, __, __, __, __,
			__, __, __, __, T0, T0, __, __, __, __,
			__, __, __, __, T0, T0, __, __, __, __,
			L0, L0, L0, L0, L0, L0, L0, __, __, __,
			__, __, __, __, __, __, L0, L0, L0, L0,
			__, __, __, __, __, __, __, __, __, __,

			__, __, __, __, T0, T0, __, __, __, __,
			__, __, __, __, T0, T0, __, __, __, __,
			__, __, __, __, T0, T0, __, __, __, __,
			__, __, __, __, T0, T0, __, __, __, __,
			__, __, __, __, T0, T0, __, __, __, __,
			__, __, __, __, T0, T0, __, __, __, __,
			__, __, __, __, T0, T0, __, __, __, __,
			L0, L0, L0, L0, L0, T0, __, __, __, __,
			__, __, __, L0, L0, L0, L0, L0, L0, L0,
			__, __, __, __, __, __, __, __, __, __,
			__, __, __, __, __, __, __, __, __, __,

			__, __, __, __, __, __, __, __, __, __,
			__, __, __, __, __, __, __, __, __, __,
			__, __, __, __, __, __, __, __, __, __,
			__, __, __, __, __, __, __, __, __, __,
			__, __, __, __, __, __, __, __, __, __,
			__, __, __, __, __, __, __, __, __, __,
			__, __, __, __, __, __, __, __, __, __,
			L0, L0, L0, L0, L0, __, __, __, __, __,
			__, __, __, __, L0, L0, L0, L0, L0, L0,
			__, __, __, __, __, __, __, __, __, __,
			__, __, __, __, __, __, __, __, __, __,

			__, __, __, __, __, __, __, __, __, __,
			__, __, __, __, __, __, __, __, __, __,
			__, __, __, __, __, __, __, __, __, __,
			__, __, __, __, __, __, __, __, __, __,
			__, __, __, __, __, __, __, __, __, __,
			__, __, __, __, __, __, __, __, __, __,
			__, __, __, __, __, __, __, __, __, __,
			__, L0, L0, L0, L0, __, __, __, __, __,
			__, __, __, __, __, L0, L0, L0, L0, __,
			__, __, __, __, __, __, __, __, __, __,
			__, __, __, __, __, __, __, __, __, __,

			__, __, __, __, __, __, __, __, __, __,
			__, __, __, __, __, __, __, __, __, __,
			__, __, __, __, __, __, __, __, __, __,
			__, __, __, __, __, __, __, __, __, __,
			__, __, __, __, __, __, __, __, __, __,
			__, __, __, __, __, __, __, __, __, __,
			__, __, __, __, __, __, __, __, __, __,
			__, __, L0, L0, L0, __, __, __, __, __,
			__, __, __, __, __, L0, L0, L0, __, __,
			__, __, __, __, __, __, __, __, __, __,
			__, __, __, __, __, __, __, __, __, __,

			__, __, __, __, __, __, __, __, __, __,
			__, __, __, __, __, __, __, __, __, __,
			__, __, __, __, __, __, __, __, __, __,
			__, __, __, __, __, __, __, __, __, __,
			__, __, __, __, __, __, __, __, __, __,
			__, __, __, __, __, __, __, __, __, __,
			__, __, __, __, __, __, __, __, __, __,
			__, __, __, L0, L0, __, __, __, __, __,
			__, __, __, __, __, L0, L0, __, __, __,
			__, __, __, __, __, __, __, __, __, __,
			__, __, __, __, __, __, __, __, __, __
		},
		yslice_prob = {
			{prob = 254, ypos = 0},
			{prob = 254, ypos = 1},
			{prob = 254, ypos = 2},
			{prob = 254, ypos = 3},
			{prob = 254, ypos = 4},
			{prob = 254, ypos = 5},
			{prob = 254, ypos = 6},
			{prob = 254, ypos = 7},
			{prob = 254, ypos = 8},
			{prob = 254, ypos = 9},
			{prob = 254, ypos = 10}
		}
	}

	T0 = {name = "lib_ecology:mushroom_02_trunk", param2 = 0, prob = 254}
	L0 = {name = "lib_ecology:mushroom_02_cap_red", param2 = 0, prob = 254}
	lib_ecology.schem_mushroom_short = {
		size = {x = 3,y = 5,z = 3},
		data = {
			__, __, __,
			__, __, __,
			__, __, __,
			__, __, __,
			L0, L0, L0,

			__, T0, __,
			__, T0, __,
			__, T0, __,
			__, T0, __,
			L0, L0, L0,

			__, __, __,
			__, __, __,
			__, __, __,
			__, __, __,
			L0, L0, L0
		},
		yslice_prob = {
			{ypos = 0, prob = 254},
			{ypos = 1, prob = 254},
			{ypos = 2, prob = 254},
			{ypos = 3, prob = 254},
			{ypos = 4, prob = 254}
		}
	}

	T0 = {name = "lib_ecology:mushroom_02_trunk", param2 = 0, prob = 254}
	L0 = {name = "lib_ecology:mushroom_02_cap_brown", param2 = 0, prob = 254}
	lib_ecology.schem_mushroom_tall = {
		size = {x = 5,y = 10,z = 5},
		data = {
			__, __, __, __, __,
			__, __, __, __, __,
			__, __, __, __, __,
			__, __, __, __, __,
			__, __, __, __, __,
			__, __, __, __, __,
			__, __, __, __, __,
			__, __, __, __, __,
			__, L0, L0, L0, __,
			__, __, __, __, __,

			__, __, __, __, __,
			__, __, __, __, __,
			__, __, __, __, __,
			__, __, __, __, __,
			__, __, __, __, __,
			__, __, __, __, __,
			__, __, __, __, __,
			__, __, __, __, __,
			L0, L0, L0, L0, L0,
			__, L0, L0, L0, __,

			__, __, T0, __, __,
			__, __, T0, __, __,
			__, __, T0, __, __,
			__, __, T0, __, __,
			__, __, T0, __, __,
			__, __, T0, __, __,
			__, __, T0, __, __,
			__, __, T0, __, __,
			L0, L0, L0, L0, L0,
			__, L0, L0, L0, __,

			__, __, __, __, __,
			__, __, __, __, __,
			__, __, __, __, __,
			__, __, __, __, __,
			__, __, __, __, __,
			__, __, __, __, __,
			__, __, __, __, __,
			__, __, __, __, __,
			L0, L0, L0, L0, L0,
			__, L0, L0, L0, __,

			__, __, __, __, __,
			__, __, __, __, __,
			__, __, __, __, __,
			__, __, __, __, __,
			__, __, __, __, __,
			__, __, __, __, __,
			__, __, __, __, __,
			__, __, __, __, __,
			__, L0, L0, L0, __,
			__, __, __, __, __
		},
		yslice_prob = {
			{ypos = 0, prob = 254},
			{ypos = 1, prob = 254},
			{ypos = 2, prob = 254},
			{ypos = 3, prob = 254},
			{ypos = 4, prob = 254},
			{ypos = 5, prob = 254},
			{ypos = 6, prob = 254},
			{ypos = 7, prob = 254},
			{ypos = 8, prob = 254},
			{ypos = 9, prob = 254}
		}
	}


	T0 = {name = "lib_ecology:mushroom_02_trunk", param2 = 0, prob = 254}
	L0 = {name = "lib_ecology:mushroom_cap_blue", param2 = 0, prob = 254}
	lib_ecology.schem_mushroom_blue = {
		size = {x = 10,y = 11,z = 10},
		data = {
			__, __, __, __, __, __, __, __, __, __,
			__, __, __, __, __, __, __, __, __, __,
			__, __, __, __, __, __, __, __, __, __,
			__, __, __, __, __, __, __, __, __, __,
			__, __, __, __, __, __, __, __, __, __,
			__, __, __, __, __, __, __, __, __, __,
			__, __, __, __, __, __, __, __, __, __,
			__, __, __, __, __, __, __, __, __, __,
			__, __, __, L0, L0, __, __, __, __, __,
			__, __, __, __, __, L0, L0, __, __, __,
			__, __, __, __, __, __, __, __, __, __,

			__, __, __, __, __, __, __, __, __, __,
			__, __, __, __, __, __, __, __, __, __,
			__, __, __, __, __, __, __, __, __, __,
			__, __, __, __, __, __, __, __, __, __,
			__, __, __, __, __, __, __, __, __, __,
			__, __, __, __, __, __, __, __, __, __,
			__, __, __, __, __, __, __, __, __, __,
			__, __, __, __, __, __, __, __, __, __,
			__, __, L0, L0, L0, __, __, __, __, __,
			__, __, __, __, __, L0, L0, L0, __, __,
			__, __, __, __, __, __, __, __, __, __,

			__, __, __, __, __, __, __, __, __, __,
			__, __, __, __, __, __, __, __, __, __,
			__, __, __, __, __, __, __, __, __, __,
			__, __, __, __, __, __, __, __, __, __,
			__, __, __, __, __, __, __, __, __, __,
			__, __, __, __, __, __, __, __, __, __,
			__, __, __, __, __, __, __, __, __, __,
			__, __, __, __, __, __, __, __, __, __,
			__, L0, L0, L0, L0, __, __, __, __, __,
			__, __, __, __, __, L0, L0, L0, L0, __,
			__, __, __, __, __, __, __, __, __, __,

			__, __, __, __, __, __, __, __, __, __,
			__, __, __, __, __, __, __, __, __, __,
			__, __, __, __, __, __, __, __, __, __,
			__, __, __, __, __, __, __, __, __, __,
			__, __, __, __, __, __, __, __, __, __,
			__, __, __, __, __, __, __, __, __, __,
			__, __, __, __, __, __, __, __, __, __,
			__, __, __, __, __, __, __, __, __, __,
			L0, L0, L0, L0, L0, L0, __, __, __, __,
			__, __, __, __, __, L0, L0, L0, L0, L0,
			__, __, __, __, __, __, __, __, __, __,

			__, __, __, __, T0, T0, __, __, __, __,
			__, __, __, __, T0, T0, __, __, __, __,
			__, __, __, __, T0, T0, __, __, __, __,
			__, __, __, __, T0, T0, __, __, __, __,
			__, __, __, __, T0, T0, __, __, __, __,
			__, __, __, __, T0, T0, __, __, __, __,
			__, __, __, __, T0, T0, __, __, __, __,
			__, __, __, __, T0, T0, __, __, __, __,
			L0, L0, L0, L0, L0, L0, L0, __, __, __,
			__, __, __, __, __, __, L0, L0, L0, L0,
			__, __, __, __, __, __, __, __, __, __,

			__, __, __, __, T0, T0, __, __, __, __,
			__, __, __, __, T0, T0, __, __, __, __,
			__, __, __, __, T0, T0, __, __, __, __,
			__, __, __, __, T0, T0, __, __, __, __,
			__, __, __, __, T0, T0, __, __, __, __,
			__, __, __, __, T0, T0, __, __, __, __,
			__, __, __, __, T0, T0, __, __, __, __,
			L0, L0, L0, L0, L0, T0, __, __, __, __,
			__, __, __, L0, L0, L0, L0, L0, L0, L0,
			__, __, __, __, __, __, __, __, __, __,
			__, __, __, __, __, __, __, __, __, __,

			__, __, __, __, __, __, __, __, __, __,
			__, __, __, __, __, __, __, __, __, __,
			__, __, __, __, __, __, __, __, __, __,
			__, __, __, __, __, __, __, __, __, __,
			__, __, __, __, __, __, __, __, __, __,
			__, __, __, __, __, __, __, __, __, __,
			__, __, __, __, __, __, __, __, __, __,
			L0, L0, L0, L0, L0, __, __, __, __, __,
			__, __, __, __, L0, L0, L0, L0, L0, L0,
			__, __, __, __, __, __, __, __, __, __,
			__, __, __, __, __, __, __, __, __, __,

			__, __, __, __, __, __, __, __, __, __,
			__, __, __, __, __, __, __, __, __, __,
			__, __, __, __, __, __, __, __, __, __,
			__, __, __, __, __, __, __, __, __, __,
			__, __, __, __, __, __, __, __, __, __,
			__, __, __, __, __, __, __, __, __, __,
			__, __, __, __, __, __, __, __, __, __,
			__, L0, L0, L0, L0, __, __, __, __, __,
			__, __, __, __, __, L0, L0, L0, L0, __,
			__, __, __, __, __, __, __, __, __, __,
			__, __, __, __, __, __, __, __, __, __,

			__, __, __, __, __, __, __, __, __, __,
			__, __, __, __, __, __, __, __, __, __,
			__, __, __, __, __, __, __, __, __, __,
			__, __, __, __, __, __, __, __, __, __,
			__, __, __, __, __, __, __, __, __, __,
			__, __, __, __, __, __, __, __, __, __,
			__, __, __, __, __, __, __, __, __, __,
			__, __, L0, L0, L0, __, __, __, __, __,
			__, __, __, __, __, L0, L0, L0, __, __,
			__, __, __, __, __, __, __, __, __, __,
			__, __, __, __, __, __, __, __, __, __,

			__, __, __, __, __, __, __, __, __, __,
			__, __, __, __, __, __, __, __, __, __,
			__, __, __, __, __, __, __, __, __, __,
			__, __, __, __, __, __, __, __, __, __,
			__, __, __, __, __, __, __, __, __, __,
			__, __, __, __, __, __, __, __, __, __,
			__, __, __, __, __, __, __, __, __, __,
			__, __, __, L0, L0, __, __, __, __, __,
			__, __, __, __, __, L0, L0, __, __, __,
			__, __, __, __, __, __, __, __, __, __,
			__, __, __, __, __, __, __, __, __, __
		},
		yslice_prob = {
			{prob = 254, ypos = 0},
			{prob = 254, ypos = 1},
			{prob = 254, ypos = 2},
			{prob = 254, ypos = 3},
			{prob = 254, ypos = 4},
			{prob = 254, ypos = 5},
			{prob = 254, ypos = 6},
			{prob = 254, ypos = 7},
			{prob = 254, ypos = 8},
			{prob = 254, ypos = 9},
			{prob = 254, ypos = 10}
		}
	}

	T0 = {name = "lib_ecology:mushroom_02_trunk", param2 = 0, prob = 254}
	L0 = {name = "lib_ecology:mushroom_cap_green_spotted", param2 = 0, prob = 254}
	lib_ecology.schem_mushroom_green_spotted = {
		size = {x = 3,y = 5,z = 3},
		data = {
			__, __, __,
			__, __, __,
			__, __, __,
			__, __, __,
			L0, L0, L0,

			__, T0, __,
			__, T0, __,
			__, T0, __,
			__, T0, __,
			L0, L0, L0,

			__, __, __,
			__, __, __,
			__, __, __,
			__, __, __,
			L0, L0, L0
		},
		yslice_prob = {
			{ypos = 0, prob = 254},
			{ypos = 1, prob = 254},
			{ypos = 2, prob = 254},
			{ypos = 3, prob = 254},
			{ypos = 4, prob = 254}
		}
	}

	T0 = {name = "lib_ecology:mushroom_01_trunk", param2 = 0, prob = 254}
	L0 = {name = "lib_ecology:mushroom_cap_green_dk", param2 = 0, prob = 254}
	lib_ecology.schem_mushroom_green_dark = {
		size = {x = 5,y = 10,z = 5},
		data = {
			__, __, __, __, __,
			__, __, __, __, __,
			__, __, __, __, __,
			__, __, __, __, __,
			__, __, __, __, __,
			__, __, __, __, __,
			__, __, __, __, __,
			__, __, __, __, __,
			__, L0, L0, L0, __,
			__, __, __, __, __,

			__, __, __, __, __,
			__, __, __, __, __,
			__, __, __, __, __,
			__, __, __, __, __,
			__, __, __, __, __,
			__, __, __, __, __,
			__, __, __, __, __,
			__, __, __, __, __,
			L0, L0, L0, L0, L0,
			__, L0, L0, L0, __,

			__, __, T0, __, __,
			__, __, T0, __, __,
			__, __, T0, __, __,
			__, __, T0, __, __,
			__, __, T0, __, __,
			__, __, T0, __, __,
			__, __, T0, __, __,
			__, __, T0, __, __,
			L0, L0, L0, L0, L0,
			__, L0, L0, L0, __,

			__, __, __, __, __,
			__, __, __, __, __,
			__, __, __, __, __,
			__, __, __, __, __,
			__, __, __, __, __,
			__, __, __, __, __,
			__, __, __, __, __,
			__, __, __, __, __,
			L0, L0, L0, L0, L0,
			__, L0, L0, L0, __,

			__, __, __, __, __,
			__, __, __, __, __,
			__, __, __, __, __,
			__, __, __, __, __,
			__, __, __, __, __,
			__, __, __, __, __,
			__, __, __, __, __,
			__, __, __, __, __,
			__, L0, L0, L0, __,
			__, __, __, __, __
		},
		yslice_prob = {
			{ypos = 0, prob = 254},
			{ypos = 1, prob = 254},
			{ypos = 2, prob = 254},
			{ypos = 3, prob = 254},
			{ypos = 4, prob = 254},
			{ypos = 5, prob = 254},
			{ypos = 6, prob = 254},
			{ypos = 7, prob = 254},
			{ypos = 8, prob = 254},
			{ypos = 9, prob = 254}
		}
	}

	T0 = {name = "lib_ecology:mushroom_01_trunk", param2 = 0, prob = 254}
	L0 = {name = "lib_ecology:mushroom_cap_purple", param2 = 0, prob = 254}
	lib_ecology.schem_mushroom_purple = {
		size = {x = 16,y = 11,z = 16},
		data = {
			__, __, __, __, __, __, __, __, __, __, __, __, __, __, __, __,
			__, __, __, __, __, __, __, __, __, __, __, __, __, __, __, __,
			__, __, __, __, __, __, __, __, __, __, __, __, __, __, __, __,
			__, __, __, __, __, __, __, __, __, __, __, __, __, __, __, __,
			__, __, __, __, __, __, __, __, __, __, __, __, __, __, __, __,
			__, __, __, __, __, __, __, __, __, __, __, __, __, __, __, __,
			__, __, __, __, __, __, __, __, __, __, __, __, __, __, __, __,
			__, __, __, __, __, __, __, __, __, __, __, __, __, __, __, __,
			__, __, __, __, __, L0, L0, L0, __, __, __, __, __, __, __, __,
			__, __, __, __, __, __, __, __, L0, L0, L0, __, __, __, __, __,
			__, __, __, __, __, __, __, __, __, __, __, __, __, __, __, __,

			__, __, __, __, __, __, __, __, __, __, __, __, __, __, __, __,
			__, __, __, __, __, __, __, __, __, __, __, __, __, __, __, __,
			__, __, __, __, __, __, __, __, __, __, __, __, __, __, __, __,
			__, __, __, __, __, __, __, __, __, __, __, __, __, __, __, __,
			__, __, __, __, __, __, __, __, __, __, __, __, __, __, __, __,
			__, __, __, __, __, __, __, __, __, __, __, __, __, __, __, __,
			__, __, __, __, __, __, __, __, __, __, __, __, __, __, __, __,
			__, __, __, __, __, __, __, __, __, __, __, __, __, __, __, __,
			__, __, __, L0, L0, L0, L0, L0, __, __, __, __, __, __, __, __,
			__, __, __, __, __, __, __, __, L0, L0, L0, L0, L0, __, __, __,
			__, __, __, __, __, __, __, __, __, __, __, __, __, __, __, __,

			__, __, __, __, __, __, __, __, __, __, __, __, __, __, __, __,
			__, __, __, __, __, __, __, __, __, __, __, __, __, __, __, __,
			__, __, __, __, __, __, __, __, __, __, __, __, __, __, __, __,
			__, __, __, __, __, __, __, __, __, __, __, __, __, __, __, __,
			__, __, __, __, __, __, __, __, __, __, __, __, __, __, __, __,
			__, __, __, __, __, __, __, __, __, __, __, __, __, __, __, __,
			__, __, __, __, __, __, __, __, __, __, __, __, __, __, __, __,
			__, __, __, __, __, __, __, __, __, __, __, __, __, __, __, __,
			__, __, L0, L0, L0, L0, L0, L0, __, __, __, __, __, __, __, __,
			__, __, __, __, __, __, __, __, L0, L0, L0, L0, L0, L0, __, __,
			__, __, __, __, __, __, __, __, __, __, __, __, __, __, __, __,

			__, __, __, __, __, __, __, __, __, __, __, __, __, __, __, __,
			__, __, __, __, __, __, __, __, __, __, __, __, __, __, __, __,
			__, __, __, __, __, __, __, __, __, __, __, __, __, __, __, __,
			__, __, __, __, __, __, __, __, __, __, __, __, __, __, __, __,
			__, __, __, __, __, __, __, __, __, __, __, __, __, __, __, __,
			__, __, __, __, __, __, __, __, __, __, __, __, __, __, __, __,
			__, __, __, __, __, __, __, __, __, __, __, __, __, __, __, __,
			__, __, __, __, __, __, __, __, __, __, __, __, __, __, __, __,
			__, L0, L0, L0, L0, L0, L0, L0, T0, T0, __, __, __, __, __, __,
			__, __, __, __, __, __, __, __, L0, L0, L0, L0, L0, L0, L0, __,
			__, __, __, __, __, __, __, __, __, __, __, __, __, __, __, __,

			__, __, __, __, __, __, T0, T0, T0, T0, __, __, __, __, __, __,
			__, __, __, __, __, T0, T0, T0, T0, T0, T0, __, __, __, __, __,
			__, __, __, __, __, T0, T0, T0, T0, T0, T0, __, __, __, __, __,
			__, __, __, __, __, T0, T0, T0, T0, T0, T0, __, __, __, __, __,
			__, __, __, __, __, T0, T0, T0, T0, T0, T0, __, __, __, __, __,
			__, __, __, __, __, T0, T0, T0, T0, T0, T0, __, __, __, __, __,
			__, __, __, __, __, T0, T0, T0, T0, T0, T0, __, __, __, __, __,
			__, __, __, __, __, T0, T0, T0, T0, T0, T0, __, __, __, __, __,
			__, L0, L0, L0, L0, L0, L0, L0, T0, T0, __, __, __, __, __, __,
			__, __, __, __, __, __, __, __, L0, L0, L0, L0, L0, L0, L0, __,
			__, __, __, __, __, __, __, __, __, __, __, __, __, __, __, __,

			__, __, __, __, __, T0, T0, T0, T0, T0, T0, __, __, __, __, __,
			__, __, __, __, T0, T0, __, __, __, __, T0, T0, __, __, __, __,
			__, __, __, __, T0, T0, __, __, __, __, T0, T0, __, __, __, __,
			__, __, __, __, T0, T0, __, __, __, __, T0, T0, __, __, __, __,
			__, __, __, __, T0, T0, __, __, __, __, T0, T0, __, __, __, __,
			__, __, __, __, T0, T0, __, __, __, __, T0, T0, __, __, __, __,
			__, __, __, __, T0, T0, __, __, __, __, T0, T0, __, __, __, __,
			__, __, __, __, __, __, T0, __, __, __, T0, T0, __, __, __, __,
			__, __, L0, L0, L0, L0, L0, L0, __, T0, T0, __, __, __, __, __,
			L0, L0, __, __, __, __, __, __, L0, L0, L0, L0, L0, L0, L0, L0,
			__, __, __, __, __, __, __, __, __, __, __, __, __, __, __, __,

			__, __, __, __, __, T0, T0, T0, T0, T0, T0, __, __, __, __, __,
			__, __, __, __, T0, __, __, __, __, __, __, T0, __, __, __, __,
			__, __, __, __, T0, __, __, __, __, __, __, T0, __, __, __, __,
			__, __, __, __, T0, __, __, __, __, __, __, T0, __, __, __, __,
			__, __, __, __, T0, __, __, __, __, __, __, T0, __, __, __, __,
			__, __, __, __, T0, __, __, __, __, __, __, T0, __, __, __, __,
			__, __, __, __, T0, __, __, __, __, __, __, T0, __, __, __, __,
			__, __, __, __, __, T0, __, __, __, __, T0, __, __, __, __, __,
			L0, L0, L0, L0, L0, L0, L0, L0, L0, T0, __, __, __, __, __, __,
			__, __, __, __, __, __, __, __, L0, L0, L0, L0, L0, L0, L0, L0,
			__, __, __, __, __, __, __, __, __, __, __, __, __, __, __, __,

			__, __, __, __, __, T0, T0, T0, T0, T0, T0, __, __, __, __, __,
			__, __, __, __, T0, __, __, __, __, __, __, T0, __, __, __, __,
			__, __, __, __, T0, __, __, __, __, __, __, T0, __, __, __, __,
			__, __, __, __, T0, __, __, __, __, __, __, T0, __, __, __, __,
			__, __, __, __, T0, __, __, __, __, __, __, T0, __, __, __, __,
			__, __, __, __, T0, __, __, __, __, __, __, T0, __, __, __, __,
			__, __, __, __, T0, __, __, __, __, __, __, T0, __, __, __, __,
			__, __, __, __, __, T0, __, __, __, __, T0, __, __, __, __, __,
			L0, L0, L0, L0, L0, L0, L0, L0, L0, L0, T0, __, __, __, __, __,
			__, __, __, __, __, __, __, __, __, L0, L0, L0, L0, L0, L0, L0,
			__, __, __, __, __, __, __, __, __, __, __, __, __, __, __, __,

			__, __, __, __, __, T0, T0, T0, T0, T0, T0, __, __, __, __, __,
			__, __, __, __, T0, __, __, __, __, __, __, T0, __, __, __, __,
			__, __, __, __, T0, __, __, __, __, __, __, T0, __, __, __, __,
			__, __, __, __, T0, __, __, __, __, __, __, T0, __, __, __, __,
			__, __, __, __, T0, __, __, __, __, __, __, T0, __, __, __, __,
			__, __, __, __, T0, __, __, __, __, __, __, T0, __, __, __, __,
			__, __, __, __, __, T0, __, __, __, __, T0, __, __, __, __, __,
			L0, L0, L0, L0, L0, L0, L0, L0, __, __, T0, __, __, __, __, __,
			__, __, __, __, __, __, L0, L0, L0, L0, L0, L0, L0, L0, L0, L0,
			__, __, __, __, __, __, __, __, __, __, __, __, __, __, __, __,
			__, __, __, __, __, __, __, __, __, __, __, __, __, __, __, __,

			__, __, __, __, __, T0, T0, T0, T0, T0, T0, __, __, __, __, __,
			__, __, __, __, T0, __, __, __, __, __, __, T0, __, __, __, __,
			__, __, __, __, T0, __, __, __, __, __, __, T0, __, __, __, __,
			__, __, __, __, T0, __, __, __, __, __, __, T0, __, __, __, __,
			__, __, __, __, T0, __, __, __, __, __, __, T0, __, __, __, __,
			__, __, __, __, T0, __, __, __, __, __, __, T0, __, __, __, __,
			__, __, __, __, __, T0, __, __, __, __, T0, __, __, __, __, __,
			L0, L0, L0, L0, L0, L0, L0, L0, __, T0, __, __, __, __, __, __,
			__, __, __, __, __, __, __, L0, L0, L0, L0, L0, L0, L0, L0, L0,
			__, __, __, __, __, __, __, __, __, __, __, __, __, __, __, __,
			__, __, __, __, __, __, __, __, __, __, __, __, __, __, __, __,

			__, __, __, __, __, T0, T0, T0, T0, T0, T0, __, __, __, __, __,
			__, __, __, __, T0, T0, __, __, __, __, T0, T0, __, __, __, __,
			__, __, __, __, T0, T0, __, __, __, __, T0, T0, __, __, __, __,
			__, __, __, __, T0, T0, __, __, __, __, T0, T0, __, __, __, __,
			__, __, __, __, T0, T0, __, __, __, __, T0, T0, __, __, __, __,
			__, __, __, __, T0, T0, __, __, __, __, T0, T0, __, __, __, __,
			__, __, __, __, __, T0, __, __, __, T0, __, __, __, __, __, __,
			L0, L0, L0, L0, L0, L0, L0, L0, __, T0, __, __, __, __, __, __,
			__, __, __, __, __, __, __, __, L0, L0, L0, L0, L0, L0, L0, L0,
			__, __, __, __, __, __, __, __, __, __, __, __, __, __, __, __,
			__, __, __, __, __, __, __, __, __, __, __, __, __, __, __, __,

			__, __, __, __, __, __, T0, T0, T0, T0, __, __, __, __, __, __,
			__, __, __, __, __, T0, T0, T0, T0, T0, T0, __, __, __, __, __,
			__, __, __, __, __, T0, T0, T0, T0, T0, T0, __, __, __, __, __,
			__, __, __, __, __, T0, T0, T0, T0, T0, T0, __, __, __, __, __,
			__, __, __, __, __, T0, T0, T0, T0, T0, T0, __, __, __, __, __,
			__, __, __, __, __, T0, T0, T0, T0, T0, T0, __, __, __, __, __,
			__, __, __, __, __, __, T0, T0, T0, T0, __, __, __, __, __, __,
			__, L0, L0, L0, L0, L0, L0, L0, T0, T0, __, __, __, __, __, __,
			__, __, __, __, __, __, __, __, L0, L0, L0, L0, L0, L0, L0, __,
			__, __, __, __, __, __, __, __, __, __, __, __, __, __, __, __,
			__, __, __, __, __, __, __, __, __, __, __, __, __, __, __, __,

			__, __, __, __, __, __, __, __, __, __, __, __, __, __, __, __,
			__, __, __, __, __, __, __, __, __, __, __, __, __, __, __, __,
			__, __, __, __, __, __, __, __, __, __, __, __, __, __, __, __,
			__, __, __, __, __, __, __, __, __, __, __, __, __, __, __, __,
			__, __, __, __, __, __, __, __, __, __, __, __, __, __, __, __,
			__, __, __, __, __, __, __, __, __, __, __, __, __, __, __, __,
			__, __, __, __, __, __, __, __, __, __, __, __, __, __, __, __,
			__, L0, L0, L0, L0, L0, L0, L0, T0, T0, __, __, __, __, __, __,
			__, __, __, __, __, __, __, __, L0, L0, L0, L0, L0, L0, L0, __,
			__, __, __, __, __, __, __, __, __, __, __, __, __, __, __, __,
			__, __, __, __, __, __, __, __, __, __, __, __, __, __, __, __,
			
			__, __, __, __, __, __, __, __, __, __, __, __, __, __, __, __,
			__, __, __, __, __, __, __, __, __, __, __, __, __, __, __, __,
			__, __, __, __, __, __, __, __, __, __, __, __, __, __, __, __,
			__, __, __, __, __, __, __, __, __, __, __, __, __, __, __, __,
			__, __, __, __, __, __, __, __, __, __, __, __, __, __, __, __,
			__, __, __, __, __, __, __, __, __, __, __, __, __, __, __, __,
			__, __, __, __, __, __, __, __, __, __, __, __, __, __, __, __,
			__, __, L0, L0, L0, L0, L0, L0, __, __, __, __, __, __, __, __,
			__, __, __, __, __, __, __, __, L0, L0, L0, L0, L0, L0, __, __,
			__, __, __, __, __, __, __, __, __, __, __, __, __, __, __, __,
			__, __, __, __, __, __, __, __, __, __, __, __, __, __, __, __,

			__, __, __, __, __, __, __, __, __, __, __, __, __, __, __, __,
			__, __, __, __, __, __, __, __, __, __, __, __, __, __, __, __,
			__, __, __, __, __, __, __, __, __, __, __, __, __, __, __, __,
			__, __, __, __, __, __, __, __, __, __, __, __, __, __, __, __,
			__, __, __, __, __, __, __, __, __, __, __, __, __, __, __, __,
			__, __, __, __, __, __, __, __, __, __, __, __, __, __, __, __,
			__, __, __, __, __, __, __, __, __, __, __, __, __, __, __, __,
			__, __, __, L0, L0, L0, L0, L0, __, __, __, __, __, __, __, __,
			__, __, __, __, __, __, __, __, L0, L0, L0, L0, L0, __, __, __,
			__, __, __, __, __, __, __, __, __, __, __, __, __, __, __, __,
			__, __, __, __, __, __, __, __, __, __, __, __, __, __, __, __,

			__, __, __, __, __, __, __, __, __, __, __, __, __, __, __, __,
			__, __, __, __, __, __, __, __, __, __, __, __, __, __, __, __,
			__, __, __, __, __, __, __, __, __, __, __, __, __, __, __, __,
			__, __, __, __, __, __, __, __, __, __, __, __, __, __, __, __,
			__, __, __, __, __, __, __, __, __, __, __, __, __, __, __, __,
			__, __, __, __, __, __, __, __, __, __, __, __, __, __, __, __,
			__, __, __, __, __, __, __, __, __, __, __, __, __, __, __, __,
			__, __, __, __, __, L0, L0, L0, __, __, __, __, __, __, __, __,
			__, __, __, __, __, __, __, __, L0, L0, L0, __, __, __, __, __,
			__, __, __, __, __, __, __, __, __, __, __, __, __, __, __, __,
			__, __, __, __, __, __, __, __, __, __, __, __, __, __, __, __
		},
		yslice_prob = {
			{prob = 254, ypos = 0},
			{prob = 254, ypos = 1},
			{prob = 254, ypos = 2},
			{prob = 254, ypos = 3},
			{prob = 254, ypos = 4},
			{prob = 254, ypos = 5},
			{prob = 254, ypos = 6},
			{prob = 254, ypos = 7},
			{prob = 254, ypos = 8},
			{prob = 254, ypos = 9},
			{prob = 254, ypos = 10}
		}
	}




	local ms = {name = "lib_ecology:mushroom_03_stem", param2 = 0, prob = 254}
	local mc = {name = "lib_ecology:mushroom_03_cap_giant", param2 = 0, prob = 254}
	lib_ecology.mushroom_03_a = {
		size = {x = 1, y = 3, z = 1},
		data = {
			ms,
			ms,
			mc,
		},
	}
	local ms = {name = "lib_ecology:mushroom_03_stem", param2 = 0, prob = 254}
	local mc = {name = "lib_ecology:mushroom_03_cap_huge", param2 = 0, prob = 254}
	lib_ecology.mushroom_03_b = {
		size = {x = 1, y = 3, z = 1},
		data = {
			ms,
			ms,
			mc,
		},
	}



-- waterlilies
	lib_ecology.waterlily_pink = {
		size = {x = 1, y = 3, z = 1},
		data = {
			{name = "lib_materials:sand", param2 = 0, prob = 254},
			{name = "default:water_source", param2 = 0, prob = 254},
			{name = "lib_ecology:plant_waterlily_pink", param2 = 0, prob = 254}
		},
	}
	lib_ecology.waterlily_yellow = {
		size = {x = 1, y = 3, z = 1},
		data = {
			{name = "lib_materials:sand", param2 = 0, prob = 254},
			{name = "default:water_source", param2 = 0, prob = 254},
			{name = "lib_ecology:plant_waterlily_yellow", param2 = 0, prob = 254}
		},
	}



--TREES

--Acacia Trees and Log
	--minetest.log(S("TREES - Acacia"))
	T0 = {name = "lib_ecology:tree_acacia_trunk", param2 = 0, prob = 254}
	L0 = {name = "lib_ecology:tree_acacia_leaves", param2 = 0, prob = 254}
	L1 = {name = "lib_ecology:tree_acacia_leaves", param2 = 0, prob = 222}
	lib_ecology.schem_tree_acacia_01 = {
		size = {x = 9,y = 8,z = 9},
		data = {
			__, __, __, __, __, __, __, __, __,
			__, __, __, __, __, __, __, __, __,
			__, __, __, __, __, __, __, __, __,
			__, __, __, __, __, __, __, __, __,
			__, __, __, __, __, __, __, __, __,
			__, __, __, __, __, __, __, __, __,
			L1, L1, L1, L1, __, __, __, __, __,
			__, __, __, __, L1, L1, L1, L1, L1,
			
			__, __, __, __, __, __, __, __, __,
			__, __, __, __, __, __, __, __, __,
			__, __, __, __, __, __, __, __, __,
			__, __, __, __, __, __, __, __, __,
			__, __, __, __, __, __, __, __, __,
			__, __, __, __, __, __, __, __, __,
			L1, L0, L0, L1, __, __, __, __, __,
			__, __, __, __, L1, L0, L0, L0, L1,
			
			__, __, __, __, __, __, __, __, __,
			__, __, __, __, __, __, __, __, __,
			__, __, __, __, __, __, __, __, __,
			__, __, __, __, __, __, __, __, __,
			__, __, __, __, __, __, __, __, __,
			__, __, T0, __, __, __, __, __, __,
			L1, L0, L0, L1, __, __, T0, __, __,
			__, __, __, __, L1, L0, L0, L0, L1,
			
			__, __, __, __, __, __, __, __, __,
			__, __, __, __, __, __, __, __, __,
			__, __, __, __, __, __, __, __, __,
			__, __, __, __, __, __, __, __, __,
			__, __, __, T0, __, __, __, __, __,
			__, __, __, __, __, T0, __, __, __,
			L1, L1, L1, L1, __, __, __, __, __,
			__, __, __, __, L1, L0, L0, L0, L1,
			
			__, __, __, __, T0, __, __, __, __,
			__, __, __, __, T0, __, __, __, __,
			__, __, __, __, T0, __, __, __, __,
			__, __, __, __, T0, __, __, __, __,
			__, __, __, __, T0, __, __, __, __,
			__, __, __, __, __, __, __, __, __,
			__, __, __, __, __, __, __, __, __,
			L1, L1, L1, L1, L1, L1, L1, L1, L1,
			
			__, __, __, __, __, __, __, __, __,
			__, __, __, __, __, __, __, __, __,
			__, __, __, __, __, __, __, __, __,
			__, __, __, __, __, __, __, __, __,
			__, __, __, __, __, T0, __, __, __,
			__, __, __, T0, __, __, __, __, __,
			__, __, __, __, __, L1, L1, L1, L1,
			L1, L0, L0, L0, L1, __, __, __, __,
			
			__, __, __, __, __, __, __, __, __,
			__, __, __, __, __, __, __, __, __,
			__, __, __, __, __, __, __, __, __,
			__, __, __, __, __, __, __, __, __,
			__, __, __, __, __, __, __, __, __,
			__, __, __, __, __, __, T0, __, __,
			__, __, T0, __, __, L1, L0, L0, L1,
			L1, L0, L0, L0, L1, __, __, __, __,
			
			__, __, __, __, __, __, __, __, __,
			__, __, __, __, __, __, __, __, __,
			__, __, __, __, __, __, __, __, __,
			__, __, __, __, __, __, __, __, __,
			__, __, __, __, __, __, __, __, __,
			__, __, __, __, __, __, __, __, __,
			__, __, __, __, __, L1, L0, L0, L1,
			L1, L0, L0, L0, L1, __, __, __, __,
			
			__, __, __, __, __, __, __, __, __,
			__, __, __, __, __, __, __, __, __,
			__, __, __, __, __, __, __, __, __,
			__, __, __, __, __, __, __, __, __,
			__, __, __, __, __, __, __, __, __,
			__, __, __, __, __, __, __, __, __,
			__, __, __, __, __, L1, L1, L1, L1,
			L1, L1, L1, L1, L1, __, __, __, __
		},
		yslice_prob = {
			{ypos = 0,prob = 254},
			{ypos = 1,prob = 254},
			{ypos = 2,prob = 126},
			{ypos = 3,prob = 254},
			{ypos = 4,prob = 254},
			{ypos = 5,prob = 254},
			{ypos = 6,prob = 254},
			{ypos = 7,prob = 254}
		}
	}
	lib_ecology.schem_tree_acacia_02 = {
		size = {x = 11,y = 11,z = 11},
		data = {
			__, __, __, __, __, __, __, __, __, __, __,
			__, __, __, __, __, __, __, __, __, __, __,
			__, __, __, __, __, __, __, __, __, __, __,
			__, __, __, __, __, __, __, __, __, __, __,
			__, __, __, __, __, __, __, __, __, __, __,
			__, __, __, __, __, __, __, __, __, __, __,
			__, __, __, __, __, __, __, __, __, __, __,
			__, __, __, __, __, __, __, __, __, __, __,
			__, __, __, __, __, __, __, __, __, __, __,
			__, __, __, __, __, L0, __, __, __, __, __,
			__, __, __, __, __, __, __, __, __, __, __,
			
			__, __, __, __, __, __, __, __, __, __, __,
			__, __, __, __, __, __, __, __, __, __, __,
			__, __, __, __, __, __, __, __, __, __, __,
			__, __, __, __, __, __, __, __, __, __, __,
			__, __, __, __, __, __, __, __, __, __, __,
			__, __, __, __, __, __, __, __, __, __, __,
			__, __, __, __, __, __, __, __, __, __, __,
			__, __, __, __, __, __, __, __, __, __, __,
			__, __, __, __, __, __, __, __, __, __, __,
			__, __, __, __, L0, L0, L0, __, __, __, __,
			__, __, __, __, __, __, __, __, __, __, __,
			
			__, __, __, __, __, __, __, __, __, __, __,
			__, __, __, __, __, __, __, __, __, __, __,
			__, __, __, __, __, __, __, __, __, __, __,
			__, __, __, __, __, __, __, __, __, __, __,
			__, __, __, __, __, __, __, __, __, __, __,
			__, __, __, __, __, __, __, __, __, __, __,
			__, __, __, __, __, __, __, __, __, __, __,
			__, __, __, __, __, __, __, __, __, __, __,
			__, __, __, __, __, T0, __, __, __, __, __,
			__, __, __, L0, L0, L0, L0, L0, __, __, __,
			__, __, __, __, __, L0, __, __, __, __, __,
			
			__, __, __, __, __, __, __, __, __, __, __,
			__, __, __, __, __, __, __, __, __, __, __,
			__, __, __, __, __, __, __, __, __, __, __,
			__, __, __, __, __, __, __, __, __, __, __,
			__, __, __, __, __, __, __, __, __, __, __,
			__, __, __, __, __, __, __, __, __, __, __,
			__, __, __, __, __, __, __, __, __, __, __,
			__, __, __, __, __, T0, __, __, __, __, __,
			__, __, __, __, __, __, __, __, __, __, __,
			__, __, L0, L0, L0, L0, L0, L0, L0, __, __,
			__, __, __, L0, L0, L0, L0, L0, __, __, __,
			
			__, __, __, __, __, __, __, __, __, __, __,
			__, __, __, __, __, __, __, __, __, __, __,
			__, __, __, __, __, __, __, __, __, __, __,
			__, __, __, __, __, __, __, __, __, __, __,
			__, __, __, __, __, __, __, __, __, __, __,
			__, __, __, __, __, __, __, __, __, __, __,
			__, __, __, __, __, T0, __, __, __, __, __,
			__, __, __, __, __, __, __, __, __, __, __,
			__, __, __, __, __, __, __, __, __, __, __,
			__, L0, L0, L0, L0, L0, L0, L0, L0, L0, __,
			__, __, __, L0, L0, L0, L0, L0, __, __, __,
			
			__, __, __, __, __, T0, __, __, __, __, __,
			__, __, __, __, __, T0, __, __, __, __, __,
			__, __, __, __, __, T0, __, __, __, __, __,
			__, __, __, __, __, T0, __, __, __, __, __,
			__, __, __, __, __, T0, __, __, __, __, __,
			__, __, __, __, __, T0, __, __, __, __, __,
			__, __, __, __, T0, __, T0, __, __, __, __,
			__, __, __, T0, __, __, __, T0, __, __, __,
			__, __, T0, __, __, __, __, __, T0, __, __,
			L0, L0, L0, L0, L0, L0, L0, L0, L0, L0, L0,
			__, __, L0, L0, L0, L0, L0, L0, L0, __, __,
			
			__, __, __, __, __, __, __, __, __, __, __,
			__, __, __, __, __, __, __, __, __, __, __,
			__, __, __, __, __, __, __, __, __, __, __,
			__, __, __, __, __, __, __, __, __, __, __,
			__, __, __, __, __, __, __, __, __, __, __,
			__, __, __, __, __, __, __, __, __, __, __,
			__, __, __, __, __, T0, __, __, __, __, __,
			__, __, __, __, __, __, __, __, __, __, __,
			__, __, __, __, __, __, __, __, __, __, __,
			__, L0, L0, L0, L0, L0, L0, L0, L0, L0, __,
			__, __, __, L0, L0, L0, L0, L0, __, __, __,
			
			__, __, __, __, __, __, __, __, __, __, __,
			__, __, __, __, __, __, __, __, __, __, __,
			__, __, __, __, __, __, __, __, __, __, __,
			__, __, __, __, __, __, __, __, __, __, __,
			__, __, __, __, __, __, __, __, __, __, __,
			__, __, __, __, __, __, __, __, __, __, __,
			__, __, __, __, __, __, __, __, __, __, __,
			__, __, __, __, __, T0, __, __, __, __, __,
			__, __, __, __, __, __, __, __, __, __, __,
			__, __, L0, L0, L0, L0, L0, L0, L0, __, __,
			__, __, __, L0, L0, L0, L0, L0, __, __, __,
			
			__, __, __, __, __, __, __, __, __, __, __,
			__, __, __, __, __, __, __, __, __, __, __,
			__, __, __, __, __, __, __, __, __, __, __,
			__, __, __, __, __, __, __, __, __, __, __,
			__, __, __, __, __, __, __, __, __, __, __,
			__, __, __, __, __, __, __, __, __, __, __,
			__, __, __, __, __, __, __, __, __, __, __,
			__, __, __, __, __, __, __, __, __, __, __,
			__, __, __, __, __, T0, __, __, __, __, __,
			__, __, __, L0, L0, L0, L0, L0, __, __, __,
			__, __, __, __, __, L0, __, __, __, __, __,
			
			__, __, __, __, __, __, __, __, __, __, __,
			__, __, __, __, __, __, __, __, __, __, __,
			__, __, __, __, __, __, __, __, __, __, __,
			__, __, __, __, __, __, __, __, __, __, __,
			__, __, __, __, __, __, __, __, __, __, __,
			__, __, __, __, __, __, __, __, __, __, __,
			__, __, __, __, __, __, __, __, __, __, __,
			__, __, __, __, __, __, __, __, __, __, __,
			__, __, __, __, __, __, __, __, __, __, __,
			__, __, __, __, L0, L0, L0, __, __, __, __,
			__, __, __, __, __, __, __, __, __, __, __,
			
			__, __, __, __, __, __, __, __, __, __, __,
			__, __, __, __, __, __, __, __, __, __, __,
			__, __, __, __, __, __, __, __, __, __, __,
			__, __, __, __, __, __, __, __, __, __, __,
			__, __, __, __, __, __, __, __, __, __, __,
			__, __, __, __, __, __, __, __, __, __, __,
			__, __, __, __, __, __, __, __, __, __, __,
			__, __, __, __, __, __, __, __, __, __, __,
			__, __, __, __, __, __, __, __, __, __, __,
			__, __, __, __, __, L0, __, __, __, __, __,
			__, __, __, __, __, __, __, __, __, __, __
		},
		yslice_prob = {
			{ypos = 0,prob = 254},
			{ypos = 1,prob = 254},
			{ypos = 2,prob = 254},
			{ypos = 3,prob = 254},
			{ypos = 4,prob = 254},
			{ypos = 5,prob = 254},
			{ypos = 6,prob = 254},
			{ypos = 7,prob = 254},
			{ypos = 8,prob = 254},
			{ypos = 9,prob = 254},
			{ypos = 10,prob = 254}
		}
	}
	lib_ecology.schem_tree_acacia_03 = {
		size = {x = 9,y = 8,z = 9},
		data = {
			__, __, __, __, __, __, __, __, __,
			__, __, __, __, __, __, __, __, __,
			__, __, __, __, __, __, __, __, __,
			__, __, __, __, __, __, __, __, __,
			__, __, __, __, __, __, __, __, __,
			__, __, __, __, __, __, __, __, __,
			L1, L1, L1, L1, __, __, __, __, __,
			__, __, __, __, L1, L1, L1, L1, L1,
			__, __, __, __, __, __, __, __, __,
			
			__, __, __, __, __, __, __, __, __,
			__, __, __, __, __, __, __, __, __,
			__, __, __, __, __, __, __, __, __,
			__, __, __, __, __, __, __, __, __,
			__, __, __, __, __, __, __, __, __,
			L1, L0, L0, L1, __, __, __, __, __,
			__, __, __, __, L1, L0, L0, L0, L1,
			__, __, __, __, __, __, __, __, __,
			__, __, __, __, __, __, __, __, __,
			
			__, __, __, __, __, __, __, __, __,
			__, __, __, __, __, __, __, __, __,
			__, __, __, __, __, __, __, __, __,
			__, __, T0, __, __, __, __, __, __,
			L1, L0, L0, L1, __, __, T0, __, __,
			__, __, __, __, L1, L0, L0, L0, L1,
			__, __, __, __, __, __, __, __, __,
			__, __, __, __, __, __, __, __, __,
			__, __, __, __, __, __, __, __, __,
			
			__, __, __, __, __, __, __, __, __,
			__, __, __, T0, __, __, __, __, __,
			__, __, __, __, __, T0, __, __, __,
			L1, L1, L1, L1, __, __, __, __, __,
			__, __, __, __, L1, L0, L0, L0, L1,
			__, __, __, __, T0, __, __, __, __,
			__, __, __, __, T0, __, __, __, __,
			__, __, __, __, T0, __, __, __, __,
			__, __, __, __, T0, __, __, __, __,
			
			__, __, __, __, T0, __, __, __, __,
			__, __, __, __, __, __, __, __, __,
			__, __, __, __, __, __, __, __, __,
			L1, L1, L1, L1, L1, L1, L1, L1, L1,
			__, __, __, __, __, __, __, __, __,
			__, __, __, __, __, __, __, __, __,
			__, __, __, __, __, __, __, __, __,
			__, __, __, __, __, __, __, __, __,
			__, __, __, __, __, T0, __, __, __,
			
			__, __, __, T0, __, __, __, __, __,
			__, __, __, __, __, L1, L1, L1, L1,
			L1, L0, L0, L0, L1, __, __, __, __,
			__, __, __, __, __, __, __, __, __,
			__, __, __, __, __, __, __, __, __,
			__, __, __, __, __, __, __, __, __,
			__, __, __, __, __, __, __, __, __,
			__, __, __, __, __, __, __, __, __,
			__, __, __, __, __, __, T0, __, __,
			
			__, __, T0, __, __, L1, L0, L0, L1,
			L1, L0, L0, L0, L1, __, __, __, __,
			__, __, __, __, __, __, __, __, __,
			__, __, __, __, __, __, __, __, __,
			__, __, __, __, __, __, __, __, __,
			__, __, __, __, __, __, __, __, __,
			__, __, __, __, __, __, __, __, __,
			__, __, __, __, __, __, __, __, __,
			__, __, __, __, __, L1, L0, L0, L1,
			
			L1, L0, L0, L0, L1, __, __, __, __,
			__, __, __, __, __, __, __, __, __,
			__, __, __, __, __, __, __, __, __,
			__, __, __, __, __, __, __, __, __,
			__, __, __, __, __, __, __, __, __,
			__, __, __, __, __, __, __, __, __,
			__, __, __, __, __, __, __, __, __,
			__, __, __, __, __, L1, L1, L1, L1,
			L1, L1, L1, L1, L1, __, __, __, __
		},
		yslice_prob = {
			{ypos = 0,prob = 254},
			{ypos = 1,prob = 254},
			{ypos = 2,prob = 126},
			{ypos = 3,prob = 254},
			{ypos = 4,prob = 254},
			{ypos = 5,prob = 254},
			{ypos = 6,prob = 254},
			{ypos = 7,prob = 254}
		}
	}
	lib_ecology.schem_tree_acacia_04 = {
		size = {x = 17,y = 12,z = 17},
		data = {
			__, __, __, __, __, __, __, __, __, __, __, __, __, __, __, __, __,
			__, __, __, __, __, __, __, __, __, __, __, __, __, __, __, __, __,
			__, __, __, __, __, __, __, __, __, __, __, __, __, __, __, __, __,
			__, __, __, __, __, __, __, __, __, __, __, __, __, __, __, __, __,
			__, __, __, __, __, __, __, __, __, __, __, __, __, __, __, __, __,
			__, __, __, __, __, __, __, __, __, __, __, __, __, __, __, __, __,
			__, __, __, __, __, __, __, __, __, __, __, __, __, __, __, __, __,
			__, __, __, __, __, __, __, __, __, __, __, __, __, __, __, __, __,
			__, __, __, __, __, __, __, __, __, __, __, __, __, __, __, __, __,
			__, __, __, __, __, __, __, __, __, __, __, __, __, __, __, __, __,
			__, __, __, __, __, __, __, __, __, __, L0, __, __, __, __, __, __,
			__, __, __, __, __, __, __, __, __, __, __, __, __, __, __, __, __,
			
			__, __, __, __, __, __, __, __, __, __, __, __, __, __, __, __, __,
			__, __, __, __, __, __, __, __, __, __, __, __, __, __, __, __, __,
			__, __, __, __, __, __, __, __, __, __, __, __, __, __, __, __, __,
			__, __, __, __, __, __, __, __, __, __, __, __, __, __, __, __, __,
			__, __, __, __, __, __, __, __, __, __, __, __, __, __, __, __, __,
			__, __, __, __, __, __, __, __, __, __, __, __, __, __, __, __, __,
			__, __, __, __, __, __, __, __, __, __, __, __, __, __, __, __, __,
			__, __, __, __, __, __, __, __, __, __, __, __, __, __, __, __, __,
			__, __, __, __, __, __, __, __, __, __, __, __, __, __, __, __, __,
			__, __, __, __, __, __, __, __, __, __, __, __, __, __, __, __, __,
			__, __, __, __, __, __, __, __, L0, L0, __, __, L0, __, __, __, __,
			__, __, __, __, __, __, __, __, __, L0, __, __, L0, __, __, __, __,
			
			__, __, __, __, __, __, __, __, __, __, __, __, __, __, __, __, __,
			__, __, __, __, __, __, __, __, __, __, __, __, __, __, __, __, __,
			__, __, __, __, __, __, __, __, __, __, __, __, __, __, __, __, __,
			__, __, __, __, __, __, __, __, __, __, __, __, __, __, __, __, __,
			__, __, __, __, __, __, __, __, __, __, __, __, __, __, __, __, __,
			__, __, __, __, __, __, __, __, __, __, __, __, __, __, __, __, __,
			__, __, __, __, __, __, __, __, __, __, __, __, __, __, __, __, __,
			__, __, __, __, __, __, __, __, __, __, __, __, __, __, __, __, __,
			__, __, __, __, __, __, __, __, __, __, __, __, __, __, __, __, __,
			__, __, __, __, __, __, __, __, __, __, __, __, __, __, __, __, __,
			
			__, __, L0, __, __, L0, L0, L0, L0, L0, L0, L0, L0, __, L0, __, __,
			__, __, __, __, __, __, L0, L0, L0, L0, L0, L0, __, __, __, __, __,
			__, __, __, __, __, __, __, __, __, __, __, __, __, __, __, __, __,
			__, __, __, __, __, __, __, __, __, __, __, __, __, __, __, __, __,
			__, __, __, __, __, __, __, __, __, __, __, __, __, __, __, __, __,
			__, __, __, __, __, __, __, __, __, __, __, __, __, __, __, __, __,
			__, __, __, __, __, __, __, __, __, __, __, __, __, __, __, __, __,
			__, __, __, __, __, __, __, __, __, __, __, __, __, __, __, __, __,
			__, __, __, __, __, __, __, __, __, __, __, __, __, __, __, __, __,
			__, __, __, __, __, __, __, __, __, __, __, __, __, __, __, __, __,
			
			__, __, __, __, __, __, __, __, __, __, __, __, __, __, __, __, __,
			__, __, __, __, __, __, __, __, __, __, __, __, __, __, __, __, __,
			__, __, __, L0, __, L0, L0, L0, __, L0, L0, L0, __, L0, __, __, __,
			__, __, __, __, __, __, L0, L0, __, L0, L0, L0, __, __, __, __, __,
			__, __, __, __, __, __, __, __, __, __, __, __, __, __, __, __, __,
			__, __, __, __, __, __, __, __, __, __, __, __, __, __, __, __, __,
			__, __, __, __, __, __, __, __, __, __, __, __, __, __, __, __, __,
			__, __, __, __, __, __, __, __, __, __, __, __, __, __, __, __, __,
			__, __, __, __, __, __, __, __, __, __, __, __, __, __, __, __, __,
			__, __, __, __, __, __, __, __, __, __, __, __, __, __, __, __, __,
			__, __, __, __, __, __, __, __, __, __, __, __, __, __, __, __, __,
			__, __, __, __, __, __, __, __, __, __, __, __, __, __, __, __, __,
			
			__, __, __, __, __, __, __, __, __, __, __, __, __, __, __, __, __,
			__, __, __, __, __, __, __, __, __, __, __, __, __, __, __, __, __,
			__, L0, L0, __, L0, L0, L0, L0, L0, L0, __, L0, L0, __, __, __, __,
			__, L0, __, __, L0, L0, L0, __, L0, L0, __, L0, L0, __, __, __, __,
			__, __, __, __, __, __, __, __, __, __, __, __, __, __, __, __, __,
			__, __, __, __, __, __, __, __, __, __, __, __, __, __, __, __, __,
			__, __, __, __, __, __, __, __, __, __, __, __, __, __, __, __, __,
			__, __, __, __, __, __, __, __, __, __, __, __, __, __, __, __, __,
			__, __, __, __, __, __, __, __, __, __, __, __, __, __, __, __, __,
			__, __, __, __, __, __, __, __, __, __, __, __, __, __, __, __, __,
			__, __, __, __, __, __, __, __, __, __, __, __, __, __, __, __, __,
			__, __, __, __, __, __, __, __, __, __, __, __, __, __, __, __, __,
			
			__, __, __, __, __, __, __, __, __, __, __, __, __, __, __, __, __,
			__, __, __, __, __, T0, __, __, __, __, __, T0, __, __, __, __, __,
			__, __, L0, L0, L0, L0, L0, L0, L0, L0, L0, L0, L0, L0, L0, __, __,
			__, __, L0, L0, L0, L0, L0, L0, L0, L0, L0, L0, L0, __, __, __, __,
			__, __, __, __, __, __, __, __, __, __, __, __, __, __, __, __, __,
			__, __, __, __, __, __, __, __, __, __, __, __, __, __, __, __, __,
			__, __, __, __, __, __, __, __, __, __, __, __, __, __, __, __, __,
			__, __, __, __, __, __, __, __, __, __, __, __, __, __, __, __, __,
			__, __, __, __, __, __, __, __, __, __, __, __, __, __, __, __, __,
			__, __, __, __, __, __, __, __, __, __, __, __, __, __, __, __, __,
			__, __, __, __, __, __, __, __, __, __, __, __, __, __, __, __, __,
			__, __, __, __, __, __, __, __, __, __, __, __, __, __, __, __, __,

			__, __, __, __, __, __, __, __, __, __, __, __, __, __, __, __, __,
			__, __, __, __, __, __, T0, __, __, __, T0, __, __, __, __, __, __,
			L0, __, L0, L0, __, L0, L0, L0, L0, L0, L0, L0, L0, L0, L0, __, __,
			__, __, L0, L0, __, L0, L0, L0, __, L0, L0, L0, L0, L0, L0, __, __,
			__, __, __, __, __, __, __, __, __, __, __, __, __, __, __, __, __,
			__, __, __, __, __, __, __, __, __, __, __, __, __, __, __, __, __,
			__, __, __, __, __, __, __, __, __, __, __, __, __, __, __, __, __,
			__, __, __, __, __, __, __, __, __, __, __, __, __, __, __, __, __,
			__, __, __, __, __, __, __, __, __, __, __, __, __, __, __, __, __,
			__, __, __, __, __, __, __, __, __, __, __, __, __, __, __, __, __,
			__, __, __, __, __, __, __, __, __, __, __, __, __, __, __, __, __,
			__, __, __, __, __, __, __, T0, __, T0, __, __, __, __, __, __, __,

			__, __, __, __, __, __, T0, __, __, T0, __, __, __, __, __, __, __,
			__, __, __, __, __, __, __, __, __, __, __, __, __, __, __, __, __,
			__, L0, L0, L0, L0, L0, L0, L0, L0, L0, L0, L0, L0, L0, L0, __, __,
			__, L0, L0, L0, L0, L0, L0, L0, L0, L0, L0, L0, __, L0, L0, __, __,
			__, __, __, __, __, __, __, __, T0, __, __, __, __, __, __, __, __,
			__, __, __, __, __, __, __, __, T0, __, __, __, __, __, __, __, __,
			__, __, __, __, __, __, __, __, T0, __, __, __, __, __, __, __, __,
			__, __, __, __, __, __, __, __, T0, __, __, __, __, __, __, __, __,
			__, __, __, __, __, __, __, __, T0, __, __, __, __, __, __, __, __,
			__, __, __, __, __, __, __, __, T0, __, __, __, __, __, __, __, __,
			__, __, __, __, __, __, __, __, T0, __, __, __, __, __, __, __, __,
			__, __, __, __, __, __, __, T0, T0, __, __, __, __, __, __, __, __,

			__, __, __, __, __, __, __, __, __, __, __, __, __, __, __, __, __,
			__, __, __, __, __, __, __, __, __, __, __, __, __, __, __, __, __,
			__, L0, L0, __, L0, L0, L0, L0, L0, L0, L0, L0, L0, __, L0, L0, __,
			__, __, L0, __, L0, L0, __, L0, __, L0, __, L0, L0, __, L0, __, __,
			__, __, __, __, __, __, __, __, __, __, __, __, __, __, __, __, __,
			__, __, __, __, __, __, __, __, __, __, __, __, __, __, __, __, __,
			__, __, __, __, __, __, __, __, __, __, __, __, __, __, __, __, __,
			__, __, __, __, __, __, __, __, __, __, __, __, __, __, __, __, __,
			__, __, __, __, __, __, __, __, __, __, __, __, __, __, __, __, __,
			__, __, __, __, __, __, __, __, __, __, __, __, __, __, __, __, __,
			__, __, __, __, __, __, __, __, __, __, __, __, __, __, __, __, __,
			__, __, __, __, __, __, __, T0, __, T0, __, __, __, __, __, __, __,
			__, __, __, __, __, __, T0, __, __, T0, __, __, __, __, __, __, __,

			__, __, __, __, __, __, __, __, __, __, __, __, __, __, __, __, __,
			__, __, L0, L0, L0, L0, L0, L0, L0, L0, L0, L0, L0, L0, L0, L0, __,
			__, __, L0, L0, __, L0, L0, L0, L0, L0, L0, L0, L0, L0, L0, L0, __,
			__, __, __, __, __, __, __, __, __, __, __, __, __, __, __, __, __,
			__, __, __, __, __, __, __, __, __, __, __, __, __, __, __, __, __,
			__, __, __, __, __, __, __, __, __, __, __, __, __, __, __, __, __,
			__, __, __, __, __, __, __, __, __, __, __, __, __, __, __, __, __,
			__, __, __, __, __, __, __, __, __, __, __, __, __, __, __, __, __,
			__, __, __, __, __, __, __, __, __, __, __, __, __, __, __, __, __,
			__, __, __, __, __, __, __, __, __, __, __, __, __, __, __, __, __,
			__, __, __, __, __, __, __, __, __, __, __, __, __, __, __, __, __,
			__, __, __, __, __, __, __, __, __, __, __, __, __, __, __, __, __,
			__, __, __, __, __, __, T0, __, __, __, T0, __, __, __, __, __, __,

			__, __, L0, L0, L0, L0, L0, L0, L0, L0, L0, L0, __, L0, L0, __, L0,
			__, __, L0, L0, L0, L0, L0, L0, __, L0, L0, L0, __, L0, L0, __, __,
			__, __, __, __, __, __, __, __, __, __, __, __, __, __, __, __, __,
			__, __, __, __, __, __, __, __, __, __, __, __, __, __, __, __, __,
			__, __, __, __, __, __, __, __, __, __, __, __, __, __, __, __, __,
			__, __, __, __, __, __, __, __, __, __, __, __, __, __, __, __, __,
			__, __, __, __, __, __, __, __, __, __, __, __, __, __, __, __, __,
			__, __, __, __, __, __, __, __, __, __, __, __, __, __, __, __, __,
			__, __, __, __, __, __, __, __, __, __, __, __, __, __, __, __, __,
			__, __, __, __, __, __, __, __, __, __, __, __, __, __, __, __, __,
			__, __, __, __, __, __, __, __, __, __, __, __, __, __, __, __, __,
			__, __, __, __, __, T0, __, __, __, __, __, T0, __, __, __, __, __,
			
			__, __, L0, L0, L0, L0, L0, L0, L0, L0, L0, L0, L0, L0, L0, __, __,
			__, __, __, __, L0, L0, L0, L0, L0, L0, L0, L0, L0, L0, L0, __, __,
			__, __, __, __, __, __, __, __, __, __, __, __, __, __, __, __, __,
			__, __, __, __, __, __, __, __, __, __, __, __, __, __, __, __, __,
			__, __, __, __, __, __, __, __, __, __, __, __, __, __, __, __, __,
			__, __, __, __, __, __, __, __, __, __, __, __, __, __, __, __, __,
			__, __, __, __, __, __, __, __, __, __, __, __, __, __, __, __, __,
			__, __, __, __, __, __, __, __, __, __, __, __, __, __, __, __, __,
			__, __, __, __, __, __, __, __, __, __, __, __, __, __, __, __, __,
			__, __, __, __, __, __, __, __, __, __, __, __, __, __, __, __, __,
			__, __, __, __, __, __, __, __, __, __, __, __, __, __, __, __, __,
			__, __, __, __, __, __, __, __, __, __, __, __, __, __, __, __, __,

			__, __, __, __, L0, L0, __, L0, L0, L0, L0, L0, L0, __, L0, L0, __,
			__, __, __, __, L0, L0, __, L0, L0, __, L0, L0, L0, __, __, L0, __,
			__, __, __, __, __, __, __, __, __, __, __, __, __, __, __, __, __,
			__, __, __, __, __, __, __, __, __, __, __, __, __, __, __, __, __,
			__, __, __, __, __, __, __, __, __, __, __, __, __, __, __, __, __,
			__, __, __, __, __, __, __, __, __, __, __, __, __, __, __, __, __,
			__, __, __, __, __, __, __, __, __, __, __, __, __, __, __, __, __,
			__, __, __, __, __, __, __, __, __, __, __, __, __, __, __, __, __,
			__, __, __, __, __, __, __, __, __, __, __, __, __, __, __, __, __,
			__, __, __, __, __, __, __, __, __, __, __, __, __, __, __, __, __,
			__, __, __, __, __, __, __, __, __, __, __, __, __, __, __, __, __,
			__, __, __, __, __, __, __, __, __, __, __, __, __, __, __, __, __,

			__, __, __, L0, __, L0, L0, L0, __, L0, L0, L0, __, L0, __, __, __,
			__, __, __, __, __, L0, L0, L0, __, L0, L0, __, __, __, __, __, __,
			__, __, __, __, __, __, __, __, __, __, __, __, __, __, __, __, __,
			__, __, __, __, __, __, __, __, __, __, __, __, __, __, __, __, __,
			__, __, __, __, __, __, __, __, __, __, __, __, __, __, __, __, __,
			__, __, __, __, __, __, __, __, __, __, __, __, __, __, __, __, __,
			__, __, __, __, __, __, __, __, __, __, __, __, __, __, __, __, __,
			__, __, __, __, __, __, __, __, __, __, __, __, __, __, __, __, __,
			__, __, __, __, __, __, __, __, __, __, __, __, __, __, __, __, __,
			__, __, __, __, __, __, __, __, __, __, __, __, __, __, __, __, __,
			__, __, __, __, __, __, __, __, __, __, __, __, __, __, __, __, __,
			__, __, __, __, __, __, __, __, __, __, __, __, __, __, __, __, __, __, __, L0, __, L0, L0, L0, L0, L0, L0, L0, L0, __, __, L0, __, __, __, __, __, __, __, L0, L0, L0, L0, L0, L0, __, __, __, __, __, __, __, __, __, __, __, __, __, __, __, __, __, __, __, __, __, __, __, __, __, __, __, __, __, __, __, __, __, __, __, __, __, __, __, __, __, __, __, __, __, __, __, __, __, __, __, __, __, __, __, __, __, __, __, __, __, __, __, __, __, __, __, __, __, __, __, __, __, __, __, __, __, __, __, __, __, __, __, __, __, __, __, __, __, __, __, __, __, __, __, __, __, __, __, __, __, __, __, __, __, __, __, __, __, __, __, __, __, __, __, __, __, __, __, __, __, __, __, __, __, __, __, __, __, __, __, __, __, __, __, __, __, __, __, __, __, __, __, __, __, __, __, __, __, __, __, __, __, __, __, __, __, __, __, __, __, __, __, __, __, __, __, __, __, __, __, __, __, __, __, __, __, __, __, __, L0, __, __, L0, L0, __, __, __, __, __, __, __, __, __, __, __, __, L0, __, __, L0, __, __, __, __, __, __, __, __, __, __, __, __, __, __, __, __, __, __, __, __, __, __, __, __, __, __, __, __, __, __, __, __, __, __, __, __, __, __, __, __, __, __, __, __, __, __, __, __, __, __, __, __, __, __, __, __, __, __, __, __, __, __, __, __, __, __, __, __, __, __, __, __, __, __, __, __, __, __, __, __, __, __, __, __, __, __, __, __, __, __, __, __, __, __, __, __, __, __, __, __, __, __, __, __, __, __, __, __, __, __, __, __, __, __, __, __, __, __, __, __, __, __, __, __, __, __, __, __, __, __, __, __, __, __, __, __, __, __, __, __, __, __, __, __, __, __, __, __, __, __, __, __, __, __, __, __, __, __, __, __, __, __, __, __, __, __, __, __, __, __, __, __, __, __, __, __, __, __, __, __, __, __, __, __, __, L0, __, __, __, __, __, __, __, __, __, __, __, __, __, __, __, __, __, __, __, __, __, __, __, __, __, __, __
		},
		yslice_prob = {
			{ypos = 0,prob = 254},
			{ypos = 1,prob = 254},
			{ypos = 2,prob = 254},
			{ypos = 3,prob = 254},
			{ypos = 4,prob = 254},
			{ypos = 5,prob = 254},
			{ypos = 6,prob = 254},
			{ypos = 7,prob = 254},
			{ypos = 8,prob = 254},
			{ypos = 9,prob = 254},
			{ypos = 10,prob = 254},
			{ypos = 11,prob = 254}
		}
	}
	lib_ecology.schem_tree_acacia_05 = {
		size = {
			y = 12,
			x = 17,
			z = 17
		},
		data = {
